Workbook

Sheet TERadj
A1: record_id | B1: company | C1: region | D1: country | E1: region2 | F1: date | G1: regionalstrategyasiapacific_vehicletype_total | H1: regionalstrategyeurope_vehicletype_total | I1: regionalstrategynorthamerica_vehicletype_total | J1: regionalstrategyglobal_vehicletype_total | K1: regionalstrategysouthamerica_vehicletype_total | L1: regionalstrategyafrica_vehicletype_total | M1: nonlistedrealestate | N1: regionalstrategy_nonlistedfunds_total | O1: regionalstrategy_separateaccountsdirect_total | P1: regionalstrategy_separateaccountsindirect_total | Q1: regionalstrategy_jvs_total | R1: regionalstrategy_fundsoffunds_total | S1: regionalstrategy_debt_total | T1: investordomicileasiapacific_nonlistedfunds | U1: investordomicileeurope_nonlistedfunds | V1: investordomicilenorthamerica_nonlistedfunds | W1: investordomicilesouthamerica_nonlistedfunds | X1: investordomicileafrica_nonlistedfunds | Y1: investordomicileasiapacific_separateaccountsdirect | Z1: investordomicileeurope_separateaccountsdirect | AA1: investordomicilenorthamerica_separateaccountsdirect | AB1: investordomicilesouthamerica_separateaccountsdirect | AC1: investordomicileafrica_separateaccountsdirect | AD1: investordomicileasiapacific_separateaccountsindirect | AE1: investordomicileeurope_separateaccountsindirect | AF1: investordomicilenorthamerica_separateaccountsindirect | AG1: investordomicilesouthamerica_separateaccountsindirect | AH1: investordomicileafrica_separateaccountsindirect | AI1: investordomicileasiapacific_jvs | AJ1: investordomicileeurope_jvs | AK1: investordomicilenorthamerica_jvs | AL1: investordomicilesouthamerica_jvs | AM1: investordomicileafrica_jvs | AN1: investordomicileasiapacific_fundsoffunds | AO1: investordomicileeurope_fundsoffunds | AP1: investordomicilenorthamerica_fundsoffunds | AQ1: investordomicilesouthamerica_fundsoffunds | AR1: investordomicileafrica_fundsoffunds | AS1: investordomicileasiapacific_debt | AT1: investordomicileeurope_debt | AU1: investordomicilenorthamerica_debt | AV1: investordomicilesouthamerica_debt | AW1: investordomicileafrica_debt | AX1: capitalraisingactivity_nonlistedrealestatevehicles | AY1: nocapitalraisingactivity_reason | AZ1: percentmethod_placementagent | BA1: percentmethod_investorscontactingdirectly | BB1: percentmethod_relationshipwithinvestors | BC1: percentmethod_other | BD1: capitalraisingactivity_development | BE1: capitalraisingactivity_impactregulation | BF1: capitalinvested_nonlistedrealestate | BG1: nov_regionalstrategyasiapacific_vehicletype_total | BH1: nov_regionalstrategyeurope_vehicletype_total | BI1: nov_regionalstrategynorthamerica_vehicletype_total | BJ1: nov_regionalstrategyglobal_vehicletype_total | BK1: nov_regionalstrategysouthamerica_vehicletype_total | BL1: nov_regionalstrategyafrica_vehicletype_total | BM1: nov_regionalstrategy_vehicletype_total | BN1: regionalstrategy_vehicletype_total | BO1: nov_regionalstrategy_nonlistedfunds_total | BP1: nov_regionalstrategy_separateaccountsdirect_total | BQ1: nov_regionalstrategy_separateaccountsindirect_total | BR1: nov_regionalstrategy_jvs_total | BS1: nov_regionalstrategy_fundsoffunds_total | BT1: nov_regionalstrategy_debt_total | BU1: regionalstrategyasiapacific_nonlistedfunds | BV1: regionalstrategyeurope_nonlistedfunds | BW1: regionalstrategynorthamerica_nonlistedfunds | BX1: regionalstrategyglobal_nonlistedfunds | BY1: regionalstrategysouthamerica_nonlistedfunds | BZ1: regionalstrategyafrica_nonlistedfunds | CA1: regionalstrategyasiapacific_separateaccountsdirect | CB1: regionalstrategyeurope_separateaccountsdirect | CC1: regionalstrategynorthamerica_separateaccountsdirect | CD1: regionalstrategyglobal_separateaccountsdirect | CE1: regionalstrategysouthamerica_separateaccountsdirect | CF1: regionalstrategyafrica_separateaccountsdirect | CG1: regionalstrategyasiapacific_separateaccountsindirect | CH1: regionalstrategyeurope_separateaccountsindirect | CI1: regionalstrategynorthamerica_separateaccountsindirect | CJ1: regionalstrategyglobal_separateaccountsindirect | CK1: regionalstrategysouthamerica_separateaccountsindirect | CL1: regionalstrategyafrica_separateaccountsindirect | CM1: regionalstrategyasiapacific_jvs | CN1: regionalstrategyeurope_jvs | CO1: regionalstrategynorthamerica_jvs | CP1: regionalstrategyglobal_jvs | CQ1: regionalstrategysouthamerica_jvs | CR1: regionalstrategyafrica_jvs | CS1: regionalstrategyasiapacific_fundsoffunds | CT1: regionalstrategyeurope_fundsoffunds | CU1: regionalstrategynorthamerica_fundsoffunds | CV1: regionalstrategyglobal_fundsoffunds | CW1: regionalstrategysouthamerica_fundsoffunds | CX1: regionalstrategyafrica_fundsoffunds | CY1: regionalstrategyasiapacific_debt | CZ1: regionalstrategyeurope_debt | DA1: regionalstrategynorthamerica_debt | DB1: regionalstrategyglobal_debt | DC1: regionalstrategysouthamerica_debt | DD1: regionalstrategyafrica_debt | DE1: regionalstrategyasiapacific_operatingplatforms | DF1: regionalstrategyeurope_operatingplatforms | DG1: regionalstrategynorthamerica_operatingplatforms | DH1: regionalstrategyglobal_operatingplatforms | DI1: regionalstrategysouthamerica_operatingplatforms | DJ1: regionalstrategyafrica_operatingplatforms | DK1: nov_regionalstrategyasiapacific_nonlistedfunds | DL1: nov_regionalstrategyeurope_nonlistedfunds | DM1: nov_regionalstrategynorthamerica_nonlistedfunds | DN1: nov_regionalstrategyglobal_nonlistedfunds | DO1: nov_regionalstrategysouthamerica_nonlistedfunds | DP1: nov_regionalstrategyafrica_nonlistedfunds | DQ1: nov_regionalstrategyasiapacific_separateaccountsdirect | DR1: nov_regionalstrategyeurope_separateaccountsdirect | DS1: nov_regionalstrategynorthamerica_separateaccountsdirect | DT1: nov_regionalstrategyglobal_separateaccountsdirect | DU1: nov_regionalstrategysouthamerica_separateaccountsdirect | DV1: nov_regionalstrategyafrica_separateaccountsdirect | DW1: nov_regionalstrategyasiapacific_separateaccountsindirect | DX1: nov_regionalstrategyeurope_separateaccountsindirect | DY1: nov_regionalstrategynorthamerica_separateaccountsindirect | DZ1: nov_regionalstrategyglobal_separateaccountsindirect | EA1: nov_regionalstrategysouthamerica_separateaccountsindirect | EB1: nov_regionalstrategyafrica_separateaccountsindirect | EC1: nov_regionalstrategyasiapacific_jvs | ED1: nov_regionalstrategyeurope_jvs | EE1: nov_regionalstrategynorthamerica_jvs | EF1: nov_regionalstrategyglobal_jvs | EG1: nov_regionalstrategysouthamerica_jvs | EH1: nov_regionalstrategyafrica_jvs | EI1: nov_regionalstrategyasiapacific_fundsoffunds | EJ1: nov_regionalstrategyeurope_fundsoffunds | EK1: nov_regionalstrategynorthamerica_fundsoffunds | EL1: nov_regionalstrategyglobal_fundsoffunds | EM1: nov_regionalstrategysouthamerica_fundsoffunds | EN1: nov_regionalstrategyafrica_fundsoffunds | EO1: nov_regionalstrategyasiapacific_debt | EP1: nov_regionalstrategyeurope_debt | EQ1: nov_regionalstrategynorthamerica_debt | ER1: nov_regionalstrategyglobal_debt | ES1: nov_regionalstrategysouthamerica_debt | ET1: nov_regionalstrategyafrica_debt | EU1: pensionfunds_vehicletype_total | EV1: insurancecompanies_vehicletype_total | EW1: sovereignwealthfunds_vehicletype_total | EX1: governmentinstitutions_vehicletype_total | EY1: charitiesfoundationsnonprofitorganizations_vehicletype_total | EZ1: fundsoffunds_vehicletype_total | FA1: highnetworthindividualsfamilyoffices_vehicletype_total | FB1: otherinvestortype_vehicletype_total | FC1: pensionfunds_nonlistedfunds | FD1: insurancecompanies_nonlistedfunds | FE1: sovereignwealthfunds_nonlistedfunds | FF1: governmentinstitutions_nonlistedfunds | FG1: charitiesfoundationsnonprofitorganizations_nonlistedfunds | FH1: fundsoffunds_nonlistedfunds | FI1: highnetworthindividualsfamilyoffices_nonlistedfunds | FJ1: otherinvestortype_nonlistedfunds | FK1: pensionfunds_separateaccountsdirect | FL1: insurancecompanies_separateaccountsdirect | FM1: sovereignwealthfunds_separateaccountsdirect | FN1: governmentinstitutions_separateaccountsdirect | FO1: charitiesfoundationsnonprofitorganizations_separateaccountsdirect | FP1: fundsoffunds_separateaccountsdirect | FQ1: highnetworthindividualsfamilyoffices_separateaccountsdirect | FR1: otherinvestortype_separateaccountsdirect | FS1: pensionfunds_separateaccountsindirect | FT1: insurancecompanies_separateaccountsindirect | FU1: sovereignwealthfunds_separateaccountsindirect | FV1: governmentinstitutions_separateaccountsindirect | FW1: charitiesfoundationsnonprofitorganizations_separateaccountsindirect | FX1: fundsoffunds_separateaccountsindirect | FY1: highnetworthindividualsfamilyoffices_separateaccountsindirect | FZ1: otherinvestortype_separateaccountsindirect | GA1: pensionfunds_jvs | GB1: insurancecompanies_jvs | GC1: sovereignwealthfunds_jvs | GD1: governmentinstitutions_jvs | GE1: charitiesfoundationsnonprofitorganizations_jvs | GF1: fundsoffunds_jvs | GG1: highnetworthindividualsfamilyoffices_jvs | GH1: otherinvestortype_jvs | GI1: pensionfunds_fundsoffunds | GJ1: insurancecompanies_fundsoffunds | GK1: sovereignwealthfunds_fundsoffunds | GL1: governmentinstitutions_fundsoffunds | GM1: charitiesfoundationsnonprofitorganizations_fundsoffunds | GN1: fundsoffunds_fundsoffunds | GO1: highnetworthindividualsfamilyoffices_fundsoffunds | GP1: otherinvestortype_fundsoffunds | GQ1: pensionfunds_debt | GR1: insurancecompanies_debt | GS1: sovereignwealthfunds_debt | GT1: governmentinstitutions_debt | GU1: charitiesfoundationsnonprofitorganizations_debt | GV1: fundsoffunds_debt | GW1: highnetworthindividualsfamilyoffices_debt | GX1: otherinvestortype_debt | GY1: investordomicileasiapacific_vehicletype_total | GZ1: investordomicileeurope_vehicletype_total | HA1: investordomicilenorthamerica_vehicletype_total | HB1: investordomicilesouthamerica_vehicletype_total | HC1: investordomicileafrica_vehicletype_total | HD1: global_pensionfunds_vehicletype_total | HE1: global_insurancecompanies_vehicletype_total | HF1: global_sovereignwealthfunds_vehicletype_total | HG1: global_governmentinstitutions_vehicletype_total | HH1: global_charitiesfoundationsnonprofitorganizations_vehicletype_total | HI1: global_fundsoffunds_vehicletype_total | HJ1: global_highnetworthindividualsfamilyoffices_vehicletype_total | HK1: global_otherinvestortype_vehicletype_total | HL1: global_investortype_nonlistedfunds_total | HM1: global_investortype_separateaccountsdirect_total | HN1: global_investortype_separateaccountsindirect_total | HO1: global_investortype_jvs_total | HP1: global_investortype_fundsoffunds_total | HQ1: global_investortype_debt_total | HR1: global_investortype_operatingplatforms_total | HS1: global_investordomicileasiapacific_vehicletype_total | HT1: global_investordomicileeurope_vehicletype_total | HU1: global_investordomicilenorthamerica_vehicletype_total | HV1: global_investordomicilesouthamerica_vehicletype_total | HW1: global_investordomicileafrica_vehicletype_total | HX1: global_nonlistedfunds_singlesectoroffice | HY1: global_nonlistedfunds_singlesectorretail | HZ1: global_nonlistedfunds_singlesectorindustrial_logistics | IA1: global_nonlistedfunds_singlesectorresidential_multifamily_apartments | IB1: global_nonlistedfunds_singlesectorstudenthousing | IC1: global_nonlistedfunds_singlesectorseniorliving_agedcare_healthcare | ID1: global_nonlistedfunds_singlesectorhotel_leisure | IE1: global_nonlistedfunds_singlesectorother | IF1: global_nonlistedfunds_multisectormainsectors | IG1: global_nonlistedfunds_multisectoralternativesectors | IH1: global_nonlistedfunds_multisectormixmainalternativesectors | II1: global_separateaccountsdirect_singlesectoroffice | IJ1: global_separateaccountsdirect_singlesectorretail | IK1: global_separateaccountsdirect_singlesectorindustrial_logistics | IL1: global_separateaccountsdirect_singlesectorresidential_multifamily_apartments | IM1: global_separateaccountsdirect_singlesectorstudenthousing | IN1: global_separateaccountsdirect_singlesectorseniorliving_agedcare_healthcare | IO1: global_separateaccountsdirect_singlesectorhotel_leisure | IP1: global_separateaccountsdirect_singlesectorother | IQ1: global_separateaccountsdirect_multisectormainsectors | IR1: global_separateaccountsdirect_multisectoralternativesectors | IS1: global_separateaccountsdirect_multisectormixmainalternativesectors | IT1: global_separateaccountsindirect_singlesectoroffice | IU1: global_separateaccountsindirect_singlesectorretail | IV1: global_separateaccountsindirect_singlesectorindustrial_logistics | IW1: global_separateaccountsindirect_singlesectorresidential_multifamily_apartments | IX1: global_separateaccountsindirect_singlesectorstudenthousing | IY1: global_separateaccountsindirect_singlesectorseniorliving_agedcare_healthcare | IZ1: global_separateaccountsindirect_singlesectorhotel_leisure | JA1: global_separateaccountsindirect_singlesectorother | JB1: global_separateaccountsindirect_multisectormainsectors | JC1: global_separateaccountsindirect_multisectoralternativesectors | JD1: global_separateaccountsindirect_multisectormixmainalternativesectors | JE1: global_jvs_singlesectoroffice | JF1: global_jvs_singlesectorretail | JG1: global_jvs_singlesectorindustrial_logistics | JH1: global_jvs_singlesectorresidential_multifamily_apartments | JI1: global_jvs_singlesectorstudenthousing | JJ1: global_jvs_singlesectorseniorliving_agedcare_healthcare | JK1: global_jvs_singlesectorhotel_leisure | JL1: global_jvs_singlesectorother | JM1: global_jvs_multisectormainsectors | JN1: global_jvs_multisectoralternativesectors | JO1: global_jvs_multisectormixmainalternativesectors | JP1: global_fundsoffunds_singlesectoroffice | JQ1: global_fundsoffunds_singlesectorretail | JR1: global_fundsoffunds_singlesectorindustrial_logistics | JS1: global_fundsoffunds_singlesectorresidential_multifamily_apartments | JT1: global_fundsoffunds_singlesectorstudenthousing | JU1: global_fundsoffunds_singlesectorseniorliving_agedcare_healthcare | JV1: global_fundsoffunds_singlesectorhotel_leisure | JW1: global_fundsoffunds_singlesectorother | JX1: global_fundsoffunds_multisectormainsectors | JY1: global_fundsoffunds_multisectoralternativesectors | JZ1: global_fundsoffunds_multisectormixmainalternativesectors | KA1: global_debt_singlesectoroffice | KB1: global_debt_singlesectorretail | KC1: global_debt_singlesectorindustrial_logistics | KD1: global_debt_singlesectorresidential_multifamily_apartments | KE1: global_debt_singlesectorstudenthousing | KF1: global_debt_singlesectorseniorliving_agedcare_healthcare | KG1: global_debt_singlesectorhotel_leisure | KH1: global_debt_singlesectorother | KI1: global_debt_multisectormainsectors | KJ1: global_debt_multisectoralternativesectors | KK1: global_debt_multisectormixmainalternativesectors | KL1: global_investordomicileasiapacific_nonlistedfunds | KM1: global_investordomicileeurope_nonlistedfunds | KN1: global_investordomicilenorthamerica_nonlistedfunds | KO1: global_investordomicilesouthamerica_nonlistedfunds | KP1: global_investordomicileafrica_nonlistedfunds | KQ1: global_investordomicileasiapacific_separateaccountsdirect | KR1: global_investordomicileeurope_separateaccountsdirect | KS1: global_investordomicilenorthamerica_separateaccountsdirect | KT1: global_investordomicilesouthamerica_separateaccountsdirect | KU1: global_investordomicileafrica_separateaccountsdirect | KV1: global_investordomicileasiapacific_separateaccountsindirect | KW1: global_investordomicileeurope_separateaccountsindirect | KX1: global_investordomicilenorthamerica_separateaccountsindirect | KY1: global_investordomicilesouthamerica_separateaccountsindirect | KZ1: global_investordomicileafrica_separateaccountsindirect | LA1: global_investordomicileasiapacific_jvs | LB1: global_investordomicileeurope_jvs | LC1: global_investordomicilenorthamerica_jvs | LD1: global_investordomicilesouthamerica_jvs | LE1: global_investordomicileafrica_jvs | LF1: global_investordomicileasiapacific_fundsoffunds | LG1: global_investordomicileeurope_fundsoffunds | LH1: global_investordomicilenorthamerica_fundsoffunds | LI1: global_investordomicilesouthamerica_fundsoffunds | LJ1: global_investordomicileafrica_fundsoffunds | LK1: global_investordomicileasiapacific_debt | LL1: global_investordomicileeurope_debt | LM1: global_investordomicilenorthamerica_debt | LN1: global_investordomicilesouthamerica_debt | LO1: global_investordomicileafrica_debt | LP1: global_nonlistedfunds_singlecountry | LQ1: global_nonlistedfunds_multicountry | LR1: global_countrystrategy_nonlistedfunds_total | LS1: global_separateaccountsdirect_singlecountry | LT1: global_separateaccountsdirect_multicountry | LU1: global_countrystrategy_separateaccountsdirect_total | LV1: global_separateaccountsindirect_singlecountry | LW1: global_separateaccountsindirect_multicountry | LX1: global_countrystrategy_separateaccountsindirect_total | LY1: global_jvs_singlecountry | LZ1: global_jvs_multicountry | MA1: global_countrystrategy_jvs_total | MB1: global_fundsoffunds_singlecountry | MC1: global_fundsoffunds_multicountry | MD1: global_countrystrategy_fundsoffunds_total | ME1: global_debt_singlecountry | MF1: global_debt_multicountry | MG1: global_countrystrategy_debt_total | MH1: global_countrystrategy_operatingplatforms_total | MI1: global_nonlistedfunds_core_seniordebt | MJ1: global_separateaccountsdirect_core_seniordebt | MK1: global_separateaccountsindirect_core_seniordebt | ML1: global_jvs_core_seniordebt | MM1: global_fundsoffunds_core_seniordebt | MN1: global_debt_core_seniordebt | MO1: global_nonlistedvehicles_core_seniordebt_total | MP1: global_nonlistedfunds_valueadded_juniorandsubordinateddebt | MQ1: global_separateaccountsdirect_valueadded_juniorandsubordinateddebt | MR1: global_separateaccountsindirect_valueadded_juniorandsubordinateddebt | MS1: global_jvs_valueadded_juniorandsubordinateddebt | MT1: global_fundsoffunds_valueadded_juniorandsubordinateddebt | MU1: global_debt_valueadded_juniorandsubordinateddebt | MV1: global_nonlistedvehicles_valueadded_juniorandsubordinateddebt_total | MW1: global_nonlistedfunds_opportunistic_mezzaninedebt | MX1: global_separateaccountsdirect_opportunistic_mezzaninedebt | MY1: global_separateaccountsindirect_opportunistic_mezzaninedebt | MZ1: global_jvs_opportunistic_mezzaninedebt | NA1: global_fundsoffunds_opportunistic_mezzaninedebt | NB1: global_debt_opportunistic_mezzaninedebt | NC1: global_nonlistedvehicles_opportunistic_mezzaninedebt_total | ND1: global_nonlistedfunds_mixedstrategies | NE1: global_separateaccountsdirect_mixedstrategies | NF1: global_separateaccountsindirect_mixedstrategies | NG1: global_jvs_mixedstrategies | NH1: global_fundsoffunds_mixedstrategies | NI1: global_debt_mixedstrategies | NJ1: global_nonlistedvehicles_mixedstrategies_total | NK1: europe_pensionfunds_vehicletype_total | NL1: europe_insurancecompanies_vehicletype_total | NM1: europe_sovereignwealthfunds_vehicletype_total | NN1: europe_governmentinstitutions_vehicletype_total | NO1: europe_charitiesfoundationsnonprofitorganizations_vehicletype_total | NP1: europe_fundsoffunds_vehicletype_total | NQ1: europe_highnetworthindividualsfamilyoffices_vehicletype_total | NR1: europe_otherinvestortype_vehicletype_total | NS1: europe_investortype_nonlistedfunds_total | NT1: europe_investortype_separateaccountsdirect_total | NU1: europe_investortype_separateaccountsindirect_total | NV1: europe_investortype_jvs_total | NW1: europe_investortype_fundsoffunds_total | NX1: europe_investortype_debt_total | NY1: europe_investortype_operatingplatforms_total | NZ1: europe_nonlistedfunds_singlecountry | OA1: europe_nonlistedfunds_multicountry | OB1: europe_countrystrategy_nonlistedfunds_total | OC1: europe_separateaccountsdirect_singlecountry | OD1: europe_separateaccountsdirect_multicountry | OE1: europe_countrystrategy_separateaccountsdirect_total | OF1: europe_separateaccountsindirect_singlecountry | OG1: europe_separateaccountsindirect_multicountry | OH1: europe_countrystrategy_separateaccountsindirect_total | OI1: europe_jvs_singlecountry | OJ1: europe_jvs_multicountry | OK1: europe_countrystrategy_jvs_total | OL1: europe_fundsoffunds_singlecountry | OM1: europe_fundsoffunds_multicountry | ON1: europe_countrystrategy_fundsoffunds_total | OO1: europe_debt_singlecountry | OP1: europe_debt_multicountry | OQ1: europe_countrystrategy_debt_total | OR1: europe_countrystrategy_operatingplatforms_total | OS1: europe_investordomicileasiapacific_vehicletype_total | OT1: europe_investordomicileeurope_vehicletype_total | OU1: europe_investordomicilenorthamerica_vehicletype_total | OV1: europe_investordomicilesouthamerica_vehicletype_total | OW1: europe_investordomicileafrica_vehicletype_total | OX1: europe_pensionfunds_nonlistedfunds | OY1: europe_pensionfunds_separateaccountsdirect | OZ1: europe_pensionfunds_separateaccountsindirect | PA1: europe_pensionfunds_jvs | PB1: europe_pensionfunds_fundsoffunds | PC1: europe_pensionfunds_debt | PD1: europe_insurancecompanies_nonlistedfunds | PE1: europe_insurancecompanies_separateaccountsdirect | PF1: europe_insurancecompanies_separateaccountsindirect | PG1: europe_insurancecompanies_jvs | PH1: europe_insurancecompanies_fundsoffunds | PI1: europe_insurancecompanies_debt | PJ1: europe_sovereignwealthfunds_nonlistedfunds | PK1: europe_sovereignwealthfunds_separateaccountsdirect | PL1: europe_sovereignwealthfunds_separateaccountsindirect | PM1: europe_sovereignwealthfunds_jvs | PN1: europe_sovereignwealthfunds_fundsoffunds | PO1: europe_sovereignwealthfunds_debt | PP1: europe_governmentinstitutions_nonlistedfunds | PQ1: europe_governmentinstitutions_separateaccountsdirect | PR1: europe_governmentinstitutions_separateaccountsindirect | PS1: europe_governmentinstitutions_jvs | PT1: europe_governmentinstitutions_fundsoffunds | PU1: europe_governmentinstitutions_debt | PV1: europe_charitiesfoundationsnonprofitorganizations_nonlistedfunds | PW1: europe_charitiesfoundationsnonprofitorganizations_separateaccountsdirect | PX1: europe_charitiesfoundationsnonprofitorganizations_separateaccountsindirect | PY1: europe_charitiesfoundationsnonprofitorganizations_jvs | PZ1: europe_charitiesfoundationsnonprofitorganizations_fundsoffunds | QA1: europe_charitiesfoundationsnonprofitorganizations_debt | QB1: europe_fundsoffunds_nonlistedfunds | QC1: europe_fundsoffunds_separateaccountsdirect | QD1: europe_fundsoffunds_separateaccountsindirect | QE1: europe_fundsoffunds_jvs | QF1: europe_fundsoffunds_fundsoffunds | QG1: europe_fundsoffunds_debt | QH1: europe_highnetworthindividualsfamilyoffices_nonlistedfunds | QI1: europe_highnetworthindividualsfamilyoffices_separateaccountsdirect | QJ1: europe_highnetworthindividualsfamilyoffices_separateaccountsindirect | QK1: europe_highnetworthindividualsfamilyoffices_jvs | QL1: europe_highnetworthindividualsfamilyoffices_fundsoffunds | QM1: europe_highnetworthindividualsfamilyoffices_debt | QN1: europe_otherinvestortype_nonlistedfunds | QO1: europe_otherinvestortype_separateaccountsdirect | QP1: europe_otherinvestortype_separateaccountsindirect | QQ1: europe_otherinvestortype_jvs | QR1: europe_otherinvestortype_fundsoffunds | QS1: europe_otherinvestortype_debt | QT1: europe_nonlistedfunds_singlesectoroffice | QU1: europe_nonlistedfunds_singlesectorretail | QV1: europe_nonlistedfunds_singlesectorindustrial_logistics | QW1: europe_nonlistedfunds_singlesectorresidential_multifamily_apartments | QX1: europe_nonlistedfunds_singlesectorstudenthousing | QY1: europe_nonlistedfunds_singlesectorseniorliving_agedcare_healthcare | QZ1: europe_nonlistedfunds_singlesectorhotel_leisure | RA1: europe_nonlistedfunds_singlesectorother | RB1: europe_nonlistedfunds_multisectormainsectors | RC1: europe_nonlistedfunds_multisectoralternativesectors | RD1: europe_nonlistedfunds_multisectormixmainalternativesectors | RE1: europe_separateaccountsdirect_singlesectoroffice | RF1: europe_separateaccountsdirect_singlesectorretail | RG1: europe_separateaccountsdirect_singlesectorindustrial_logistics | RH1: europe_separateaccountsdirect_singlesectorresidential_multifamily_apartments | RI1: europe_separateaccountsdirect_singlesectorstudenthousing | RJ1: europe_separateaccountsdirect_singlesectorseniorliving_agedcare_healthcare | RK1: europe_separateaccountsdirect_singlesectorhotel_leisure | RL1: europe_separateaccountsdirect_singlesectorother | RM1: europe_separateaccountsdirect_multisectormainsectors | RN1: europe_separateaccountsdirect_multisectoralternativesectors | RO1: europe_separateaccountsdirect_multisectormixmainalternativesectors | RP1: europe_separateaccountsindirect_singlesectoroffice | RQ1: europe_separateaccountsindirect_singlesectorretail | RR1: europe_separateaccountsindirect_singlesectorindustrial_logistics | RS1: europe_separateaccountsindirect_singlesectorresidential_multifamily_apartments | RT1: europe_separateaccountsindirect_singlesectorstudenthousing | RU1: europe_separateaccountsindirect_singlesectorseniorliving_agedcare_healthcare | RV1: europe_separateaccountsindirect_singlesectorhotel_leisure | RW1: europe_separateaccountsindirect_singlesectorother | RX1: europe_separateaccountsindirect_multisectormainsectors | RY1: europe_separateaccountsindirect_multisectoralternativesectors | RZ1: europe_separateaccountsindirect_multisectormixmainalternativesectors | SA1: europe_jvs_singlesectoroffice | SB1: europe_jvs_singlesectorretail | SC1: europe_jvs_singlesectorindustrial_logistics | SD1: europe_jvs_singlesectorresidential_multifamily_apartments | SE1: europe_jvs_singlesectorstudenthousing | SF1: europe_jvs_singlesectorseniorliving_agedcare_healthcare | SG1: europe_jvs_singlesectorhotel_leisure | SH1: europe_jvs_singlesectorother | SI1: europe_jvs_multisectormainsectors | SJ1: europe_jvs_multisectoralternativesectors | SK1: europe_jvs_multisectormixmainalternativesectors | SL1: europe_fundsoffunds_singlesectoroffice | SM1: europe_fundsoffunds_singlesectorretail | SN1: europe_fundsoffunds_singlesectorindustrial_logistics | SO1: europe_fundsoffunds_singlesectorresidential_multifamily_apartments | SP1: europe_fundsoffunds_singlesectorstudenthousing | SQ1: europe_fundsoffunds_singlesectorseniorliving_agedcare_healthcare | SR1: europe_fundsoffunds_singlesectorhotel_leisure | SS1: europe_fundsoffunds_singlesectorother | ST1: europe_fundsoffunds_multisectormainsectors | SU1: europe_fundsoffunds_multisectoralternativesectors | SV1: europe_fundsoffunds_multisectormixmainalternativesectors | SW1: europe_debt_singlesectoroffice | SX1: europe_debt_singlesectorretail | SY1: europe_debt_singlesectorindustrial_logistics | SZ1: europe_debt_singlesectorresidential_multifamily_apartments | TA1: europe_debt_singlesectorstudenthousing | TB1: europe_debt_singlesectorseniorliving_agedcare_healthcare | TC1: europe_debt_singlesectorhotel_leisure | TD1: europe_debt_singlesectorother | TE1: europe_debt_multisectormainsectors | TF1: europe_debt_multisectoralternativesectors | TG1: europe_debt_multisectormixmainalternativesectors | TH1: europe_nonlistedvehicles_singlesectoroffice_total | TI1: europe_nonlistedvehicles_singlesectorretail_total | TJ1: europe_nonlistedvehicles_singlesectorindustrial_logistics_total | TK1: europe_nonlistedvehicles_singlesectorresidential_multifamily_apartments_total | TL1: europe_nonlistedvehicles_singlesectorstudenthousing_total | TM1: europe_nonlistedvehicles_singlesectorseniorliving_agedcare_healthcare_total | TN1: europe_nonlistedvehicles_singlesectorhotel_leisure_total | TO1: europe_nonlistedvehicles_singlesectorother_total | TP1: europe_nonlistedvehicles_multisectormainsectors_total | TQ1: europe_nonlistedvehicles_multisectoralternativesectors_total | TR1: europe_nonlistedvehicles_multisectormixmainalternativesectors_total | TS1: europe_investordomicileasiapacific_nonlistedfunds | TT1: europe_investordomicileeurope_nonlistedfunds | TU1: europe_investordomicilenorthamerica_nonlistedfunds | TV1: europe_investordomicilesouthamerica_nonlistedfunds | TW1: europe_investordomicileafrica_nonlistedfunds | TX1: europe_investordomicileasiapacific_separateaccountsdirect | TY1: europe_investordomicileeurope_separateaccountsdirect | TZ1: europe_investordomicilenorthamerica_separateaccountsdirect | UA1: europe_investordomicilesouthamerica_separateaccountsdirect | UB1: europe_investordomicileafrica_separateaccountsdirect | UC1: europe_investordomicileasiapacific_separateaccountsindirect | UD1: europe_investordomicileeurope_separateaccountsindirect | UE1: europe_investordomicilenorthamerica_separateaccountsindirect | UF1: europe_investordomicilesouthamerica_separateaccountsindirect | UG1: europe_investordomicileafrica_separateaccountsindirect | UH1: europe_investordomicileasiapacific_jvs | UI1: europe_investordomicileeurope_jvs | UJ1: europe_investordomicilenorthamerica_jvs | UK1: europe_investordomicilesouthamerica_jvs | UL1: europe_investordomicileafrica_jvs | UM1: europe_investordomicileasiapacific_fundsoffunds | UN1: europe_investordomicileeurope_fundsoffunds | UO1: europe_investordomicilenorthamerica_fundsoffunds | UP1: europe_investordomicilesouthamerica_fundsoffunds | UQ1: europe_investordomicileafrica_fundsoffunds | UR1: europe_investordomicileasiapacific_debt | US1: europe_investordomicileeurope_debt | UT1: europe_investordomicilenorthamerica_debt | UU1: europe_investordomicilesouthamerica_debt | UV1: europe_investordomicileafrica_debt | UW1: europe_nonlistedfunds_core_seniordebt | UX1: europe_separateaccountsdirect_core_seniordebt | UY1: europe_separateaccountsindirect_core_seniordebt | UZ1: europe_jvs_core_seniordebt | VA1: europe_fundsoffunds_core_seniordebt | VB1: europe_debt_core_seniordebt | VC1: europe_nonlistedfunds_valueadded_juniorandsubordinateddebt | VD1: europe_separateaccountsdirect_valueadded_juniorandsubordinateddebt | VE1: europe_separateaccountsindirect_valueadded_juniorandsubordinateddebt | VF1: europe_jvs_valueadded_juniorandsubordinateddebt | VG1: europe_fundsoffunds_valueadded_juniorandsubordinateddebt | VH1: europe_debt_valueadded_juniorandsubordinateddebt | VI1: europe_nonlistedfunds_opportunistic_mezzaninedebt | VJ1: europe_separateaccountsdirect_opportunistic_mezzaninedebt | VK1: europe_separateaccountsindirect_opportunistic_mezzaninedebt | VL1: europe_jvs_opportunistic_mezzaninedebt | VM1: europe_fundsoffunds_opportunistic_mezzaninedebt | VN1: europe_debt_opportunistic_mezzaninedebt | VO1: europe_nonlistedfunds_mixedstrategies | VP1: europe_separateaccountsdirect_mixedstrategies | VQ1: europe_separateaccountsindirect_mixedstrategies | VR1: europe_jvs_mixedstrategies | VS1: europe_fundsoffunds_mixedstrategies | VT1: europe_debt_mixedstrategies | VU1: global_pensionfunds_nonlistedfunds | VV1: global_insurancecompanies_nonlistedfunds | VW1: global_sovereignwealthfunds_nonlistedfunds | VX1: global_governmentinstitutions_nonlistedfunds | VY1: global_charitiesfoundationsnonprofitorganizations_nonlistedfunds | VZ1: global_fundsoffunds_nonlistedfunds | WA1: global_highnetworthindividualsfamilyoffices_nonlistedfunds | WB1: global_otherinvestortype_nonlistedfunds | WC1: global_pensionfunds_separateaccountsdirect | WD1: global_insurancecompanies_separateaccountsdirect | WE1: global_sovereignwealthfunds_separateaccountsdirect | WF1: global_governmentinstitutions_separateaccountsdirect | WG1: global_charitiesfoundationsnonprofitorganizations_separateaccountsdirect | WH1: global_fundsoffunds_separateaccountsdirect | WI1: global_highnetworthindividualsfamilyoffices_separateaccountsdirect | WJ1: global_otherinvestortype_separateaccountsdirect | WK1: global_pensionfunds_separateaccountsindirect | WL1: global_insurancecompanies_separateaccountsindirect | WM1: global_sovereignwealthfunds_separateaccountsindirect | WN1: global_governmentinstitutions_separateaccountsindirect | WO1: global_charitiesfoundationsnonprofitorganizations_separateaccountsindirect | WP1: global_fundsoffunds_separateaccountsindirect | WQ1: global_highnetworthindividualsfamilyoffices_separateaccountsindirect | WR1: global_otherinvestortype_separateaccountsindirect | WS1: global_pensionfunds_jvs | WT1: global_insurancecompanies_jvs | WU1: global_sovereignwealthfunds_jvs | WV1: global_governmentinstitutions_jvs | WW1: global_charitiesfoundationsnonprofitorganizations_jvs | WX1: global_fundsoffunds_jvs | WY1: global_highnetworthindividualsfamilyoffices_jvs | WZ1: global_otherinvestortype_jvs | XA1: global_pensionfunds_fundsoffunds | XB1: global_insurancecompanies_fundsoffunds | XC1: global_sovereignwealthfunds_fundsoffunds | XD1: global_governmentinstitutions_fundsoffunds | XE1: global_charitiesfoundationsnonprofitorganizations_fundsoffunds | XF1: global_fundsoffunds_fundsoffunds | XG1: global_highnetworthindividualsfamilyoffices_fundsoffunds | XH1: global_otherinvestortype_fundsoffunds | XI1: global_pensionfunds_debt | XJ1: global_insurancecompanies_debt | XK1: global_sovereignwealthfunds_debt | XL1: global_governmentinstitutions_debt | XM1: global_charitiesfoundationsnonprofitorganizations_debt | XN1: global_fundsoffunds_debt | XO1: global_highnetworthindividualsfamilyoffices_debt | XP1: global_otherinvestortype_debt
A2: cr_2025-684 | B2: Blue Vista Management | C2: North America | D2: United States | E2: US | F2: 45700 | G2: 0 | H2: 0 | I2: 144.41968 | J2: 0 | K2: 0 | L2: 0 | M2: 144.41968 | N2: 120.34973 | O2: 0 | P2: 0 | Q2: 24.069946 | R2: 0 | S2: 0 | T2: 28.883936 | U2: 62.58186 | V2: 28.883936 | W2: 0 | X2: 0 | Y2: 0 | Z2: 0 | AA2: 0 | AB2: 0 | AC2: 0 | AD2: 0 | AE2: 0 | AF2: 0 | AG2: 0 | AH2: 0 | AI2: 0 | AJ2: 0 | AK2: 0 | AL2: 0 | AM2: 24.069946 | AN2: 0 | AO2: 0 | AP2: 0 | AQ2: 0 | AR2: 0 | AS2: 0 | AT2: 0 | AU2: 0 | AV2: 0 | AW2: 0 | AX2: 1 | AY2: 0 | AZ2: 0 | BA2: 0 | BB2: 100 | BC2: 0 | BD2: 1 | BE2: 3 | BF2: 72.209839 | BG2: 0 | BH2: 0 | BI2: 2 | BJ2: 0 | BK2: 0 | BL2: 0 | BM2: 2 | BN2: 144.41968 | BO2: 1 | BP2: 0 | BQ2: 0 | BR2: 1 | BS2: 0 | BT2: 0 | BU2: 0 | BV2: 0 | BW2: 120.34973 | BX2: 0 | BY2: 0 | BZ2: 0 | CA2: 0 | CB2: 0 | CC2: 0 | CD2: 0 | CE2: 0 | CF2: 0 | CG2: 0 | CH2: 0 | CI2: 0 | CJ2: 0 | CK2: 0 | CL2: 0 | CM2: 0 | CN2: 0 | CO2: 24.069946 | CP2: 0 | CQ2: 0 | CR2: 0 | CS2: 0 | CT2: 0 | CU2: 0 | CV2: 0 | CW2: 0 | CX2: 0 | CY2: 0 | CZ2: 0 | DA2: 0 | DB2: 0 | DC2: 0 | DD2: 0 | DE2: 0 | DF2: 0 | DG2: 0 | DH2: 0 | DI2: 0 | DJ2: 0 | DK2: 0 | DL2: 0 | DM2: 1 | DN2: 0 | DO2: 0 | DP2: 0 | DQ2: 0 | DR2: 0 | DS2: 0 | DT2: 0 | DU2: 0 | DV2: 0 | DW2: 0 | DX2: 0 | DY2: 0 | DZ2: 0 | EA2: 0 | EB2: 0 | EC2: 0 | ED2: 0 | EE2: 1 | EF2: 0 | EG2: 0 | EH2: 0 | EI2: 0 | EJ2: 0 | EK2: 0 | EL2: 0 | EM2: 0 | EN2: 0 | EO2: 0 | EP2: 0 | EQ2: 0 | ER2: 0 | ES2: 0 | ET2: 0 | EU2: 91.465797 | EV2: 24.069946 | EW2: 0 | EX2: 0 | EY2: 0 | EZ2: 28.883936 | FA2: 0 | FB2: 0 | FC2: 91.465797 | FD2: 0 | FE2: 0 | FF2: 0 | FG2: 0 | FH2: 28.883936 | FI2: 0 | FJ2: 0 | FK2: 0 | FL2: 0 | FM2: 0 | FN2: 0 | FO2: 0 | FP2: 0 | FQ2: 0 | FR2: 0 | FS2: 0 | FT2: 0 | FU2: 0 | FV2: 0 | FW2: 0 | FX2: 0 | FY2: 0 | FZ2: 0 | GA2: 0 | GB2: 24.069946 | GC2: 0 | GD2: 0 | GE2: 0 | GF2: 0 | GG2: 0 | GH2: 0 | GI2: 0 | GJ2: 0 | GK2: 0 | GL2: 0 | GM2: 0 | GN2: 0 | GO2: 0 | GP2: 0 | GQ2: 0 | GR2: 0 | GS2: 0 | GT2: 0 | GU2: 0 | GV2: 0 | GW2: 0 | GX2: 0 | GY2: 28.883936 | GZ2: 62.58186 | HA2: 28.883936 | HB2: 0 | HC2: 24.069946 | HD2: 0 | HE2: 0 | HF2: 0 | HG2: 0 | HH2: 0 | HI2: 0 | HJ2: 0 | HK2: 0 | HL2: 0 | HM2: 0 | HN2: 0 | HO2: 0 | HP2: 0 | HQ2: 0 | HR2: 0 | HS2: 0 | HT2: 0 | HU2: 0 | HV2: 0 | HW2: 0 | HX2: 0 | HY2: 0 | HZ2: 0 | IA2: 0 | IB2: 0 | IC2: 0 | ID2: 0 | IE2: 0 | IF2: 0 | IG2: 0 | IH2: 0 | II2: 0 | IJ2: 0 | IK2: 0 | IL2: 0 | IM2: 0 | IN2: 0 | IO2: 0 | IP2: 0 | IQ2: 0 | IR2: 0 | IS2: 0 | IT2: 0 | IU2: 0 | IV2: 0 | IW2: 0 | IX2: 0 | IY2: 0 | IZ2: 0 | JA2: 0 | JB2: 0 | JC2: 0 | JD2: 0 | JE2: 0 | JF2: 0 | JG2: 0 | JH2: 0 | JI2: 0 | JJ2: 0 | JK2: 0 | JL2: 0 | JM2: 0 | JN2: 0 | JO2: 0 | JP2: 0 | JQ2: 0 | JR2: 0 | JS2: 0 | JT2: 0 | JU2: 0 | JV2: 0 | JW2: 0 | JX2: 0 | JY2: 0 | JZ2: 0 | KA2: 0 | KB2: 0 | KC2: 0 | KD2: 0 | KE2: 0 | KF2: 0 | KG2: 0 | KH2: 0 | KI2: 0 | KJ2: 0 | KK2: 0 | KL2: 0 | KM2: 0 | KN2: 0 | KO2: 0 | KP2: 0 | KQ2: 0 | KR2: 0 | KS2: 0 | KT2: 0 | KU2: 0 | KV2: 0 | KW2: 0 | KX2: 0 | KY2: 0 | KZ2: 0 | LA2: 0 | LB2: 0 | LC2: 0 | LD2: 0 | LE2: 0 | LF2: 0 | LG2: 0 | LH2: 0 | LI2: 0 | LJ2: 0 | LK2: 0 | LL2: 0 | LM2: 0 | LN2: 0 | LO2: 0 | LP2: 0 | LQ2: 0 | LR2: 0 | LS2: 0 | LT2: 0 | LU2: 0 | LV2: 0 | LW2: 0 | LX2: 0 | LY2: 0 | LZ2: 0 | MA2: 0 | MB2: 0 | MC2: 0 | MD2: 0 | ME2: 0 | MF2: 0 | MG2: 0 | MH2: 0 | MI2: 0 | MJ2: 0 | MK2: 0 | ML2: 0 | MM2: 0 | MN2: 0 | MO2: 0 | MP2: 0 | MQ2: 0 | MR2: 0 | MS2: 0 | MT2: 0 | MU2: 0 | MV2: 0 | MW2: 0 | MX2: 0 | MY2: 0 | MZ2: 0 | NA2: 0 | NB2: 0 | NC2: 0 | ND2: 0 | NE2: 0 | NF2: 0 | NG2: 0 | NH2: 0 | NI2: 0 | NJ2: 0 | NK2: 0 | NL2: 0 | NM2: 0 | NN2: 0 | NO2: 0 | NP2: 0 | NQ2: 0 | NR2: 0 | NS2: 0 | NT2: 0 | NU2: 0 | NV2: 0 | NW2: 0 | NX2: 0 | NY2: 0 | NZ2: 0 | OA2: 0 | OB2: 0 | OC2: 0 | OD2: 0 | OE2: 0 | OF2: 0 | OG2: 0 | OH2: 0 | OI2: 0 | OJ2: 0 | OK2: 0 | OL2: 0 | OM2: 0 | ON2: 0 | OO2: 0 | OP2: 0 | OQ2: 0 | OR2: 0 | OS2: 0 | OT2: 0 | OU2: 0 | OV2: 0 | OW2: 0 | OX2: 0 | OY2: 0 | OZ2: 0 | PA2: 0 | PB2: 0 | PC2: 0 | PD2: 0 | PE2: 0 | PF2: 0 | PG2: 0 | PH2: 0 | PI2: 0 | PJ2: 0 | PK2: 0 | PL2: 0 | PM2: 0 | PN2: 0 | PO2: 0 | PP2: 0 | PQ2: 0 | PR2: 0 | PS2: 0 | PT2: 0 | PU2: 0 | PV2: 0 | PW2: 0 | PX2: 0 | PY2: 0 | PZ2: 0 | QA2: 0 | QB2: 0 | QC2: 0 | QD2: 0 | QE2: 0 | QF2: 0 | QG2: 0 | QH2: 0 | QI2: 0 | QJ2: 0 | QK2: 0 | QL2: 0 | QM2: 0 | QN2: 0 | QO2: 0 | QP2: 0 | QQ2: 0 | QR2: 0 | QS2: 0 | QT2: 0 | QU2: 0 | QV2: 0 | QW2: 0 | QX2: 0 | QY2: 0 | QZ2: 0 | RA2: 0 | RB2: 0 | RC2: 0 | RD2: 0 | RE2: 0 | RF2: 0 | RG2: 0 | RH2: 0 | RI2: 0 | RJ2: 0 | RK2: 0 | RL2: 0 | RM2: 0 | RN2: 0 | RO2: 0 | RP2: 0 | RQ2: 0 | RR2: 0 | RS2: 0 | RT2: 0 | RU2: 0 | RV2: 0 | RW2: 0 | RX2: 0 | RY2: 0 | RZ2: 0 | SA2: 0 | SB2: 0 | SC2: 0 | SD2: 0 | SE2: 0 | SF2: 0 | SG2: 0 | SH2: 0 | SI2: 0 | SJ2: 0 | SK2: 0 | SL2: 0 | SM2: 0 | SN2: 0 | SO2: 0 | SP2: 0 | SQ2: 0 | SR2: 0 | SS2: 0 | ST2: 0 | SU2: 0 | SV2: 0 | SW2: 0 | SX2: 0 | SY2: 0 | SZ2: 0 | TA2: 0 | TB2: 0 | TC2: 0 | TD2: 0 | TE2: 0 | TF2: 0 | TG2: 0 | TH2: 0 | TI2: 0 | TJ2: 0 | TK2: 0 | TL2: 0 | TM2: 0 | TN2: 0 | TO2: 0 | TP2: 0 | TQ2: 0 | TR2: 0 | TS2: 0 | TT2: 0 | TU2: 0 | TV2: 0 | TW2: 0 | TX2: 0 | TY2: 0 | TZ2: 0 | UA2: 0 | UB2: 0 | UC2: 0 | UD2: 0 | UE2: 0 | UF2: 0 | UG2: 0 | UH2: 0 | UI2: 0 | UJ2: 0 | UK2: 0 | UL2: 0 | UM2: 0 | UN2: 0 | UO2: 0 | UP2: 0 | UQ2: 0 | UR2: 0 | US2: 0 | UT2: 0 | UU2: 0 | UV2: 0 | UW2: 0 | UX2: 0 | UY2: 0 | UZ2: 0 | VA2: 0 | VB2: 0 | VC2: 0 | VD2: 0 | VE2: 0 | VF2: 0 | VG2: 0 | VH2: 0 | VI2: 0 | VJ2: 0 | VK2: 0 | VL2: 0 | VM2: 0 | VN2: 0 | VO2: 0 | VP2: 0 | VQ2: 0 | VR2: 0 | VS2: 0 | VT2: 0 | VU2: 0 | VV2: 0 | VW2: 0 | VX2: 0 | VY2: 0 | VZ2: 0 | WA2: 0 | WB2: 0 | WC2: 0 | WD2: 0 | WE2: 0 | WF2: 0 | WG2: 0 | WH2: 0 | WI2: 0 | WJ2: 0 | WK2: 0 | WL2: 0 | WM2: 0 | WN2: 0 | WO2: 0 | WP2: 0 | WQ2: 0 | WR2: 0 | WS2: 0 | WT2: 0 | WU2: 0 | WV2: 0 | WW2: 0 | WX2: 0 | WY2: 0 | WZ2: 0 | XA2: 0 | XB2: 0 | XC2: 0 | XD2: 0 | XE2: 0 | XF2: 0 | XG2: 0 | XH2: 0 | XI2: 0 | XJ2: 0 | XK2: 0 | XL2: 0 | XM2: 0 | XN2: 0 | XO2: 0 | XP2: 0
A3: cr_2025-695 | B3: Capitaland Investment | C3: Asia Pacific | D3: Singapore | E3: Asia Pacific | F3: 45723 | G3: 1519.2915 | H3: 0 | I3: 0 | J3: 0 | K3: 0 | L3: 0 | M3: 1519.2915 | N3: 149.8092 | O3: 485.46661 | P3: 0 | Q3: 593.58362 | R3: 0 | S3: 290.43201 | T3: 149.8092 | U3: 0 | V3: 0 | W3: 0 | X3: 0 | Y3: 485.46661 | Z3: 0 | AA3: 0 | AB3: 0 | AC3: 0 | AD3: 0 | AE3: 0 | AF3: 0 | AG3: 0 | AH3: 0 | AI3: 456.49408 | AJ3: 137.08955 | AK3: 0 | AL3: 0 | AM3: 0 | AN3: 0 | AO3: 0 | AP3: 0 | AQ3: 0 | AR3: 0 | AS3: 290.43201 | AT3: 0 | AU3: 0 | AV3: 0 | AW3: 0 | AX3: 1 | AY3: 0 | AZ3: 3 | BA3: 0 | BB3: 97 | BC3: 0 | BD3: 2 | BE3: 3 | BF3: 0 | BG3: 11 | BH3: 0 | BI3: 0 | BJ3: 0 | BK3: 0 | BL3: 0 | BM3: 11 | BN3: 1519.2915 | BO3: 2 | BP3: 2 | BQ3: 0 | BR3: 5 | BS3: 0 | BT3: 2 | BU3: 149.8092 | BV3: 0 | BW3: 0 | BX3: 0 | BY3: 0 | BZ3: 0 | CA3: 485.46661 | CB3: 0 | CC3: 0 | CD3: 0 | CE3: 0 | CF3: 0 | CG3: 0 | CH3: 0 | CI3: 0 | CJ3: 0 | CK3: 0 | CL3: 0 | CM3: 593.58362 | CN3: 0 | CO3: 0 | CP3: 0 | CQ3: 0 | CR3: 0 | CS3: 0 | CT3: 0 | CU3: 0 | CV3: 0 | CW3: 0 | CX3: 0 | CY3: 290.43201 | CZ3: 0 | DA3: 0 | DB3: 0 | DC3: 0 | DD3: 0 | DE3: 0 | DF3: 0 | DG3: 0 | DH3: 0 | DI3: 0 | DJ3: 0 | DK3: 2 | DL3: 0 | DM3: 0 | DN3: 0 | DO3: 0 | DP3: 0 | DQ3: 2 | DR3: 0 | DS3: 0 | DT3: 0 | DU3: 0 | DV3: 0 | DW3: 0 | DX3: 0 | DY3: 0 | DZ3: 0 | EA3: 0 | EB3: 0 | EC3: 5 | ED3: 0 | EE3: 0 | EF3: 0 | EG3: 0 | EH3: 0 | EI3: 0 | EJ3: 0 | EK3: 0 | EL3: 0 | EM3: 0 | EN3: 0 | EO3: 2 | EP3: 0 | EQ3: 0 | ER3: 0 | ES3: 0 | ET3: 0 | EU3: 204.92769 | EV3: 369.57648 | EW3: 0 | EX3: 0 | EY3: 0 | EZ3: 0 | FA3: 200.68781 | FB3: 744.09949 | FC3: 0 | FD3: 0 | FE3: 0 | FF3: 0 | FG3: 0 | FH3: 0 | FI3: 17.66618 | FJ3: 132.14302 | FK3: 0 | FL3: 298.91177 | FM3: 0 | FN3: 0 | FO3: 0 | FP3: 0 | FQ3: 170.30197 | FR3: 16.252886 | FS3: 0 | FT3: 0 | FU3: 0 | FV3: 0 | FW3: 0 | FX3: 0 | FY3: 0 | FZ3: 0 | GA3: 137.08955 | GB3: 70.664719 | GC3: 0 | GD3: 0 | GE3: 0 | GF3: 0 | GG3: 0 | GH3: 385.82938 | GI3: 0 | GJ3: 0 | GK3: 0 | GL3: 0 | GM3: 0 | GN3: 0 | GO3: 0 | GP3: 0 | GQ3: 67.838127 | GR3: 0 | GS3: 0 | GT3: 0 | GU3: 0 | GV3: 0 | GW3: 12.719649 | GX3: 209.87422 | GY3: 1382.2019 | GZ3: 137.08955 | HA3: 0 | HB3: 0 | HC3: 0 | HD3: 0 | HE3: 0 | HF3: 0 | HG3: 0 | HH3: 0 | HI3: 0 | HJ3: 0 | HK3: 0 | HL3: 0 | HM3: 0 | HN3: 0 | HO3: 0 | HP3: 0 | HQ3: 0 | HR3: 0 | HS3: 0 | HT3: 0 | HU3: 0 | HV3: 0 | HW3: 0 | HX3: 0 | HY3: 0 | HZ3: 0 | IA3: 0 | IB3: 0 | IC3: 0 | ID3: 0 | IE3: 0 | IF3: 0 | IG3: 0 | IH3: 0 | II3: 0 | IJ3: 0 | IK3: 0 | IL3: 0 | IM3: 0 | IN3: 0 | IO3: 0 | IP3: 0 | IQ3: 0 | IR3: 0 | IS3: 0 | IT3: 0 | IU3: 0 | IV3: 0 | IW3: 0 | IX3: 0 | IY3: 0 | IZ3: 0 | JA3: 0 | JB3: 0 | JC3: 0 | JD3: 0 | JE3: 0 | JF3: 0 | JG3: 0 | JH3: 0 | JI3: 0 | JJ3: 0 | JK3: 0 | JL3: 0 | JM3: 0 | JN3: 0 | JO3: 0 | JP3: 0 | JQ3: 0 | JR3: 0 | JS3: 0 | JT3: 0 | JU3: 0 | JV3: 0 | JW3: 0 | JX3: 0 | JY3: 0 | JZ3: 0 | KA3: 0 | KB3: 0 | KC3: 0 | KD3: 0 | KE3: 0 | KF3: 0 | KG3: 0 | KH3: 0 | KI3: 0 | KJ3: 0 | KK3: 0 | KL3: 0 | KM3: 0 | KN3: 0 | KO3: 0 | KP3: 0 | KQ3: 0 | KR3: 0 | KS3: 0 | KT3: 0 | KU3: 0 | KV3: 0 | KW3: 0 | KX3: 0 | KY3: 0 | KZ3: 0 | LA3: 0 | LB3: 0 | LC3: 0 | LD3: 0 | LE3: 0 | LF3: 0 | LG3: 0 | LH3: 0 | LI3: 0 | LJ3: 0 | LK3: 0 | LL3: 0 | LM3: 0 | LN3: 0 | LO3: 0 | LP3: 0 | LQ3: 0 | LR3: 0 | LS3: 0 | LT3: 0 | LU3: 0 | LV3: 0 | LW3: 0 | LX3: 0 | LY3: 0 | LZ3: 0 | MA3: 0 | MB3: 0 | MC3: 0 | MD3: 0 | ME3: 0 | MF3: 0 | MG3: 0 | MH3: 0 | MI3: 0 | MJ3: 0 | MK3: 0 | ML3: 0 | MM3: 0 | MN3: 0 | MO3: 0 | MP3: 0 | MQ3: 0 | MR3: 0 | MS3: 0 | MT3: 0 | MU3: 0 | MV3: 0 | MW3: 0 | MX3: 0 | MY3: 0 | MZ3: 0 | NA3: 0 | NB3: 0 | NC3: 0 | ND3: 0 | NE3: 0 | NF3: 0 | NG3: 0 | NH3: 0 | NI3: 0 | NJ3: 0 | NK3: 0 | NL3: 0 | NM3: 0 | NN3: 0 | NO3: 0 | NP3: 0 | NQ3: 0 | NR3: 0 | NS3: 0 | NT3: 0 | NU3: 0 | NV3: 0 | NW3: 0 | NX3: 0 | NY3: 0 | NZ3: 0 | OA3: 0 | OB3: 0 | OC3: 0 | OD3: 0 | OE3: 0 | OF3: 0 | OG3: 0 | OH3: 0 | OI3: 0 | OJ3: 0 | OK3: 0 | OL3: 0 | OM3: 0 | ON3: 0 | OO3: 0 | OP3: 0 | OQ3: 0 | OR3: 0 | OS3: 0 | OT3: 0 | OU3: 0 | OV3: 0 | OW3: 0 | OX3: 0 | OY3: 0 | OZ3: 0 | PA3: 0 | PB3: 0 | PC3: 0 | PD3: 0 | PE3: 0 | PF3: 0 | PG3: 0 | PH3: 0 | PI3: 0 | PJ3: 0 | PK3: 0 | PL3: 0 | PM3: 0 | PN3: 0 | PO3: 0 | PP3: 0 | PQ3: 0 | PR3: 0 | PS3: 0 | PT3: 0 | PU3: 0 | PV3: 0 | PW3: 0 | PX3: 0 | PY3: 0 | PZ3: 0 | QA3: 0 | QB3: 0 | QC3: 0 | QD3: 0 | QE3: 0 | QF3: 0 | QG3: 0 | QH3: 0 | QI3: 0 | QJ3: 0 | QK3: 0 | QL3: 0 | QM3: 0 | QN3: 0 | QO3: 0 | QP3: 0 | QQ3: 0 | QR3: 0 | QS3: 0 | QT3: 0 | QU3: 0 | QV3: 0 | QW3: 0 | QX3: 0 | QY3: 0 | QZ3: 0 | RA3: 0 | RB3: 0 | RC3: 0 | RD3: 0 | RE3: 0 | RF3: 0 | RG3: 0 | RH3: 0 | RI3: 0 | RJ3: 0 | RK3: 0 | RL3: 0 | RM3: 0 | RN3: 0 | RO3: 0 | RP3: 0 | RQ3: 0 | RR3: 0 | RS3: 0 | RT3: 0 | RU3: 0 | RV3: 0 | RW3: 0 | RX3: 0 | RY3: 0 | RZ3: 0 | SA3: 0 | SB3: 0 | SC3: 0 | SD3: 0 | SE3: 0 | SF3: 0 | SG3: 0 | SH3: 0 | SI3: 0 | SJ3: 0 | SK3: 0 | SL3: 0 | SM3: 0 | SN3: 0 | SO3: 0 | SP3: 0 | SQ3: 0 | SR3: 0 | SS3: 0 | ST3: 0 | SU3: 0 | SV3: 0 | SW3: 0 | SX3: 0 | SY3: 0 | SZ3: 0 | TA3: 0 | TB3: 0 | TC3: 0 | TD3: 0 | TE3: 0 | TF3: 0 | TG3: 0 | TH3: 0 | TI3: 0 | TJ3: 0 | TK3: 0 | TL3: 0 | TM3: 0 | TN3: 0 | TO3: 0 | TP3: 0 | TQ3: 0 | TR3: 0 | TS3: 0 | TT3: 0 | TU3: 0 | TV3: 0 | TW3: 0 | TX3: 0 | TY3: 0 | TZ3: 0 | UA3: 0 | UB3: 0 | UC3: 0 | UD3: 0 | UE3: 0 | UF3: 0 | UG3: 0 | UH3: 0 | UI3: 0 | UJ3: 0 | UK3: 0 | UL3: 0 | UM3: 0 | UN3: 0 | UO3: 0 | UP3: 0 | UQ3: 0 | UR3: 0 | US3: 0 | UT3: 0 | UU3: 0 | UV3: 0 | UW3: 0 | UX3: 0 | UY3: 0 | UZ3: 0 | VA3: 0 | VB3: 0 | VC3: 0 | VD3: 0 | VE3: 0 | VF3: 0 | VG3: 0 | VH3: 0 | VI3: 0 | VJ3: 0 | VK3: 0 | VL3: 0 | VM3: 0 | VN3: 0 | VO3: 0 | VP3: 0 | VQ3: 0 | VR3: 0 | VS3: 0 | VT3: 0 | VU3: 0 | VV3: 0 | VW3: 0 | VX3: 0 | VY3: 0 | VZ3: 0 | WA3: 0 | WB3: 0 | WC3: 0 | WD3: 0 | WE3: 0 | WF3: 0 | WG3: 0 | WH3: 0 | WI3: 0 | WJ3: 0 | WK3: 0 | WL3: 0 | WM3: 0 | WN3: 0 | WO3: 0 | WP3: 0 | WQ3: 0 | WR3: 0 | WS3: 0 | WT3: 0 | WU3: 0 | WV3: 0 | WW3: 0 | WX3: 0 | WY3: 0 | WZ3: 0 | XA3: 0 | XB3: 0 | XC3: 0 | XD3: 0 | XE3: 0 | XF3: 0 | XG3: 0 | XH3: 0 | XI3: 0 | XJ3: 0 | XK3: 0 | XL3: 0 | XM3: 0 | XN3: 0 | XO3: 0 | XP3: 0
A4: cr_2025-654 | B4: Amvest | C4: Europe | D4: Netherlands | E4: Europe | F4: 45699 | G4: 0 | H4: 30 | I4: 0 | J4: 0 | K4: 0 | L4: 0 | M4: 30 | N4: 30 | O4: 0 | P4: 0 | Q4: 0 | R4: 0 | S4: 0 | T4: 0 | U4: 30 | V4: 0 | W4: 0 | X4: 0 | Y4: 0 | Z4: 0 | AA4: 0 | AB4: 0 | AC4: 0 | AD4: 0 | AE4: 0 | AF4: 0 | AG4: 0 | AH4: 0 | AI4: 0 | AJ4: 0 | AK4: 0 | AL4: 0 | AM4: 0 | AN4: 0 | AO4: 0 | AP4: 0 | AQ4: 0 | AR4: 0 | AS4: 0 | AT4: 0 | AU4: 0 | AV4: 0 | AW4: 0 | AX4: 1 | AY4: 0 | AZ4: 0 | BA4: 0 | BB4: 100 | BC4: 0 | BD4: 1 | BE4: 2 | BF4: 30 | BG4: 0 | BH4: 1 | BI4: 0 | BJ4: 0 | BK4: 0 | BL4: 0 | BM4: 1 | BN4: 30 | BO4: 1 | BP4: 0 | BQ4: 0 | BR4: 0 | BS4: 0 | BT4: 0 | BU4: 0 | BV4: 30 | BW4: 0 | BX4: 0 | BY4: 0 | BZ4: 0 | CA4: 0 | CB4: 0 | CC4: 0 | CD4: 0 | CE4: 0 | CF4: 0 | CG4: 0 | CH4: 0 | CI4: 0 | CJ4: 0 | CK4: 0 | CL4: 0 | CM4: 0 | CN4: 0 | CO4: 0 | CP4: 0 | CQ4: 0 | CR4: 0 | CS4: 0 | CT4: 0 | CU4: 0 | CV4: 0 | CW4: 0 | CX4: 0 | CY4: 0 | CZ4: 0 | DA4: 0 | DB4: 0 | DC4: 0 | DD4: 0 | DE4: 0 | DF4: 0 | DG4: 0 | DH4: 0 | DI4: 0 | DJ4: 0 | DK4: 0 | DL4: 1 | DM4: 0 | DN4: 0 | DO4: 0 | DP4: 0 | DQ4: 0 | DR4: 0 | DS4: 0 | DT4: 0 | DU4: 0 | DV4: 0 | DW4: 0 | DX4: 0 | DY4: 0 | DZ4: 0 | EA4: 0 | EB4: 0 | EC4: 0 | ED4: 0 | EE4: 0 | EF4: 0 | EG4: 0 | EH4: 0 | EI4: 0 | EJ4: 0 | EK4: 0 | EL4: 0 | EM4: 0 | EN4: 0 | EO4: 0 | EP4: 0 | EQ4: 0 | ER4: 0 | ES4: 0 | ET4: 0 | EU4: 30 | EV4: 0 | EW4: 0 | EX4: 0 | EY4: 0 | EZ4: 0 | FA4: 0 | FB4: 0 | FC4: 30 | FD4: 0 | FE4: 0 | FF4: 0 | FG4: 0 | FH4: 0 | FI4: 0 | FJ4: 0 | FK4: 0 | FL4: 0 | FM4: 0 | FN4: 0 | FO4: 0 | FP4: 0 | FQ4: 0 | FR4: 0 | FS4: 0 | FT4: 0 | FU4: 0 | FV4: 0 | FW4: 0 | FX4: 0 | FY4: 0 | FZ4: 0 | GA4: 0 | GB4: 0 | GC4: 0 | GD4: 0 | GE4: 0 | GF4: 0 | GG4: 0 | GH4: 0 | GI4: 0 | GJ4: 0 | GK4: 0 | GL4: 0 | GM4: 0 | GN4: 0 | GO4: 0 | GP4: 0 | GQ4: 0 | GR4: 0 | GS4: 0 | GT4: 0 | GU4: 0 | GV4: 0 | GW4: 0 | GX4: 0 | GY4: 0 | GZ4: 30 | HA4: 0 | HB4: 0 | HC4: 0 | HD4: 0 | HE4: 0 | HF4: 0 | HG4: 0 | HH4: 0 | HI4: 0 | HJ4: 0 | HK4: 0 | HL4: 0 | HM4: 0 | HN4: 0 | HO4: 0 | HP4: 0 | HQ4: 0 | HR4: 0 | HS4: 0 | HT4: 0 | HU4: 0 | HV4: 0 | HW4: 0 | HX4: 0 | HY4: 0 | HZ4: 0 | IA4: 0 | IB4: 0 | IC4: 0 | ID4: 0 | IE4: 0 | IF4: 0 | IG4: 0 | IH4: 0 | II4: 0 | IJ4: 0 | IK4: 0 | IL4: 0 | IM4: 0 | IN4: 0 | IO4: 0 | IP4: 0 | IQ4: 0 | IR4: 0 | IS4: 0 | IT4: 0 | IU4: 0 | IV4: 0 | IW4: 0 | IX4: 0 | IY4: 0 | IZ4: 0 | JA4: 0 | JB4: 0 | JC4: 0 | JD4: 0 | JE4: 0 | JF4: 0 | JG4: 0 | JH4: 0 | JI4: 0 | JJ4: 0 | JK4: 0 | JL4: 0 | JM4: 0 | JN4: 0 | JO4: 0 | JP4: 0 | JQ4: 0 | JR4: 0 | JS4: 0 | JT4: 0 | JU4: 0 | JV4: 0 | JW4: 0 | JX4: 0 | JY4: 0 | JZ4: 0 | KA4: 0 | KB4: 0 | KC4: 0 | KD4: 0 | KE4: 0 | KF4: 0 | KG4: 0 | KH4: 0 | KI4: 0 | KJ4: 0 | KK4: 0 | KL4: 0 | KM4: 0 | KN4: 0 | KO4: 0 | KP4: 0 | KQ4: 0 | KR4: 0 | KS4: 0 | KT4: 0 | KU4: 0 | KV4: 0 | KW4: 0 | KX4: 0 | KY4: 0 | KZ4: 0 | LA4: 0 | LB4: 0 | LC4: 0 | LD4: 0 | LE4: 0 | LF4: 0 | LG4: 0 | LH4: 0 | LI4: 0 | LJ4: 0 | LK4: 0 | LL4: 0 | LM4: 0 | LN4: 0 | LO4: 0 | LP4: 0 | LQ4: 0 | LR4: 0 | LS4: 0 | LT4: 0 | LU4: 0 | LV4: 0 | LW4: 0 | LX4: 0 | LY4: 0 | LZ4: 0 | MA4: 0 | MB4: 0 | MC4: 0 | MD4: 0 | ME4: 0 | MF4: 0 | MG4: 0 | MH4: 0 | MI4: 0 | MJ4: 0 | MK4: 0 | ML4: 0 | MM4: 0 | MN4: 0 | MO4: 0 | MP4: 0 | MQ4: 0 | MR4: 0 | MS4: 0 | MT4: 0 | MU4: 0 | MV4: 0 | MW4: 0 | MX4: 0 | MY4: 0 | MZ4: 0 | NA4: 0 | NB4: 0 | NC4: 0 | ND4: 0 | NE4: 0 | NF4: 0 | NG4: 0 | NH4: 0 | NI4: 0 | NJ4: 0 | NK4: 30 | NL4: 0 | NM4: 0 | NN4: 0 | NO4: 0 | NP4: 0 | NQ4: 0 | NR4: 0 | NS4: 30 | NT4: 0 | NU4: 0 | NV4: 0 | NW4: 0 | NX4: 0 | NY4: 0 | NZ4: 30 | OA4: 0 | OB4: 30 | OC4: 0 | OD4: 0 | OE4: 0 | OF4: 0 | OG4: 0 | OH4: 0 | OI4: 0 | OJ4: 0 | OK4: 0 | OL4: 0 | OM4: 0 | ON4: 0 | OO4: 0 | OP4: 0 | OQ4: 0 | OR4: 0 | OS4: 0 | OT4: 30 | OU4: 0 | OV4: 0 | OW4: 0 | OX4: 30 | OY4: 0 | OZ4: 0 | PA4: 0 | PB4: 0 | PC4: 0 | PD4: 0 | PE4: 0 | PF4: 0 | PG4: 0 | PH4: 0 | PI4: 0 | PJ4: 0 | PK4: 0 | PL4: 0 | PM4: 0 | PN4: 0 | PO4: 0 | PP4: 0 | PQ4: 0 | PR4: 0 | PS4: 0 | PT4: 0 | PU4: 0 | PV4: 0 | PW4: 0 | PX4: 0 | PY4: 0 | PZ4: 0 | QA4: 0 | QB4: 0 | QC4: 0 | QD4: 0 | QE4: 0 | QF4: 0 | QG4: 0 | QH4: 0 | QI4: 0 | QJ4: 0 | QK4: 0 | QL4: 0 | QM4: 0 | QN4: 0 | QO4: 0 | QP4: 0 | QQ4: 0 | QR4: 0 | QS4: 0 | QT4: 0 | QU4: 0 | QV4: 0 | QW4: 30 | QX4: 0 | QY4: 0 | QZ4: 0 | RA4: 0 | RB4: 0 | RC4: 0 | RD4: 0 | RE4: 0 | RF4: 0 | RG4: 0 | RH4: 0 | RI4: 0 | RJ4: 0 | RK4: 0 | RL4: 0 | RM4: 0 | RN4: 0 | RO4: 0 | RP4: 0 | RQ4: 0 | RR4: 0 | RS4: 0 | RT4: 0 | RU4: 0 | RV4: 0 | RW4: 0 | RX4: 0 | RY4: 0 | RZ4: 0 | SA4: 0 | SB4: 0 | SC4: 0 | SD4: 0 | SE4: 0 | SF4: 0 | SG4: 0 | SH4: 0 | SI4: 0 | SJ4: 0 | SK4: 0 | SL4: 0 | SM4: 0 | SN4: 0 | SO4: 0 | SP4: 0 | SQ4: 0 | SR4: 0 | SS4: 0 | ST4: 0 | SU4: 0 | SV4: 0 | SW4: 0 | SX4: 0 | SY4: 0 | SZ4: 0 | TA4: 0 | TB4: 0 | TC4: 0 | TD4: 0 | TE4: 0 | TF4: 0 | TG4: 0 | TH4: 0 | TI4: 0 | TJ4: 0 | TK4: 30 | TL4: 0 | TM4: 0 | TN4: 0 | TO4: 0 | TP4: 0 | TQ4: 0 | TR4: 0 | TS4: 0 | TT4: 30 | TU4: 0 | TV4: 0 | TW4: 0 | TX4: 0 | TY4: 0 | TZ4: 0 | UA4: 0 | UB4: 0 | UC4: 0 | UD4: 0 | UE4: 0 | UF4: 0 | UG4: 0 | UH4: 0 | UI4: 0 | UJ4: 0 | UK4: 0 | UL4: 0 | UM4: 0 | UN4: 0 | UO4: 0 | UP4: 0 | UQ4: 0 | UR4: 0 | US4: 0 | UT4: 0 | UU4: 0 | UV4: 0 | UW4: 30 | UX4: 0 | UY4: 0 | UZ4: 0 | VA4: 0 | VB4: 0 | VC4: 0 | VD4: 0 | VE4: 0 | VF4: 0 | VG4: 0 | VH4: 0 | VI4: 0 | VJ4: 0 | VK4: 0 | VL4: 0 | VM4: 0 | VN4: 0 | VO4: 0 | VP4: 0 | VQ4: 0 | VR4: 0 | VS4: 0 | VT4: 0 | VU4: 0 | VV4: 0 | VW4: 0 | VX4: 0 | VY4: 0 | VZ4: 0 | WA4: 0 | WB4: 0 | WC4: 0 | WD4: 0 | WE4: 0 | WF4: 0 | WG4: 0 | WH4: 0 | WI4: 0 | WJ4: 0 | WK4: 0 | WL4: 0 | WM4: 0 | WN4: 0 | WO4: 0 | WP4: 0 | WQ4: 0 | WR4: 0 | WS4: 0 | WT4: 0 | WU4: 0 | WV4: 0 | WW4: 0 | WX4: 0 | WY4: 0 | WZ4: 0 | XA4: 0 | XB4: 0 | XC4: 0 | XD4: 0 | XE4: 0 | XF4: 0 | XG4: 0 | XH4: 0 | XI4: 0 | XJ4: 0 | XK4: 0 | XL4: 0 | XM4: 0 | XN4: 0 | XO4: 0 | XP4: 0
A5: cr_2025-644 | B5: Edmond De Rothschild Reim | C5: Europe | D5: Switzerland | E5: Europe | F5: 45720 | G5: 0 | H5: 187.38 | I5: 0 | J5: 0 | K5: 0 | L5: 0 | M5: 187.38 | N5: 99.709999 | O5: 68 | P5: 0 | Q5: 19.67 | R5: 0 | S5: 0 | T5: 0 | U5: 99.709999 | V5: 0 | W5: 0 | X5: 0 | Y5: 0 | Z5: 68 | AA5: 0 | AB5: 0 | AC5: 0 | AD5: 0 | AE5: 0 | AF5: 0 | AG5: 0 | AH5: 0 | AI5: 0 | AJ5: 0 | AK5: 19.67 | AL5: 0 | AM5: 0 | AN5: 0 | AO5: 0 | AP5: 0 | AQ5: 0 | AR5: 0 | AS5: 0 | AT5: 0 | AU5: 0 | AV5: 0 | AW5: 0 | AX5: 1 | AY5: 0 | AZ5: 0 | BA5: 0 | BB5: 100 | BC5: 0 | BD5: 1 | BE5: 3 | BF5: 149.64 | BG5: 0 | BH5: 5 | BI5: 0 | BJ5: 0 | BK5: 0 | BL5: 0 | BM5: 5 | BN5: 187.38 | BO5: 3 | BP5: 1 | BQ5: 0 | BR5: 1 | BS5: 0 | BT5: 0 | BU5: 0 | BV5: 99.709999 | BW5: 0 | BX5: 0 | BY5: 0 | BZ5: 0 | CA5: 0 | CB5: 68 | CC5: 0 | CD5: 0 | CE5: 0 | CF5: 0 | CG5: 0 | CH5: 0 | CI5: 0 | CJ5: 0 | CK5: 0 | CL5: 0 | CM5: 0 | CN5: 19.67 | CO5: 0 | CP5: 0 | CQ5: 0 | CR5: 0 | CS5: 0 | CT5: 0 | CU5: 0 | CV5: 0 | CW5: 0 | CX5: 0 | CY5: 0 | CZ5: 0 | DA5: 0 | DB5: 0 | DC5: 0 | DD5: 0 | DE5: 0 | DF5: 0 | DG5: 0 | DH5: 0 | DI5: 0 | DJ5: 0 | DK5: 0 | DL5: 3 | DM5: 0 | DN5: 0 | DO5: 0 | DP5: 0 | DQ5: 0 | DR5: 1 | DS5: 0 | DT5: 0 | DU5: 0 | DV5: 0 | DW5: 0 | DX5: 0 | DY5: 0 | DZ5: 0 | EA5: 0 | EB5: 0 | EC5: 0 | ED5: 1 | EE5: 0 | EF5: 0 | EG5: 0 | EH5: 0 | EI5: 0 | EJ5: 0 | EK5: 0 | EL5: 0 | EM5: 0 | EN5: 0 | EO5: 0 | EP5: 0 | EQ5: 0 | ER5: 0 | ES5: 0 | ET5: 0 | EU5: 125.8 | EV5: 34.669998 | EW5: 0 | EX5: 0 | EY5: 0 | EZ5: 15 | FA5: 4.1999998 | FB5: 7.71 | FC5: 57.799999 | FD5: 15 | FE5: 0 | FF5: 0 | FG5: 0 | FH5: 15 | FI5: 4.1999998 | FJ5: 7.71 | FK5: 68 | FL5: 0 | FM5: 0 | FN5: 0 | FO5: 0 | FP5: 0 | FQ5: 0 | FR5: 0 | FS5: 0 | FT5: 0 | FU5: 0 | FV5: 0 | FW5: 0 | FX5: 0 | FY5: 0 | FZ5: 0 | GA5: 0 | GB5: 19.67 | GC5: 0 | GD5: 0 | GE5: 0 | GF5: 0 | GG5: 0 | GH5: 0 | GI5: 0 | GJ5: 0 | GK5: 0 | GL5: 0 | GM5: 0 | GN5: 0 | GO5: 0 | GP5: 0 | GQ5: 0 | GR5: 0 | GS5: 0 | GT5: 0 | GU5: 0 | GV5: 0 | GW5: 0 | GX5: 0 | GY5: 0 | GZ5: 167.71001 | HA5: 19.67 | HB5: 0 | HC5: 0 | HD5: 0 | HE5: 0 | HF5: 0 | HG5: 0 | HH5: 0 | HI5: 0 | HJ5: 0 | HK5: 0 | HL5: 0 | HM5: 0 | HN5: 0 | HO5: 0 | HP5: 0 | HQ5: 0 | HR5: 0 | HS5: 0 | HT5: 0 | HU5: 0 | HV5: 0 | HW5: 0 | HX5: 0 | HY5: 0 | HZ5: 0 | IA5: 0 | IB5: 0 | IC5: 0 | ID5: 0 | IE5: 0 | IF5: 0 | IG5: 0 | IH5: 0 | II5: 0 | IJ5: 0 | IK5: 0 | IL5: 0 | IM5: 0 | IN5: 0 | IO5: 0 | IP5: 0 | IQ5: 0 | IR5: 0 | IS5: 0 | IT5: 0 | IU5: 0 | IV5: 0 | IW5: 0 | IX5: 0 | IY5: 0 | IZ5: 0 | JA5: 0 | JB5: 0 | JC5: 0 | JD5: 0 | JE5: 0 | JF5: 0 | JG5: 0 | JH5: 0 | JI5: 0 | JJ5: 0 | JK5: 0 | JL5: 0 | JM5: 0 | JN5: 0 | JO5: 0 | JP5: 0 | JQ5: 0 | JR5: 0 | JS5: 0 | JT5: 0 | JU5: 0 | JV5: 0 | JW5: 0 | JX5: 0 | JY5: 0 | JZ5: 0 | KA5: 0 | KB5: 0 | KC5: 0 | KD5: 0 | KE5: 0 | KF5: 0 | KG5: 0 | KH5: 0 | KI5: 0 | KJ5: 0 | KK5: 0 | KL5: 0 | KM5: 0 | KN5: 0 | KO5: 0 | KP5: 0 | KQ5: 0 | KR5: 0 | KS5: 0 | KT5: 0 | KU5: 0 | KV5: 0 | KW5: 0 | KX5: 0 | KY5: 0 | KZ5: 0 | LA5: 0 | LB5: 0 | LC5: 0 | LD5: 0 | LE5: 0 | LF5: 0 | LG5: 0 | LH5: 0 | LI5: 0 | LJ5: 0 | LK5: 0 | LL5: 0 | LM5: 0 | LN5: 0 | LO5: 0 | LP5: 0 | LQ5: 0 | LR5: 0 | LS5: 0 | LT5: 0 | LU5: 0 | LV5: 0 | LW5: 0 | LX5: 0 | LY5: 0 | LZ5: 0 | MA5: 0 | MB5: 0 | MC5: 0 | MD5: 0 | ME5: 0 | MF5: 0 | MG5: 0 | MH5: 0 | MI5: 0 | MJ5: 0 | MK5: 0 | ML5: 0 | MM5: 0 | MN5: 0 | MO5: 0 | MP5: 0 | MQ5: 0 | MR5: 0 | MS5: 0 | MT5: 0 | MU5: 0 | MV5: 0 | MW5: 0 | MX5: 0 | MY5: 0 | MZ5: 0 | NA5: 0 | NB5: 0 | NC5: 0 | ND5: 0 | NE5: 0 | NF5: 0 | NG5: 0 | NH5: 0 | NI5: 0 | NJ5: 0 | NK5: 125.8 | NL5: 34.669998 | NM5: 0 | NN5: 0 | NO5: 0 | NP5: 15 | NQ5: 4.1999998 | NR5: 7.71 | NS5: 99.709999 | NT5: 68 | NU5: 0 | NV5: 19.67 | NW5: 0 | NX5: 0 | NY5: 0 | NZ5: 57.799999 | OA5: 41.91 | OB5: 99.709999 | OC5: 68 | OD5: 0 | OE5: 68 | OF5: 0 | OG5: 0 | OH5: 0 | OI5: 19.67 | OJ5: 0 | OK5: 19.67 | OL5: 0 | OM5: 0 | ON5: 0 | OO5: 0 | OP5: 0 | OQ5: 0 | OR5: 0 | OS5: 0 | OT5: 167.71001 | OU5: 19.67 | OV5: 0 | OW5: 0 | OX5: 57.799999 | OY5: 68 | OZ5: 0 | PA5: 0 | PB5: 0 | PC5: 0 | PD5: 15 | PE5: 0 | PF5: 0 | PG5: 19.67 | PH5: 0 | PI5: 0 | PJ5: 0 | PK5: 0 | PL5: 0 | PM5: 0 | PN5: 0 | PO5: 0 | PP5: 0 | PQ5: 0 | PR5: 0 | PS5: 0 | PT5: 0 | PU5: 0 | PV5: 0 | PW5: 0 | PX5: 0 | PY5: 0 | PZ5: 0 | QA5: 0 | QB5: 15 | QC5: 0 | QD5: 0 | QE5: 0 | QF5: 0 | QG5: 0 | QH5: 4.1999998 | QI5: 0 | QJ5: 0 | QK5: 0 | QL5: 0 | QM5: 0 | QN5: 7.71 | QO5: 0 | QP5: 0 | QQ5: 0 | QR5: 0 | QS5: 0 | QT5: 0 | QU5: 0 | QV5: 37.709999 | QW5: 0 | QX5: 0 | QY5: 0 | QZ5: 0 | RA5: 0 | RB5: 62 | RC5: 0 | RD5: 0 | RE5: 0 | RF5: 0 | RG5: 0 | RH5: 68 | RI5: 0 | RJ5: 0 | RK5: 0 | RL5: 0 | RM5: 0 | RN5: 0 | RO5: 0 | RP5: 0 | RQ5: 0 | RR5: 0 | RS5: 0 | RT5: 0 | RU5: 0 | RV5: 0 | RW5: 0 | RX5: 0 | RY5: 0 | RZ5: 0 | SA5: 0 | SB5: 0 | SC5: 19.67 | SD5: 0 | SE5: 0 | SF5: 0 | SG5: 0 | SH5: 0 | SI5: 0 | SJ5: 0 | SK5: 0 | SL5: 0 | SM5: 0 | SN5: 0 | SO5: 0 | SP5: 0 | SQ5: 0 | SR5: 0 | SS5: 0 | ST5: 0 | SU5: 0 | SV5: 0 | SW5: 0 | SX5: 0 | SY5: 0 | SZ5: 0 | TA5: 0 | TB5: 0 | TC5: 0 | TD5: 0 | TE5: 0 | TF5: 0 | TG5: 0 | TH5: 0 | TI5: 0 | TJ5: 57.380001 | TK5: 68 | TL5: 0 | TM5: 0 | TN5: 0 | TO5: 0 | TP5: 62 | TQ5: 0 | TR5: 0 | TS5: 0 | TT5: 99.709999 | TU5: 0 | TV5: 0 | TW5: 0 | TX5: 0 | TY5: 68 | TZ5: 0 | UA5: 0 | UB5: 0 | UC5: 0 | UD5: 0 | UE5: 0 | UF5: 0 | UG5: 0 | UH5: 0 | UI5: 0 | UJ5: 19.67 | UK5: 0 | UL5: 0 | UM5: 0 | UN5: 0 | UO5: 0 | UP5: 0 | UQ5: 0 | UR5: 0 | US5: 0 | UT5: 0 | UU5: 0 | UV5: 0 | UW5: 95.510002 | UX5: 68 | UY5: 0 | UZ5: 0 | VA5: 0 | VB5: 0 | VC5: 4.1999998 | VD5: 0 | VE5: 0 | VF5: 19.67 | VG5: 0 | VH5: 0 | VI5: 0 | VJ5: 0 | VK5: 0 | VL5: 0 | VM5: 0 | VN5: 0 | VO5: 0 | VP5: 0 | VQ5: 0 | VR5: 0 | VS5: 0 | VT5: 0 | VU5: 0 | VV5: 0 | VW5: 0 | VX5: 0 | VY5: 0 | VZ5: 0 | WA5: 0 | WB5: 0 | WC5: 0 | WD5: 0 | WE5: 0 | WF5: 0 | WG5: 0 | WH5: 0 | WI5: 0 | WJ5: 0 | WK5: 0 | WL5: 0 | WM5: 0 | WN5: 0 | WO5: 0 | WP5: 0 | WQ5: 0 | WR5: 0 | WS5: 0 | WT5: 0 | WU5: 0 | WV5: 0 | WW5: 0 | WX5: 0 | WY5: 0 | WZ5: 0 | XA5: 0 | XB5: 0 | XC5: 0 | XD5: 0 | XE5: 0 | XF5: 0 | XG5: 0 | XH5: 0 | XI5: 0 | XJ5: 0 | XK5: 0 | XL5: 0 | XM5: 0 | XN5: 0 | XO5: 0 | XP5: 0
