Workbook

Sheet DFanalysis
A1: Company Name | B1: Vehicle Name | C1: ID | D1: Loan Strategy | E1: Target Regional Strategy | F1: Vehicle Structure | G1: year of first closing | H1: RaisedCapital | I1: WhyNo | J1: Other (please specify) | K1: Currency of Reporting | L1: EUR | M1: TotalAmountRaised | N1: PensionFunds | O1: InsuranceCompanies | P1: SWFs | Q1: Government | R1: Charities | S1: FundOfFunds | T1: HNWI | U1: Other | V1: Europe | W1: APAC | X1: NorthAmerica | Y1: SouthAmerica | Z1: Africa | AA1: PlacementAgent | AB1: InvestorsContacting | AC1: OwnRelationship | AD1: Other2 | AE1: Expectations | AF1: Name
A2: =IF(OR(ISTEXT([1]DFsmonkeyCompl!J3),ISNUMBER([1]DFsmonkeyCompl!J3)),[1]DFsmonkeyCompl!J3,"") -> PGIM Real Estate | B2: =IF(OR(ISTEXT([1]DFsmonkeyCompl!K3),ISNUMBER([1]DFsmonkeyCompl!K3)),[1]DFsmonkeyCompl!K3,"") -> PRECap VII | C2: {=INDEX([1]DebtFundUniverse!$A$85:$A$95,MATCH(B2,[1]DebtFundUniverse!$B$85:$B$95,0),0)} -> 97174 | D2: =INDEX([1]DebtFundUniverse!$B$2:$EU$200,MATCH(DFanalysis[[#This Row],[ID]],[1]DebtFundUniverse!$A$2:$A$200,0),MATCH(DFanalysis[[#Headers],[Loan Strategy]],[1]DebtFundUniverse!$B$1:$EU$1,0)) -> Mixed: Senior+Subordinated+Preferred equity | E2: =INDEX([1]DebtFundUniverse!$B$2:$EU$200,MATCH(DFanalysis[[#This Row],[ID]],[1]DebtFundUniverse!$A$2:$A$200,0),MATCH(DFanalysis[[#Headers],[Target Regional Strategy]],[1]DebtFundUniverse!$B$1:$EU$1,0)) -> Europe | F2: =INDEX([1]DebtFundUniverse!$B$2:$EU$200,MATCH(DFanalysis[[#This Row],[ID]],[1]DebtFundUniverse!$A$2:$A$200,0),MATCH(DFanalysis[[#Headers],[Vehicle Structure]],[1]DebtFundUniverse!$B$1:$EU$1,0)) -> Closed end | G2: =INDEX([1]DebtFundUniverse!$B$2:$EU$200,MATCH(DFanalysis[[#This Row],[ID]],[1]DebtFundUniverse!$A$2:$A$200,0),MATCH(DFanalysis[[#Headers],[year of first closing]],[1]DebtFundUniverse!$B$1:$EU$1,0)) -> 2019 | H2: =IF(ISBLANK([1]DFsmonkeyCompl!L3),"",[1]DFsmonkeyCompl!L3) -> Yes | I2: =IF(ISBLANK([1]DFsmonkeyCompl!M3),"",[1]DFsmonkeyCompl!M3) | J2: =IF(ISBLANK([1]DFsmonkeyCompl!N3),"",[1]DFsmonkeyCompl!N3) | K2: =INDEX([1]DebtFundUniverse!$B$2:$EU$200,MATCH(DFanalysis[[#This Row],[ID]],[1]DebtFundUniverse!$A$2:$A$200,0),MATCH(DFanalysis[[#Headers],[Currency of Reporting]],[1]DebtFundUniverse!$B$1:$EU$1,0)) -> GBP | L2: =VLOOKUP(DFanalysis[[#This Row],[Currency of Reporting]],'[1]Xrate31.12.20'!$K$1:$M$25,3,0) -> 1.1130928 | M2: =IFERROR(IF(ISBLANK([1]DFsmonkeyCompl!O3),"",[1]DFsmonkeyCompl!O3*DFanalysis[[#This Row],[EUR]]),"") -> 1021.8192 | N2: =IFERROR(IF(ISBLANK([1]DFsmonkeyCompl!P3),"",[1]DFsmonkeyCompl!P3*DFanalysis[[#This Row],[EUR]]),"") -> 906.05753 | O2: =IFERROR(IF(ISBLANK([1]DFsmonkeyCompl!Q3),"",[1]DFsmonkeyCompl!Q3*DFanalysis[[#This Row],[EUR]]),"") | P2: =IFERROR(IF(ISBLANK([1]DFsmonkeyCompl!R3),"",[1]DFsmonkeyCompl!R3*DFanalysis[[#This Row],[EUR]]),"") -> 57.880825 | Q2: =IFERROR(IF(ISBLANK([1]DFsmonkeyCompl!S3),"",[1]DFsmonkeyCompl!S3*DFanalysis[[#This Row],[EUR]]),"") | R2: =IFERROR(IF(ISBLANK([1]DFsmonkeyCompl!T3),"",[1]DFsmonkeyCompl!T3*DFanalysis[[#This Row],[EUR]]),"") | S2: =IFERROR(IF(ISBLANK([1]DFsmonkeyCompl!U3),"",[1]DFsmonkeyCompl!U3*DFanalysis[[#This Row],[EUR]]),"") | T2: =IFERROR(IF(ISBLANK([1]DFsmonkeyCompl!V3),"",[1]DFsmonkeyCompl!V3*DFanalysis[[#This Row],[EUR]]),"") | ... Z2: =IFERROR(IF(ISBLANK([1]DFsmonkeyCompl!AB3),"",[1]DFsmonkeyCompl!AB3*DFanalysis[[#This Row],[EUR]]),"") | AA2: =IF(ISBLANK([1]DFsmonkeyCompl!AC3),"",[1]DFsmonkeyCompl!AC3) | AB2: =IF(ISBLANK([1]DFsmonkeyCompl!AD3),"",[1]DFsmonkeyCompl!AD3) | AC2: =IF(ISBLANK([1]DFsmonkeyCompl!AE3),"",[1]DFsmonkeyCompl!AE3) -> 100 | AD2: =IF(ISBLANK([1]DFsmonkeyCompl!AF3),"",[1]DFsmonkeyCompl!AF3) | AE2: =IF(ISBLANK([1]DFsmonkeyCompl!AG3),"",[1]DFsmonkeyCompl!AG3) -> Increase | AF2: =IF(ISBLANK([1]DFsmonkeyCompl!AH3),"",[1]DFsmonkeyCompl!AH3) -> Yes
A3: =IF(OR(ISTEXT([1]DFsmonkeyCompl!J4),ISNUMBER([1]DFsmonkeyCompl!J4)),[1]DFsmonkeyCompl!J4,"") -> BentallGreenOak | B3: =IF(OR(ISTEXT([1]DFsmonkeyCompl!K4),ISNUMBER([1]DFsmonkeyCompl!K4)),[1]DFsmonkeyCompl!K4,"") -> UK Secured Lending III | C3: {=INDEX([1]DebtFundUniverse!$A$85:$A$95,MATCH(B3,[1]DebtFundUniverse!$B$85:$B$95,0),0)} -> 10000001 | D3: =INDEX([1]DebtFundUniverse!$B$2:$EU$200,MATCH(DFanalysis[[#This Row],[ID]],[1]DebtFundUniverse!$A$2:$A$200,0),MATCH(DFanalysis[[#Headers],[Loan Strategy]],[1]DebtFundUniverse!$B$1:$EU$1,0)) -> Senior | E3: =INDEX([1]DebtFundUniverse!$B$2:$EU$200,MATCH(DFanalysis[[#This Row],[ID]],[1]DebtFundUniverse!$A$2:$A$200,0),MATCH(DFanalysis[[#Headers],[Target Regional Strategy]],[1]DebtFundUniverse!$B$1:$EU$1,0)) -> Europe | F3: =INDEX([1]DebtFundUniverse!$B$2:$EU$200,MATCH(DFanalysis[[#This Row],[ID]],[1]DebtFundUniverse!$A$2:$A$200,0),MATCH(DFanalysis[[#Headers],[Vehicle Structure]],[1]DebtFundUniverse!$B$1:$EU$1,0)) -> Closed end | G3: =INDEX([1]DebtFundUniverse!$B$2:$EU$200,MATCH(DFanalysis[[#This Row],[ID]],[1]DebtFundUniverse!$A$2:$A$200,0),MATCH(DFanalysis[[#Headers],[year of first closing]],[1]DebtFundUniverse!$B$1:$EU$1,0)) -> 2020 | H3: =IF(ISBLANK([1]DFsmonkeyCompl!L4),"",[1]DFsmonkeyCompl!L4) -> Yes | I3: =IF(ISBLANK([1]DFsmonkeyCompl!M4),"",[1]DFsmonkeyCompl!M4) | J3: =IF(ISBLANK([1]DFsmonkeyCompl!N4),"",[1]DFsmonkeyCompl!N4) | K3: =INDEX([1]DebtFundUniverse!$B$2:$EU$200,MATCH(DFanalysis[[#This Row],[ID]],[1]DebtFundUniverse!$A$2:$A$200,0),MATCH(DFanalysis[[#Headers],[Currency of Reporting]],[1]DebtFundUniverse!$B$1:$EU$1,0)) -> GBP | L3: =VLOOKUP(DFanalysis[[#This Row],[Currency of Reporting]],'[1]Xrate31.12.20'!$K$1:$M$25,3,0) -> 1.1130928 | M3: =IFERROR(IF(ISBLANK([1]DFsmonkeyCompl!O4),"",[1]DFsmonkeyCompl!O4*DFanalysis[[#This Row],[EUR]]),"") -> 400.7134 | N3: =IFERROR(IF(ISBLANK([1]DFsmonkeyCompl!P4),"",[1]DFsmonkeyCompl!P4*DFanalysis[[#This Row],[EUR]]),"") -> 400.7134 | O3: =IFERROR(IF(ISBLANK([1]DFsmonkeyCompl!Q4),"",[1]DFsmonkeyCompl!Q4*DFanalysis[[#This Row],[EUR]]),"") | P3: =IFERROR(IF(ISBLANK([1]DFsmonkeyCompl!R4),"",[1]DFsmonkeyCompl!R4*DFanalysis[[#This Row],[EUR]]),"") | Q3: =IFERROR(IF(ISBLANK([1]DFsmonkeyCompl!S4),"",[1]DFsmonkeyCompl!S4*DFanalysis[[#This Row],[EUR]]),"") | R3: =IFERROR(IF(ISBLANK([1]DFsmonkeyCompl!T4),"",[1]DFsmonkeyCompl!T4*DFanalysis[[#This Row],[EUR]]),"") | S3: =IFERROR(IF(ISBLANK([1]DFsmonkeyCompl!U4),"",[1]DFsmonkeyCompl!U4*DFanalysis[[#This Row],[EUR]]),"") | T3: =IFERROR(IF(ISBLANK([1]DFsmonkeyCompl!V4),"",[1]DFsmonkeyCompl!V4*DFanalysis[[#This Row],[EUR]]),"") | ... Z3: =IFERROR(IF(ISBLANK([1]DFsmonkeyCompl!AB4),"",[1]DFsmonkeyCompl!AB4*DFanalysis[[#This Row],[EUR]]),"") | AA3: =IF(ISBLANK([1]DFsmonkeyCompl!AC4),"",[1]DFsmonkeyCompl!AC4) | AB3: =IF(ISBLANK([1]DFsmonkeyCompl!AD4),"",[1]DFsmonkeyCompl!AD4) | AC3: =IF(ISBLANK([1]DFsmonkeyCompl!AE4),"",[1]DFsmonkeyCompl!AE4) -> 100 | AD3: =IF(ISBLANK([1]DFsmonkeyCompl!AF4),"",[1]DFsmonkeyCompl!AF4) | AE3: =IF(ISBLANK([1]DFsmonkeyCompl!AG4),"",[1]DFsmonkeyCompl!AG4) -> Increase | AF3: =IF(ISBLANK([1]DFsmonkeyCompl!AH4),"",[1]DFsmonkeyCompl!AH4) -> Yes
A4: =IF(OR(ISTEXT([1]DFsmonkeyCompl!J5),ISNUMBER([1]DFsmonkeyCompl!J5)),[1]DFsmonkeyCompl!J5,"") -> BentallGreenOak | B4: =IF(OR(ISTEXT([1]DFsmonkeyCompl!K5),ISNUMBER([1]DFsmonkeyCompl!K5)),[1]DFsmonkeyCompl!K5,"") -> Europe Secured Lending II | C4: {=INDEX([1]DebtFundUniverse!$A$85:$A$95,MATCH(B4,[1]DebtFundUniverse!$B$85:$B$95,0),0)} -> 10000002 | D4: =INDEX([1]DebtFundUniverse!$B$2:$EU$200,MATCH(DFanalysis[[#This Row],[ID]],[1]DebtFundUniverse!$A$2:$A$200,0),MATCH(DFanalysis[[#Headers],[Loan Strategy]],[1]DebtFundUniverse!$B$1:$EU$1,0)) -> Senior | E4: =INDEX([1]DebtFundUniverse!$B$2:$EU$200,MATCH(DFanalysis[[#This Row],[ID]],[1]DebtFundUniverse!$A$2:$A$200,0),MATCH(DFanalysis[[#Headers],[Target Regional Strategy]],[1]DebtFundUniverse!$B$1:$EU$1,0)) -> Europe | F4: =INDEX([1]DebtFundUniverse!$B$2:$EU$200,MATCH(DFanalysis[[#This Row],[ID]],[1]DebtFundUniverse!$A$2:$A$200,0),MATCH(DFanalysis[[#Headers],[Vehicle Structure]],[1]DebtFundUniverse!$B$1:$EU$1,0)) -> Closed end | G4: =INDEX([1]DebtFundUniverse!$B$2:$EU$200,MATCH(DFanalysis[[#This Row],[ID]],[1]DebtFundUniverse!$A$2:$A$200,0),MATCH(DFanalysis[[#Headers],[year of first closing]],[1]DebtFundUniverse!$B$1:$EU$1,0)) -> 2020 | H4: =IF(ISBLANK([1]DFsmonkeyCompl!L5),"",[1]DFsmonkeyCompl!L5) -> Yes | I4: =IF(ISBLANK([1]DFsmonkeyCompl!M5),"",[1]DFsmonkeyCompl!M5) | J4: =IF(ISBLANK([1]DFsmonkeyCompl!N5),"",[1]DFsmonkeyCompl!N5) | K4: =INDEX([1]DebtFundUniverse!$B$2:$EU$200,MATCH(DFanalysis[[#This Row],[ID]],[1]DebtFundUniverse!$A$2:$A$200,0),MATCH(DFanalysis[[#Headers],[Currency of Reporting]],[1]DebtFundUniverse!$B$1:$EU$1,0)) -> GBP | L4: =VLOOKUP(DFanalysis[[#This Row],[Currency of Reporting]],'[1]Xrate31.12.20'!$K$1:$M$25,3,0) -> 1.1130928 | M4: =IFERROR(IF(ISBLANK([1]DFsmonkeyCompl!O5),"",[1]DFsmonkeyCompl!O5*DFanalysis[[#This Row],[EUR]]),"") -> 122.44021 | N4: =IFERROR(IF(ISBLANK([1]DFsmonkeyCompl!P5),"",[1]DFsmonkeyCompl!P5*DFanalysis[[#This Row],[EUR]]),"") -> 122.44021 | O4: =IFERROR(IF(ISBLANK([1]DFsmonkeyCompl!Q5),"",[1]DFsmonkeyCompl!Q5*DFanalysis[[#This Row],[EUR]]),"") | P4: =IFERROR(IF(ISBLANK([1]DFsmonkeyCompl!R5),"",[1]DFsmonkeyCompl!R5*DFanalysis[[#This Row],[EUR]]),"") | Q4: =IFERROR(IF(ISBLANK([1]DFsmonkeyCompl!S5),"",[1]DFsmonkeyCompl!S5*DFanalysis[[#This Row],[EUR]]),"") | R4: =IFERROR(IF(ISBLANK([1]DFsmonkeyCompl!T5),"",[1]DFsmonkeyCompl!T5*DFanalysis[[#This Row],[EUR]]),"") | S4: =IFERROR(IF(ISBLANK([1]DFsmonkeyCompl!U5),"",[1]DFsmonkeyCompl!U5*DFanalysis[[#This Row],[EUR]]),"") | T4: =IFERROR(IF(ISBLANK([1]DFsmonkeyCompl!V5),"",[1]DFsmonkeyCompl!V5*DFanalysis[[#This Row],[EUR]]),"") | ... Z4: =IFERROR(IF(ISBLANK([1]DFsmonkeyCompl!AB5),"",[1]DFsmonkeyCompl!AB5*DFanalysis[[#This Row],[EUR]]),"") | AA4: =IF(ISBLANK([1]DFsmonkeyCompl!AC5),"",[1]DFsmonkeyCompl!AC5) | AB4: =IF(ISBLANK([1]DFsmonkeyCompl!AD5),"",[1]DFsmonkeyCompl!AD5) | AC4: =IF(ISBLANK([1]DFsmonkeyCompl!AE5),"",[1]DFsmonkeyCompl!AE5) -> 100 | AD4: =IF(ISBLANK([1]DFsmonkeyCompl!AF5),"",[1]DFsmonkeyCompl!AF5) | AE4: =IF(ISBLANK([1]DFsmonkeyCompl!AG5),"",[1]DFsmonkeyCompl!AG5) -> Increase | AF4: =IF(ISBLANK([1]DFsmonkeyCompl!AH5),"",[1]DFsmonkeyCompl!AH5) -> Yes
A5: =IF(OR(ISTEXT([1]DFsmonkeyCompl!J6),ISNUMBER([1]DFsmonkeyCompl!J6)),[1]DFsmonkeyCompl!J6,"") -> SCOR Investment Partners | B5: =IF(OR(ISTEXT([1]DFsmonkeyCompl!K6),ISNUMBER([1]DFsmonkeyCompl!K6)),[1]DFsmonkeyCompl!K6,"") -> SCOR Real Estate Loans IV | C5: {=INDEX([1]DebtFundUniverse!$A$85:$A$95,MATCH(B5,[1]DebtFundUniverse!$B$85:$B$95,0),0)} -> 76090 | D5: =INDEX([1]DebtFundUniverse!$B$2:$EU$200,MATCH(DFanalysis[[#This Row],[ID]],[1]DebtFundUniverse!$A$2:$A$200,0),MATCH(DFanalysis[[#Headers],[Loan Strategy]],[1]DebtFundUniverse!$B$1:$EU$1,0)) -> Senior | E5: =INDEX([1]DebtFundUniverse!$B$2:$EU$200,MATCH(DFanalysis[[#This Row],[ID]],[1]DebtFundUniverse!$A$2:$A$200,0),MATCH(DFanalysis[[#Headers],[Target Regional Strategy]],[1]DebtFundUniverse!$B$1:$EU$1,0)) -> Europe | F5: =INDEX([1]DebtFundUniverse!$B$2:$EU$200,MATCH(DFanalysis[[#This Row],[ID]],[1]DebtFundUniverse!$A$2:$A$200,0),MATCH(DFanalysis[[#Headers],[Vehicle Structure]],[1]DebtFundUniverse!$B$1:$EU$1,0)) -> Closed end | G5: =INDEX([1]DebtFundUniverse!$B$2:$EU$200,MATCH(DFanalysis[[#This Row],[ID]],[1]DebtFundUniverse!$A$2:$A$200,0),MATCH(DFanalysis[[#Headers],[year of first closing]],[1]DebtFundUniverse!$B$1:$EU$1,0)) -> 2020 | H5: =IF(ISBLANK([1]DFsmonkeyCompl!L6),"",[1]DFsmonkeyCompl!L6) -> Yes | I5: =IF(ISBLANK([1]DFsmonkeyCompl!M6),"",[1]DFsmonkeyCompl!M6) | J5: =IF(ISBLANK([1]DFsmonkeyCompl!N6),"",[1]DFsmonkeyCompl!N6) | K5: =INDEX([1]DebtFundUniverse!$B$2:$EU$200,MATCH(DFanalysis[[#This Row],[ID]],[1]DebtFundUniverse!$A$2:$A$200,0),MATCH(DFanalysis[[#Headers],[Currency of Reporting]],[1]DebtFundUniverse!$B$1:$EU$1,0)) -> EUR | L5: =VLOOKUP(DFanalysis[[#This Row],[Currency of Reporting]],'[1]Xrate31.12.20'!$K$1:$M$25,3,0) -> 1 | M5: =IFERROR(IF(ISBLANK([1]DFsmonkeyCompl!O6),"",[1]DFsmonkeyCompl!O6*DFanalysis[[#This Row],[EUR]]),"") -> 175 | N5: =IFERROR(IF(ISBLANK([1]DFsmonkeyCompl!P6),"",[1]DFsmonkeyCompl!P6*DFanalysis[[#This Row],[EUR]]),"") -> 0 | O5: =IFERROR(IF(ISBLANK([1]DFsmonkeyCompl!Q6),"",[1]DFsmonkeyCompl!Q6*DFanalysis[[#This Row],[EUR]]),"") -> 150 | P5: =IFERROR(IF(ISBLANK([1]DFsmonkeyCompl!R6),"",[1]DFsmonkeyCompl!R6*DFanalysis[[#This Row],[EUR]]),"") -> 0 | Q5: =IFERROR(IF(ISBLANK([1]DFsmonkeyCompl!S6),"",[1]DFsmonkeyCompl!S6*DFanalysis[[#This Row],[EUR]]),"") -> 0 | R5: =IFERROR(IF(ISBLANK([1]DFsmonkeyCompl!T6),"",[1]DFsmonkeyCompl!T6*DFanalysis[[#This Row],[EUR]]),"") -> 0 | S5: =IFERROR(IF(ISBLANK([1]DFsmonkeyCompl!U6),"",[1]DFsmonkeyCompl!U6*DFanalysis[[#This Row],[EUR]]),"") -> 0 | T5: =IFERROR(IF(ISBLANK([1]DFsmonkeyCompl!V6),"",[1]DFsmonkeyCompl!V6*DFanalysis[[#This Row],[EUR]]),"") -> 0 | ... Z5: =IFERROR(IF(ISBLANK([1]DFsmonkeyCompl!AB6),"",[1]DFsmonkeyCompl!AB6*DFanalysis[[#This Row],[EUR]]),"") -> 0 | AA5: =IF(ISBLANK([1]DFsmonkeyCompl!AC6),"",[1]DFsmonkeyCompl!AC6) -> 0 | AB5: =IF(ISBLANK([1]DFsmonkeyCompl!AD6),"",[1]DFsmonkeyCompl!AD6) -> 0 | AC5: =IF(ISBLANK([1]DFsmonkeyCompl!AE6),"",[1]DFsmonkeyCompl!AE6) -> 100 | AD5: =IF(ISBLANK([1]DFsmonkeyCompl!AF6),"",[1]DFsmonkeyCompl!AF6) -> 0 | AE5: =IF(ISBLANK([1]DFsmonkeyCompl!AG6),"",[1]DFsmonkeyCompl!AG6) -> No change | AF5: =IF(ISBLANK([1]DFsmonkeyCompl!AH6),"",[1]DFsmonkeyCompl!AH6) -> No
A6: =IF(OR(ISTEXT([1]DFsmonkeyCompl!J7),ISNUMBER([1]DFsmonkeyCompl!J7)),[1]DFsmonkeyCompl!J7,"") -> LaSalle Investment Management | B6: =IF(OR(ISTEXT([1]DFsmonkeyCompl!K7),ISNUMBER([1]DFsmonkeyCompl!K7)),[1]DFsmonkeyCompl!K7,"") -> LaSalle Real Estate Debt Strategies IV | C6: {=INDEX([1]DebtFundUniverse!$A$85:$A$95,MATCH(B6,[1]DebtFundUniverse!$B$85:$B$95,0),0)} -> 105571 | D6: =INDEX([1]DebtFundUniverse!$B$2:$EU$200,MATCH(DFanalysis[[#This Row],[ID]],[1]DebtFundUniverse!$A$2:$A$200,0),MATCH(DFanalysis[[#Headers],[Loan Strategy]],[1]DebtFundUniverse!$B$1:$EU$1,0)) -> Subordinated: Junior+Mezzanine | E6: =INDEX([1]DebtFundUniverse!$B$2:$EU$200,MATCH(DFanalysis[[#This Row],[ID]],[1]DebtFundUniverse!$A$2:$A$200,0),MATCH(DFanalysis[[#Headers],[Target Regional Strategy]],[1]DebtFundUniverse!$B$1:$EU$1,0)) -> Europe | F6: =INDEX([1]DebtFundUniverse!$B$2:$EU$200,MATCH(DFanalysis[[#This Row],[ID]],[1]DebtFundUniverse!$A$2:$A$200,0),MATCH(DFanalysis[[#Headers],[Vehicle Structure]],[1]DebtFundUniverse!$B$1:$EU$1,0)) -> Closed end | G6: =INDEX([1]DebtFundUniverse!$B$2:$EU$200,MATCH(DFanalysis[[#This Row],[ID]],[1]DebtFundUniverse!$A$2:$A$200,0),MATCH(DFanalysis[[#Headers],[year of first closing]],[1]DebtFundUniverse!$B$1:$EU$1,0)) -> 2020 | H6: =IF(ISBLANK([1]DFsmonkeyCompl!L7),"",[1]DFsmonkeyCompl!L7) -> Yes | I6: =IF(ISBLANK([1]DFsmonkeyCompl!M7),"",[1]DFsmonkeyCompl!M7) | J6: =IF(ISBLANK([1]DFsmonkeyCompl!N7),"",[1]DFsmonkeyCompl!N7) | K6: =INDEX([1]DebtFundUniverse!$B$2:$EU$200,MATCH(DFanalysis[[#This Row],[ID]],[1]DebtFundUniverse!$A$2:$A$200,0),MATCH(DFanalysis[[#Headers],[Currency of Reporting]],[1]DebtFundUniverse!$B$1:$EU$1,0)) -> EUR | L6: =VLOOKUP(DFanalysis[[#This Row],[Currency of Reporting]],'[1]Xrate31.12.20'!$K$1:$M$25,3,0) -> 1 | M6: =IFERROR(IF(ISBLANK([1]DFsmonkeyCompl!O7),"",[1]DFsmonkeyCompl!O7*DFanalysis[[#This Row],[EUR]]),"") -> 435 | N6: =IFERROR(IF(ISBLANK([1]DFsmonkeyCompl!P7),"",[1]DFsmonkeyCompl!P7*DFanalysis[[#This Row],[EUR]]),"") -> 310 | O6: =IFERROR(IF(ISBLANK([1]DFsmonkeyCompl!Q7),"",[1]DFsmonkeyCompl!Q7*DFanalysis[[#This Row],[EUR]]),"") -> 100 | P6: =IFERROR(IF(ISBLANK([1]DFsmonkeyCompl!R7),"",[1]DFsmonkeyCompl!R7*DFanalysis[[#This Row],[EUR]]),"") | Q6: =IFERROR(IF(ISBLANK([1]DFsmonkeyCompl!S7),"",[1]DFsmonkeyCompl!S7*DFanalysis[[#This Row],[EUR]]),"") | R6: =IFERROR(IF(ISBLANK([1]DFsmonkeyCompl!T7),"",[1]DFsmonkeyCompl!T7*DFanalysis[[#This Row],[EUR]]),"") | S6: =IFERROR(IF(ISBLANK([1]DFsmonkeyCompl!U7),"",[1]DFsmonkeyCompl!U7*DFanalysis[[#This Row],[EUR]]),"") | T6: =IFERROR(IF(ISBLANK([1]DFsmonkeyCompl!V7),"",[1]DFsmonkeyCompl!V7*DFanalysis[[#This Row],[EUR]]),"") | ... Z6: =IFERROR(IF(ISBLANK([1]DFsmonkeyCompl!AB7),"",[1]DFsmonkeyCompl!AB7*DFanalysis[[#This Row],[EUR]]),"") | AA6: =IF(ISBLANK([1]DFsmonkeyCompl!AC7),"",[1]DFsmonkeyCompl!AC7) | AB6: =IF(ISBLANK([1]DFsmonkeyCompl!AD7),"",[1]DFsmonkeyCompl!AD7) | AC6: =IF(ISBLANK([1]DFsmonkeyCompl!AE7),"",[1]DFsmonkeyCompl!AE7) -> 100 | AD6: =IF(ISBLANK([1]DFsmonkeyCompl!AF7),"",[1]DFsmonkeyCompl!AF7) | AE6: =IF(ISBLANK([1]DFsmonkeyCompl!AG7),"",[1]DFsmonkeyCompl!AG7) -> Increase | AF6: =IF(ISBLANK([1]DFsmonkeyCompl!AH7),"",[1]DFsmonkeyCompl!AH7) -> Yes
A7: =IF(OR(ISTEXT([1]DFsmonkeyCompl!J8),ISNUMBER([1]DFsmonkeyCompl!J8)),[1]DFsmonkeyCompl!J8,"") -> Octopus Investments | B7: =IF(OR(ISTEXT([1]DFsmonkeyCompl!K8),ISNUMBER([1]DFsmonkeyCompl!K8)),[1]DFsmonkeyCompl!K8,"") -> Commercial Real Estate Debt Fund | C7: 18415 | D7: =INDEX([1]DebtFundUniverse!$B$2:$EU$200,MATCH(DFanalysis[[#This Row],[ID]],[1]DebtFundUniverse!$A$2:$A$200,0),MATCH(DFanalysis[[#Headers],[Loan Strategy]],[1]DebtFundUniverse!$B$1:$EU$1,0)) -> Senior | E7: =INDEX([1]DebtFundUniverse!$B$2:$EU$200,MATCH(DFanalysis[[#This Row],[ID]],[1]DebtFundUniverse!$A$2:$A$200,0),MATCH(DFanalysis[[#Headers],[Target Regional Strategy]],[1]DebtFundUniverse!$B$1:$EU$1,0)) -> Europe | F7: =INDEX([1]DebtFundUniverse!$B$2:$EU$200,MATCH(DFanalysis[[#This Row],[ID]],[1]DebtFundUniverse!$A$2:$A$200,0),MATCH(DFanalysis[[#Headers],[Vehicle Structure]],[1]DebtFundUniverse!$B$1:$EU$1,0)) -> Closed end | G7: =INDEX([1]DebtFundUniverse!$B$2:$EU$200,MATCH(DFanalysis[[#This Row],[ID]],[1]DebtFundUniverse!$A$2:$A$200,0),MATCH(DFanalysis[[#Headers],[year of first closing]],[1]DebtFundUniverse!$B$1:$EU$1,0)) -> 2014 | H7: =IF(ISBLANK([1]DFsmonkeyCompl!L8),"",[1]DFsmonkeyCompl!L8) -> No | I7: =IF(ISBLANK([1]DFsmonkeyCompl!M8),"",[1]DFsmonkeyCompl!M8) -> Other (please specify) | J7: =IF(ISBLANK([1]DFsmonkeyCompl!N8),"",[1]DFsmonkeyCompl!N8) -> Market | K7: =INDEX([1]DebtFundUniverse!$B$2:$EU$200,MATCH(DFanalysis[[#This Row],[ID]],[1]DebtFundUniverse!$A$2:$A$200,0),MATCH(DFanalysis[[#Headers],[Currency of Reporting]],[1]DebtFundUniverse!$B$1:$EU$1,0)) -> GBP | L7: =VLOOKUP(DFanalysis[[#This Row],[Currency of Reporting]],'[1]Xrate31.12.20'!$K$1:$M$25,3,0) -> 1.1130928 | M7: =IFERROR(IF(ISBLANK([1]DFsmonkeyCompl!O8),"",[1]DFsmonkeyCompl!O8*DFanalysis[[#This Row],[EUR]]),"") | N7: =IFERROR(IF(ISBLANK([1]DFsmonkeyCompl!P8),"",[1]DFsmonkeyCompl!P8*DFanalysis[[#This Row],[EUR]]),"") | O7: =IFERROR(IF(ISBLANK([1]DFsmonkeyCompl!Q8),"",[1]DFsmonkeyCompl!Q8*DFanalysis[[#This Row],[EUR]]),"") | P7: =IFERROR(IF(ISBLANK([1]DFsmonkeyCompl!R8),"",[1]DFsmonkeyCompl!R8*DFanalysis[[#This Row],[EUR]]),"") | Q7: =IFERROR(IF(ISBLANK([1]DFsmonkeyCompl!S8),"",[1]DFsmonkeyCompl!S8*DFanalysis[[#This Row],[EUR]]),"") | R7: =IFERROR(IF(ISBLANK([1]DFsmonkeyCompl!T8),"",[1]DFsmonkeyCompl!T8*DFanalysis[[#This Row],[EUR]]),"") | S7: =IFERROR(IF(ISBLANK([1]DFsmonkeyCompl!U8),"",[1]DFsmonkeyCompl!U8*DFanalysis[[#This Row],[EUR]]),"") | T7: =IFERROR(IF(ISBLANK([1]DFsmonkeyCompl!V8),"",[1]DFsmonkeyCompl!V8*DFanalysis[[#This Row],[EUR]]),"") | ... Z7: =IFERROR(IF(ISBLANK([1]DFsmonkeyCompl!AB8),"",[1]DFsmonkeyCompl!AB8*DFanalysis[[#This Row],[EUR]]),"") | AA7: =IF(ISBLANK([1]DFsmonkeyCompl!AC8),"",[1]DFsmonkeyCompl!AC8) | AB7: =IF(ISBLANK([1]DFsmonkeyCompl!AD8),"",[1]DFsmonkeyCompl!AD8) | AC7: =IF(ISBLANK([1]DFsmonkeyCompl!AE8),"",[1]DFsmonkeyCompl!AE8) | AD7: =IF(ISBLANK([1]DFsmonkeyCompl!AF8),"",[1]DFsmonkeyCompl!AF8) | AE7: =IF(ISBLANK([1]DFsmonkeyCompl!AG8),"",[1]DFsmonkeyCompl!AG8) -> Increase | AF7: =IF(ISBLANK([1]DFsmonkeyCompl!AH8),"",[1]DFsmonkeyCompl!AH8) -> Yes
A8: =IF(OR(ISTEXT([1]DFsmonkeyCompl!J9),ISNUMBER([1]DFsmonkeyCompl!J9)),[1]DFsmonkeyCompl!J9,"") -> LaSalle Investment Management | B8: =IF(OR(ISTEXT([1]DFsmonkeyCompl!K9),ISNUMBER([1]DFsmonkeyCompl!K9)),[1]DFsmonkeyCompl!K9,"") -> LaSalle Whole Loan Strategy I | C8: {=INDEX([1]DebtFundUniverse!$A$85:$A$95,MATCH(B8,[1]DebtFundUniverse!$B$85:$B$95,0),0)} -> 101287 | D8: =INDEX([1]DebtFundUniverse!$B$2:$EU$200,MATCH(DFanalysis[[#This Row],[ID]],[1]DebtFundUniverse!$A$2:$A$200,0),MATCH(DFanalysis[[#Headers],[Loan Strategy]],[1]DebtFundUniverse!$B$1:$EU$1,0)) -> Whole Loans | E8: =INDEX([1]DebtFundUniverse!$B$2:$EU$200,MATCH(DFanalysis[[#This Row],[ID]],[1]DebtFundUniverse!$A$2:$A$200,0),MATCH(DFanalysis[[#Headers],[Target Regional Strategy]],[1]DebtFundUniverse!$B$1:$EU$1,0)) -> Europe | F8: =INDEX([1]DebtFundUniverse!$B$2:$EU$200,MATCH(DFanalysis[[#This Row],[ID]],[1]DebtFundUniverse!$A$2:$A$200,0),MATCH(DFanalysis[[#Headers],[Vehicle Structure]],[1]DebtFundUniverse!$B$1:$EU$1,0)) -> Closed end | G8: =INDEX([1]DebtFundUniverse!$B$2:$EU$200,MATCH(DFanalysis[[#This Row],[ID]],[1]DebtFundUniverse!$A$2:$A$200,0),MATCH(DFanalysis[[#Headers],[year of first closing]],[1]DebtFundUniverse!$B$1:$EU$1,0)) -> 2019 | H8: =IF(ISBLANK([1]DFsmonkeyCompl!L9),"",[1]DFsmonkeyCompl!L9) -> Yes | I8: =IF(ISBLANK([1]DFsmonkeyCompl!M9),"",[1]DFsmonkeyCompl!M9) | J8: =IF(ISBLANK([1]DFsmonkeyCompl!N9),"",[1]DFsmonkeyCompl!N9) | K8: =INDEX([1]DebtFundUniverse!$B$2:$EU$200,MATCH(DFanalysis[[#This Row],[ID]],[1]DebtFundUniverse!$A$2:$A$200,0),MATCH(DFanalysis[[#Headers],[Currency of Reporting]],[1]DebtFundUniverse!$B$1:$EU$1,0)) -> EUR | L8: =VLOOKUP(DFanalysis[[#This Row],[Currency of Reporting]],'[1]Xrate31.12.20'!$K$1:$M$25,3,0) -> 1 | M8: =IFERROR(IF(ISBLANK([1]DFsmonkeyCompl!O9),"",[1]DFsmonkeyCompl!O9*DFanalysis[[#This Row],[EUR]]),"") -> 300 | N8: =IFERROR(IF(ISBLANK([1]DFsmonkeyCompl!P9),"",[1]DFsmonkeyCompl!P9*DFanalysis[[#This Row],[EUR]]),"") | O8: =IFERROR(IF(ISBLANK([1]DFsmonkeyCompl!Q9),"",[1]DFsmonkeyCompl!Q9*DFanalysis[[#This Row],[EUR]]),"") -> 300 | P8: =IFERROR(IF(ISBLANK([1]DFsmonkeyCompl!R9),"",[1]DFsmonkeyCompl!R9*DFanalysis[[#This Row],[EUR]]),"") | Q8: =IFERROR(IF(ISBLANK([1]DFsmonkeyCompl!S9),"",[1]DFsmonkeyCompl!S9*DFanalysis[[#This Row],[EUR]]),"") | R8: =IFERROR(IF(ISBLANK([1]DFsmonkeyCompl!T9),"",[1]DFsmonkeyCompl!T9*DFanalysis[[#This Row],[EUR]]),"") | S8: =IFERROR(IF(ISBLANK([1]DFsmonkeyCompl!U9),"",[1]DFsmonkeyCompl!U9*DFanalysis[[#This Row],[EUR]]),"") | T8: =IFERROR(IF(ISBLANK([1]DFsmonkeyCompl!V9),"",[1]DFsmonkeyCompl!V9*DFanalysis[[#This Row],[EUR]]),"") | ... Z8: =IFERROR(IF(ISBLANK([1]DFsmonkeyCompl!AB9),"",[1]DFsmonkeyCompl!AB9*DFanalysis[[#This Row],[EUR]]),"") | AA8: =IF(ISBLANK([1]DFsmonkeyCompl!AC9),"",[1]DFsmonkeyCompl!AC9) | AB8: =IF(ISBLANK([1]DFsmonkeyCompl!AD9),"",[1]DFsmonkeyCompl!AD9) | AC8: =IF(ISBLANK([1]DFsmonkeyCompl!AE9),"",[1]DFsmonkeyCompl!AE9) -> 100 | AD8: =IF(ISBLANK([1]DFsmonkeyCompl!AF9),"",[1]DFsmonkeyCompl!AF9) | AE8: =IF(ISBLANK([1]DFsmonkeyCompl!AG9),"",[1]DFsmonkeyCompl!AG9) -> Increase | AF8: =IF(ISBLANK([1]DFsmonkeyCompl!AH9),"",[1]DFsmonkeyCompl!AH9) -> Yes
A9: =IF(OR(ISTEXT([1]DFsmonkeyCompl!J10),ISNUMBER([1]DFsmonkeyCompl!J10)),[1]DFsmonkeyCompl!J10,"") -> LaSalle Investment Management | B9: =IF(OR(ISTEXT([1]DFsmonkeyCompl!K10),ISNUMBER([1]DFsmonkeyCompl!K10)),[1]DFsmonkeyCompl!K10,"") -> LaSalle Real Estate Strategies IV | C9: {=INDEX([1]DebtFundUniverse!$A$85:$A$95,MATCH(B9,[1]DebtFundUniverse!$B$85:$B$95,0),0)} -> 105571 | D9: =INDEX([1]DebtFundUniverse!$B$2:$EU$200,MATCH(DFanalysis[[#This Row],[ID]],[1]DebtFundUniverse!$A$2:$A$200,0),MATCH(DFanalysis[[#Headers],[Loan Strategy]],[1]DebtFundUniverse!$B$1:$EU$1,0)) -> Subordinated: Junior+Mezzanine | E9: =INDEX([1]DebtFundUniverse!$B$2:$EU$200,MATCH(DFanalysis[[#This Row],[ID]],[1]DebtFundUniverse!$A$2:$A$200,0),MATCH(DFanalysis[[#Headers],[Target Regional Strategy]],[1]DebtFundUniverse!$B$1:$EU$1,0)) -> Europe | F9: =INDEX([1]DebtFundUniverse!$B$2:$EU$200,MATCH(DFanalysis[[#This Row],[ID]],[1]DebtFundUniverse!$A$2:$A$200,0),MATCH(DFanalysis[[#Headers],[Vehicle Structure]],[1]DebtFundUniverse!$B$1:$EU$1,0)) -> Closed end | G9: =INDEX([1]DebtFundUniverse!$B$2:$EU$200,MATCH(DFanalysis[[#This Row],[ID]],[1]DebtFundUniverse!$A$2:$A$200,0),MATCH(DFanalysis[[#Headers],[year of first closing]],[1]DebtFundUniverse!$B$1:$EU$1,0)) -> 2020 | H9: =IF(ISBLANK([1]DFsmonkeyCompl!L10),"",[1]DFsmonkeyCompl!L10) -> Yes | I9: =IF(ISBLANK([1]DFsmonkeyCompl!M10),"",[1]DFsmonkeyCompl!M10) | J9: =IF(ISBLANK([1]DFsmonkeyCompl!N10),"",[1]DFsmonkeyCompl!N10) | K9: =INDEX([1]DebtFundUniverse!$B$2:$EU$200,MATCH(DFanalysis[[#This Row],[ID]],[1]DebtFundUniverse!$A$2:$A$200,0),MATCH(DFanalysis[[#Headers],[Currency of Reporting]],[1]DebtFundUniverse!$B$1:$EU$1,0)) -> EUR | L9: =VLOOKUP(DFanalysis[[#This Row],[Currency of Reporting]],'[1]Xrate31.12.20'!$K$1:$M$25,3,0) -> 1 | M9: =IFERROR(IF(ISBLANK([1]DFsmonkeyCompl!O10),"",[1]DFsmonkeyCompl!O10*DFanalysis[[#This Row],[EUR]]),"") | N9: =IFERROR(IF(ISBLANK([1]DFsmonkeyCompl!P10),"",[1]DFsmonkeyCompl!P10*DFanalysis[[#This Row],[EUR]]),"") | O9: =IFERROR(IF(ISBLANK([1]DFsmonkeyCompl!Q10),"",[1]DFsmonkeyCompl!Q10*DFanalysis[[#This Row],[EUR]]),"") | P9: =IFERROR(IF(ISBLANK([1]DFsmonkeyCompl!R10),"",[1]DFsmonkeyCompl!R10*DFanalysis[[#This Row],[EUR]]),"") | Q9: =IFERROR(IF(ISBLANK([1]DFsmonkeyCompl!S10),"",[1]DFsmonkeyCompl!S10*DFanalysis[[#This Row],[EUR]]),"") | R9: =IFERROR(IF(ISBLANK([1]DFsmonkeyCompl!T10),"",[1]DFsmonkeyCompl!T10*DFanalysis[[#This Row],[EUR]]),"") | S9: =IFERROR(IF(ISBLANK([1]DFsmonkeyCompl!U10),"",[1]DFsmonkeyCompl!U10*DFanalysis[[#This Row],[EUR]]),"") | T9: =IFERROR(IF(ISBLANK([1]DFsmonkeyCompl!V10),"",[1]DFsmonkeyCompl!V10*DFanalysis[[#This Row],[EUR]]),"") | ... Z9: =IFERROR(IF(ISBLANK([1]DFsmonkeyCompl!AB10),"",[1]DFsmonkeyCompl!AB10*DFanalysis[[#This Row],[EUR]]),"") | AA9: =IF(ISBLANK([1]DFsmonkeyCompl!AC10),"",[1]DFsmonkeyCompl!AC10) | AB9: =IF(ISBLANK([1]DFsmonkeyCompl!AD10),"",[1]DFsmonkeyCompl!AD10) | AC9: =IF(ISBLANK([1]DFsmonkeyCompl!AE10),"",[1]DFsmonkeyCompl!AE10) | AD9: =IF(ISBLANK([1]DFsmonkeyCompl!AF10),"",[1]DFsmonkeyCompl!AF10) | AE9: =IF(ISBLANK([1]DFsmonkeyCompl!AG10),"",[1]DFsmonkeyCompl!AG10) | AF9: =IF(ISBLANK([1]DFsmonkeyCompl!AH10),"",[1]DFsmonkeyCompl!AH10)
A10: =IF(OR(ISTEXT([1]DFsmonkeyCompl!J11),ISNUMBER([1]DFsmonkeyCompl!J11)),[1]DFsmonkeyCompl!J11,"") -> Octopus Real Estate | B10: =IF(OR(ISTEXT([1]DFsmonkeyCompl!K11),ISNUMBER([1]DFsmonkeyCompl!K11)),[1]DFsmonkeyCompl!K11,"") -> CREDF II-S | C10: 73412 | D10: =INDEX([1]DebtFundUniverse!$B$2:$EU$200,MATCH(DFanalysis[[#This Row],[ID]],[1]DebtFundUniverse!$A$2:$A$200,0),MATCH(DFanalysis[[#Headers],[Loan Strategy]],[1]DebtFundUniverse!$B$1:$EU$1,0)) -> Subordinated: Junior+Mezzanine | E10: =INDEX([1]DebtFundUniverse!$B$2:$EU$200,MATCH(DFanalysis[[#This Row],[ID]],[1]DebtFundUniverse!$A$2:$A$200,0),MATCH(DFanalysis[[#Headers],[Target Regional Strategy]],[1]DebtFundUniverse!$B$1:$EU$1,0)) -> Europe | F10: =INDEX([1]DebtFundUniverse!$B$2:$EU$200,MATCH(DFanalysis[[#This Row],[ID]],[1]DebtFundUniverse!$A$2:$A$200,0),MATCH(DFanalysis[[#Headers],[Vehicle Structure]],[1]DebtFundUniverse!$B$1:$EU$1,0)) -> Closed end | G10: =INDEX([1]DebtFundUniverse!$B$2:$EU$200,MATCH(DFanalysis[[#This Row],[ID]],[1]DebtFundUniverse!$A$2:$A$200,0),MATCH(DFanalysis[[#Headers],[year of first closing]],[1]DebtFundUniverse!$B$1:$EU$1,0)) -> 2017 | H10: =IF(ISBLANK([1]DFsmonkeyCompl!L11),"",[1]DFsmonkeyCompl!L11) -> Yes | I10: =IF(ISBLANK([1]DFsmonkeyCompl!M11),"",[1]DFsmonkeyCompl!M11) | J10: =IF(ISBLANK([1]DFsmonkeyCompl!N11),"",[1]DFsmonkeyCompl!N11) | K10: =INDEX([1]DebtFundUniverse!$B$2:$EU$200,MATCH(DFanalysis[[#This Row],[ID]],[1]DebtFundUniverse!$A$2:$A$200,0),MATCH(DFanalysis[[#Headers],[Currency of Reporting]],[1]DebtFundUniverse!$B$1:$EU$1,0)) -> GBP | L10: =VLOOKUP(DFanalysis[[#This Row],[Currency of Reporting]],'[1]Xrate31.12.20'!$K$1:$M$25,3,0) -> 1.1130928 | M10: =IFERROR(IF(ISBLANK([1]DFsmonkeyCompl!O11),"",[1]DFsmonkeyCompl!O11*DFanalysis[[#This Row],[EUR]]),"") -> 84.595052 | N10: =IFERROR(IF(ISBLANK([1]DFsmonkeyCompl!P11),"",[1]DFsmonkeyCompl!P11*DFanalysis[[#This Row],[EUR]]),"") -> 28.940413 | O10: =IFERROR(IF(ISBLANK([1]DFsmonkeyCompl!Q11),"",[1]DFsmonkeyCompl!Q11*DFanalysis[[#This Row],[EUR]]),"") | P10: =IFERROR(IF(ISBLANK([1]DFsmonkeyCompl!R11),"",[1]DFsmonkeyCompl!R11*DFanalysis[[#This Row],[EUR]]),"") | Q10: =IFERROR(IF(ISBLANK([1]DFsmonkeyCompl!S11),"",[1]DFsmonkeyCompl!S11*DFanalysis[[#This Row],[EUR]]),"") | R10: =IFERROR(IF(ISBLANK([1]DFsmonkeyCompl!T11),"",[1]DFsmonkeyCompl!T11*DFanalysis[[#This Row],[EUR]]),"") | S10: =IFERROR(IF(ISBLANK([1]DFsmonkeyCompl!U11),"",[1]DFsmonkeyCompl!U11*DFanalysis[[#This Row],[EUR]]),"") -> 55.654639 | T10: =IFERROR(IF(ISBLANK([1]DFsmonkeyCompl!V11),"",[1]DFsmonkeyCompl!V11*DFanalysis[[#This Row],[EUR]]),"") | ... Z10: =IFERROR(IF(ISBLANK([1]DFsmonkeyCompl!AB11),"",[1]DFsmonkeyCompl!AB11*DFanalysis[[#This Row],[EUR]]),"") | AA10: =IF(ISBLANK([1]DFsmonkeyCompl!AC11),"",[1]DFsmonkeyCompl!AC11) -> 0 | AB10: =IF(ISBLANK([1]DFsmonkeyCompl!AD11),"",[1]DFsmonkeyCompl!AD11) -> 0 | AC10: =IF(ISBLANK([1]DFsmonkeyCompl!AE11),"",[1]DFsmonkeyCompl!AE11) -> 100 | AD10: =IF(ISBLANK([1]DFsmonkeyCompl!AF11),"",[1]DFsmonkeyCompl!AF11) -> 0 | AE10: =IF(ISBLANK([1]DFsmonkeyCompl!AG11),"",[1]DFsmonkeyCompl!AG11) -> Increase | AF10: =IF(ISBLANK([1]DFsmonkeyCompl!AH11),"",[1]DFsmonkeyCompl!AH11) -> Yes
A11: =IF(OR(ISTEXT([1]DFsmonkeyCompl!J12),ISNUMBER([1]DFsmonkeyCompl!J12)),[1]DFsmonkeyCompl!J12,"") -> AgFe LLP | B11: =IF(OR(ISTEXT([1]DFsmonkeyCompl!K12),ISNUMBER([1]DFsmonkeyCompl!K12)),[1]DFsmonkeyCompl!K12,"") -> Managed Accounts | C11: 17383 | D11: =INDEX([1]DebtFundUniverse!$B$2:$EU$200,MATCH(DFanalysis[[#This Row],[ID]],[1]DebtFundUniverse!$A$2:$A$200,0),MATCH(DFanalysis[[#Headers],[Loan Strategy]],[1]DebtFundUniverse!$B$1:$EU$1,0)) -> Senior | E11: =INDEX([1]DebtFundUniverse!$B$2:$EU$200,MATCH(DFanalysis[[#This Row],[ID]],[1]DebtFundUniverse!$A$2:$A$200,0),MATCH(DFanalysis[[#Headers],[Target Regional Strategy]],[1]DebtFundUniverse!$B$1:$EU$1,0)) -> 0 | F11: =INDEX([1]DebtFundUniverse!$B$2:$EU$200,MATCH(DFanalysis[[#This Row],[ID]],[1]DebtFundUniverse!$A$2:$A$200,0),MATCH(DFanalysis[[#Headers],[Vehicle Structure]],[1]DebtFundUniverse!$B$1:$EU$1,0)) -> Closed end | G11: =INDEX([1]DebtFundUniverse!$B$2:$EU$200,MATCH(DFanalysis[[#This Row],[ID]],[1]DebtFundUniverse!$A$2:$A$200,0),MATCH(DFanalysis[[#Headers],[year of first closing]],[1]DebtFundUniverse!$B$1:$EU$1,0)) -> 2014 | H11: =IF(ISBLANK([1]DFsmonkeyCompl!L12),"",[1]DFsmonkeyCompl!L12) -> Yes | I11: =IF(ISBLANK([1]DFsmonkeyCompl!M12),"",[1]DFsmonkeyCompl!M12) | J11: =IF(ISBLANK([1]DFsmonkeyCompl!N12),"",[1]DFsmonkeyCompl!N12) | K11: =INDEX([1]DebtFundUniverse!$B$2:$EU$200,MATCH(DFanalysis[[#This Row],[ID]],[1]DebtFundUniverse!$A$2:$A$200,0),MATCH(DFanalysis[[#Headers],[Currency of Reporting]],[1]DebtFundUniverse!$B$1:$EU$1,0)) -> GBP | L11: =VLOOKUP(DFanalysis[[#This Row],[Currency of Reporting]],'[1]Xrate31.12.20'!$K$1:$M$25,3,0) -> 1.1130928 | M11: =IFERROR(IF(ISBLANK([1]DFsmonkeyCompl!O12),"",[1]DFsmonkeyCompl!O12*DFanalysis[[#This Row],[EUR]]),"") -> 890.47423 | N11: =IFERROR(IF(ISBLANK([1]DFsmonkeyCompl!P12),"",[1]DFsmonkeyCompl!P12*DFanalysis[[#This Row],[EUR]]),"") | O11: =IFERROR(IF(ISBLANK([1]DFsmonkeyCompl!Q12),"",[1]DFsmonkeyCompl!Q12*DFanalysis[[#This Row],[EUR]]),"") -> 890.47423 | P11: =IFERROR(IF(ISBLANK([1]DFsmonkeyCompl!R12),"",[1]DFsmonkeyCompl!R12*DFanalysis[[#This Row],[EUR]]),"") | Q11: =IFERROR(IF(ISBLANK([1]DFsmonkeyCompl!S12),"",[1]DFsmonkeyCompl!S12*DFanalysis[[#This Row],[EUR]]),"") | R11: =IFERROR(IF(ISBLANK([1]DFsmonkeyCompl!T12),"",[1]DFsmonkeyCompl!T12*DFanalysis[[#This Row],[EUR]]),"") | S11: =IFERROR(IF(ISBLANK([1]DFsmonkeyCompl!U12),"",[1]DFsmonkeyCompl!U12*DFanalysis[[#This Row],[EUR]]),"") | T11: =IFERROR(IF(ISBLANK([1]DFsmonkeyCompl!V12),"",[1]DFsmonkeyCompl!V12*DFanalysis[[#This Row],[EUR]]),"") | ... Z11: =IFERROR(IF(ISBLANK([1]DFsmonkeyCompl!AB12),"",[1]DFsmonkeyCompl!AB12*DFanalysis[[#This Row],[EUR]]),"") | AA11: =IF(ISBLANK([1]DFsmonkeyCompl!AC12),"",[1]DFsmonkeyCompl!AC12) | AB11: =IF(ISBLANK([1]DFsmonkeyCompl!AD12),"",[1]DFsmonkeyCompl!AD12) | AC11: =IF(ISBLANK([1]DFsmonkeyCompl!AE12),"",[1]DFsmonkeyCompl!AE12) -> 100 | AD11: =IF(ISBLANK([1]DFsmonkeyCompl!AF12),"",[1]DFsmonkeyCompl!AF12) | AE11: =IF(ISBLANK([1]DFsmonkeyCompl!AG12),"",[1]DFsmonkeyCompl!AG12) -> Decrease | AF11: =IF(ISBLANK([1]DFsmonkeyCompl!AH12),"",[1]DFsmonkeyCompl!AH12) -> Yes
A12: =IF(OR(ISTEXT([1]DFsmonkeyCompl!J13),ISNUMBER([1]DFsmonkeyCompl!J13)),[1]DFsmonkeyCompl!J13,"") -> Generali Real Estate SGR S.p.A. | B12: =IF(OR(ISTEXT([1]DFsmonkeyCompl!K13),ISNUMBER([1]DFsmonkeyCompl!K13)),[1]DFsmonkeyCompl!K13,"") -> Generali Real Estate Debt Investment Fund | C12: 19302 | D12: =INDEX([1]DebtFundUniverse!$B$2:$EU$200,MATCH(DFanalysis[[#This Row],[ID]],[1]DebtFundUniverse!$A$2:$A$200,0),MATCH(DFanalysis[[#Headers],[Loan Strategy]],[1]DebtFundUniverse!$B$1:$EU$1,0)) -> Mixed: Senior+Subordinated | E12: =INDEX([1]DebtFundUniverse!$B$2:$EU$200,MATCH(DFanalysis[[#This Row],[ID]],[1]DebtFundUniverse!$A$2:$A$200,0),MATCH(DFanalysis[[#Headers],[Target Regional Strategy]],[1]DebtFundUniverse!$B$1:$EU$1,0)) -> 0 | F12: =INDEX([1]DebtFundUniverse!$B$2:$EU$200,MATCH(DFanalysis[[#This Row],[ID]],[1]DebtFundUniverse!$A$2:$A$200,0),MATCH(DFanalysis[[#Headers],[Vehicle Structure]],[1]DebtFundUniverse!$B$1:$EU$1,0)) -> Closed end | G12: =INDEX([1]DebtFundUniverse!$B$2:$EU$200,MATCH(DFanalysis[[#This Row],[ID]],[1]DebtFundUniverse!$A$2:$A$200,0),MATCH(DFanalysis[[#Headers],[year of first closing]],[1]DebtFundUniverse!$B$1:$EU$1,0)) -> 2019 | H12: =IF(ISBLANK([1]DFsmonkeyCompl!L13),"",[1]DFsmonkeyCompl!L13) -> Yes | I12: =IF(ISBLANK([1]DFsmonkeyCompl!M13),"",[1]DFsmonkeyCompl!M13) | J12: =IF(ISBLANK([1]DFsmonkeyCompl!N13),"",[1]DFsmonkeyCompl!N13) | K12: =INDEX([1]DebtFundUniverse!$B$2:$EU$200,MATCH(DFanalysis[[#This Row],[ID]],[1]DebtFundUniverse!$A$2:$A$200,0),MATCH(DFanalysis[[#Headers],[Currency of Reporting]],[1]DebtFundUniverse!$B$1:$EU$1,0)) -> EUR | L12: =VLOOKUP(DFanalysis[[#This Row],[Currency of Reporting]],'[1]Xrate31.12.20'!$K$1:$M$25,3,0) -> 1 | M12: =IFERROR(IF(ISBLANK([1]DFsmonkeyCompl!O13),"",[1]DFsmonkeyCompl!O13*DFanalysis[[#This Row],[EUR]]),"") -> 214 | N12: =IFERROR(IF(ISBLANK([1]DFsmonkeyCompl!P13),"",[1]DFsmonkeyCompl!P13*DFanalysis[[#This Row],[EUR]]),"") | O12: =IFERROR(IF(ISBLANK([1]DFsmonkeyCompl!Q13),"",[1]DFsmonkeyCompl!Q13*DFanalysis[[#This Row],[EUR]]),"") -> 214 | P12: =IFERROR(IF(ISBLANK([1]DFsmonkeyCompl!R13),"",[1]DFsmonkeyCompl!R13*DFanalysis[[#This Row],[EUR]]),"") | Q12: =IFERROR(IF(ISBLANK([1]DFsmonkeyCompl!S13),"",[1]DFsmonkeyCompl!S13*DFanalysis[[#This Row],[EUR]]),"") | R12: =IFERROR(IF(ISBLANK([1]DFsmonkeyCompl!T13),"",[1]DFsmonkeyCompl!T13*DFanalysis[[#This Row],[EUR]]),"") | S12: =IFERROR(IF(ISBLANK([1]DFsmonkeyCompl!U13),"",[1]DFsmonkeyCompl!U13*DFanalysis[[#This Row],[EUR]]),"") | T12: =IFERROR(IF(ISBLANK([1]DFsmonkeyCompl!V13),"",[1]DFsmonkeyCompl!V13*DFanalysis[[#This Row],[EUR]]),"") | ... Z12: =IFERROR(IF(ISBLANK([1]DFsmonkeyCompl!AB13),"",[1]DFsmonkeyCompl!AB13*DFanalysis[[#This Row],[EUR]]),"") | AA12: =IF(ISBLANK([1]DFsmonkeyCompl!AC13),"",[1]DFsmonkeyCompl!AC13) | AB12: =IF(ISBLANK([1]DFsmonkeyCompl!AD13),"",[1]DFsmonkeyCompl!AD13) | AC12: =IF(ISBLANK([1]DFsmonkeyCompl!AE13),"",[1]DFsmonkeyCompl!AE13) -> 100 | AD12: =IF(ISBLANK([1]DFsmonkeyCompl!AF13),"",[1]DFsmonkeyCompl!AF13) | AE12: =IF(ISBLANK([1]DFsmonkeyCompl!AG13),"",[1]DFsmonkeyCompl!AG13) | AF12: =IF(ISBLANK([1]DFsmonkeyCompl!AH13),"",[1]DFsmonkeyCompl!AH13)
A13: =IF(OR(ISTEXT([1]DFsmonkeyCompl!J14),ISNUMBER([1]DFsmonkeyCompl!J14)),[1]DFsmonkeyCompl!J14,"") -> DRC Capital | B13: =IF(OR(ISTEXT([1]DFsmonkeyCompl!K14),ISNUMBER([1]DFsmonkeyCompl!K14)),[1]DFsmonkeyCompl!K14,"") -> European Real Estate Senior Debt 6 | C13: {=INDEX([1]DebtFundUniverse!$A$85:$A$95,MATCH(B13,[1]DebtFundUniverse!$B$85:$B$95,0),0)} -> XXX/ | D13: =INDEX([1]DebtFundUniverse!$B$2:$EU$200,MATCH(DFanalysis[[#This Row],[ID]],[1]DebtFundUniverse!$A$2:$A$200,0),MATCH(DFanalysis[[#Headers],[Loan Strategy]],[1]DebtFundUniverse!$B$1:$EU$1,0)) -> #N/A | E13: =INDEX([1]DebtFundUniverse!$B$2:$EU$200,MATCH(DFanalysis[[#This Row],[ID]],[1]DebtFundUniverse!$A$2:$A$200,0),MATCH(DFanalysis[[#Headers],[Target Regional Strategy]],[1]DebtFundUniverse!$B$1:$EU$1,0)) -> #N/A | F13: =INDEX([1]DebtFundUniverse!$B$2:$EU$200,MATCH(DFanalysis[[#This Row],[ID]],[1]DebtFundUniverse!$A$2:$A$200,0),MATCH(DFanalysis[[#Headers],[Vehicle Structure]],[1]DebtFundUniverse!$B$1:$EU$1,0)) -> #N/A | G13: =INDEX([1]DebtFundUniverse!$B$2:$EU$200,MATCH(DFanalysis[[#This Row],[ID]],[1]DebtFundUniverse!$A$2:$A$200,0),MATCH(DFanalysis[[#Headers],[year of first closing]],[1]DebtFundUniverse!$B$1:$EU$1,0)) -> #N/A | H13: =IF(ISBLANK([1]DFsmonkeyCompl!L14),"",[1]DFsmonkeyCompl!L14) -> Yes | I13: =IF(ISBLANK([1]DFsmonkeyCompl!M14),"",[1]DFsmonkeyCompl!M14) | J13: =IF(ISBLANK([1]DFsmonkeyCompl!N14),"",[1]DFsmonkeyCompl!N14) | K13: =INDEX([1]DebtFundUniverse!$B$2:$EU$200,MATCH(DFanalysis[[#This Row],[ID]],[1]DebtFundUniverse!$A$2:$A$200,0),MATCH(DFanalysis[[#Headers],[Currency of Reporting]],[1]DebtFundUniverse!$B$1:$EU$1,0)) -> #N/A | L13: =VLOOKUP(DFanalysis[[#This Row],[Currency of Reporting]],'[1]Xrate31.12.20'!$K$1:$M$25,3,0) -> #N/A | M13: =IFERROR(IF(ISBLANK([1]DFsmonkeyCompl!O14),"",[1]DFsmonkeyCompl!O14*DFanalysis[[#This Row],[EUR]]),"") | N13: =IFERROR(IF(ISBLANK([1]DFsmonkeyCompl!P14),"",[1]DFsmonkeyCompl!P14*DFanalysis[[#This Row],[EUR]]),"") | O13: =IFERROR(IF(ISBLANK([1]DFsmonkeyCompl!Q14),"",[1]DFsmonkeyCompl!Q14*DFanalysis[[#This Row],[EUR]]),"") | P13: =IFERROR(IF(ISBLANK([1]DFsmonkeyCompl!R14),"",[1]DFsmonkeyCompl!R14*DFanalysis[[#This Row],[EUR]]),"") | Q13: =IFERROR(IF(ISBLANK([1]DFsmonkeyCompl!S14),"",[1]DFsmonkeyCompl!S14*DFanalysis[[#This Row],[EUR]]),"") | R13: =IFERROR(IF(ISBLANK([1]DFsmonkeyCompl!T14),"",[1]DFsmonkeyCompl!T14*DFanalysis[[#This Row],[EUR]]),"") | S13: =IFERROR(IF(ISBLANK([1]DFsmonkeyCompl!U14),"",[1]DFsmonkeyCompl!U14*DFanalysis[[#This Row],[EUR]]),"") | T13: =IFERROR(IF(ISBLANK([1]DFsmonkeyCompl!V14),"",[1]DFsmonkeyCompl!V14*DFanalysis[[#This Row],[EUR]]),"") | ... Z13: =IFERROR(IF(ISBLANK([1]DFsmonkeyCompl!AB14),"",[1]DFsmonkeyCompl!AB14*DFanalysis[[#This Row],[EUR]]),"") | AA13: =IF(ISBLANK([1]DFsmonkeyCompl!AC14),"",[1]DFsmonkeyCompl!AC14) | AB13: =IF(ISBLANK([1]DFsmonkeyCompl!AD14),"",[1]DFsmonkeyCompl!AD14) -> 100 | AC13: =IF(ISBLANK([1]DFsmonkeyCompl!AE14),"",[1]DFsmonkeyCompl!AE14) | AD13: =IF(ISBLANK([1]DFsmonkeyCompl!AF14),"",[1]DFsmonkeyCompl!AF14) | AE13: =IF(ISBLANK([1]DFsmonkeyCompl!AG14),"",[1]DFsmonkeyCompl!AG14) -> Increase | AF13: =IF(ISBLANK([1]DFsmonkeyCompl!AH14),"",[1]DFsmonkeyCompl!AH14) -> Yes
A14: =IF(OR(ISTEXT([1]DFsmonkeyCompl!J15),ISNUMBER([1]DFsmonkeyCompl!J15)),[1]DFsmonkeyCompl!J15,"") -> DRC Capital | B14: =IF(OR(ISTEXT([1]DFsmonkeyCompl!K15),ISNUMBER([1]DFsmonkeyCompl!K15)),[1]DFsmonkeyCompl!K15,"") -> DRC European Real Estate Senior Debt 4 | C14: {=INDEX([1]DebtFundUniverse!$A$85:$A$95,MATCH(B14,[1]DebtFundUniverse!$B$85:$B$95,0),0)} -> 105974 | D14: =INDEX([1]DebtFundUniverse!$B$2:$EU$200,MATCH(DFanalysis[[#This Row],[ID]],[1]DebtFundUniverse!$A$2:$A$200,0),MATCH(DFanalysis[[#Headers],[Loan Strategy]],[1]DebtFundUniverse!$B$1:$EU$1,0)) -> Mixed: Senior+Subordinated+Preferred equity | E14: =INDEX([1]DebtFundUniverse!$B$2:$EU$200,MATCH(DFanalysis[[#This Row],[ID]],[1]DebtFundUniverse!$A$2:$A$200,0),MATCH(DFanalysis[[#Headers],[Target Regional Strategy]],[1]DebtFundUniverse!$B$1:$EU$1,0)) -> Europe | F14: =INDEX([1]DebtFundUniverse!$B$2:$EU$200,MATCH(DFanalysis[[#This Row],[ID]],[1]DebtFundUniverse!$A$2:$A$200,0),MATCH(DFanalysis[[#Headers],[Vehicle Structure]],[1]DebtFundUniverse!$B$1:$EU$1,0)) -> Closed end | G14: =INDEX([1]DebtFundUniverse!$B$2:$EU$200,MATCH(DFanalysis[[#This Row],[ID]],[1]DebtFundUniverse!$A$2:$A$200,0),MATCH(DFanalysis[[#Headers],[year of first closing]],[1]DebtFundUniverse!$B$1:$EU$1,0)) -> 2019 | H14: =IF(ISBLANK([1]DFsmonkeyCompl!L15),"",[1]DFsmonkeyCompl!L15) -> Yes | I14: =IF(ISBLANK([1]DFsmonkeyCompl!M15),"",[1]DFsmonkeyCompl!M15) | J14: =IF(ISBLANK([1]DFsmonkeyCompl!N15),"",[1]DFsmonkeyCompl!N15) | K14: =INDEX([1]DebtFundUniverse!$B$2:$EU$200,MATCH(DFanalysis[[#This Row],[ID]],[1]DebtFundUniverse!$A$2:$A$200,0),MATCH(DFanalysis[[#Headers],[Currency of Reporting]],[1]DebtFundUniverse!$B$1:$EU$1,0)) -> GBP | L14: =VLOOKUP(DFanalysis[[#This Row],[Currency of Reporting]],'[1]Xrate31.12.20'!$K$1:$M$25,3,0) -> 1.1130928 | M14: =IFERROR(IF(ISBLANK([1]DFsmonkeyCompl!O15),"",[1]DFsmonkeyCompl!O15*DFanalysis[[#This Row],[EUR]]),"") -> 111.30928 | N14: =IFERROR(IF(ISBLANK([1]DFsmonkeyCompl!P15),"",[1]DFsmonkeyCompl!P15*DFanalysis[[#This Row],[EUR]]),"") -> 111.30928 | O14: =IFERROR(IF(ISBLANK([1]DFsmonkeyCompl!Q15),"",[1]DFsmonkeyCompl!Q15*DFanalysis[[#This Row],[EUR]]),"") | P14: =IFERROR(IF(ISBLANK([1]DFsmonkeyCompl!R15),"",[1]DFsmonkeyCompl!R15*DFanalysis[[#This Row],[EUR]]),"") | Q14: =IFERROR(IF(ISBLANK([1]DFsmonkeyCompl!S15),"",[1]DFsmonkeyCompl!S15*DFanalysis[[#This Row],[EUR]]),"") | R14: =IFERROR(IF(ISBLANK([1]DFsmonkeyCompl!T15),"",[1]DFsmonkeyCompl!T15*DFanalysis[[#This Row],[EUR]]),"") | S14: =IFERROR(IF(ISBLANK([1]DFsmonkeyCompl!U15),"",[1]DFsmonkeyCompl!U15*DFanalysis[[#This Row],[EUR]]),"") | T14: =IFERROR(IF(ISBLANK([1]DFsmonkeyCompl!V15),"",[1]DFsmonkeyCompl!V15*DFanalysis[[#This Row],[EUR]]),"") | ... Z14: =IFERROR(IF(ISBLANK([1]DFsmonkeyCompl!AB15),"",[1]DFsmonkeyCompl!AB15*DFanalysis[[#This Row],[EUR]]),"") | AA14: =IF(ISBLANK([1]DFsmonkeyCompl!AC15),"",[1]DFsmonkeyCompl!AC15) | AB14: =IF(ISBLANK([1]DFsmonkeyCompl!AD15),"",[1]DFsmonkeyCompl!AD15) | AC14: =IF(ISBLANK([1]DFsmonkeyCompl!AE15),"",[1]DFsmonkeyCompl!AE15) -> 100 | AD14: =IF(ISBLANK([1]DFsmonkeyCompl!AF15),"",[1]DFsmonkeyCompl!AF15) | AE14: =IF(ISBLANK([1]DFsmonkeyCompl!AG15),"",[1]DFsmonkeyCompl!AG15) -> Increase | AF14: =IF(ISBLANK([1]DFsmonkeyCompl!AH15),"",[1]DFsmonkeyCompl!AH15) -> Yes
A15: =IF(OR(ISTEXT([1]DFsmonkeyCompl!J16),ISNUMBER([1]DFsmonkeyCompl!J16)),[1]DFsmonkeyCompl!J16,"") -> DRC Capital | B15: =IF(OR(ISTEXT([1]DFsmonkeyCompl!K16),ISNUMBER([1]DFsmonkeyCompl!K16)),[1]DFsmonkeyCompl!K16,"") -> DRC UK Whole Loan Fund II | C15: {=INDEX([1]DebtFundUniverse!$A$85:$A$95,MATCH(B15,[1]DebtFundUniverse!$B$85:$B$95,0),0)} -> 120207 | D15: =INDEX([1]DebtFundUniverse!$B$2:$EU$200,MATCH(DFanalysis[[#This Row],[ID]],[1]DebtFundUniverse!$A$2:$A$200,0),MATCH(DFanalysis[[#Headers],[Loan Strategy]],[1]DebtFundUniverse!$B$1:$EU$1,0)) -> Whole Loans | E15: =INDEX([1]DebtFundUniverse!$B$2:$EU$200,MATCH(DFanalysis[[#This Row],[ID]],[1]DebtFundUniverse!$A$2:$A$200,0),MATCH(DFanalysis[[#Headers],[Target Regional Strategy]],[1]DebtFundUniverse!$B$1:$EU$1,0)) -> Europe | F15: =INDEX([1]DebtFundUniverse!$B$2:$EU$200,MATCH(DFanalysis[[#This Row],[ID]],[1]DebtFundUniverse!$A$2:$A$200,0),MATCH(DFanalysis[[#Headers],[Vehicle Structure]],[1]DebtFundUniverse!$B$1:$EU$1,0)) -> Closed end | G15: =INDEX([1]DebtFundUniverse!$B$2:$EU$200,MATCH(DFanalysis[[#This Row],[ID]],[1]DebtFundUniverse!$A$2:$A$200,0),MATCH(DFanalysis[[#Headers],[year of first closing]],[1]DebtFundUniverse!$B$1:$EU$1,0)) -> 2020 | H15: =IF(ISBLANK([1]DFsmonkeyCompl!L16),"",[1]DFsmonkeyCompl!L16) -> Yes | I15: =IF(ISBLANK([1]DFsmonkeyCompl!M16),"",[1]DFsmonkeyCompl!M16) | J15: =IF(ISBLANK([1]DFsmonkeyCompl!N16),"",[1]DFsmonkeyCompl!N16) | K15: =INDEX([1]DebtFundUniverse!$B$2:$EU$200,MATCH(DFanalysis[[#This Row],[ID]],[1]DebtFundUniverse!$A$2:$A$200,0),MATCH(DFanalysis[[#Headers],[Currency of Reporting]],[1]DebtFundUniverse!$B$1:$EU$1,0)) -> GBP | L15: =VLOOKUP(DFanalysis[[#This Row],[Currency of Reporting]],'[1]Xrate31.12.20'!$K$1:$M$25,3,0) -> 1.1130928 | M15: =IFERROR(IF(ISBLANK([1]DFsmonkeyCompl!O16),"",[1]DFsmonkeyCompl!O16*DFanalysis[[#This Row],[EUR]]),"") -> 161.39845 | N15: =IFERROR(IF(ISBLANK([1]DFsmonkeyCompl!P16),"",[1]DFsmonkeyCompl!P16*DFanalysis[[#This Row],[EUR]]),"") -> 161.39845 | O15: =IFERROR(IF(ISBLANK([1]DFsmonkeyCompl!Q16),"",[1]DFsmonkeyCompl!Q16*DFanalysis[[#This Row],[EUR]]),"") | P15: =IFERROR(IF(ISBLANK([1]DFsmonkeyCompl!R16),"",[1]DFsmonkeyCompl!R16*DFanalysis[[#This Row],[EUR]]),"") | Q15: =IFERROR(IF(ISBLANK([1]DFsmonkeyCompl!S16),"",[1]DFsmonkeyCompl!S16*DFanalysis[[#This Row],[EUR]]),"") | R15: =IFERROR(IF(ISBLANK([1]DFsmonkeyCompl!T16),"",[1]DFsmonkeyCompl!T16*DFanalysis[[#This Row],[EUR]]),"") | S15: =IFERROR(IF(ISBLANK([1]DFsmonkeyCompl!U16),"",[1]DFsmonkeyCompl!U16*DFanalysis[[#This Row],[EUR]]),"") | T15: =IFERROR(IF(ISBLANK([1]DFsmonkeyCompl!V16),"",[1]DFsmonkeyCompl!V16*DFanalysis[[#This Row],[EUR]]),"") | ... Z15: =IFERROR(IF(ISBLANK([1]DFsmonkeyCompl!AB16),"",[1]DFsmonkeyCompl!AB16*DFanalysis[[#This Row],[EUR]]),"") | AA15: =IF(ISBLANK([1]DFsmonkeyCompl!AC16),"",[1]DFsmonkeyCompl!AC16) | AB15: =IF(ISBLANK([1]DFsmonkeyCompl!AD16),"",[1]DFsmonkeyCompl!AD16) | AC15: =IF(ISBLANK([1]DFsmonkeyCompl!AE16),"",[1]DFsmonkeyCompl!AE16) -> 100 | AD15: =IF(ISBLANK([1]DFsmonkeyCompl!AF16),"",[1]DFsmonkeyCompl!AF16) | AE15: =IF(ISBLANK([1]DFsmonkeyCompl!AG16),"",[1]DFsmonkeyCompl!AG16) -> Increase | AF15: =IF(ISBLANK([1]DFsmonkeyCompl!AH16),"",[1]DFsmonkeyCompl!AH16) -> Yes
A16: =IF(OR(ISTEXT([1]DFsmonkeyCompl!J17),ISNUMBER([1]DFsmonkeyCompl!J17)),[1]DFsmonkeyCompl!J17,"") -> DRC Capital | B16: =IF(OR(ISTEXT([1]DFsmonkeyCompl!K17),ISNUMBER([1]DFsmonkeyCompl!K17)),[1]DFsmonkeyCompl!K17,"") -> DRC European Real Estate Debt Fund IV | C16: 19301 | D16: =INDEX([1]DebtFundUniverse!$B$2:$EU$200,MATCH(DFanalysis[[#This Row],[ID]],[1]DebtFundUniverse!$A$2:$A$200,0),MATCH(DFanalysis[[#Headers],[Loan Strategy]],[1]DebtFundUniverse!$B$1:$EU$1,0)) -> Mixed: Senior+Subordinated | E16: =INDEX([1]DebtFundUniverse!$B$2:$EU$200,MATCH(DFanalysis[[#This Row],[ID]],[1]DebtFundUniverse!$A$2:$A$200,0),MATCH(DFanalysis[[#Headers],[Target Regional Strategy]],[1]DebtFundUniverse!$B$1:$EU$1,0)) -> 0 | F16: =INDEX([1]DebtFundUniverse!$B$2:$EU$200,MATCH(DFanalysis[[#This Row],[ID]],[1]DebtFundUniverse!$A$2:$A$200,0),MATCH(DFanalysis[[#Headers],[Vehicle Structure]],[1]DebtFundUniverse!$B$1:$EU$1,0)) -> Closed end | G16: =INDEX([1]DebtFundUniverse!$B$2:$EU$200,MATCH(DFanalysis[[#This Row],[ID]],[1]DebtFundUniverse!$A$2:$A$200,0),MATCH(DFanalysis[[#Headers],[year of first closing]],[1]DebtFundUniverse!$B$1:$EU$1,0)) -> 2019 | H16: =IF(ISBLANK([1]DFsmonkeyCompl!L17),"",[1]DFsmonkeyCompl!L17) -> Yes | I16: =IF(ISBLANK([1]DFsmonkeyCompl!M17),"",[1]DFsmonkeyCompl!M17) | J16: =IF(ISBLANK([1]DFsmonkeyCompl!N17),"",[1]DFsmonkeyCompl!N17) | K16: =INDEX([1]DebtFundUniverse!$B$2:$EU$200,MATCH(DFanalysis[[#This Row],[ID]],[1]DebtFundUniverse!$A$2:$A$200,0),MATCH(DFanalysis[[#Headers],[Currency of Reporting]],[1]DebtFundUniverse!$B$1:$EU$1,0)) -> GBP | L16: =VLOOKUP(DFanalysis[[#This Row],[Currency of Reporting]],'[1]Xrate31.12.20'!$K$1:$M$25,3,0) -> 1.1130928 | M16: =IFERROR(IF(ISBLANK([1]DFsmonkeyCompl!O17),"",[1]DFsmonkeyCompl!O17*DFanalysis[[#This Row],[EUR]]),"") -> 115.76165 | N16: =IFERROR(IF(ISBLANK([1]DFsmonkeyCompl!P17),"",[1]DFsmonkeyCompl!P17*DFanalysis[[#This Row],[EUR]]),"") -> 87.93433 | O16: =IFERROR(IF(ISBLANK([1]DFsmonkeyCompl!Q17),"",[1]DFsmonkeyCompl!Q17*DFanalysis[[#This Row],[EUR]]),"") -> 27.82732 | P16: =IFERROR(IF(ISBLANK([1]DFsmonkeyCompl!R17),"",[1]DFsmonkeyCompl!R17*DFanalysis[[#This Row],[EUR]]),"") | Q16: =IFERROR(IF(ISBLANK([1]DFsmonkeyCompl!S17),"",[1]DFsmonkeyCompl!S17*DFanalysis[[#This Row],[EUR]]),"") | R16: =IFERROR(IF(ISBLANK([1]DFsmonkeyCompl!T17),"",[1]DFsmonkeyCompl!T17*DFanalysis[[#This Row],[EUR]]),"") | S16: =IFERROR(IF(ISBLANK([1]DFsmonkeyCompl!U17),"",[1]DFsmonkeyCompl!U17*DFanalysis[[#This Row],[EUR]]),"") | T16: =IFERROR(IF(ISBLANK([1]DFsmonkeyCompl!V17),"",[1]DFsmonkeyCompl!V17*DFanalysis[[#This Row],[EUR]]),"") | ... Z16: =IFERROR(IF(ISBLANK([1]DFsmonkeyCompl!AB17),"",[1]DFsmonkeyCompl!AB17*DFanalysis[[#This Row],[EUR]]),"") | AA16: =IF(ISBLANK([1]DFsmonkeyCompl!AC17),"",[1]DFsmonkeyCompl!AC17) -> 74 | AB16: =IF(ISBLANK([1]DFsmonkeyCompl!AD17),"",[1]DFsmonkeyCompl!AD17) | AC16: =IF(ISBLANK([1]DFsmonkeyCompl!AE17),"",[1]DFsmonkeyCompl!AE17) -> 26 | AD16: =IF(ISBLANK([1]DFsmonkeyCompl!AF17),"",[1]DFsmonkeyCompl!AF17) | AE16: =IF(ISBLANK([1]DFsmonkeyCompl!AG17),"",[1]DFsmonkeyCompl!AG17) -> Increase | AF16: =IF(ISBLANK([1]DFsmonkeyCompl!AH17),"",[1]DFsmonkeyCompl!AH17) -> Yes
A17: =IF(OR(ISTEXT([1]DFsmonkeyCompl!J18),ISNUMBER([1]DFsmonkeyCompl!J18)),[1]DFsmonkeyCompl!J18,"") -> Pluto Finance | B17: =IF(OR(ISTEXT([1]DFsmonkeyCompl!K18),ISNUMBER([1]DFsmonkeyCompl!K18)),[1]DFsmonkeyCompl!K18,"") -> Fund V | C17: 19296 | D17: =INDEX([1]DebtFundUniverse!$B$2:$EU$200,MATCH(DFanalysis[[#This Row],[ID]],[1]DebtFundUniverse!$A$2:$A$200,0),MATCH(DFanalysis[[#Headers],[Loan Strategy]],[1]DebtFundUniverse!$B$1:$EU$1,0)) -> Senior | E17: =INDEX([1]DebtFundUniverse!$B$2:$EU$200,MATCH(DFanalysis[[#This Row],[ID]],[1]DebtFundUniverse!$A$2:$A$200,0),MATCH(DFanalysis[[#Headers],[Target Regional Strategy]],[1]DebtFundUniverse!$B$1:$EU$1,0)) -> 0 | F17: =INDEX([1]DebtFundUniverse!$B$2:$EU$200,MATCH(DFanalysis[[#This Row],[ID]],[1]DebtFundUniverse!$A$2:$A$200,0),MATCH(DFanalysis[[#Headers],[Vehicle Structure]],[1]DebtFundUniverse!$B$1:$EU$1,0)) -> Open end | G17: =INDEX([1]DebtFundUniverse!$B$2:$EU$200,MATCH(DFanalysis[[#This Row],[ID]],[1]DebtFundUniverse!$A$2:$A$200,0),MATCH(DFanalysis[[#Headers],[year of first closing]],[1]DebtFundUniverse!$B$1:$EU$1,0)) -> 2017 | H17: =IF(ISBLANK([1]DFsmonkeyCompl!L18),"",[1]DFsmonkeyCompl!L18) -> Yes | I17: =IF(ISBLANK([1]DFsmonkeyCompl!M18),"",[1]DFsmonkeyCompl!M18) | J17: =IF(ISBLANK([1]DFsmonkeyCompl!N18),"",[1]DFsmonkeyCompl!N18) | K17: =INDEX([1]DebtFundUniverse!$B$2:$EU$200,MATCH(DFanalysis[[#This Row],[ID]],[1]DebtFundUniverse!$A$2:$A$200,0),MATCH(DFanalysis[[#Headers],[Currency of Reporting]],[1]DebtFundUniverse!$B$1:$EU$1,0)) -> GBP | L17: =VLOOKUP(DFanalysis[[#This Row],[Currency of Reporting]],'[1]Xrate31.12.20'!$K$1:$M$25,3,0) -> 1.1130928 | M17: =IFERROR(IF(ISBLANK([1]DFsmonkeyCompl!O18),"",[1]DFsmonkeyCompl!O18*DFanalysis[[#This Row],[EUR]]),"") -> 53.428454 | N17: =IFERROR(IF(ISBLANK([1]DFsmonkeyCompl!P18),"",[1]DFsmonkeyCompl!P18*DFanalysis[[#This Row],[EUR]]),"") -> 11.130928 | O17: =IFERROR(IF(ISBLANK([1]DFsmonkeyCompl!Q18),"",[1]DFsmonkeyCompl!Q18*DFanalysis[[#This Row],[EUR]]),"") -> 31.166598 | P17: =IFERROR(IF(ISBLANK([1]DFsmonkeyCompl!R18),"",[1]DFsmonkeyCompl!R18*DFanalysis[[#This Row],[EUR]]),"") | Q17: =IFERROR(IF(ISBLANK([1]DFsmonkeyCompl!S18),"",[1]DFsmonkeyCompl!S18*DFanalysis[[#This Row],[EUR]]),"") | R17: =IFERROR(IF(ISBLANK([1]DFsmonkeyCompl!T18),"",[1]DFsmonkeyCompl!T18*DFanalysis[[#This Row],[EUR]]),"") | S17: =IFERROR(IF(ISBLANK([1]DFsmonkeyCompl!U18),"",[1]DFsmonkeyCompl!U18*DFanalysis[[#This Row],[EUR]]),"") -> 11.130928 | T17: =IFERROR(IF(ISBLANK([1]DFsmonkeyCompl!V18),"",[1]DFsmonkeyCompl!V18*DFanalysis[[#This Row],[EUR]]),"") | ... Z17: =IFERROR(IF(ISBLANK([1]DFsmonkeyCompl!AB18),"",[1]DFsmonkeyCompl!AB18*DFanalysis[[#This Row],[EUR]]),"") | AA17: =IF(ISBLANK([1]DFsmonkeyCompl!AC18),"",[1]DFsmonkeyCompl!AC18) | AB17: =IF(ISBLANK([1]DFsmonkeyCompl!AD18),"",[1]DFsmonkeyCompl!AD18) | AC17: =IF(ISBLANK([1]DFsmonkeyCompl!AE18),"",[1]DFsmonkeyCompl!AE18) -> 100 | AD17: =IF(ISBLANK([1]DFsmonkeyCompl!AF18),"",[1]DFsmonkeyCompl!AF18) | AE17: =IF(ISBLANK([1]DFsmonkeyCompl!AG18),"",[1]DFsmonkeyCompl!AG18) -> Increase | AF17: =IF(ISBLANK([1]DFsmonkeyCompl!AH18),"",[1]DFsmonkeyCompl!AH18) -> No
A18: =IF(OR(ISTEXT([1]DFsmonkeyCompl!J19),ISNUMBER([1]DFsmonkeyCompl!J19)),[1]DFsmonkeyCompl!J19,"") -> CBRE Global Investors | B18: =IF(OR(ISTEXT([1]DFsmonkeyCompl!K19),ISNUMBER([1]DFsmonkeyCompl!K19)),[1]DFsmonkeyCompl!K19,"") -> Special Situations Fund | C18: 28321 | D18: =INDEX([1]DebtFundUniverse!$B$2:$EU$200,MATCH(DFanalysis[[#This Row],[ID]],[1]DebtFundUniverse!$A$2:$A$200,0),MATCH(DFanalysis[[#Headers],[Loan Strategy]],[1]DebtFundUniverse!$B$1:$EU$1,0)) -> Mixed: Senior+Subordinated | E18: =INDEX([1]DebtFundUniverse!$B$2:$EU$200,MATCH(DFanalysis[[#This Row],[ID]],[1]DebtFundUniverse!$A$2:$A$200,0),MATCH(DFanalysis[[#Headers],[Target Regional Strategy]],[1]DebtFundUniverse!$B$1:$EU$1,0)) -> North America | F18: =INDEX([1]DebtFundUniverse!$B$2:$EU$200,MATCH(DFanalysis[[#This Row],[ID]],[1]DebtFundUniverse!$A$2:$A$200,0),MATCH(DFanalysis[[#Headers],[Vehicle Structure]],[1]DebtFundUniverse!$B$1:$EU$1,0)) -> Open end | G18: =INDEX([1]DebtFundUniverse!$B$2:$EU$200,MATCH(DFanalysis[[#This Row],[ID]],[1]DebtFundUniverse!$A$2:$A$200,0),MATCH(DFanalysis[[#Headers],[year of first closing]],[1]DebtFundUniverse!$B$1:$EU$1,0)) -> 2009 | H18: =IF(ISBLANK([1]DFsmonkeyCompl!L19),"",[1]DFsmonkeyCompl!L19) -> Yes | I18: =IF(ISBLANK([1]DFsmonkeyCompl!M19),"",[1]DFsmonkeyCompl!M19) | J18: =IF(ISBLANK([1]DFsmonkeyCompl!N19),"",[1]DFsmonkeyCompl!N19) | K18: =INDEX([1]DebtFundUniverse!$B$2:$EU$200,MATCH(DFanalysis[[#This Row],[ID]],[1]DebtFundUniverse!$A$2:$A$200,0),MATCH(DFanalysis[[#Headers],[Currency of Reporting]],[1]DebtFundUniverse!$B$1:$EU$1,0)) -> USD | L18: =VLOOKUP(DFanalysis[[#This Row],[Currency of Reporting]],'[1]Xrate31.12.20'!$K$1:$M$25,3,0) -> 0.81541286 | M18: =IFERROR(IF(ISBLANK([1]DFsmonkeyCompl!O19),"",[1]DFsmonkeyCompl!O19*DFanalysis[[#This Row],[EUR]]),"") -> 73.387158 | N18: =IFERROR(IF(ISBLANK([1]DFsmonkeyCompl!P19),"",[1]DFsmonkeyCompl!P19*DFanalysis[[#This Row],[EUR]]),"") -> 66.863855 | O18: =IFERROR(IF(ISBLANK([1]DFsmonkeyCompl!Q19),"",[1]DFsmonkeyCompl!Q19*DFanalysis[[#This Row],[EUR]]),"") | P18: =IFERROR(IF(ISBLANK([1]DFsmonkeyCompl!R19),"",[1]DFsmonkeyCompl!R19*DFanalysis[[#This Row],[EUR]]),"") | Q18: =IFERROR(IF(ISBLANK([1]DFsmonkeyCompl!S19),"",[1]DFsmonkeyCompl!S19*DFanalysis[[#This Row],[EUR]]),"") | R18: =IFERROR(IF(ISBLANK([1]DFsmonkeyCompl!T19),"",[1]DFsmonkeyCompl!T19*DFanalysis[[#This Row],[EUR]]),"") | S18: =IFERROR(IF(ISBLANK([1]DFsmonkeyCompl!U19),"",[1]DFsmonkeyCompl!U19*DFanalysis[[#This Row],[EUR]]),"") | T18: =IFERROR(IF(ISBLANK([1]DFsmonkeyCompl!V19),"",[1]DFsmonkeyCompl!V19*DFanalysis[[#This Row],[EUR]]),"") | ... Z18: =IFERROR(IF(ISBLANK([1]DFsmonkeyCompl!AB19),"",[1]DFsmonkeyCompl!AB19*DFanalysis[[#This Row],[EUR]]),"") | AA18: =IF(ISBLANK([1]DFsmonkeyCompl!AC19),"",[1]DFsmonkeyCompl!AC19) | AB18: =IF(ISBLANK([1]DFsmonkeyCompl!AD19),"",[1]DFsmonkeyCompl!AD19) | AC18: =IF(ISBLANK([1]DFsmonkeyCompl!AE19),"",[1]DFsmonkeyCompl!AE19) -> 100 | AD18: =IF(ISBLANK([1]DFsmonkeyCompl!AF19),"",[1]DFsmonkeyCompl!AF19) | AE18: =IF(ISBLANK([1]DFsmonkeyCompl!AG19),"",[1]DFsmonkeyCompl!AG19) -> Increase | AF18: =IF(ISBLANK([1]DFsmonkeyCompl!AH19),"",[1]DFsmonkeyCompl!AH19) -> Yes
B19: =IF(OR(ISTEXT([1]DFsmonkeyCompl!K20),ISNUMBER([1]DFsmonkeyCompl!K20)),[1]DFsmonkeyCompl!K20,"") -> Heitman Closed End Debt Fund | D19: =INDEX([1]DebtFundUniverse!$B$2:$EU$200,MATCH(DFanalysis[[#This Row],[ID]],[1]DebtFundUniverse!$A$2:$A$200,0),MATCH(DFanalysis[[#Headers],[Loan Strategy]],[1]DebtFundUniverse!$B$1:$EU$1,0)) -> #N/A | E19: =INDEX([1]DebtFundUniverse!$B$2:$EU$200,MATCH(DFanalysis[[#This Row],[ID]],[1]DebtFundUniverse!$A$2:$A$200,0),MATCH(DFanalysis[[#Headers],[Target Regional Strategy]],[1]DebtFundUniverse!$B$1:$EU$1,0)) -> #N/A | F19: =INDEX([1]DebtFundUniverse!$B$2:$EU$200,MATCH(DFanalysis[[#This Row],[ID]],[1]DebtFundUniverse!$A$2:$A$200,0),MATCH(DFanalysis[[#Headers],[Vehicle Structure]],[1]DebtFundUniverse!$B$1:$EU$1,0)) -> #N/A | G19: =INDEX([1]DebtFundUniverse!$B$2:$EU$200,MATCH(DFanalysis[[#This Row],[ID]],[1]DebtFundUniverse!$A$2:$A$200,0),MATCH(DFanalysis[[#Headers],[year of first closing]],[1]DebtFundUniverse!$B$1:$EU$1,0)) -> #N/A | H19: =IF(ISBLANK([1]DFsmonkeyCompl!L20),"",[1]DFsmonkeyCompl!L20) -> Yes | I19: =IF(ISBLANK([1]DFsmonkeyCompl!M20),"",[1]DFsmonkeyCompl!M20) | J19: =IF(ISBLANK([1]DFsmonkeyCompl!N20),"",[1]DFsmonkeyCompl!N20) | K19: =INDEX([1]DebtFundUniverse!$B$2:$EU$200,MATCH(DFanalysis[[#This Row],[ID]],[1]DebtFundUniverse!$A$2:$A$200,0),MATCH(DFanalysis[[#Headers],[Currency of Reporting]],[1]DebtFundUniverse!$B$1:$EU$1,0)) -> #N/A | L19: =VLOOKUP(DFanalysis[[#This Row],[Currency of Reporting]],'[1]Xrate31.12.20'!$K$1:$M$25,3,0) -> #N/A | M19: =IFERROR(IF(ISBLANK([1]DFsmonkeyCompl!O20),"",[1]DFsmonkeyCompl!O20*DFanalysis[[#This Row],[EUR]]),"") | N19: =IFERROR(IF(ISBLANK([1]DFsmonkeyCompl!P20),"",[1]DFsmonkeyCompl!P20*DFanalysis[[#This Row],[EUR]]),"") | O19: =IFERROR(IF(ISBLANK([1]DFsmonkeyCompl!Q20),"",[1]DFsmonkeyCompl!Q20*DFanalysis[[#This Row],[EUR]]),"") | P19: =IFERROR(IF(ISBLANK([1]DFsmonkeyCompl!R20),"",[1]DFsmonkeyCompl!R20*DFanalysis[[#This Row],[EUR]]),"") | Q19: =IFERROR(IF(ISBLANK([1]DFsmonkeyCompl!S20),"",[1]DFsmonkeyCompl!S20*DFanalysis[[#This Row],[EUR]]),"") | R19: =IFERROR(IF(ISBLANK([1]DFsmonkeyCompl!T20),"",[1]DFsmonkeyCompl!T20*DFanalysis[[#This Row],[EUR]]),"") | S19: =IFERROR(IF(ISBLANK([1]DFsmonkeyCompl!U20),"",[1]DFsmonkeyCompl!U20*DFanalysis[[#This Row],[EUR]]),"") | T19: =IFERROR(IF(ISBLANK([1]DFsmonkeyCompl!V20),"",[1]DFsmonkeyCompl!V20*DFanalysis[[#This Row],[EUR]]),"") | ... Z19: =IFERROR(IF(ISBLANK([1]DFsmonkeyCompl!AB20),"",[1]DFsmonkeyCompl!AB20*DFanalysis[[#This Row],[EUR]]),"") | AA19: =IF(ISBLANK([1]DFsmonkeyCompl!AC20),"",[1]DFsmonkeyCompl!AC20) | AB19: =IF(ISBLANK([1]DFsmonkeyCompl!AD20),"",[1]DFsmonkeyCompl!AD20) | AC19: =IF(ISBLANK([1]DFsmonkeyCompl!AE20),"",[1]DFsmonkeyCompl!AE20) -> 100 | AD19: =IF(ISBLANK([1]DFsmonkeyCompl!AF20),"",[1]DFsmonkeyCompl!AF20) | AE19: =IF(ISBLANK([1]DFsmonkeyCompl!AG20),"",[1]DFsmonkeyCompl!AG20) -> Increase | AF19: =IF(ISBLANK([1]DFsmonkeyCompl!AH20),"",[1]DFsmonkeyCompl!AH20) -> Yes
