Workbook
Name RMITeam: [1]ContactDetails!$B$9:$B$13

Sheet DataCompleted
A1: RecordNo | B1: Version | C1: DateCompleted | D1: qName | E1: qCompany | F1: mnumber | G1: qJobtitle | H1: qEmail | I1: qTelephone | J1: qCountry | K1: qCurrency | L1: qCurrencyOther | M1: q1 | N1: q2 | O1: q2other | P1: q31_1 | Q1: q31_2 | R1: q31_3 | S1: q31_4 | T1: q31_5 | U1: q31_6 | V1: q3ROW1_hidden | W1: q32_1 | X1: q32_2 | Y1: q32_3 | Z1: q32_4 | AA1: q32_5 | AB1: q32_6 | AC1: q3ROW2_hidden | AD1: q33_1 | AE1: q33_2 | AF1: q33_3 | AG1: q33_4 | AH1: q33_5 | AI1: q33_6 | AJ1: q3ROW3_hidden | AK1: q34_1 | AL1: q34_2 | AM1: q34_3 | AN1: q34_4 | AO1: q34_5 | AP1: q34_6 | AQ1: q3ROW4_hidden | AR1: q35_1 | AS1: q35_2 | AT1: q35_3 | AU1: q35_4 | AV1: q35_5 | AW1: q35_6 | AX1: q3ROW5_hidden | AY1: q36_1 | AZ1: q36_2 | BA1: q36_3 | BB1: q36_4 | BC1: q36_5 | BD1: q36_6 | BE1: q3ROW6_hidden | BF1: q3COL1_hidden | BG1: q3COL2_hidden | BH1: q3COL3_hidden | BI1: q3COL4_hidden | BJ1: q3COL5_hidden | BK1: q3COL6_hidden | BL1: q3GRANDTotal_hidden | BM1: q41_1 | BN1: q41_2 | BO1: q41_3 | BP1: q41_4 | BQ1: q41_5 | BR1: q41_6 | BS1: q4ROW1_hidden | BT1: q42_1 | BU1: q42_2 | BV1: q42_3 | BW1: q42_4 | BX1: q42_5 | BY1: q42_6 | BZ1: q4ROW2_hidden | CA1: q43_1 | CB1: q43_2 | CC1: q43_3 | CD1: q43_4 | CE1: q43_5 | CF1: q43_6 | CG1: q4ROW3_hidden | CH1: q44_1 | CI1: q44_2 | CJ1: q44_3 | CK1: q44_4 | CL1: q44_5 | CM1: q44_6 | CN1: q4ROW4_hidden | CO1: q45_1 | CP1: q45_2 | CQ1: q45_3 | CR1: q45_4 | CS1: q45_5 | CT1: q45_6 | CU1: q4ROW5_hidden | CV1: q46_1 | CW1: q46_2 | CX1: q46_3 | CY1: q46_4 | CZ1: q46_5 | DA1: q46_6 | DB1: q4ROW6_hidden | DC1: q4COL1_hidden | DD1: q4COL2_hidden | DE1: q4COL3_hidden | DF1: q4COL4_hidden | DG1: q4COL5_hidden | DH1: q4COL6_hidden | DI1: q4GRANDTotal_hidden | DJ1: Alert41_1 | DK1: Alert41_2 | DL1: Alert41_3 | DM1: Alert41_4 | DN1: Alert41_5 | DO1: Alert41_6 | DP1: Alert42_1 | DQ1: Alert42_2 | DR1: Alert42_3 | DS1: Alert42_4 | DT1: Alert42_5 | DU1: Alert42_6 | DV1: Alert43_1 | DW1: Alert43_2 | DX1: Alert43_3 | DY1: Alert43_4 | DZ1: Alert43_5 | EA1: Alert43_6 | EB1: Alert44_1 | EC1: Alert44_2 | ED1: Alert44_3 | EE1: Alert44_4 | EF1: Alert44_5 | EG1: Alert44_6 | EH1: Alert45_1 | EI1: Alert45_2 | EJ1: Alert45_3 | EK1: Alert45_4 | EL1: Alert45_5 | EM1: Alert45_6 | EN1: Alert46_1 | EO1: Alert46_2 | EP1: Alert46_3 | EQ1: Alert46_4 | ER1: Alert46_5 | ES1: Alert46_6 | ET1: q51_1 | EU1: q51_2 | EV1: q51_3 | EW1: q51_4 | EX1: q51_5 | EY1: q51_6 | EZ1: q5ROW1_hidden | FA1: q52_1 | FB1: q52_2 | FC1: q52_3 | FD1: q52_4 | FE1: q52_5 | FF1: q52_6 | FG1: q5ROW2_hidden | FH1: q53_1 | FI1: q53_2 | FJ1: q53_3 | FK1: q53_4 | FL1: q53_5 | FM1: q53_6 | FN1: q5ROW3_hidden | FO1: q54_1 | FP1: q54_2 | FQ1: q54_3 | FR1: q54_4 | FS1: q54_5 | FT1: q54_6 | FU1: q5ROW4_hidden | FV1: q55_1 | FW1: q55_2 | FX1: q55_3 | FY1: q55_4 | FZ1: q55_5 | GA1: q55_6 | GB1: q5ROW5_hidden | GC1: q56_1 | GD1: q56_2 | GE1: q56_3 | GF1: q56_4 | GG1: q56_5 | GH1: q56_6 | GI1: q5ROW6_hidden | GJ1: q57_1 | GK1: q57_2 | GL1: q57_3 | GM1: q57_4 | GN1: q57_5 | GO1: q57_6 | GP1: q5ROW7_hidden | GQ1: q5other | GR1: q58_1 | GS1: q58_2 | GT1: q58_3 | GU1: q58_4 | GV1: q58_5 | GW1: q58_6 | GX1: q5ROW8_hidden | GY1: q5COL1_hidden | GZ1: q5COL2_hidden | HA1: q5COL3_hidden | HB1: q5COL4_hidden | HC1: q5COL5_hidden | HD1: q5COL6_hidden | HE1: q5GRANDTotal_hidden | HF1: q61_1 | HG1: q61_2 | HH1: q61_3 | HI1: q61_4 | HJ1: q61_5 | HK1: q61_6 | HL1: q6ROW1_hidden | HM1: q62_1 | HN1: q62_2 | HO1: q62_3 | HP1: q62_4 | HQ1: q62_5 | HR1: q62_6 | HS1: q6ROW2_hidden | HT1: q63_1 | HU1: q63_2 | HV1: q63_3 | HW1: q63_4 | HX1: q63_5 | HY1: q63_6 | HZ1: q6ROW3_hidden | IA1: q64_1 | IB1: q64_2 | IC1: q64_3 | ID1: q64_4 | IE1: q64_5 | IF1: q64_6 | IG1: q6ROW4_hidden | IH1: q65_1 | II1: q65_2 | IJ1: q65_3 | IK1: q65_4 | IL1: q65_5 | IM1: q65_6 | IN1: q6ROW5_hidden | IO1: q6COL1_hidden | IP1: q6COL2_hidden | IQ1: q6COL3_hidden | IR1: q6COL4_hidden | IS1: q6COL5_hidden | IT1: q6COL6_hidden | IU1: q6GRANDTotal_hidden | IV1: q7_1 | IW1: q7_2 | IX1: q7_3 | IY1: q7other | IZ1: q7_4 | JA1: q8 | JB1: q9 | JC1: q91 | JD1: ASIA PACIFIC_apac | JE1: q101_1_apac | JF1: q101_2_apac | JG1: q101_3_apac | JH1: q101_4_apac | JI1: q101_5_apac | JJ1: q101_6_apac | JK1: q10ROW1_hidden_apac | JL1: q102_1_apac | JM1: q102_2_apac | JN1: q102_3_apac | JO1: q102_4_apac | JP1: q102_5_apac | JQ1: q102_6_apac | JR1: q10ROW2_hidden_apac | JS1: q103_1_apac | JT1: q103_2_apac | JU1: q103_3_apac | JV1: q103_4_apac | JW1: q103_5_apac | JX1: q103_6_apac | JY1: q10ROW3_hidden_apac | JZ1: q104_1_apac | KA1: q104_2_apac | KB1: q104_3_apac | KC1: q104_4_apac | KD1: q104_5_apac | KE1: q104_6_apac | KF1: q10ROW4_hidden_apac | KG1: q105_1_apac | KH1: q105_2_apac | KI1: q105_3_apac | KJ1: q105_4_apac | KK1: q105_5_apac | KL1: q105_6_apac | KM1: q10ROW5_hidden_apac | KN1: q106_1_apac | KO1: q106_2_apac | KP1: q106_3_apac | KQ1: q106_4_apac | KR1: q106_5_apac | KS1: q106_6_apac | KT1: q10ROW6_hidden_apac | KU1: q107_1_apac | KV1: q107_2_apac | KW1: q107_3_apac | KX1: q107_4_apac | KY1: q107_5_apac | KZ1: q107_6_apac | LA1: q10ROW7_hidden_apac | LB1: q10other_apac | LC1: q108_1_apac | LD1: q108_2_apac | LE1: q108_3_apac | LF1: q108_4_apac | LG1: q108_5_apac | LH1: q108_6_apac | LI1: q10ROW8_hidden_apac | LJ1: q10COL1_hidden_apac | LK1: q10COL2_hidden_apac | LL1: q10COL3_hidden_apac | LM1: q10COL4_hidden_apac | LN1: q10COL5_hidden_apac | LO1: q10COL6_hidden_apac | LP1: q10GRANDTotal_hidden_apac | LQ1: q111_1_apac | LR1: q111_2_apac | LS1: q111_3_apac | LT1: q111_4_apac | LU1: q111_5_apac | LV1: q111_6_apac | LW1: q11ROW1_hidden_apac | LX1: q112_1_apac | LY1: q112_2_apac | LZ1: q112_3_apac | MA1: q112_4_apac | MB1: q112_5_apac | MC1: q112_6_apac | MD1: q11ROW2_hidden_apac | ME1: q113_1_apac | MF1: q113_2_apac | MG1: q113_3_apac | MH1: q113_4_apac | MI1: q113_5_apac | MJ1: q113_6_apac | MK1: q11ROW3_hidden_apac | ML1: q114_1_apac | MM1: q114_2_apac | MN1: q114_3_apac | MO1: q114_4_apac | MP1: q114_5_apac | MQ1: q114_6_apac | MR1: q11ROW4_hidden_apac | MS1: q115_1_apac | MT1: q115_2_apac | MU1: q115_3_apac | MV1: q115_4_apac | MW1: q115_5_apac | MX1: q115_6_apac | MY1: q11ROW5_hidden_apac | MZ1: q11COL1_hidden_apac | NA1: q11COL2_hidden_apac | NB1: q11COL3_hidden_apac | NC1: q11COL4_hidden_apac | ND1: q11COL5_hidden_apac | NE1: q11COL6_hidden_apac | NF1: q11GRANDTotal_hidden_apac | NG1: EUROPE_europe | NH1: q101_1_europe | NI1: q101_2_europe | NJ1: q101_3_europe | NK1: q101_4_europe | NL1: q101_5_europe | NM1: q101_6_europe | NN1: q10ROW1_hidden_europe | NO1: q102_1_europe | NP1: q102_2_europe | NQ1: q102_3_europe | NR1: q102_4_europe | NS1: q102_5_europe | NT1: q102_6_europe | NU1: q10ROW2_hidden_europe | NV1: q103_1_europe | NW1: q103_2_europe | NX1: q103_3_europe | NY1: q103_4_europe | NZ1: q103_5_europe | OA1: q103_6_europe | OB1: q10ROW3_hidden_europe | OC1: q104_1_europe | OD1: q104_2_europe | OE1: q104_3_europe | OF1: q104_4_europe | OG1: q104_5_europe | OH1: q104_6_europe | OI1: q10ROW4_hidden_europe | OJ1: q105_1_europe | OK1: q105_2_europe | OL1: q105_3_europe | OM1: q105_4_europe | ON1: q105_5_europe | OO1: q105_6_europe | OP1: q10ROW5_hidden_europe | OQ1: q106_1_europe | OR1: q106_2_europe | OS1: q106_3_europe | OT1: q106_4_europe | OU1: q106_5_europe | OV1: q106_6_europe | OW1: q10ROW6_hidden_europe | OX1: q107_1_europe | OY1: q107_2_europe | OZ1: q107_3_europe | PA1: q107_4_europe | PB1: q107_5_europe | PC1: q107_6_europe | PD1: q10ROW7_hidden_europe | PE1: q10other_europe | PF1: q108_1_europe | PG1: q108_2_europe | PH1: q108_3_europe | PI1: q108_4_europe | PJ1: q108_5_europe | PK1: q108_6_europe | PL1: q10ROW8_hidden_europe | PM1: q10COL1_hidden_europe | PN1: q10COL2_hidden_europe | PO1: q10COL3_hidden_europe | PP1: q10COL4_hidden_europe | PQ1: q10COL5_hidden_europe | PR1: q10COL6_hidden_europe | PS1: q10GRANDTotal_hidden_europe | PT1: q111_1_europe | PU1: q111_2_europe | PV1: q111_3_europe | PW1: q111_4_europe | PX1: q111_5_europe | PY1: q111_6_europe | PZ1: q11ROW1_hidden_europe | QA1: q112_1_europe | QB1: q112_2_europe | QC1: q112_3_europe | QD1: q112_4_europe | QE1: q112_5_europe | QF1: q112_6_europe | QG1: q11ROW2_hidden_europe | QH1: q113_1_europe | QI1: q113_2_europe | QJ1: q113_3_europe | QK1: q113_4_europe | QL1: q113_5_europe | QM1: q113_6_europe | QN1: q11ROW3_hidden_europe | QO1: q114_1_europe | QP1: q114_2_europe | QQ1: q114_3_europe | QR1: q114_4_europe | QS1: q114_5_europe | QT1: q114_6_europe | QU1: q11ROW4_hidden_europe | QV1: q115_1_europe | QW1: q115_2_europe | QX1: q115_3_europe | QY1: q115_4_europe | QZ1: q115_5_europe | RA1: q115_6_europe | RB1: q11ROW5_hidden_europe | RC1: q11COL1_hidden_europe | RD1: q11COL2_hidden_europe | RE1: q11COL3_hidden_europe | RF1: q11COL4_hidden_europe | RG1: q11COL5_hidden_europe | RH1: q11COL6_hidden_europe | RI1: q11GRANDTotal_hidden_europe | RJ1: NORTH AMERICA_northamerica | RK1: q101_1_northamerica | RL1: q101_2_northamerica | RM1: q101_3_northamerica | RN1: q101_4_northamerica | RO1: q101_5_northamerica | RP1: q101_6_northamerica | RQ1: q10ROW1_hidden_northamerica | RR1: q102_1_northamerica | RS1: q102_2_northamerica | RT1: q102_3_northamerica | RU1: q102_4_northamerica | RV1: q102_5_northamerica | RW1: q102_6_northamerica | RX1: q10ROW2_hidden_northamerica | RY1: q103_1_northamerica | RZ1: q103_2_northamerica | SA1: q103_3_northamerica | SB1: q103_4_northamerica | SC1: q103_5_northamerica | SD1: q103_6_northamerica | SE1: q10ROW3_hidden_northamerica | SF1: q104_1_northamerica | SG1: q104_2_northamerica | SH1: q104_3_northamerica | SI1: q104_4_northamerica | SJ1: q104_5_northamerica | SK1: q104_6_northamerica | SL1: q10ROW4_hidden_northamerica | SM1: q105_1_northamerica | SN1: q105_2_northamerica | SO1: q105_3_northamerica | SP1: q105_4_northamerica | SQ1: q105_5_northamerica | SR1: q105_6_northamerica | SS1: q10ROW5_hidden_northamerica | ST1: q106_1_northamerica | SU1: q106_2_northamerica | SV1: q106_3_northamerica | SW1: q106_4_northamerica | SX1: q106_5_northamerica | SY1: q106_6_northamerica | SZ1: q10ROW6_hidden_northamerica | TA1: q107_1_northamerica | TB1: q107_2_northamerica | TC1: q107_3_northamerica | TD1: q107_4_northamerica | TE1: q107_5_northamerica | TF1: q107_6_northamerica | TG1: q10ROW7_hidden_northamerica | TH1: q10other_northamerica | TI1: q108_1_northamerica | TJ1: q108_2_northamerica | TK1: q108_3_northamerica | TL1: q108_4_northamerica | TM1: q108_5_northamerica | TN1: q108_6_northamerica | TO1: q10ROW8_hidden_northamerica | TP1: q10COL1_hidden_northamerica | TQ1: q10COL2_hidden_northamerica | TR1: q10COL3_hidden_northamerica | TS1: q10COL4_hidden_northamerica | TT1: q10COL5_hidden_northamerica | TU1: q10COL6_hidden_northamerica | TV1: q10GRANDTotal_hidden_northamerica | TW1: q111_1_northamerica | TX1: q111_2_northamerica | TY1: q111_3_northamerica | TZ1: q111_4_northamerica | UA1: q111_5_northamerica | UB1: q111_6_northamerica | UC1: q11ROW1_hidden_northamerica | UD1: q112_1_northamerica | UE1: q112_2_northamerica | UF1: q112_3_northamerica | UG1: q112_4_northamerica | UH1: q112_5_northamerica | UI1: q112_6_northamerica | UJ1: q11ROW2_hidden_northamerica | UK1: q113_1_northamerica | UL1: q113_2_northamerica | UM1: q113_3_northamerica | UN1: q113_4_northamerica | UO1: q113_5_northamerica | UP1: q113_6_northamerica | UQ1: q11ROW3_hidden_northamerica | UR1: q114_1_northamerica | US1: q114_2_northamerica | UT1: q114_3_northamerica | UU1: q114_4_northamerica | UV1: q114_5_northamerica | UW1: q114_6_northamerica | UX1: q11ROW4_hidden_northamerica | UY1: q115_1_northamerica | UZ1: q115_2_northamerica | VA1: q115_3_northamerica | VB1: q115_4_northamerica | VC1: q115_5_northamerica | VD1: q115_6_northamerica | VE1: q11ROW5_hidden_northamerica | VF1: q11COL1_hidden_northamerica | VG1: q11COL2_hidden_northamerica | VH1: q11COL3_hidden_northamerica | VI1: q11COL4_hidden_northamerica | VJ1: q11COL5_hidden_northamerica | VK1: q11COL6_hidden_northamerica | VL1: q11GRANDTotal_hidden_northamerica | VM1: Global_global | VN1: q101_1_global | VO1: q101_2_global | VP1: q101_3_global | VQ1: q101_4_global | VR1: q101_5_global | VS1: q101_6_global | VT1: q10ROW1_hidden_global | VU1: q102_1_global | VV1: q102_2_global | VW1: q102_3_global | VX1: q102_4_global | VY1: q102_5_global | VZ1: q102_6_global | WA1: q10ROW2_hidden_global | WB1: q103_1_global | WC1: q103_2_global | WD1: q103_3_global | WE1: q103_4_global | WF1: q103_5_global | WG1: q103_6_global | WH1: q10ROW3_hidden_global | WI1: q104_1_global | WJ1: q104_2_global | WK1: q104_3_global | WL1: q104_4_global | WM1: q104_5_global | WN1: q104_6_global | WO1: q10ROW4_hidden_global | WP1: q105_1_global | WQ1: q105_2_global | WR1: q105_3_global | WS1: q105_4_global | WT1: q105_5_global | WU1: q105_6_global | WV1: q10ROW5_hidden_global | WW1: q106_1_global | WX1: q106_2_global | WY1: q106_3_global | WZ1: q106_4_global | XA1: q106_5_global | XB1: q106_6_global | XC1: q10ROW6_hidden_global | XD1: q107_1_global | XE1: q107_2_global | XF1: q107_3_global | XG1: q107_4_global | XH1: q107_5_global | XI1: q107_6_global | XJ1: q10ROW7_hidden_global | XK1: q10other_global | XL1: q108_1_global | XM1: q108_2_global | XN1: q108_3_global | XO1: q108_4_global | XP1: q108_5_global | XQ1: q108_6_global | XR1: q10ROW8_hidden_global | XS1: q10COL1_hidden_global | XT1: q10COL2_hidden_global | XU1: q10COL3_hidden_global | XV1: q10COL4_hidden_global | XW1: q10COL5_hidden_global | XX1: q10COL6_hidden_global | XY1: q10GRANDTotal_hidden_global | XZ1: q111_1_global | YA1: q111_2_global | YB1: q111_3_global | YC1: q111_4_global | YD1: q111_5_global | YE1: q111_6_global | YF1: q11ROW1_hidden_global | YG1: q112_1_global | YH1: q112_2_global | YI1: q112_3_global | YJ1: q112_4_global | YK1: q112_5_global | YL1: q112_6_global | YM1: q11ROW2_hidden_global | YN1: q113_1_global | YO1: q113_2_global | YP1: q113_3_global | YQ1: q113_4_global | YR1: q113_5_global | YS1: q113_6_global | YT1: q11ROW3_hidden_global | YU1: q114_1_global | YV1: q114_2_global | YW1: q114_3_global | YX1: q114_4_global | YY1: q114_5_global | YZ1: q114_6_global | ZA1: q11ROW4_hidden_global | ZB1: q115_1_global | ZC1: q115_2_global | ZD1: q115_3_global | ZE1: q115_4_global | ZF1: q115_5_global | ZG1: q115_6_global | ZH1: q11ROW5_hidden_global | ZI1: q11COL1_hidden_global | ZJ1: q11COL2_hidden_global | ZK1: q11COL3_hidden_global | ZL1: q11COL4_hidden_global | ZM1: q11COL5_hidden_global | ZN1: q11COL6_hidden_global | ZO1: q11GRANDTotal_hidden_global | ZP1: SOUTH AMERICA_southamerica | ZQ1: q101_1_southamerica | ZR1: q101_2_southamerica | ZS1: q101_3_southamerica | ZT1: q101_4_southamerica | ZU1: q101_5_southamerica | ZV1: q101_6_southamerica | ZW1: q10ROW1_hidden_southamerica | ZX1: q102_1_southamerica | ZY1: q102_2_southamerica | ZZ1: q102_3_southamerica | AAA1: q102_4_southamerica | AAB1: q102_5_southamerica | AAC1: q102_6_southamerica | AAD1: q10ROW2_hidden_southamerica | AAE1: q103_1_southamerica | AAF1: q103_2_southamerica | AAG1: q103_3_southamerica | AAH1: q103_4_southamerica | AAI1: q103_5_southamerica | AAJ1: q103_6_southamerica | AAK1: q10ROW3_hidden_southamerica | AAL1: q104_1_southamerica | AAM1: q104_2_southamerica | AAN1: q104_3_southamerica | AAO1: q104_4_southamerica | AAP1: q104_5_southamerica | AAQ1: q104_6_southamerica | AAR1: q10ROW4_hidden_southamerica | AAS1: q105_1_southamerica | AAT1: q105_2_southamerica | AAU1: q105_3_southamerica | AAV1: q105_4_southamerica | AAW1: q105_5_southamerica | AAX1: q105_6_southamerica | AAY1: q10ROW5_hidden_southamerica | AAZ1: q106_1_southamerica | ABA1: q106_2_southamerica | ABB1: q106_3_southamerica | ABC1: q106_4_southamerica | ABD1: q106_5_southamerica | ABE1: q106_6_southamerica | ABF1: q10ROW6_hidden_southamerica | ABG1: q107_1_southamerica | ABH1: q107_2_southamerica | ABI1: q107_3_southamerica | ABJ1: q107_4_southamerica | ABK1: q107_5_southamerica | ABL1: q107_6_southamerica | ABM1: q10ROW7_hidden_southamerica | ABN1: q10other_southamerica | ABO1: q108_1_southamerica | ABP1: q108_2_southamerica | ABQ1: q108_3_southamerica | ABR1: q108_4_southamerica | ABS1: q108_5_southamerica | ABT1: q108_6_southamerica | ABU1: q10ROW8_hidden_southamerica | ABV1: q10COL1_hidden_southamerica | ABW1: q10COL2_hidden_southamerica | ABX1: q10COL3_hidden_southamerica | ABY1: q10COL4_hidden_southamerica | ABZ1: q10COL5_hidden_southamerica | ACA1: q10COL6_hidden_southamerica | ACB1: q10GRANDTotal_hidden_southamerica | ACC1: q111_1_southamerica | ACD1: q111_2_southamerica | ACE1: q111_3_southamerica | ACF1: q111_4_southamerica | ACG1: q111_5_southamerica | ACH1: q111_6_southamerica | ACI1: q11ROW1_hidden_southamerica | ACJ1: q112_1_southamerica | ACK1: q112_2_southamerica | ACL1: q112_3_southamerica | ACM1: q112_4_southamerica | ACN1: q112_5_southamerica | ACO1: q112_6_southamerica | ACP1: q11ROW2_hidden_southamerica | ACQ1: q113_1_southamerica | ACR1: q113_2_southamerica | ACS1: q113_3_southamerica | ACT1: q113_4_southamerica | ACU1: q113_5_southamerica | ACV1: q113_6_southamerica | ACW1: q11ROW3_hidden_southamerica | ACX1: q114_1_southamerica | ACY1: q114_2_southamerica | ACZ1: q114_3_southamerica | ADA1: q114_4_southamerica | ADB1: q114_5_southamerica | ADC1: q114_6_southamerica | ADD1: q11ROW4_hidden_southamerica | ADE1: q115_1_southamerica | ADF1: q115_2_southamerica | ADG1: q115_3_southamerica | ADH1: q115_4_southamerica | ADI1: q115_5_southamerica | ADJ1: q115_6_southamerica | ADK1: q11ROW5_hidden_southamerica | ADL1: q11COL1_hidden_southamerica | ADM1: q11COL2_hidden_southamerica | ADN1: q11COL3_hidden_southamerica | ADO1: q11COL4_hidden_southamerica | ADP1: q11COL5_hidden_southamerica | ADQ1: q11COL6_hidden_southamerica | ADR1: q11GRANDTotal_hidden_southamerica | ADS1: AFRICA_africa | ADT1: q101_1_africa | ADU1: q101_2_africa | ADV1: q101_3_africa | ADW1: q101_4_africa | ADX1: q101_5_africa | ADY1: q101_6_africa | ADZ1: q10ROW1_hidden_africa | AEA1: q102_1_africa | AEB1: q102_2_africa | AEC1: q102_3_africa | AED1: q102_4_africa | AEE1: q102_5_africa | AEF1: q102_6_africa | AEG1: q10ROW2_hidden_africa | AEH1: q103_1_africa | AEI1: q103_2_africa | AEJ1: q103_3_africa | AEK1: q103_4_africa | AEL1: q103_5_africa | AEM1: q103_6_africa | AEN1: q10ROW3_hidden_africa | AEO1: q104_1_africa | AEP1: q104_2_africa | AEQ1: q104_3_africa | AER1: q104_4_africa | AES1: q104_5_africa | AET1: q104_6_africa | AEU1: q10ROW4_hidden_africa | AEV1: q105_1_africa | AEW1: q105_2_africa | AEX1: q105_3_africa | AEY1: q105_4_africa | AEZ1: q105_5_africa | AFA1: q105_6_africa | AFB1: q10ROW5_hidden_africa | AFC1: q106_1_africa | AFD1: q106_2_africa | AFE1: q106_3_africa | AFF1: q106_4_africa | AFG1: q106_5_africa | AFH1: q106_6_africa | AFI1: q10ROW6_hidden_africa | AFJ1: q107_1_africa | AFK1: q107_2_africa | AFL1: q107_3_africa | AFM1: q107_4_africa | AFN1: q107_5_africa | AFO1: q107_6_africa | AFP1: q10ROW7_hidden_africa | AFQ1: q10other_africa | AFR1: q108_1_africa | AFS1: q108_2_africa | AFT1: q108_3_africa | AFU1: q108_4_africa | AFV1: q108_5_africa | AFW1: q108_6_africa | AFX1: q10ROW8_hidden_africa | AFY1: q10COL1_hidden_africa | AFZ1: q10COL2_hidden_africa | AGA1: q10COL3_hidden_africa | AGB1: q10COL4_hidden_africa | AGC1: q10COL5_hidden_africa | AGD1: q10COL6_hidden_africa | AGE1: q10GRANDTotal_hidden_africa | AGF1: q111_1_africa | AGG1: q111_2_africa | AGH1: q111_3_africa | AGI1: q111_4_africa | AGJ1: q111_5_africa | AGK1: q111_6_africa | AGL1: q11ROW1_hidden_africa | AGM1: q112_1_africa | AGN1: q112_2_africa | AGO1: q112_3_africa | AGP1: q112_4_africa | AGQ1: q112_5_africa | AGR1: q112_6_africa | AGS1: q11ROW2_hidden_africa | AGT1: q113_1_africa | AGU1: q113_2_africa | AGV1: q113_3_africa | AGW1: q113_4_africa | AGX1: q113_5_africa | AGY1: q113_6_africa | AGZ1: q11ROW3_hidden_africa | AHA1: q114_1_africa | AHB1: q114_2_africa | AHC1: q114_3_africa | AHD1: q114_4_africa | AHE1: q114_5_africa | AHF1: q114_6_africa | AHG1: q11ROW4_hidden_africa | AHH1: q115_1_africa | AHI1: q115_2_africa | AHJ1: q115_3_africa | AHK1: q115_4_africa | AHL1: q115_5_africa | AHM1: q115_6_africa | AHN1: q11ROW5_hidden_africa | AHO1: q11COL1_hidden_africa | AHP1: q11COL2_hidden_africa | AHQ1: q11COL3_hidden_africa | AHR1: q11COL4_hidden_africa | AHS1: q11COL5_hidden_africa | AHT1: q11COL6_hidden_africa | AHU1: q11GRANDTotal_hidden_africa
A2: 121 | B2: ANREV | C2: 42761.069 | D2: Viola Chee | E2: SilkRoad Property Partners | F2: =VLOOKUP(MID(H2,SEARCH("@",H2,1),LEN(H2)-SEARCH("@",H2,1)+1),[2]Sheet1!$D:$F,3,FALSE) -> M0182 | G2: VP Financial Controller | H2: viola.chee@silkroadpp.com | I2: 6569225560 | J2: Singapore | K2: USD | M2: 1 | P2: 109 | V2: 109 | AC2: 0 | AJ2: 0 | AQ2: 0 | AX2: 0 | BE2: 0 | BF2: 109 | BG2: 0 | BH2: 0 | BI2: 0 | BJ2: 0 | BK2: 0 | BL2: 109 | BM2: 2 | BS2: 2 | BZ2: 0 | CG2: 0 | CN2: 0 | CU2: 0 | DB2: 0 | DC2: 2 | DD2: 0 | DE2: 0 | DF2: 0 | DG2: 0 | DH2: 0 | DI2: 2 | DJ2: YES | DK2: NO | DL2: NO | DM2: NO | DN2: NO | DO2: NO | DP2: NO | DQ2: NO | DR2: NO | DS2: NO | DT2: NO | DU2: NO | DV2: NO | DW2: NO | DX2: NO | DY2: NO | DZ2: NO | EA2: NO | EB2: NO | EC2: NO | ED2: NO | EE2: NO | EF2: NO | EG2: NO | EH2: NO | EI2: NO | EJ2: NO | EK2: NO | EL2: NO | EM2: NO | EN2: NO | EO2: NO | EP2: NO | EQ2: NO | ER2: NO | ES2: NO | ET2: 45 | EZ2: 45 | FA2: 47 | FG2: 47 | FN2: 0 | FU2: 0 | GB2: 0 | GI2: 0 | GJ2: 2 | GP2: 2 | GQ2: University | GR2: 15 | GX2: 15 | GY2: 109 | GZ2: 0 | HA2: 0 | HB2: 0 | HC2: 0 | HD2: 0 | HE2: 109 | HF2: 2 | HL2: 2 | HM2: 67 | HS2: 67 | HT2: 40 | HZ2: 40 | IG2: 0 | IN2: 0 | IO2: 109 | IP2: 0 | IQ2: 0 | IR2: 0 | IS2: 0 | IT2: 0 | IU2: 109 | IV2: 100 | JA2: 3 | JB2: 3 | JC2: 2 | JD2: START Asia Pacific: | JE2: 45 | JK2: 45 | JL2: 47 | JR2: 47 | JY2: 0 | KF2: 0 | KM2: 0 | KT2: 0 | KU2: 2 | LA2: 2 | LC2: 15 | LI2: 15 | LJ2: 109 | LK2: 0 | LL2: 0 | LM2: 0 | LN2: 0 | LO2: 0 | LP2: 109 | LQ2: 67 | LW2: 67 | LX2: 2 | MD2: 2 | ME2: 40 | MK2: 40 | MR2: 0 | MY2: 0 | MZ2: 109 | NA2: 0 | NB2: 0 | NC2: 0 | ND2: 0 | NE2: 0 | NF2: 109 | NG2: START Europe: | RJ2: START North America: | VM2: START Global: | ZP2: START SOUTH America: | ADS2: START Africa:
A3: 78 | B3: ANREV | C3: 42780 | D3: Sarah Berg | E3: Heitman | F3: =VLOOKUP(MID(H3,SEARCH("@",H3,1),LEN(H3)-SEARCH("@",H3,1)+1),[2]Sheet1!$D:$F,3,FALSE) -> M107 | G3: Vice President | H3: consultant.services@heitman.com | I3: 312-425-0432 | J3: United States | K3: USD | M3: 1 | V3: 0 | W3: 152 | AC3: 152 | AD3: 911 | AE3: 742 | AI3: 355 | AJ3: 2008 | AQ3: 0 | AX3: 0 | BE3: 0 | BF3: 1063 | BG3: 742 | BH3: 0 | BI3: 0 | BJ3: 0 | BK3: 355 | BL3: 2160 | BS3: 0 | BT3: 1 | BZ3: 1 | CA3: 1 | CB3: 3 | CF3: 2 | CG3: 6 | CN3: 0 | CU3: 0 | DB3: 0 | DC3: 2 | DD3: 3 | DE3: 0 | DF3: 0 | DG3: 0 | DH3: 2 | DI3: 7 | DJ3: NO | DK3: NO | DL3: NO | DM3: NO | DN3: NO | DO3: NO | DP3: YES | DQ3: NO | DR3: NO | DS3: NO | DT3: NO | DU3: NO | DV3: YES | DW3: YES | DX3: NO | DY3: NO | DZ3: NO | EA3: YES | EB3: NO | EC3: NO | ED3: NO | EE3: NO | EF3: NO | EG3: NO | EH3: NO | EI3: NO | EJ3: NO | EK3: NO | EL3: NO | EM3: NO | EN3: NO | EO3: NO | EP3: NO | EQ3: NO | ER3: NO | ES3: NO | ET3: 99 | EZ3: 99 | FA3: 64 | FG3: 64 | FH3: 409 | FN3: 409 | FO3: 294 | FP3: 742 | FT3: 355 | FU3: 1391 | FV3: 10 | GB3: 10 | GC3: 134 | GI3: 134 | GP3: 0 | GQ3: Taft-Hartley | GR3: 53 | GX3: 53 | GY3: 1063 | GZ3: 742 | HA3: 0 | HB3: 0 | HC3: 0 | HD3: 355 | HE3: 2160 | HF3: 400 | HL3: 400 | HM3: 186 | HS3: 186 | HT3: 477 | HU3: 742 | HY3: 355 | HZ3: 1574 | IG3: 0 | IN3: 0 | IO3: 1063 | IP3: 742 | IQ3: 0 | IR3: 0 | IS3: 0 | IT3: 355 | IU3: 2160 | IW3: 5 | IX3: 50 | IY3: new clients from prospecting | IZ3: 45 | JA3: 3 | JB3: 1 | JC3: 1 | JD3: START Asia Pacific: | NG3: START Europe: | RJ3: START North America: | VM3: START Global: | ZP3: START SOUTH America: | ADS3: START Africa:
A4: 161 | B4: ANREV | C4: 42769.068 | D4: Nick Thorn | E4: BPEA Real Estate | F4: =VLOOKUP(MID(H4,SEARCH("@",H4,1),LEN(H4)-SEARCH("@",H4,1)+1),[2]Sheet1!$D:$F,3,FALSE) -> M0149 | G4: Vice President - Investor Relations | H4: nickthorn@bpeasia.com | I4: 85228439312 | J4: Hong Kong | K4: USD | M4: 2 | N4: 6 | O4: Not a fundraising year. Last fund closed in 2015. | V4: 0 | AC4: 0 | AJ4: 0 | AQ4: 0 | AX4: 0 | BE4: 0 | BF4: 0 | BG4: 0 | BH4: 0 | BI4: 0 | BJ4: 0 | BK4: 0 | BL4: 0 | BS4: 0 | BZ4: 0 | CG4: 0 | CN4: 0 | CU4: 0 | DB4: 0 | DC4: 0 | DD4: 0 | DE4: 0 | DF4: 0 | DG4: 0 | DH4: 0 | DI4: 0 | DJ4: NO | DK4: NO | DL4: NO | DM4: NO | DN4: NO | DO4: NO | DP4: NO | DQ4: NO | DR4: NO | DS4: NO | DT4: NO | DU4: NO | DV4: NO | DW4: NO | DX4: NO | DY4: NO | DZ4: NO | EA4: NO | EB4: NO | EC4: NO | ED4: NO | EE4: NO | EF4: NO | EG4: NO | EH4: NO | EI4: NO | EJ4: NO | EK4: NO | EL4: NO | EM4: NO | EN4: NO | EO4: NO | EP4: NO | EQ4: NO | ER4: NO | ES4: NO | EZ4: 0 | FG4: 0 | FN4: 0 | FU4: 0 | GB4: 0 | GI4: 0 | GP4: 0 | GX4: 0 | GY4: 0 | GZ4: 0 | HA4: 0 | HB4: 0 | HC4: 0 | HD4: 0 | HE4: 0 | HL4: 0 | HS4: 0 | HZ4: 0 | IG4: 0 | IN4: 0 | IO4: 0 | IP4: 0 | IQ4: 0 | IR4: 0 | IS4: 0 | IT4: 0 | IU4: 0 | JA4: 1 | JB4: 2 | JC4: 1 | JD4: START Asia Pacific: | NG4: START Europe: | RJ4: START North America: | VM4: START Global: | ZP4: START SOUTH America: | ADS4: START Africa:
A5: 217 | B5: ANREV | C5: 42780 | D5: Charter Hall Group | E5: Charter Hall Group | F5: =VLOOKUP(MID(H5,SEARCH("@",H5,1),LEN(H5)-SEARCH("@",H5,1)+1),[2]Sheet1!$D:$F,3,FALSE) -> M03232 | G5: Analyst | H5: investor@charterhall.com.au | I5: +61 2 8651 9412 | J5: Australia | K5: AUD | M5: 1 | P5: 1004 | S5: 1017 | V5: 2021 | AC5: 0 | AJ5: 0 | AQ5: 0 | AX5: 0 | BE5: 0 | BF5: 1004 | BG5: 0 | BH5: 0 | BI5: 1017 | BJ5: 0 | BK5: 0 | BL5: 2021 | BM5: 6 | BP5: 7 | BS5: 13 | BZ5: 0 | CG5: 0 | CN5: 0 | CU5: 0 | DB5: 0 | DC5: 6 | DD5: 0 | DE5: 0 | DF5: 7 | DG5: 0 | DH5: 0 | DI5: 13 | DJ5: YES | DK5: NO | DL5: NO | DM5: YES | DN5: NO | DO5: NO | DP5: NO | DQ5: NO | DR5: NO | DS5: NO | DT5: NO | DU5: NO | DV5: NO | DW5: NO | DX5: NO | DY5: NO | DZ5: NO | EA5: NO | EB5: NO | EC5: NO | ED5: NO | EE5: NO | EF5: NO | EG5: NO | EH5: NO | EI5: NO | EJ5: NO | EK5: NO | EL5: NO | EM5: NO | EN5: NO | EO5: NO | EP5: NO | EQ5: NO | ER5: NO | ES5: NO | ET5: 152 | EW5: 596 | EZ5: 748 | FA5: 0 | FD5: 92 | FG5: 92 | FH5: 0 | FK5: 5 | FN5: 5 | FO5: 0 | FU5: 0 | FV5: 0 | GB5: 0 | GC5: 37 | GF5: 76 | GI5: 113 | GJ5: 97 | GM5: 0 | GP5: 97 | GQ5: Companies | GR5: 718 | GU5: 248 | GX5: 966 | GY5: 1004 | GZ5: 0 | HA5: 0 | HB5: 1017 | HC5: 0 | HD5: 0 | HE5: 2021 | HF5: 1002 | HI5: 595 | HL5: 1597 | HM5: 2 | HP5: 274 | HS5: 276 | HT5: 0 | HW5: 148 | HZ5: 148 | IA5: 0 | ID5: 0 | IG5: 0 | IH5: 0 | IK5: 0 | IN5: 0 | IO5: 1004 | IP5: 0 | IQ5: 0 | IR5: 1017 | IS5: 0 | IT5: 0 | IU5: 2021 | IX5: 100 | JA5: 1 | JB5: 1 | JC5: 1 | JD5: START Asia Pacific: | JE5: 152 | JH5: 596 | JK5: 748 | JL5: 0 | JO5: 92 | JR5: 92 | JS5: 0 | JV5: 5 | JY5: 5 | JZ5: 0 | KC5: 0 | KF5: 0 | KG5: 0 | KJ5: 0 | KM5: 0 | KN5: 38 | KQ5: 76 | KT5: 114 | KU5: 97 | KX5: 0 | LA5: 97 | LB5: Companies | LC5: 718 | LF5: 247 | LI5: 965 | LJ5: 1005 | LK5: 0 | LL5: 0 | LM5: 1016 | LN5: 0 | LO5: 0 | LP5: 2021 | LQ5: 2 | LT5: 273 | LW5: 275 | LX5: 1002 | MA5: 596 | MD5: 1598 | ME5: 0 | MH5: 148 | MK5: 148 | ML5: 0 | MO5: 0 | MR5: 0 | MS5: 0 | MV5: 0 | MY5: 0 | MZ5: 1004 | NA5: 0 | NB5: 0 | NC5: 1017 | ND5: 0 | NE5: 0 | NF5: 2021 | NG5: START Europe: | RJ5: START North America: | VM5: START Global: | ZP5: START SOUTH America: | ADS5: START Africa:
A6: 83 | B6: ANREV | C6: 42761.108 | D6: Lee, Joseph (Lee, Gyusung) | E6: IGIS Asset Management | F6: =VLOOKUP(MID(H6,SEARCH("@",H6,1),LEN(H6)-SEARCH("@",H6,1)+1),[2]Sheet1!$D:$F,3,FALSE) -> M0333 | G6: Senior Managing Director | H6: joseph.lee@igisam.com | I6: +82 2 6959 3102 | J6: Korea, Republic Of | K6: KRW | M6: 2
A7: 228 | B7: ANREV | C7: 42780 | D7: Wendy Lai | E7: ESR Singapore Pte. Ltd. | F7: =VLOOKUP(MID(H7,SEARCH("@",H7,1),LEN(H7)-SEARCH("@",H7,1)+1),[2]Sheet1!$D:$F,3,FALSE) -> M0231 | G7: Fund Controller | H7: wlai@redwoodgroup.com | I7: 6568500454 | J7: Hong Kong | K7: USD | M7: 1 | P7: 310.8 | Q7: 470 | S7: 477.3 | V7: 1258.1 | AC7: 0 | AJ7: 0 | AQ7: 0 | AX7: 0 | BE7: 0 | BF7: 310.8 | BG7: 470 | BH7: 0 | BI7: 477.3 | BJ7: 0 | BK7: 0 | BL7: 1258.1 | BM7: 1 | BN7: 2 | BP7: 3 | BS7: 6 | BZ7: 0 | CG7: 0 | CN7: 0 | CU7: 0 | DB7: 0 | DC7: 1 | DD7: 2 | DE7: 0 | DF7: 3 | DG7: 0 | DH7: 0 | DI7: 6 | DJ7: YES | DK7: YES | DL7: NO | DM7: YES | DN7: NO | DO7: NO | DP7: NO | DQ7: NO | DR7: NO | DS7: NO | DT7: NO | DU7: NO | DV7: NO | DW7: NO | DX7: NO | DY7: NO | DZ7: NO | EA7: NO | EB7: NO | EC7: NO | ED7: NO | EE7: NO | EF7: NO | EG7: NO | EH7: NO | EI7: NO | EJ7: NO | EK7: NO | EL7: NO | EM7: NO | EN7: NO | EO7: NO | EP7: NO | EQ7: NO | ER7: NO | ES7: NO | ET7: 200 | EU7: 200 | EZ7: 400 | FB7: 250 | FD7: 236.6 | FG7: 486.6 | FN7: 0 | FU7: 0 | GB7: 0 | GI7: 0 | GP7: 0 | GQ7: Institutional investor | GR7: 110.8 | GS7: 20 | GU7: 240.7 | GX7: 371.5 | GY7: 310.8 | GZ7: 470 | HA7: 0 | HB7: 477.3 | HC7: 0 | HD7: 0 | HE7: 1258.1 | HF7: 300 | HG7: 265 | HI7: 477.3 | HL7: 1042.3 | HM7: 10.8 | HS7: 10.8 | HU7: 205 | HZ7: 205 | IG7: 0 | IN7: 0 | IO7: 310.8 | IP7: 470 | IQ7: 0 | IR7: 477.3 | IS7: 0 | IT7: 0 | IU7: 1258.1 | IV7: 23.8 | IX7: 76.2 | JA7: 1 | JB7: 1 | JC7: 2 | JD7: START Asia Pacific: | JE7: 200 | JF7: 200 | JK7: 400 | JM7: 250 | JO7: 236.6 | JR7: 486.6 | JY7: 0 | KF7: 0 | KM7: 0 | KT7: 0 | LA7: 0 | LB7: Institutional investor | LC7: 110.8 | LD7: 20 | LF7: 240.7 | LI7: 371.5 | LJ7: 310.8 | LK7: 470 | LL7: 0 | LM7: 477.3 | LN7: 0 | LO7: 0 | LP7: 1258.1 | LQ7: 10.8 | LW7: 10.8 | LX7: 300 | LY7: 265 | MA7: 477.3 | MD7: 1042.3 | MF7: 205 | MK7: 205 | MR7: 0 | MY7: 0 | MZ7: 310.8 | NA7: 470 | NB7: 0 | NC7: 477.3 | ND7: 0 | NE7: 0 | NF7: 1258.1 | NG7: START Europe: | RJ7: START North America: | VM7: START Global: | ZP7: START SOUTH America: | ADS7: START Africa:
A8: 122 | B8: ANREV | C8: 42780 | D8: Niklas Schelander | E8: PAG Asia | F8: =VLOOKUP(MID(H8,SEARCH("@",H8,1),LEN(H8)-SEARCH("@",H8,1)+1),[2]Sheet1!$D:$F,3,FALSE) -> M0137 | G8: Managing Director, Group Head | H8: nschelander@pagasia.com | I8: +852 3719 6383 | J8: Hong Kong | K8: USD | M8: 1 | P8: 1150 | V8: 1150 | AC8: 0 | AJ8: 0 | AQ8: 0 | AX8: 0 | BE8: 0 | BF8: 1150 | BG8: 0 | BH8: 0 | BI8: 0 | BJ8: 0 | BK8: 0 | BL8: 1150 | BM8: 1 | BS8: 1 | BZ8: 0 | CG8: 0 | CN8: 0 | CU8: 0 | DB8: 0 | DC8: 1 | DD8: 0 | DE8: 0 | DF8: 0 | DG8: 0 | DH8: 0 | DI8: 1 | DJ8: YES | DK8: NO | DL8: NO | DM8: NO | DN8: NO | DO8: NO | DP8: NO | DQ8: NO | DR8: NO | DS8: NO | DT8: NO | DU8: NO | DV8: NO | DW8: NO | DX8: NO | DY8: NO | DZ8: NO | EA8: NO | EB8: NO | EC8: NO | ED8: NO | EE8: NO | EF8: NO | EG8: NO | EH8: NO | EI8: NO | EJ8: NO | EK8: NO | EL8: NO | EM8: NO | EN8: NO | EO8: NO | EP8: NO | EQ8: NO | ER8: NO | ES8: NO | ET8: 645 | EZ8: 645 | FG8: 0 | FH8: 375 | FN8: 375 | FU8: 0 | FV8: 35 | GB8: 35 | GC8: 55 | GI8: 55 | GP8: 0 | GQ8: Corporates + GP Commitment | GR8: 35 | GX8: 35 | GY8: 1145 | GZ8: 0 | HA8: 0 | HB8: 0 | HC8: 0 | HD8: 0 | HE8: 1145 | HF8: 430 | HL8: 430 | HM8: 35 | HS8: 35 | HT8: 680 | HZ8: 680 | IG8: 0 | IN8: 0 | IO8: 1145 | IP8: 0 | IQ8: 0 | IR8: 0 | IS8: 0 | IT8: 0 | IU8: 1145 | IV8: 33 | IX8: 67 | JA8: 1 | JB8: 3 | JC8: 1 | JD8: START Asia Pacific: | JE8: 645 | JK8: 645 | JR8: 0 | JS8: 375 | JY8: 375 | KF8: 0 | KG8: 35 | KM8: 35 | KN8: 55 | KT8: 55 | LA8: 0 | LC8: 35 | LI8: 35 | LJ8: 1145 | LK8: 0 | LL8: 0 | LM8: 0 | LN8: 0 | LO8: 0 | LP8: 1145 | LQ8: 35 | LW8: 35 | LX8: 430 | MD8: 430 | ME8: 680 | MK8: 680 | MR8: 0 | MY8: 0 | MZ8: 1145 | NA8: 0 | NB8: 0 | NC8: 0 | ND8: 0 | NE8: 0 | NF8: 1145 | NG8: START Europe: | RJ8: START North America: | VM8: START Global: | ZP8: START SOUTH America: | ADS8: START Africa:
A9: 162 | B9: ANREV | C9: 42772.408 | D9: Ingrid Nell | E9: Macquarie | F9: =VLOOKUP(MID(H9,SEARCH("@",H9,1),LEN(H9)-SEARCH("@",H9,1)+1),[2]Sheet1!$D:$F,3,FALSE) -> M766 | G9: Senior Vice President | H9: Ingrid.Nell@macquarie.com | I9: 3922-1994 | J9: Australia | K9: USD | M9: 2 | N9: 1 | V9: 0 | AC9: 0 | AJ9: 0 | AQ9: 0 | AX9: 0 | BE9: 0 | BF9: 0 | BG9: 0 | BH9: 0 | BI9: 0 | BJ9: 0 | BK9: 0 | BL9: 0 | BS9: 0 | BZ9: 0 | CG9: 0 | CN9: 0 | CU9: 0 | DB9: 0 | DC9: 0 | DD9: 0 | DE9: 0 | DF9: 0 | DG9: 0 | DH9: 0 | DI9: 0 | DJ9: NO | DK9: NO | DL9: NO | DM9: NO | DN9: NO | DO9: NO | DP9: NO | DQ9: NO | DR9: NO | DS9: NO | DT9: NO | DU9: NO | DV9: NO | DW9: NO | DX9: NO | DY9: NO | DZ9: NO | EA9: NO | EB9: NO | EC9: NO | ED9: NO | EE9: NO | EF9: NO | EG9: NO | EH9: NO | EI9: NO | EJ9: NO | EK9: NO | EL9: NO | EM9: NO | EN9: NO | EO9: NO | EP9: NO | EQ9: NO | ER9: NO | ES9: NO | EZ9: 0 | FG9: 0 | FN9: 0 | FU9: 0 | GB9: 0 | GI9: 0 | GP9: 0 | GX9: 0 | GY9: 0 | GZ9: 0 | HA9: 0 | HB9: 0 | HC9: 0 | HD9: 0 | HE9: 0 | HL9: 0 | HS9: 0 | HZ9: 0 | IG9: 0 | IN9: 0 | IO9: 0 | IP9: 0 | IQ9: 0 | IR9: 0 | IS9: 0 | IT9: 0 | IU9: 0 | JA9: 1 | JB9: 2 | JC9: 2 | JD9: START Asia Pacific: | NG9: START Europe: | RJ9: START North America: | VM9: START Global: | ZP9: START SOUTH America: | ADS9: START Africa:
A10: 226 | B10: ANREV | C10: 42780 | D10: Paul Summer | E10: J.P. Morgan Asset Management | F10: =VLOOKUP(MID(H10,SEARCH("@",H10,1),LEN(H10)-SEARCH("@",H10,1)+1),[2]Sheet1!$D:$F,3,FALSE) -> M082 | G10: Managing Director | H10: paul.t.summer@jpmorgan.com | I10: -2603 | J10: United States | K10: USD | M10: 1 | P10: 500 | S10: 75 | V10: 575 | AC10: 0 | AD10: 1377 | AG10: 500 | AH10: 287 | AI10: 280 | AJ10: 2444 | AQ10: 0 | AX10: 0 | BE10: 0 | BF10: 1877 | BG10: 0 | BH10: 0 | BI10: 575 | BJ10: 287 | BK10: 280 | BL10: 3019 | BM10: 1 | BP10: 1 | BS10: 2 | BZ10: 0 | CA10: 3 | CD10: 1 | CE10: 2 | CF10: 1 | CG10: 7 | CN10: 0 | CU10: 0 | DB10: 0 | DC10: 4 | DD10: 0 | DE10: 0 | DF10: 2 | DG10: 2 | DH10: 1 | DI10: 9 | DJ10: YES | DK10: NO | DL10: NO | DM10: YES | DN10: NO | DO10: NO | DP10: NO | DQ10: NO | DR10: NO | DS10: NO | DT10: NO | DU10: NO | DV10: YES | DW10: NO | DX10: NO | DY10: YES | DZ10: YES | EA10: YES | EB10: NO | EC10: NO | ED10: NO | EE10: NO | EF10: NO | EG10: NO | EH10: NO | EI10: NO | EJ10: NO | EK10: NO | EL10: NO | EM10: NO | EN10: NO | EO10: NO | EP10: NO | EQ10: NO | ER10: NO | ES10: NO | ET10: 1863 | EW10: 575 | EX10: 287 | EZ10: 2725 | FG10: 0 | FN10: 0 | FU10: 0 | FV10: 6 | GB10: 6 | GC10: 8 | GI10: 8 | GP10: 0 | GQ10: Corporation | GW10: 280 | GX10: 280 | GY10: 1877 | GZ10: 0 | HA10: 0 | HB10: 575 | HC10: 287 | HD10: 280 | HE10: 3019 | HK10: 280 | HL10: 280 | HM10: 50 | HS10: 50 | HT10: 1827 | HW10: 575 | HX10: 287 | HZ10: 2689 | IG10: 0 | IN10: 0 | IO10: 1877 | IP10: 0 | IQ10: 0 | IR10: 575 | IS10: 287 | IT10: 280 | IU10: 3019 | IW10: 50 | IX10: 50 | JA10: 1 | JB10: 1 | JC10: 1 | JD10: START Asia Pacific: | JE10: 500 | JH10: 75 | JK10: 575 | JR10: 0 | JY10: 0 | KF10: 0 | KM10: 0 | KT10: 0 | LA10: 0 | LI10: 0 | LJ10: 500 | LK10: 0 | LL10: 0 | LM10: 75 | LN10: 0 | LO10: 0 | LP10: 575 | LQ10: 50 | LW10: 50 | MD10: 0 | ME10: 450 | MH10: 75 | MK10: 525 | MR10: 0 | MY10: 0 | MZ10: 500 | NA10: 0 | NB10: 0 | NC10: 75 | ND10: 0 | NE10: 0 | NF10: 575 | NG10: START Europe: | RJ10: START North America: | RK10: 1363 | RN10: 500 | RO10: 287 | RQ10: 2150 | RX10: 0 | SE10: 0 | SL10: 0 | SM10: 6 | SS10: 6 | ST10: 8 | SZ10: 8 | TG10: 0 | TH10: Corporation | TN10: 280 | TO10: 280 | TP10: 1377 | TQ10: 0 | TR10: 0 | TS10: 500 | TT10: 287 | TU10: 280 | TV10: 2444 | UC10: 0 | UI10: 280 | UJ10: 280 | UK10: 1377 | UN10: 500 | UO10: 287 | UQ10: 2164 | UX10: 0 | VE10: 0 | VF10: 1377 | VG10: 0 | VH10: 0 | VI10: 500 | VJ10: 287 | VK10: 280 | VL10: 2444 | VM10: START Global: | ZP10: START SOUTH America: | ADS10: START Africa:
A11: 77 | B11: ANREV | C11: 42747.281 | D11: Don Tan | E11: KaiLong Investments | F11: =VLOOKUP(MID(H11,SEARCH("@",H11,1),LEN(H11)-SEARCH("@",H11,1)+1),[2]Sheet1!$D:$F,3,FALSE) -> M0226 | G11: VP, Fund Management | H11: don.tan@kailongrei.com | I11: 85237982627 | J11: China | K11: USD | M11: 2 | N11: 6 | O11: We are still in investment period for our other Funds | V11: 0 | AC11: 0 | AJ11: 0 | AQ11: 0 | AX11: 0 | BE11: 0 | BF11: 0 | BG11: 0 | BH11: 0 | BI11: 0 | BJ11: 0 | BK11: 0 | BL11: 0 | BS11: 0 | BZ11: 0 | CG11: 0 | CN11: 0 | CU11: 0 | DB11: 0 | DC11: 0 | DD11: 0 | DE11: 0 | DF11: 0 | DG11: 0 | DH11: 0 | DI11: 0 | DJ11: NO | DK11: NO | DL11: NO | DM11: NO | DN11: NO | DO11: NO | DP11: NO | DQ11: NO | DR11: NO | DS11: NO | DT11: NO | DU11: NO | DV11: NO | DW11: NO | DX11: NO | DY11: NO | DZ11: NO | EA11: NO | EB11: NO | EC11: NO | ED11: NO | EE11: NO | EF11: NO | EG11: NO | EH11: NO | EI11: NO | EJ11: NO | EK11: NO | EL11: NO | EM11: NO | EN11: NO | EO11: NO | EP11: NO | EQ11: NO | ER11: NO | ES11: NO | EZ11: 0 | FG11: 0 | FN11: 0 | FU11: 0 | GB11: 0 | GI11: 0 | GP11: 0 | GX11: 0 | GY11: 0 | GZ11: 0 | HA11: 0 | HB11: 0 | HC11: 0 | HD11: 0 | HE11: 0 | HL11: 0 | HS11: 0 | HZ11: 0 | IG11: 0 | IN11: 0 | IO11: 0 | IP11: 0 | IQ11: 0 | IR11: 0 | IS11: 0 | IT11: 0 | IU11: 0 | JA11: 1 | JB11: 3 | JC11: 1 | JD11: START Asia Pacific: | NG11: START Europe: | RJ11: START North America: | VM11: START Global: | ZP11: START SOUTH America: | ADS11: START Africa:
A12: 117 | B12: ANREV | C12: 42760.369 | D12: Ho Liwen | E12: SC Capital Partners | F12: =VLOOKUP(MID(H12,SEARCH("@",H12,1),LEN(H12)-SEARCH("@",H12,1)+1),[2]Sheet1!$D:$F,3,FALSE) -> M0159 | G12: Director Investor Relations | H12: liwen@recapinvestments.com | I12: -14384 | J12: Singapore | K12: USD | M12: 1 | P12: 280 | V12: 280 | AC12: 0 | AJ12: 0 | AQ12: 0 | AX12: 0 | BE12: 0 | BF12: 280 | BG12: 0 | BH12: 0 | BI12: 0 | BJ12: 0 | BK12: 0 | BL12: 280 | BM12: 1 | BS12: 1 | BZ12: 0 | CG12: 0 | CN12: 0 | CU12: 0 | DB12: 0 | DC12: 1 | DD12: 0 | DE12: 0 | DF12: 0 | DG12: 0 | DH12: 0 | DI12: 1 | DJ12: YES | DK12: NO | DL12: NO | DM12: NO | DN12: NO | DO12: NO | DP12: NO | DQ12: NO | DR12: NO | DS12: NO | DT12: NO | DU12: NO | DV12: NO | DW12: NO | DX12: NO | DY12: NO | DZ12: NO | EA12: NO | EB12: NO | EC12: NO | ED12: NO | EE12: NO | EF12: NO | EG12: NO | EH12: NO | EI12: NO | EJ12: NO | EK12: NO | EL12: NO | EM12: NO | EN12: NO | EO12: NO | EP12: NO | EQ12: NO | ER12: NO | ES12: NO | ET12: 158 | EZ12: 158 | FA12: 18 | FG12: 18 | FH12: 100 | FN12: 100 | FU12: 0 | GB12: 0 | GI12: 0 | GP12: 0 | GQ12: GP Co invest | GR12: 4 | GX12: 4 | GY12: 280 | GZ12: 0 | HA12: 0 | HB12: 0 | HC12: 0 | HD12: 0 | HE12: 280 | HL12: 0 | HM12: 88.5 | HS12: 88.5 | HT12: 191.5 | HZ12: 191.5 | IG12: 0 | IN12: 0 | IO12: 280 | IP12: 0 | IQ12: 0 | IR12: 0 | IS12: 0 | IT12: 0 | IU12: 280 | IV12: 31.6 | IX12: 68.4 | JA12: 2 | JB12: 2 | JC12: 1 | JD12: START Asia Pacific: | NG12: START Europe: | RJ12: START North America: | VM12: START Global: | ZP12: START SOUTH America: | ADS12: START Africa:
A13: 168 | B13: ANREV | C13: 42772.083 | D13: Natalie Barrington | E13: DEXUS Property Group | F13: =VLOOKUP(MID(H13,SEARCH("@",H13,1),LEN(H13)-SEARCH("@",H13,1)+1),[2]Sheet1!$D:$F,3,FALSE) -> M0090 | G13: DWPF Investor Relations and Operations Manager | H13: Natalie.Barrington@dexus.com | I13: +61 290171295 | J13: Australia | K13: AUD | M13: 2 | N13: 1 | V13: 0 | AC13: 0 | AJ13: 0 | AQ13: 0 | AX13: 0 | BE13: 0 | BF13: 0 | BG13: 0 | BH13: 0 | BI13: 0 | BJ13: 0 | BK13: 0 | BL13: 0 | BS13: 0 | BZ13: 0 | CG13: 0 | CN13: 0 | CU13: 0 | DB13: 0 | DC13: 0 | DD13: 0 | DE13: 0 | DF13: 0 | DG13: 0 | DH13: 0 | DI13: 0 | DJ13: NO | DK13: NO | DL13: NO | DM13: NO | DN13: NO | DO13: NO | DP13: NO | DQ13: NO | DR13: NO | DS13: NO | DT13: NO | DU13: NO | DV13: NO | DW13: NO | DX13: NO | DY13: NO | DZ13: NO | EA13: NO | EB13: NO | EC13: NO | ED13: NO | EE13: NO | EF13: NO | EG13: NO | EH13: NO | EI13: NO | EJ13: NO | EK13: NO | EL13: NO | EM13: NO | EN13: NO | EO13: NO | EP13: NO | EQ13: NO | ER13: NO | ES13: NO | EZ13: 0 | FG13: 0 | FN13: 0 | FU13: 0 | GB13: 0 | GI13: 0 | GP13: 0 | GX13: 0 | GY13: 0 | GZ13: 0 | HA13: 0 | HB13: 0 | HC13: 0 | HD13: 0 | HE13: 0 | HL13: 0 | HS13: 0 | HZ13: 0 | IG13: 0 | IN13: 0 | IO13: 0 | IP13: 0 | IQ13: 0 | IR13: 0 | IS13: 0 | IT13: 0 | IU13: 0 | JA13: 1 | JB13: 3 | JC13: 2 | JD13: START Asia Pacific: | NG13: START Europe: | RJ13: START North America: | VM13: START Global: | ZP13: START SOUTH America: | ADS13: START Africa:
A14: 170 | B14: ANREV | C14: 42780 | D14: Loretta Li | E14: ARCH Capital Management Co Ltd | F14: =VLOOKUP(MID(H14,SEARCH("@",H14,1),LEN(H14)-SEARCH("@",H14,1)+1),[2]Sheet1!$D:$F,3,FALSE) -> M421 | G14: CFO | H14: lli@archcapital.net | I14: 22644662 | J14: Hong Kong | K14: USD | M14: 1 | P14: 12.5 | V14: 12.5 | AC14: 0 | AJ14: 0 | AQ14: 0 | AX14: 0 | BE14: 0 | BF14: 12.5 | BG14: 0 | BH14: 0 | BI14: 0 | BJ14: 0 | BK14: 0 | BL14: 12.5 | BM14: 1 | BS14: 1 | BZ14: 0 | CG14: 0 | CN14: 0 | CU14: 0 | DB14: 0 | DC14: 1 | DD14: 0 | DE14: 0 | DF14: 0 | DG14: 0 | DH14: 0 | DI14: 1 | DJ14: YES | DK14: NO | DL14: NO | DM14: NO | DN14: NO | DO14: NO | DP14: NO | DQ14: NO | DR14: NO | DS14: NO | DT14: NO | DU14: NO | DV14: NO | DW14: NO | DX14: NO | DY14: NO | DZ14: NO | EA14: NO | EB14: NO | EC14: NO | ED14: NO | EE14: NO | EF14: NO | EG14: NO | EH14: NO | EI14: NO | EJ14: NO | EK14: NO | EL14: NO | EM14: NO | EN14: NO | EO14: NO | EP14: NO | EQ14: NO | ER14: NO | ES14: NO | EZ14: 0 | FG14: 0 | FN14: 0 | FU14: 0 | GB14: 0 | GI14: 0 | GJ14: 12.5 | GP14: 12.5 | GX14: 0 | GY14: 12.5 | GZ14: 0 | HA14: 0 | HB14: 0 | HC14: 0 | HD14: 0 | HE14: 12.5 | HL14: 0 | HM14: 12.5 | HS14: 12.5 | HZ14: 0 | IG14: 0 | IN14: 0 | IO14: 12.5 | IP14: 0 | IQ14: 0 | IR14: 0 | IS14: 0 | IT14: 0 | IU14: 12.5 | IX14: 100 | JA14: 3 | JB14: 3 | JC14: 2 | JD14: START Asia Pacific: | JK14: 0 | JR14: 0 | JY14: 0 | KF14: 0 | KM14: 0 | KT14: 0 | KU14: 12.5 | LA14: 12.5 | LI14: 0 | LJ14: 12.5 | LK14: 0 | LL14: 0 | LM14: 0 | LN14: 0 | LO14: 0 | LP14: 12.5 | LQ14: 12.5 | LW14: 12.5 | MD14: 0 | MK14: 0 | MR14: 0 | MY14: 0 | MZ14: 12.5 | NA14: 0 | NB14: 0 | NC14: 0 | ND14: 0 | NE14: 0 | NF14: 12.5 | NG14: START Europe: | RJ14: START North America: | VM14: START Global: | ZP14: START SOUTH America: | ADS14: START Africa:
A15: 236 | B15: ANREV | C15: 42780 | D15: Joel Oei | E15: Ascendas-Singbridge | F15: =VLOOKUP(MID(H15,SEARCH("@",H15,1),LEN(H15)-SEARCH("@",H15,1)+1),[2]Sheet1!$D:$F,3,FALSE) -> M0189 | G15: Manager, Fund Development | H15: joel.oei@ascendas-singbridge.com | I15: 6565088808 | J15: Singapore | K15: SGD | M15: 1 | S15: 350 | V15: 350 | AC15: 0 | AJ15: 0 | AQ15: 0 | AX15: 0 | BE15: 0 | BF15: 0 | BG15: 0 | BH15: 0 | BI15: 350 | BJ15: 0 | BK15: 0 | BL15: 350 | BP15: 1 | BS15: 1 | BZ15: 0 | CG15: 0 | CN15: 0 | CU15: 0 | DB15: 0 | DC15: 0 | DD15: 0 | DE15: 0 | DF15: 1 | DG15: 0 | DH15: 0 | DI15: 1 | DJ15: NO | DK15: NO | DL15: NO | DM15: YES | DN15: NO | DO15: NO | DP15: NO | DQ15: NO | DR15: NO | DS15: NO | DT15: NO | DU15: NO | DV15: NO | DW15: NO | DX15: NO | DY15: NO | DZ15: NO | EA15: NO | EB15: NO | EC15: NO | ED15: NO | EE15: NO | EF15: NO | EG15: NO | EH15: NO | EI15: NO | EJ15: NO | EK15: NO | EL15: NO | EM15: NO | EN15: NO | EO15: NO | EP15: NO | EQ15: NO | ER15: NO | ES15: NO | EZ15: 0 | FG15: 0 | FN15: 0 | FU15: 0 | GB15: 0 | GI15: 0 | GP15: 0 | GQ15: Corporate | GU15: 350 | GX15: 350 | GY15: 0 | GZ15: 0 | HA15: 0 | HB15: 350 | HC15: 0 | HD15: 0 | HE15: 350 | HI15: 350 | HL15: 350 | HS15: 0 | HZ15: 0 | IG15: 0 | IN15: 0 | IO15: 0 | IP15: 0 | IQ15: 0 | IR15: 350 | IS15: 0 | IT15: 0 | IU15: 350 | IX15: 100 | JA15: 1 | JB15: 2 | JC15: 1 | JD15: START Asia Pacific: | JK15: 0 | JR15: 0 | JY15: 0 | KF15: 0 | KM15: 0 | KT15: 0 | LA15: 0 | LB15: Corporate | LF15: 350 | LI15: 350 | LJ15: 0 | LK15: 0 | LL15: 0 | LM15: 350 | LN15: 0 | LO15: 0 | LP15: 350 | LW15: 0 | MA15: 350 | MD15: 350 | MK15: 0 | MR15: 0 | MY15: 0 | MZ15: 0 | NA15: 0 | NB15: 0 | NC15: 350 | ND15: 0 | NE15: 0 | NF15: 350 | NG15: START Europe: | RJ15: START North America: | VM15: START Global: | ZP15: START SOUTH America: | ADS15: START Africa:
A16: 115 | B16: ANREV | C16: 42775.332 | D16: Christine Ong | E16: Mapletree Investments Pte Ltd | F16: =VLOOKUP(MID(H16,SEARCH("@",H16,1),LEN(H16)-SEARCH("@",H16,1)+1),[2]Sheet1!$D:$F,3,FALSE) -> M0180 | G16: Head, Private Funds Management | H16: christine.ong@mapletree.com.sg | I16: 6684-7781 | J16: Singapore | K16: USD | M16: 2 | V16: 0 | AC16: 0 | AJ16: 0 | AQ16: 0 | AX16: 0 | BE16: 0 | BF16: 0 | BG16: 0 | BH16: 0 | BI16: 0 | BJ16: 0 | BK16: 0 | BL16: 0 | BS16: 0 | BZ16: 0 | CG16: 0 | CN16: 0 | CU16: 0 | DB16: 0 | DC16: 0 | DD16: 0 | DE16: 0 | DF16: 0 | DG16: 0 | DH16: 0 | DI16: 0 | DJ16: NO | DK16: NO | DL16: NO | DM16: NO | DN16: NO | DO16: NO | DP16: NO | DQ16: NO | DR16: NO | DS16: NO | DT16: NO | DU16: NO | DV16: NO | DW16: NO | DX16: NO | DY16: NO | DZ16: NO | EA16: NO | EB16: NO | EC16: NO | ED16: NO | EE16: NO | EF16: NO | EG16: NO | EH16: NO | EI16: NO | EJ16: NO | EK16: NO | EL16: NO | EM16: NO | EN16: NO | EO16: NO | EP16: NO | EQ16: NO | ER16: NO | ES16: NO | EZ16: 0 | FG16: 0 | FN16: 0 | FU16: 0 | GB16: 0 | GI16: 0 | GP16: 0 | GX16: 0 | GY16: 0 | GZ16: 0 | HA16: 0 | HB16: 0 | HC16: 0 | HD16: 0 | HE16: 0 | HL16: 0 | HS16: 0 | HZ16: 0 | IG16: 0 | IN16: 0 | IO16: 0 | IP16: 0 | IQ16: 0 | IR16: 0 | IS16: 0 | IT16: 0 | IU16: 0 | JA16: 1 | JB16: 2 | JC16: 2 | JD16: START Asia Pacific: | NG16: START Europe: | RJ16: START North America: | VM16: START Global: | ZP16: START SOUTH America: | ADS16: START Africa:
A17: 88 | B17: ANREV | C17: 42780 | D17: Serene Foong | E17: Alpha Investment Partners Limited | F17: =VLOOKUP(MID(H17,SEARCH("@",H17,1),LEN(H17)-SEARCH("@",H17,1)+1),[2]Sheet1!$D:$F,3,FALSE) -> M0106 | G17: SVP Finance | H17: serene.foong@kepcapital.com | I17: -68031736 | J17: Singapore | K17: USD | M17: 1 | P17: 281.52 | Q17: 265 | V17: 546.52 | AC17: 0 | AJ17: 0 | AK17: 132.34 | AQ17: 132.34 | AX17: 0 | BE17: 0 | BF17: 413.86 | BG17: 265 | BH17: 0 | BI17: 0 | BJ17: 0 | BK17: 0 | BL17: 678.86 | BM17: 1 | BN17: 1 | BS17: 2 | BZ17: 0 | CG17: 0 | CH17: 1 | CN17: 1 | CU17: 0 | DB17: 0 | DC17: 2 | DD17: 1 | DE17: 0 | DF17: 0 | DG17: 0 | DH17: 0 | DI17: 3 | DJ17: YES | DK17: YES | DL17: NO | DM17: NO | DN17: NO | DO17: NO | DP17: NO | DQ17: NO | DR17: NO | DS17: NO | DT17: NO | DU17: NO | DV17: NO | DW17: NO | DX17: NO | DY17: NO | DZ17: NO | EA17: NO | EB17: YES | EC17: NO | ED17: NO | EE17: NO | EF17: NO | EG17: NO | EH17: NO | EI17: NO | EJ17: NO | EK17: NO | EL17: NO | EM17: NO | EN17: NO | EO17: NO | EP17: NO | EQ17: NO | ER17: NO | ES17: NO | ET17: 134 | EU17: 265 | EZ17: 399 | FG17: 0 | FN17: 0 | FO17: 20 | FU17: 20 | FV17: 30 | GB17: 30 | GI17: 0 | GP17: 0 | GQ17: Corporates/Banks/Others | GR17: 229.86 | GX17: 229.86 | GY17: 413.86 | GZ17: 265 | HA17: 0 | HB17: 0 | HC17: 0 | HD17: 0 | HE17: 678.86 | HF17: 279.86 | HL17: 279.86 | HM17: 134 | HN17: 265 | HS17: 399 | HZ17: 0 | IG17: 0 | IN17: 0 | IO17: 413.86 | IP17: 265 | IQ17: 0 | IR17: 0 | IS17: 0 | IT17: 0 | IU17: 678.86 | IW17: 100 | JA17: 1 | JB17: 1 | JC17: 2 | JD17: START Asia Pacific: | NG17: START Europe: | RJ17: START North America: | VM17: START Global: | ZP17: START SOUTH America: | ADS17: START Africa:
A18: 114 | B18: ANREV | C18: 42774.097 | D18: David Muren | E18: Angelo, Gordon & Co. | F18: =VLOOKUP(MID(H18,SEARCH("@",H18,1),LEN(H18)-SEARCH("@",H18,1)+1),[2]Sheet1!$D:$F,3,FALSE) -> M0001 | G18: Director | H18: dmuren@angelogordon.com | I18: 212-692-0209 | J18: United States | K18: USD | M18: 1 | P18: 566 | V18: 566 | AC18: 0 | AJ18: 0 | AK18: 361 | AQ18: 361 | AX18: 0 | BE18: 0 | BF18: 927 | BG18: 0 | BH18: 0 | BI18: 0 | BJ18: 0 | BK18: 0 | BL18: 927 | BM18: 1 | BS18: 1 | BZ18: 0 | CG18: 0 | CH18: 1 | CN18: 1 | CU18: 0 | DB18: 0 | DC18: 2 | DD18: 0 | DE18: 0 | DF18: 0 | DG18: 0 | DH18: 0 | DI18: 2 | DJ18: YES | DK18: NO | DL18: NO | DM18: NO | DN18: NO | DO18: NO | DP18: NO | DQ18: NO | DR18: NO | DS18: NO | DT18: NO | DU18: NO | DV18: NO | DW18: NO | DX18: NO | DY18: NO | DZ18: NO | EA18: NO | EB18: YES | EC18: NO | ED18: NO | EE18: NO | EF18: NO | EG18: NO | EH18: NO | EI18: NO | EJ18: NO | EK18: NO | EL18: NO | EM18: NO | EN18: NO | EO18: NO | EP18: NO | EQ18: NO | ER18: NO | ES18: NO | EZ18: 0 | FG18: 0 | FN18: 0 | FU18: 0 | GB18: 0 | GI18: 0 | GP18: 0 | GX18: 0 | GY18: 0 | GZ18: 0 | HA18: 0 | HB18: 0 | HC18: 0 | HD18: 0 | HE18: 0 | HL18: 0 | HS18: 0 | HZ18: 0 | IG18: 0 | IN18: 0 | IO18: 0 | IP18: 0 | IQ18: 0 | IR18: 0 | IS18: 0 | IT18: 0 | IU18: 0 | IV18: 3 | IX18: 97 | JC18: 1 | JD18: START Asia Pacific: | JK18: 0 | JR18: 0 | JY18: 0 | KF18: 0 | KM18: 0 | KT18: 0 | LA18: 0 | LI18: 0 | LJ18: 0 | LK18: 0 | LL18: 0 | LM18: 0 | LN18: 0 | LO18: 0 | LP18: 0 | LW18: 0 | MD18: 0 | MK18: 0 | MR18: 0 | MY18: 0 | MZ18: 0 | NA18: 0 | NB18: 0 | NC18: 0 | ND18: 0 | NE18: 0 | NF18: 0 | NG18: START Europe: | RJ18: START North America: | VM18: START Global: | VT18: 0 | WA18: 0 | WH18: 0 | WO18: 0 | WV18: 0 | XC18: 0 | XJ18: 0 | XR18: 0 | XS18: 0 | XT18: 0 | XU18: 0 | XV18: 0 | XW18: 0 | XX18: 0 | XY18: 0 | YF18: 0 | YM18: 0 | YT18: 0 | ZA18: 0 | ZH18: 0 | ZI18: 0 | ZJ18: 0 | ZK18: 0 | ZL18: 0 | ZM18: 0 | ZN18: 0 | ZO18: 0 | ZP18: START SOUTH America: | ADS18: START Africa:
A19: 110 | B19: ANREV | C19: 42760.141 | D19: Tim Nation | E19: AMP Capital | F19: =VLOOKUP(MID(H19,SEARCH("@",H19,1),LEN(H19)-SEARCH("@",H19,1)+1),[2]Sheet1!$D:$F,3,FALSE) -> M0082 | G19: Head of Real Estate Capital | H19: tim.nation@ampcapital.com | I19: 61292576129 | J19: Australia | K19: AUD | M19: 1 | P19: 1408 | Q19: 30 | T19: 5 | V19: 1443 | AC19: 0 | AJ19: 0 | AQ19: 0 | AX19: 0 | BE19: 0 | BF19: 1408 | BG19: 30 | BH19: 0 | BI19: 0 | BJ19: 5 | BK19: 0 | BL19: 1443 | BM19: 4 | BN19: 1 | BQ19: 1 | BS19: 6 | BZ19: 0 | CG19: 0 | CN19: 0 | CU19: 0 | DB19: 0 | DC19: 4 | DD19: 1 | DE19: 0 | DF19: 0 | DG19: 1 | DH19: 0 | DI19: 6 | DJ19: YES | DK19: YES | DL19: NO | DM19: NO | DN19: YES | DO19: NO | DP19: NO | DQ19: NO | DR19: NO | DS19: NO | DT19: NO | DU19: NO | DV19: NO | DW19: NO | DX19: NO | DY19: NO | DZ19: NO | EA19: NO | EB19: NO | EC19: NO | ED19: NO | EE19: NO | EF19: NO | EG19: NO | EH19: NO | EI19: NO | EJ19: NO | EK19: NO | EL19: NO | EM19: NO | EN19: NO | EO19: NO | EP19: NO | EQ19: NO | ER19: NO | ES19: NO | ET19: 728.17 | EZ19: 728.17 | FA19: 89.78 | FG19: 89.78 | FN19: 0 | FO19: 116.05 | FU19: 116.05 | GB19: 0 | GI19: 0 | GK19: 30 | GP19: 30 | GQ19: Retail investors | GR19: 474 | GV19: 5 | GX19: 479 | GY19: 1408 | GZ19: 30 | HA19: 0 | HB19: 0 | HC19: 5 | HD19: 0 | HE19: 1443 | HF19: 1108.74 | HG19: 30 | HJ19: 5 | HL19: 1143.74 | HM19: 299.26 | HS19: 299.26 | HZ19: 0 | IG19: 0 | IN19: 0 | IO19: 1408 | IP19: 30 | IQ19: 0 | IR19: 0 | IS19: 5 | IT19: 0 | IU19: 1443 | IW19: 22 | IX19: 78 | JA19: 3 | JB19: 3 | JC19: 1 | JD19: START Asia Pacific: | JE19: 728.17 | JK19: 728.17 | JL19: 89.78 | JR19: 89.78 | JY19: 0 | JZ19: 116.05 | KF19: 116.05 | KM19: 0 | KT19: 0 | KV19: 30 | LA19: 30 | LB19: Retail investors | LC19: 474 | LG19: 5 | LI19: 479 | LJ19: 1408 | LK19: 30 | LL19: 0 | LM19: 0 | LN19: 5 | LO19: 0 | LP19: 1443 | LQ19: 299.26 | LW19: 299.26 | LX19: 1143.74 | MD19: 1143.74 | MK19: 0 | MR19: 0 | MY19: 0 | MZ19: 1443 | NA19: 0 | NB19: 0 | NC19: 0 | ND19: 0 | NE19: 0 | NF19: 1443 | NG19: START Europe: | RJ19: START North America: | VM19: START Global: | ZP19: START SOUTH America: | ADS19: START Africa:
A20: 242 | B20: ANREV | C20: 42780 | D20: Nicholas | E20: Investa Property Group | F20: =VLOOKUP(MID(H20,SEARCH("@",H20,1),LEN(H20)-SEARCH("@",H20,1)+1),[2]Sheet1!$D:$F,3,FALSE) -> M0077 | G20: Senior Fund Analyst | H20: nchui@investa.com.au | I20: +61 2 8226 9916 | J20: Australia | K20: AUD | M20: 1 | P20: 469 | R20: 100 | V20: 569 | AC20: 0 | AJ20: 0 | AQ20: 0 | AX20: 0 | BE20: 0 | BF20: 469 | BG20: 0 | BH20: 100 | BI20: 0 | BJ20: 0 | BK20: 0 | BL20: 569 | BM20: 1 | BO20: 1 | BS20: 2 | BZ20: 0 | CG20: 0 | CN20: 0 | CU20: 0 | DB20: 0 | DC20: 1 | DD20: 0 | DE20: 1 | DF20: 0 | DG20: 0 | DH20: 0 | DI20: 2 | DJ20: YES | DK20: NO | DL20: YES | DM20: NO | DN20: NO | DO20: NO | DP20: NO | DQ20: NO | DR20: NO | DS20: NO | DT20: NO | DU20: NO | DV20: NO | DW20: NO | DX20: NO | DY20: NO | DZ20: NO | EA20: NO | EB20: NO | EC20: NO | ED20: NO | EE20: NO | EF20: NO | EG20: NO | EH20: NO | EI20: NO | EJ20: NO | EK20: NO | EL20: NO | EM20: NO | EN20: NO | EO20: NO | EP20: NO | EQ20: NO | ER20: NO | ES20: NO | EZ20: 0 | FG20: 0 | FN20: 0 | FU20: 0 | GB20: 0 | GI20: 0 | GP20: 0 | GX20: 0 | GY20: 0 | GZ20: 0 | HA20: 0 | HB20: 0 | HC20: 0 | HD20: 0 | HE20: 0 | HF20: 427.8 | HH20: 100 | HL20: 527.8 | HM20: 40.5 | HS20: 40.5 | HZ20: 0 | IG20: 0 | IN20: 0 | IO20: 468.3 | IP20: 0 | IQ20: 100 | IR20: 0 | IS20: 0 | IT20: 0 | IU20: 568.3 | JC20: 1 | JD20: START Asia Pacific: | JK20: 0 | JR20: 0 | JY20: 0 | KF20: 0 | KM20: 0 | KT20: 0 | LA20: 0 | LI20: 0 | LJ20: 0 | LK20: 0 | LL20: 0 | LM20: 0 | LN20: 0 | LO20: 0 | LP20: 0 | LQ20: 40.5 | LS20: 100 | LW20: 140.5 | LX20: 427.8 | MD20: 427.8 | MK20: 0 | MR20: 0 | MY20: 0 | MZ20: 468.3 | NA20: 0 | NB20: 100 | NC20: 0 | ND20: 0 | NE20: 0 | NF20: 568.3 | NG20: START Europe: | RJ20: START North America: | VM20: START Global: | ZP20: START SOUTH America: | ADS20: START Africa:
A21: 237 | B21: ANREV | C21: 42780 | D21: Shawn Tsai | E21: Gaw Capital Partners | F21: =VLOOKUP(MID(H21,SEARCH("@",H21,1),LEN(H21)-SEARCH("@",H21,1)+1),[2]Sheet1!$D:$F,3,FALSE) -> M0186 | G21: Associate | H21: shawntsai@gawcapital.com | I21: 25837774 | J21: Hong Kong | K21: USD | M21: 1 | P21: 1252.2 | V21: 1252.2 | AC21: 0 | AJ21: 0 | AQ21: 0 | AX21: 0 | BE21: 0 | BF21: 1252.2 | BG21: 0 | BH21: 0 | BI21: 0 | BJ21: 0 | BK21: 0 | BL21: 1252.2 | BM21: 2 | BS21: 2 | BZ21: 0 | CG21: 0 | CN21: 0 | CU21: 0 | DB21: 0 | DC21: 2 | DD21: 0 | DE21: 0 | DF21: 0 | DG21: 0 | DH21: 0 | DI21: 2 | DJ21: YES | DK21: NO | DL21: NO | DM21: NO | DN21: NO | DO21: NO | DP21: NO | DQ21: NO | DR21: NO | DS21: NO | DT21: NO | DU21: NO | DV21: NO | DW21: NO | DX21: NO | DY21: NO | DZ21: NO | EA21: NO | EB21: NO | EC21: NO | ED21: NO | EE21: NO | EF21: NO | EG21: NO | EH21: NO | EI21: NO | EJ21: NO | EK21: NO | EL21: NO | EM21: NO | EN21: NO | EO21: NO | EP21: NO | EQ21: NO | ER21: NO | ES21: NO | ET21: 520 | EZ21: 520 | FG21: 0 | FH21: 460 | FN21: 460 | FU21: 0 | FV21: 10 | GB21: 10 | GC21: 146.4 | GI21: 146.4 | GJ21: 23 | GP21: 23 | GQ21: General Partner contribution,financial institution, corporate | GR21: 92.8 | GX21: 92.8 | GY21: 1252.2 | GZ21: 0 | HA21: 0 | HB21: 0 | HC21: 0 | HD21: 0 | HE21: 1252.2 | HF21: 589.3 | HL21: 589.3 | HM21: 297.9 | HS21: 297.9 | HT21: 365 | HZ21: 365 | IG21: 0 | IN21: 0 | IO21: 1252.2 | IP21: 0 | IQ21: 0 | IR21: 0 | IS21: 0 | IT21: 0 | IU21: 1252.2 | JA21: 1 | JB21: 2 | JC21: 1 | JD21: START Asia Pacific: | JE21: 520 | JK21: 520 | JR21: 0 | JS21: 460 | JY21: 460 | KF21: 0 | KG21: 10 | KM21: 10 | KN21: 146.4 | KT21: 146.4 | KU21: 23 | LA21: 23 | LB21: General Partner contribution, corporates, financial institution | LC21: 92.8 | LI21: 92.8 | LJ21: 1252.2 | LK21: 0 | LL21: 0 | LM21: 0 | LN21: 0 | LO21: 0 | LP21: 1252.2 | LQ21: 589.3 | LW21: 589.3 | LX21: 297.9 | MD21: 297.9 | ME21: 365 | MK21: 365 | MR21: 0 | MY21: 0 | MZ21: 1252.2 | NA21: 0 | NB21: 0 | NC21: 0 | ND21: 0 | NE21: 0 | NF21: 1252.2 | NG21: START Europe: | RJ21: START North America: | VM21: START Global: | ZP21: START SOUTH America: | ADS21: START Africa:
A22: 71 | B22: ANREV | C22: 42779.144 | D22: James Inwood | E22: Goodman Group | F22: =VLOOKUP(MID(H22,SEARCH("@",H22,1),LEN(H22)-SEARCH("@",H22,1)+1),[2]Sheet1!$D:$F,3,FALSE) -> M065 | G22: Group Head of Investment Management | H22: James.Inwood@goodman.com | I22: 9230 7417 | J22: Australia | K22: AUD | M22: 1 | S22: 1633.92 | V22: 1633.92 | Z22: 684.11 | AC22: 684.11 | AJ22: 0 | AQ22: 0 | AX22: 0 | BE22: 0 | BF22: 0 | BG22: 0 | BH22: 0 | BI22: 2318.03 | BJ22: 0 | BK22: 0 | BL22: 2318.03 | BP22: 3 | BS22: 3 | BW22: 1 | BZ22: 1 | CG22: 0 | CN22: 0 | CU22: 0 | DB22: 0 | DC22: 0 | DD22: 0 | DE22: 0 | DF22: 4 | DG22: 0 | DH22: 0 | DI22: 4 | DJ22: NO | DK22: NO | DL22: NO | DM22: YES | DN22: NO | DO22: NO | DP22: NO | DQ22: NO | DR22: NO | DS22: YES | DT22: NO | DU22: NO | DV22: NO | DW22: NO | DX22: NO | DY22: NO | DZ22: NO | EA22: NO | EB22: NO | EC22: NO | ED22: NO | EE22: NO | EF22: NO | EG22: NO | EH22: NO | EI22: NO | EJ22: NO | EK22: NO | EL22: NO | EM22: NO | EN22: NO | EO22: NO | EP22: NO | EQ22: NO | ER22: NO | ES22: NO | EW22: 2256.75 | EZ22: 2256.75 | FG22: 0 | FK22: 61.28 | FN22: 61.28 | FU22: 0 | GB22: 0 | GI22: 0 | GP22: 0 | GX22: 0 | GY22: 0 | GZ22: 0 | HA22: 0 | HB22: 2318.03 | HC22: 0 | HD22: 0 | HE22: 2318.03 | HL22: 0 | HP22: 587.17 | HS22: 587.17 | HW22: 1730.86 | HZ22: 1730.86 | IG22: 0 | IN22: 0 | IO22: 0 | IP22: 0 | IQ22: 0 | IR22: 2318.03 | IS22: 0 | IT22: 0 | IU22: 2318.03 | IX22: 100 | JA22: 3 | JB22: 3 | JC22: 1 | JD22: START Asia Pacific: | JH22: 1572.64 | JK22: 1572.64 | JR22: 0 | JV22: 61.28 | JY22: 61.28 | KF22: 0 | KM22: 0 | KT22: 0 | LA22: 0 | LI22: 0 | LJ22: 0 | LK22: 0 | LL22: 0 | LM22: 1633.92 | LN22: 0 | LO22: 0 | LP22: 1633.92 | LT22: 245.12 | LW22: 245.12 | MD22: 0 | MH22: 1388.8 | MK22: 1388.8 | MR22: 0 | MY22: 0 | MZ22: 0 | NA22: 0 | NB22: 0 | NC22: 1633.92 | ND22: 0 | NE22: 0 | NF22: 1633.92 | NG22: START Europe: | NK22: 684.11 | NN22: 684.11 | NU22: 0 | OB22: 0 | OI22: 0 | OP22: 0 | OW22: 0 | PD22: 0 | PL22: 0 | PM22: 0 | PN22: 0 | PO22: 0 | PP22: 684.11 | PQ22: 0 | PR22: 0 | PS22: 684.11 | PW22: 342.05 | PZ22: 342.05 | QG22: 0 | QK22: 342.06 | QN22: 342.06 | QU22: 0 | RB22: 0 | RC22: 0 | RD22: 0 | RE22: 0 | RF22: 684.11 | RG22: 0 | RH22: 0 | RI22: 684.11 | RJ22: START North America: | VM22: START Global: | ZP22: START SOUTH America: | ADS22: START Africa:
A23: 184 | B23: ANREV | C23: 42780 | D23: Angel | E23: CLSA | F23: =VLOOKUP(MID(H23,SEARCH("@",H23,1),LEN(H23)-SEARCH("@",H23,1)+1),[2]Sheet1!$D:$F,3,FALSE) -> M0309 | G23: MD | H23: angel.li@clsa.com | I23: na | J23: Hong Kong | K23: USD | M23: 2 | V23: 0 | AC23: 0 | AJ23: 0 | AQ23: 0 | AX23: 0 | BE23: 0 | BF23: 0 | BG23: 0 | BH23: 0 | BI23: 0 | BJ23: 0 | BK23: 0 | BL23: 0 | BS23: 0 | BZ23: 0 | CG23: 0 | CN23: 0 | CU23: 0 | DB23: 0 | DC23: 0 | DD23: 0 | DE23: 0 | DF23: 0 | DG23: 0 | DH23: 0 | DI23: 0 | DJ23: NO | DK23: NO | DL23: NO | DM23: NO | DN23: NO | DO23: NO | DP23: NO | DQ23: NO | DR23: NO | DS23: NO | DT23: NO | DU23: NO | DV23: NO | DW23: NO | DX23: NO | DY23: NO | DZ23: NO | EA23: NO | EB23: NO | EC23: NO | ED23: NO | EE23: NO | EF23: NO | EG23: NO | EH23: NO | EI23: NO | EJ23: NO | EK23: NO | EL23: NO | EM23: NO | EN23: NO | EO23: NO | EP23: NO | EQ23: NO | ER23: NO | ES23: NO | EZ23: 0 | FG23: 0 | FN23: 0 | FU23: 0 | GB23: 0 | GI23: 0 | GP23: 0 | GX23: 0 | GY23: 0 | GZ23: 0 | HA23: 0 | HB23: 0 | HC23: 0 | HD23: 0 | HE23: 0 | HL23: 0 | HS23: 0 | HZ23: 0 | IG23: 0 | IN23: 0 | IO23: 0 | IP23: 0 | IQ23: 0 | IR23: 0 | IS23: 0 | IT23: 0 | IU23: 0 | JC23: 2 | JD23: START Asia Pacific: | NG23: START Europe: | RJ23: START North America: | VM23: START Global: | ZP23: START SOUTH America: | ADS23: START Africa:
