Workbook

Sheet DataCompleted_final_analysis_AV
A1: RecordNo | B1: Surveycode | C1: URIstring | D1: DateUpdated | E1: DateCompleted | F1: PageNo | G1: PathInfo | H1: Referrer | I1: IPaddress | J1: Version | K1: qName | L1: qCompany | M1: mnumber | N1: qJobtitle | O1: qEmail | P1: qTelephone | Q1: qCountry | R1: qCurrency | S1: qCurrencyOther | T1: q1 | U1: q2 | V1: q2other | W1: q31_1 | X1: q31_2 | Y1: q31_3 | Z1: q31_4 | AA1: q31_5 | AB1: q31_6 | AC1: q3ROW1_hidden | AD1: q32_1 | AE1: q32_2 | AF1: q32_3 | AG1: q32_4 | AH1: q32_5 | AI1: q32_6 | AJ1: q3ROW2_hidden | AK1: q33_1 | AL1: q33_2 | AM1: q33_3 | AN1: q33_4 | AO1: q33_5 | AP1: q33_6 | AQ1: q3ROW3_hidden | AR1: q34_1 | AS1: q34_2 | AT1: q34_3 | AU1: q34_4 | AV1: q34_5 | AW1: q34_6 | AX1: q3ROW4_hidden | AY1: q35_1 | AZ1: q35_2 | BA1: q35_3 | BB1: q35_4 | BC1: q35_5 | BD1: q35_6 | BE1: q3ROW5_hidden | BF1: q36_1 | BG1: q36_2 | BH1: q36_3 | BI1: q36_4 | BJ1: q36_5 | BK1: q36_6 | BL1: q3ROW6_hidden | BM1: q3COL1_hidden | BN1: q3COL2_hidden | BO1: q3COL3_hidden | BP1: q3COL4_hidden | BQ1: q3COL5_hidden | BR1: q3COL6_hidden | BS1: q3GRANDTotal_hidden | BT1: ShowEurope | BU1: ShowAsia | BV1: ShowNA | BW1: ShowGlobal | BX1: ShowSA | BY1: ShowAfrica | BZ1: q41_1 | CA1: q41_2 | CB1: q41_3 | CC1: q41_4 | CD1: q41_5 | CE1: q41_6 | CF1: q4ROW1_hidden | CG1: q42_1 | CH1: q42_2 | CI1: q42_3 | CJ1: q42_4 | CK1: q42_5 | CL1: q42_6 | CM1: q4ROW2_hidden | CN1: q43_1 | CO1: q43_2 | CP1: q43_3 | CQ1: q43_4 | CR1: q43_5 | CS1: q43_6 | CT1: q4ROW3_hidden | CU1: q44_1 | CV1: q44_2 | CW1: q44_3 | CX1: q44_4 | CY1: q44_5 | CZ1: q44_6 | DA1: q4ROW4_hidden | DB1: q45_1 | DC1: q45_2 | DD1: q45_3 | DE1: q45_4 | DF1: q45_5 | DG1: q45_6 | DH1: q4ROW5_hidden | DI1: q46_1 | DJ1: q46_2 | DK1: q46_3 | DL1: q46_4 | DM1: q46_5 | DN1: q46_6 | DO1: q4ROW6_hidden | DP1: q4COL1_hidden | DQ1: q4COL2_hidden | DR1: q4COL3_hidden | DS1: q4COL4_hidden | DT1: q4COL5_hidden | DU1: q4COL6_hidden | DV1: q4GRANDTotal_hidden | DW1: Alert41_1 | DX1: Alert41_2 | DY1: Alert41_3 | DZ1: Alert41_4 | EA1: Alert41_5 | EB1: Alert41_6 | EC1: Alert42_1 | ED1: Alert42_2 | EE1: Alert42_3 | EF1: Alert42_4 | EG1: Alert42_5 | EH1: Alert42_6 | EI1: Alert43_1 | EJ1: Alert43_2 | EK1: Alert43_3 | EL1: Alert43_4 | EM1: Alert43_5 | EN1: Alert43_6 | EO1: Alert44_1 | EP1: Alert44_2 | EQ1: Alert44_3 | ER1: Alert44_4 | ES1: Alert44_5 | ET1: Alert44_6 | EU1: Alert45_1 | EV1: Alert45_2 | EW1: Alert45_3 | EX1: Alert45_4 | EY1: Alert45_5 | EZ1: Alert45_6 | FA1: Alert46_1 | FB1: Alert46_2 | FC1: Alert46_3 | FD1: Alert46_4 | FE1: Alert46_5 | FF1: Alert46_6 | FG1: q51_1 | FH1: q51_2 | FI1: q51_3 | FJ1: q51_4 | FK1: q51_5 | FL1: q51_6 | FM1: q5ROW1_hidden | FN1: q52_1 | FO1: q52_2 | FP1: q52_3 | FQ1: q52_4 | FR1: q52_5 | FS1: q52_6 | FT1: q5ROW2_hidden | FU1: q53_1 | FV1: q53_2 | FW1: q53_3 | FX1: q53_4 | FY1: q53_5 | FZ1: q53_6 | GA1: q5ROW3_hidden | GB1: q54_1 | GC1: q54_2 | GD1: q54_3 | GE1: q54_4 | GF1: q54_5 | GG1: q54_6 | GH1: q5ROW4_hidden | GI1: q55_1 | GJ1: q55_2 | GK1: q55_3 | GL1: q55_4 | GM1: q55_5 | GN1: q55_6 | GO1: q5ROW5_hidden | GP1: q56_1 | GQ1: q56_2 | GR1: q56_3 | GS1: q56_4 | GT1: q56_5 | GU1: q56_6 | GV1: q5ROW6_hidden | GW1: q57_1 | GX1: q57_2 | GY1: q57_3 | GZ1: q57_4 | HA1: q57_5 | HB1: q57_6 | HC1: q5ROW7_hidden | HD1: q5other | HE1: q58_1 | HF1: q58_2 | HG1: q58_3 | HH1: q58_4 | HI1: q58_5 | HJ1: q58_6 | HK1: q5ROW8_hidden | HL1: q5COL1_hidden | HM1: q5COL2_hidden | HN1: q5COL3_hidden | HO1: q5COL4_hidden | HP1: q5COL5_hidden | HQ1: q5COL6_hidden | HR1: q5GRANDTotal_hidden | HS1: q61_1 | HT1: q61_2 | HU1: q61_3 | HV1: q61_4 | HW1: q61_5 | HX1: q61_6 | HY1: q6ROW1_hidden | HZ1: q62_1 | IA1: q62_2 | IB1: q62_3 | IC1: q62_4 | ID1: q62_5 | IE1: q62_6 | IF1: q6ROW2_hidden | IG1: q63_1 | IH1: q63_2 | II1: q63_3 | IJ1: q63_4 | IK1: q63_5 | IL1: q63_6 | IM1: q6ROW3_hidden | IN1: q64_1 | IO1: q64_2 | IP1: q64_3 | IQ1: q64_4 | IR1: q64_5 | IS1: q64_6 | IT1: q6ROW4_hidden | IU1: q65_1 | IV1: q65_2 | IW1: q65_3 | IX1: q65_4 | IY1: q65_5 | IZ1: q65_6 | JA1: q6ROW5_hidden | JB1: q6COL1_hidden | JC1: q6COL2_hidden | JD1: q6COL3_hidden | JE1: q6COL4_hidden | JF1: q6COL5_hidden | JG1: q6COL6_hidden | JH1: q6GRANDTotal_hidden | JI1: q7_1 | JJ1: q7_2 | JK1: q7_3 | JL1: q7other | JM1: q7_4 | JN1: q81_1 | JO1: q81_2 | JP1: q81_3 | JQ1: q81_4 | JR1: q81_5 | JS1: q81_6 | JT1: q8ROW1_hidden | JU1: q82_1 | JV1: q82_2 | JW1: q82_3 | JX1: q82_4 | JY1: q82_5 | JZ1: q82_6 | KA1: q8ROW2_hidden | KB1: q83_1 | KC1: q83_2 | KD1: q83_3 | KE1: q83_4 | KF1: q83_5 | KG1: q83_6 | KH1: q8ROW3_hidden | KI1: q84_1 | KJ1: q84_2 | KK1: q84_3 | KL1: q84_4 | KM1: q84_5 | KN1: q84_6 | KO1: q8ROW4_hidden | KP1: q85_1 | KQ1: q85_2 | KR1: q85_3 | KS1: q85_4 | KT1: q85_5 | KU1: q85_6 | KV1: q8ROW5_hidden | KW1: q86_1 | KX1: q86_2 | KY1: q86_3 | KZ1: q86_4 | LA1: q86_5 | LB1: q86_6 | LC1: q8ROW6_hidden | LD1: q87_1 | LE1: q87_2 | LF1: q87_3 | LG1: q87_4 | LH1: q87_5 | LI1: q87_6 | LJ1: q8ROW7_hidden | LK1: q8other | LL1: q88_1 | LM1: q88_2 | LN1: q88_3 | LO1: q88_4 | LP1: q88_5 | LQ1: q88_6 | LR1: q8ROW8_hidden | LS1: q8COL1_hidden | LT1: q8COL2_hidden | LU1: q8COL3_hidden | LV1: q8COL4_hidden | LW1: q8COL5_hidden | LX1: q8COL6_hidden | LY1: q8GRANDTotal_hidden | LZ1: q91_1 | MA1: q91_2 | MB1: q91_3 | MC1: q91_4 | MD1: q91_5 | ME1: q91_6 | MF1: q9ROW1_hidden | MG1: q92_1 | MH1: q92_2 | MI1: q92_3 | MJ1: q92_4 | MK1: q92_5 | ML1: q92_6 | MM1: q9ROW2_hidden | MN1: q93_1 | MO1: q93_2 | MP1: q93_3 | MQ1: q93_4 | MR1: q93_5 | MS1: q93_6 | MT1: q9ROW3_hidden | MU1: q94_1 | MV1: q94_2 | MW1: q94_3 | MX1: q94_4 | MY1: q94_5 | MZ1: q94_6 | NA1: q9ROW4_hidden | NB1: q95_1 | NC1: q95_2 | ND1: q95_3 | NE1: q95_4 | NF1: q95_5 | NG1: q95_6 | NH1: q9ROW5_hidden | NI1: q96_1 | NJ1: q96_2 | NK1: q96_3 | NL1: q96_4 | NM1: q96_5 | NN1: q96_6 | NO1: q9ROW6_hidden | NP1: q97_1 | NQ1: q97_2 | NR1: q97_3 | NS1: q97_4 | NT1: q97_5 | NU1: q97_6 | NV1: q9ROW7_hidden | NW1: q9other | NX1: q98_1 | NY1: q98_2 | NZ1: q98_3 | OA1: q98_4 | OB1: q98_5 | OC1: q98_6 | OD1: q9ROW8_hidden | OE1: q9COL1_hidden | OF1: q9COL2_hidden | OG1: q9COL3_hidden | OH1: q9COL4_hidden | OI1: q9COL5_hidden | OJ1: q9COL6_hidden | OK1: q9GRANDTotal_hidden | OL1: q101_1 | OM1: q101_2 | ON1: q101_3 | OO1: q101_4 | OP1: q101_5 | OQ1: q101_6 | OR1: q10ROW1_hidden | OS1: q102_1 | OT1: q102_2 | OU1: q102_3 | OV1: q102_4 | OW1: q102_5 | OX1: q102_6 | OY1: q10ROW2_hidden | OZ1: q103_1 | PA1: q103_2 | PB1: q103_3 | PC1: q103_4 | PD1: q103_5 | PE1: q103_6 | PF1: q10ROW3_hidden | PG1: q104_1 | PH1: q104_2 | PI1: q104_3 | PJ1: q104_4 | PK1: q104_5 | PL1: q104_6 | PM1: q10ROW4_hidden | PN1: q105_1 | PO1: q105_2 | PP1: q105_3 | PQ1: q105_4 | PR1: q105_5 | PS1: q105_6 | PT1: q10ROW5_hidden | PU1: q106_1 | PV1: q106_2 | PW1: q106_3 | PX1: q106_4 | PY1: q106_5 | PZ1: q106_6 | QA1: q10ROW6_hidden | QB1: q107_1 | QC1: q107_2 | QD1: q107_3 | QE1: q107_4 | QF1: q107_5 | QG1: q107_6 | QH1: q10ROW7_hidden | QI1: q10other | QJ1: q108_1 | QK1: q108_2 | QL1: q108_3 | QM1: q108_4 | QN1: q108_5 | QO1: q108_6 | QP1: q10ROW8_hidden | QQ1: q10COL1_hidden | QR1: q10COL2_hidden | QS1: q10COL3_hidden | QT1: q10COL4_hidden | QU1: q10COL5_hidden | QV1: q10COL6_hidden | QW1: q10GRANDTotal_hidden | QX1: q111_1 | QY1: q111_2 | QZ1: q111_3 | RA1: q111_4 | RB1: q111_5 | RC1: q111_6 | RD1: q11ROW1_hidden | RE1: q112_1 | RF1: q112_2 | RG1: q112_3 | RH1: q112_4 | RI1: q112_5 | RJ1: q112_6 | RK1: q11ROW2_hidden | RL1: q113_1 | RM1: q113_2 | RN1: q113_3 | RO1: q113_4 | RP1: q113_5 | RQ1: q113_6 | RR1: q11ROW3_hidden | RS1: q114_1 | RT1: q114_2 | RU1: q114_3 | RV1: q114_4 | RW1: q114_5 | RX1: q114_6 | RY1: q11ROW4_hidden | RZ1: q115_1 | SA1: q115_2 | SB1: q115_3 | SC1: q115_4 | SD1: q115_5 | SE1: q115_6 | SF1: q11ROW5_hidden | SG1: q116_1 | SH1: q116_2 | SI1: q116_3 | SJ1: q116_4 | SK1: q116_5 | SL1: q116_6 | SM1: q11ROW6_hidden | SN1: q117_1 | SO1: q117_2 | SP1: q117_3 | SQ1: q117_4 | SR1: q117_5 | SS1: q117_6 | ST1: q11ROW7_hidden | SU1: q11other | SV1: q118_1 | SW1: q118_2 | SX1: q118_3 | SY1: q118_4 | SZ1: q118_5 | TA1: q118_6 | TB1: q11ROW8_hidden | TC1: q11COL1_hidden | TD1: q11COL2_hidden | TE1: q11COL3_hidden | TF1: q11COL4_hidden | TG1: q11COL5_hidden | TH1: q11COL6_hidden | TI1: q11GRANDTotal_hidden | TJ1: q121_1 | TK1: q121_2 | TL1: q121_3 | TM1: q121_4 | TN1: q121_5 | TO1: q121_6 | TP1: q12ROW1_hidden | TQ1: q122_1 | TR1: q122_2 | TS1: q122_3 | TT1: q122_4 | TU1: q122_5 | TV1: q122_6 | TW1: q12ROW2_hidden | TX1: q123_1 | TY1: q123_2 | TZ1: q123_3 | UA1: q123_4 | UB1: q123_5 | UC1: q123_6 | UD1: q12ROW3_hidden | UE1: q124_1 | UF1: q124_2 | UG1: q124_3 | UH1: q124_4 | UI1: q124_5 | UJ1: q124_6 | UK1: q12ROW4_hidden | UL1: q125_1 | UM1: q125_2 | UN1: q125_3 | UO1: q125_4 | UP1: q125_5 | UQ1: q125_6 | UR1: q12ROW5_hidden | US1: q126_1 | UT1: q126_2 | UU1: q126_3 | UV1: q126_4 | UW1: q126_5 | UX1: q126_6 | UY1: q12ROW6_hidden | UZ1: q127_1 | VA1: q127_2 | VB1: q127_3 | VC1: q127_4 | VD1: q127_5 | VE1: q127_6 | VF1: q12ROW7_hidden | VG1: q12other | VH1: q128_1 | VI1: q128_2 | VJ1: q128_3 | VK1: q128_4 | VL1: q128_5 | VM1: q128_6 | VN1: q12ROW8_hidden | VO1: q12COL1_hidden | VP1: q12COL2_hidden | VQ1: q12COL3_hidden | VR1: q12COL4_hidden | VS1: q12COL5_hidden | VT1: q12COL6_hidden | VU1: q12GRANDTotal_hidden | VV1: q131_1 | VW1: q131_2 | VX1: q131_3 | VY1: q131_4 | VZ1: q131_5 | WA1: q131_6 | WB1: q13ROW1_hidden | WC1: q132_1 | WD1: q132_2 | WE1: q132_3 | WF1: q132_4 | WG1: q132_5 | WH1: q132_6 | WI1: q13ROW2_hidden | WJ1: q133_1 | WK1: q133_2 | WL1: q133_3 | WM1: q133_4 | WN1: q133_5 | WO1: q133_6 | WP1: q13ROW3_hidden | WQ1: q134_1 | WR1: q134_2 | WS1: q134_3 | WT1: q134_4 | WU1: q134_5 | WV1: q134_6 | WW1: q13ROW4_hidden | WX1: q135_1 | WY1: q135_2 | WZ1: q135_3 | XA1: q135_4 | XB1: q135_5 | XC1: q135_6 | XD1: q13ROW5_hidden | XE1: q136_1 | XF1: q136_2 | XG1: q136_3 | XH1: q136_4 | XI1: q136_5 | XJ1: q136_6 | XK1: q13ROW6_hidden | XL1: q137_1 | XM1: q137_2 | XN1: q137_3 | XO1: q137_4 | XP1: q137_5 | XQ1: q137_6 | XR1: q13ROW7_hidden | XS1: q13other | XT1: q138_1 | XU1: q138_2 | XV1: q138_3 | XW1: q138_4 | XX1: q138_5 | XY1: q138_6 | XZ1: q13ROW8_hidden | YA1: q13COL1_hidden | YB1: q13COL2_hidden | YC1: q13COL3_hidden | YD1: q13COL4_hidden | YE1: q13COL5_hidden | YF1: q13COL6_hidden | YG1: q13GRANDTotal_hidden | YH1: q14 | YI1: q15 | YJ1: q16 | YK1: UserAgent | YL1: RecordNo1 | YM1: Surveycode1 | YN1: Association | YO1: Company | YP1: FullName | YQ1: EmailAddress | YR1: SampleNote | YS1: SurveyURL
A2: 23 | B2: NVWCK043 | C2: survey=NVWCK043 | D2: 42411.442 | E2: 42411.446 | F2: 14 | G2: 1|2|3|4|5|6|7|8|9|15| | I2: 205.201.132.14 | J2: INREV | K2: Harry Humble | L2: Hunter REIM | M2: =VLOOKUP(MID(O2,SEARCH("@",O2,1),LEN(O2)-SEARCH("@",O2,1)+1),[1]Sheet1!$D:$F,3,FALSE) -> M588 | N2: Director | O2: hhumble@hunterreim.com | P2: 7791109339 | Q2: United Kingdom | R2: GBP | T2: 1 | W2: 66 | X2: 40 | AC2: 106 | AJ2: 0 | AQ2: 0 | AX2: 0 | BE2: 0 | BL2: 0 | BM2: 66 | BN2: 40 | BO2: 0 | BP2: 0 | BQ2: 0 | BR2: 0 | BS2: 106 | BT2: TRUE | BU2: FALSE | BV2: FALSE | BW2: FALSE | BX2: FALSE | BY2: FALSE | BZ2: 1 | CA2: 1 | CF2: 2 | CM2: 0 | CT2: 0 | DA2: 0 | DH2: 0 | DO2: 0 | DP2: 1 | DQ2: 1 | DR2: 0 | DS2: 0 | DT2: 0 | DU2: 0 | DV2: 2 | DW2: YES | DX2: YES | DY2: NO | DZ2: NO | EA2: NO | EB2: NO | EC2: NO | ED2: NO | EE2: NO | EF2: NO | EG2: NO | EH2: NO | EI2: NO | EJ2: NO | EK2: NO | EL2: NO | EM2: NO | EN2: NO | EO2: NO | EP2: NO | EQ2: NO | ER2: NO | ES2: NO | ET2: NO | EU2: NO | EV2: NO | EW2: NO | EX2: NO | EY2: NO | EZ2: NO | FA2: NO | FB2: NO | FC2: NO | FD2: NO | FE2: NO | FF2: NO | FG2: 66 | FM2: 66 | FT2: 0 | FV2: 40 | GA2: 40 | GH2: 0 | GO2: 0 | GV2: 0 | HC2: 0 | HK2: 0 | HL2: 66 | HM2: 40 | HN2: 0 | HO2: 0 | HP2: 0 | HQ2: 0 | HR2: 106 | HS2: 66 | HY2: 66 | IF2: 0 | IH2: 40 | IM2: 40 | IT2: 0 | JA2: 0 | JB2: 66 | JC2: 40 | JD2: 0 | JE2: 0 | JF2: 0 | JG2: 0 | JH2: 106 | JK2: 100 | JN2: 66 | JT2: 66 | KA2: 0 | KC2: 40 | KH2: 40 | KO2: 0 | KV2: 0 | LC2: 0 | LJ2: 0 | LR2: 0 | LS2: 66 | LT2: 40 | LU2: 0 | LV2: 0 | LW2: 0 | LX2: 0 | LY2: 106 | OK2: 0 | QW2: 0 | TI2: 0 | VU2: 0 | YG2: 0 | YH2: 1 | YI2: 3 | YJ2: 1 | YL2: 175 | YM2: NVWCK043 | YN2: INREV | YO2: Hunter Peoperty Fund Management | YP2: Harry Humble | YQ2: hhumble@hpfm.co.uk | YS2: http://click.surveylab.co.uk/anrev-inrev-ncreif-capital-raising-2016/?survey=NVWCK043
A3: 24 | B3: NVCRW472 | C3: survey=NVCRW472 | D3: 42415.641 | E3: 42415.641 | F3: 14 | G3: 1|2|3|2|3|2|3|2|2|3|15| | I3: 89.191.216.221 | J3: INREV | K3: Robin Hubbard | L3: InfraRed Capital Partners | M3: M665 | N3: Director, Business Development | O3: robin.hubbard@ircp.com | P3: 2074841855 | Q3: United Kingdom | R3: GBP | T3: 2 | AC3: 0 | AJ3: 0 | AQ3: 0 | AX3: 0 | BE3: 0 | BL3: 0 | BM3: 0 | BN3: 0 | BO3: 0 | BP3: 0 | BQ3: 0 | BR3: 0 | BS3: 0 | BT3: FALSE | BU3: FALSE | BV3: FALSE | BW3: FALSE | BX3: FALSE | BY3: FALSE | CF3: 0 | CM3: 0 | CT3: 0 | DA3: 0 | DH3: 0 | DO3: 0 | DP3: 0 | DQ3: 0 | DR3: 0 | DS3: 0 | DT3: 0 | DU3: 0 | DV3: 0 | DW3: NO | DX3: NO | DY3: NO | DZ3: NO | EA3: NO | EB3: NO | EC3: NO | ED3: NO | EE3: NO | EF3: NO | EG3: NO | EH3: NO | EI3: NO | EJ3: NO | EK3: NO | EL3: NO | EM3: NO | EN3: NO | EO3: NO | EP3: NO | EQ3: NO | ER3: NO | ES3: NO | ET3: NO | EU3: NO | EV3: NO | EW3: NO | EX3: NO | EY3: NO | EZ3: NO | FA3: NO | FB3: NO | FC3: NO | FD3: NO | FE3: NO | FF3: NO | FM3: 0 | FT3: 0 | GA3: 0 | GH3: 0 | GO3: 0 | GV3: 0 | HC3: 0 | HK3: 0 | HL3: 0 | HM3: 0 | HN3: 0 | HO3: 0 | HP3: 0 | HQ3: 0 | HR3: 0 | HY3: 0 | IF3: 0 | IM3: 0 | IT3: 0 | JA3: 0 | JB3: 0 | JC3: 0 | JD3: 0 | JE3: 0 | JF3: 0 | JG3: 0 | JH3: 0 | JT3: 0 | KA3: 0 | KH3: 0 | KO3: 0 | KV3: 0 | LC3: 0 | LJ3: 0 | LR3: 0 | LS3: 0 | LT3: 0 | LU3: 0 | LV3: 0 | LW3: 0 | LX3: 0 | LY3: 0 | OK3: 0 | QW3: 0 | TI3: 0 | VU3: 0 | YG3: 0 | YH3: 1 | YI3: 2 | YJ3: 1 | YK3: Mozilla/5.0 (Windows NT 6.1; WOW64; Trident/7.0; rv:11.0) like Gecko | YL3: 186 | YM3: NVCRW472 | YN3: INREV | YO3: InfraRed Capital Partners Limited | YP3: Kasia Makarewicz | YQ3: kasia.makarewicz@ircp.com | YS3: http://click.surveylab.co.uk/anrev-inrev-ncreif-capital-raising-2016/?survey=NVCRW472
A4: 25 | B4: NVBVX437 | C4: survey=NVBVX437 | D4: 42416.428 | E4: 42416.427 | F4: 8 | G4: 1|2|2|2|2|2|2|2|3|4|5|6|7|8|6|7|8|3|2|3|4|2|3|4|5|3|4|5|4|5|6|7|8|2|3|4|5|6|7|8|9|6|7|8|9|6|7|8|9|2|3|4|5|6|7|8|9|15|2|3|4|5|6|7|8|9| | I4: 108.171.128.174 | J4: INREV | K4: Christopher Woodley | L4: Aberdeen Asset Management | M4: =VLOOKUP(MID(O4,SEARCH("@",O4,1),LEN(O4)-SEARCH("@",O4,1)+1),[1]Sheet1!$D:$F,3,FALSE) -> M675 | N4: Business Information Manager | O4: christopher.woodley@aberdeen-asset.com | P4: +44 20 7463 6739 | Q4: United Kingdom | R4: GBP | T4: 1 | W4: 90 | X4: 1733 | Y4: 0 | Z4: 0 | AA4: 0 | AB4: 0 | AC4: 1823 | AD4: 0 | AE4: 0 | AF4: 0 | AG4: 0 | AH4: 0 | AI4: 0 | AJ4: 0 | AK4: 0 | AL4: 0 | AM4: 0 | AN4: 0 | AO4: 0 | AP4: 0 | AQ4: 0 | AR4: 0 | AS4: 0 | AT4: 0 | AU4: 0 | AV4: 0 | AW4: 0 | AX4: 0 | AY4: 0 | AZ4: 0 | BA4: 0 | BB4: 0 | BC4: 0 | BD4: 0 | BE4: 0 | BF4: 0 | BG4: 0 | BH4: 0 | BI4: 0 | BJ4: 0 | BK4: 0 | BL4: 0 | BM4: 90 | BN4: 1733 | BO4: 0 | BP4: 0 | BQ4: 0 | BR4: 0 | BS4: 1823 | BT4: TRUE | BU4: FALSE | BV4: FALSE | BW4: FALSE | BX4: FALSE | BY4: FALSE | BZ4: 4 | CA4: 6 | CF4: 10 | CM4: 0 | CT4: 0 | DA4: 0 | DH4: 0 | DO4: 0 | DP4: 4 | DQ4: 6 | DR4: 0 | DS4: 0 | DT4: 0 | DU4: 0 | DV4: 10 | DW4: YES | DX4: YES | DY4: NO | DZ4: NO | EA4: NO | EB4: NO | EC4: NO | ED4: NO | EE4: NO | EF4: NO | EG4: NO | EH4: NO | EI4: NO | EJ4: NO | EK4: NO | EL4: NO | EM4: NO | EN4: NO | EO4: NO | EP4: NO | EQ4: NO | ER4: NO | ES4: NO | ET4: NO | EU4: NO | EV4: NO | EW4: NO | EX4: NO | EY4: NO | EZ4: NO | FA4: NO | FB4: NO | FC4: NO | FD4: NO | FE4: NO | FF4: NO | FG4: 45 | FH4: 1530 | FM4: 1575 | FN4: 6 | FO4: 0 | FT4: 6 | FU4: 0 | FV4: 0 | GA4: 0 | GB4: 2 | GC4: 203 | GH4: 205 | GI4: 0 | GJ4: 0 | GO4: 0 | GP4: 0 | GQ4: 0 | GV4: 0 | GW4: 0 | GX4: 0 | HC4: 0 | HD4: Other Corporate/Unknown | HE4: 37 | HF4: 0 | HK4: 37 | HL4: 90 | HM4: 1733 | HN4: 0 | HO4: 0 | HP4: 0 | HQ4: 0 | HR4: 1823 | HS4: 90 | HT4: 1660 | HY4: 1750 | HZ4: 0 | IA4: 0 | IF4: 0 | IG4: 0 | IH4: 73 | IM4: 73 | IN4: 0 | IO4: 0 | IT4: 0 | IU4: 0 | IV4: 0 | JA4: 0 | JB4: 90 | JC4: 1733 | JD4: 0 | JE4: 0 | JF4: 0 | JG4: 0 | JH4: 1823 | JI4: 0 | JJ4: 0 | JK4: 0 | JL4: Not available | JM4: 100 | JN4: 45 | JO4: 1530 | JT4: 1575 | JU4: 6 | JV4: 0 | KA4: 6 | KB4: 0 | KC4: 0 | KH4: 0 | KI4: 2 | KJ4: 203 | KO4: 205 | KP4: 0 | KQ4: 0 | KV4: 0 | KW4: 0 | KX4: 0 | LC4: 0 | LD4: 0 | LE4: 0 | LJ4: 0 | LK4: Other Corporate/Unknown | LL4: 37 | LM4: 0 | LR4: 37 | LS4: 90 | LT4: 1733 | LU4: 0 | LV4: 0 | LW4: 0 | LX4: 0 | LY4: 1823 | OK4: 0 | QW4: 0 | TI4: 0 | VU4: 0 | YG4: 0 | YH4: 1 | YI4: 2 | YJ4: 1 | YK4: Mozilla/5.0 (compatible; MSIE 9.0; Windows NT 6.0; WOW64; Trident/5.0; ) | YL4: 14 | YM4: NVBVX437 | YN4: INREV | YO4: Aberdeen Asset Management | YP4: Christopher Woodley | YQ4: christopher.woodley@aberdeen-asset.com | YS4: http://click.surveylab.co.uk/anrev-inrev-ncreif-capital-raising-2016/?survey=NVBVX437
A5: 26 | B5: NVXTH459 | C5: survey=NVXTH459 | D5: 42404.569 | E5: 42404.637 | F5: 14 | G5: 1|2|2|3|4|5|6|7|8|9|10|11|15| | I5: 85.115.52.201 | J5: INREV | K5: Charlie Manhoff | L5: Tishman Speyer | M5: =VLOOKUP(MID(O5,SEARCH("@",O5,1),LEN(O5)-SEARCH("@",O5,1)+1),[1]Sheet1!$D:$F,3,FALSE) -> M054 | N5: Associate, Equity Capital Markets | O5: cmanhoff@tishmanspeyer.com | P5: 212-588-8527 | Q5: United States | R5: USD | T5: 1 | W5: 196.96 | Z5: 273.42 | AC5: 470.38 | AG5: 9.15 | AJ5: 9.15 | AN5: 1301.72 | AQ5: 1301.72 | AX5: 0 | BE5: 0 | BL5: 0 | BM5: 196.96 | BN5: 0 | BO5: 0 | BP5: 1584.29 | BQ5: 0 | BR5: 0 | BS5: 1781.25 | BT5: TRUE | BU5: TRUE | BV5: TRUE | BW5: FALSE | BX5: FALSE | BY5: FALSE | BZ5: 2 | CC5: 2 | CF5: 4 | CJ5: 1 | CM5: 1 | CQ5: 8 | CT5: 8 | DA5: 0 | DH5: 0 | DO5: 0 | DP5: 2 | DQ5: 0 | DR5: 0 | DS5: 11 | DT5: 0 | DU5: 0 | DV5: 13 | DW5: YES | DX5: NO | DY5: NO | DZ5: YES | EA5: NO | EB5: NO | EC5: NO | ED5: NO | EE5: NO | EF5: YES | EG5: NO | EH5: NO | EI5: NO | EJ5: NO | EK5: NO | EL5: YES | EM5: NO | EN5: NO | EO5: NO | EP5: NO | EQ5: NO | ER5: NO | ES5: NO | ET5: NO | EU5: NO | EV5: NO | EW5: NO | EX5: NO | EY5: NO | EZ5: NO | FA5: NO | FB5: NO | FC5: NO | FD5: NO | FE5: NO | FF5: NO | FG5: 80.91 | FJ5: 730.22 | FM5: 811.13 | FQ5: 237.47 | FT5: 237.47 | FU5: 37.33 | FX5: 180.18 | GA5: 217.51 | GH5: 0 | GO5: 0 | GV5: 0 | GW5: 22.9 | HC5: 22.9 | HD5: Bank/Investment Manager/Corporate Investor | HE5: 55.81 | HH5: 436.43 | HK5: 492.24 | HL5: 196.95 | HM5: 0 | HN5: 0 | HO5: 1584.3 | HP5: 0 | HQ5: 0 | HR5: 1781.25 | HS5: 25.98 | HV5: 415.1 | HY5: 441.08 | HZ5: 84.55 | IC5: 1145.4 | IF5: 1229.95 | IG5: 68.88 | IJ5: 23.8 | IM5: 92.68 | IN5: 17.54 | IT5: 17.54 | JA5: 0 | JB5: 196.95 | JC5: 0 | JD5: 0 | JE5: 1584.3 | JF5: 0 | JG5: 0 | JH5: 1781.25 | JI5: 0 | JJ5: 0 | JK5: 100 | JN5: 80.91 | JQ5: 82.74 | JT5: 163.65 | JX5: 64.67 | KA5: 64.67 | KB5: 37.33 | KE5: 126.02 | KH5: 163.35 | KO5: 0 | KV5: 0 | LC5: 0 | LD5: 22.9 | LJ5: 22.9 | LK5: Bank/Investment Manager | LL5: 55.81 | LR5: 55.81 | LS5: 196.95 | LT5: 0 | LU5: 0 | LV5: 273.43 | LW5: 0 | LX5: 0 | LY5: 470.38 | MQ5: 9.15 | MT5: 9.15 | OH5: 9.15 | OK5: 9.15 | OO5: 647.49 | OR5: 647.49 | OV5: 172.8 | OY5: 172.8 | PC5: 45 | PF5: 45 | QI5: Corporate Investor/Local Developer | QM5: 436.43 | QP5: 436.43 | QT5: 1301.72 | QW5: 1301.72 | TI5: 0 | VU5: 0 | YG5: 0 | YH5: 1 | YI5: 1 | YJ5: 1 | YK5: Mozilla/5.0 (Windows NT 6.1; WOW64; Trident/7.0; rv:11.0) like Gecko | YL5: 338 | YM5: NVXTH459 | YN5: INREV | YO5: Tishman Speyer | YP5: Michael Spies | YQ5: mspies@tishmanspeyer.com | YS5: http://click.surveylab.co.uk/anrev-inrev-ncreif-capital-raising-2016/?survey=NVXTH459
A6: 27 | B6: NVVJT621 | C6: survey=NVVJT621 | D6: 42416.415 | E6: 42416.418 | F6: 14 | G6: 1|2|2|3|4|5|6|7|8|9|15| | I6: 38.105.189.5 | J6: INREV | K6: Danielle Apstolatos | L6: Bluehouse Capital | M6: =VLOOKUP(MID(O6,SEARCH("@",O6,1),LEN(O6)-SEARCH("@",O6,1)+1),[1]Sheet1!$D:$F,3,FALSE) -> M158 | N6: Director Investor Relations | O6: dapostolatos@bluehousecapital.com | P6: 302103628900 | Q6: Greece | R6: EUR | T6: 1 | W6: 50 | AC6: 50 | AJ6: 0 | AQ6: 0 | AX6: 0 | BE6: 0 | BL6: 0 | BM6: 50 | BN6: 0 | BO6: 0 | BP6: 0 | BQ6: 0 | BR6: 0 | BS6: 50 | BT6: TRUE | BU6: FALSE | BV6: FALSE | BW6: FALSE | BX6: FALSE | BY6: FALSE | BZ6: 1 | CF6: 1 | CM6: 0 | CT6: 0 | DA6: 0 | DH6: 0 | DO6: 0 | DP6: 1 | DQ6: 0 | DR6: 0 | DS6: 0 | DT6: 0 | DU6: 0 | DV6: 1 | DW6: YES | DX6: NO | DY6: NO | DZ6: NO | EA6: NO | EB6: NO | EC6: NO | ED6: NO | EE6: NO | EF6: NO | EG6: NO | EH6: NO | EI6: NO | EJ6: NO | EK6: NO | EL6: NO | EM6: NO | EN6: NO | EO6: NO | EP6: NO | EQ6: NO | ER6: NO | ES6: NO | ET6: NO | EU6: NO | EV6: NO | EW6: NO | EX6: NO | EY6: NO | EZ6: NO | FA6: NO | FB6: NO | FC6: NO | FD6: NO | FE6: NO | FF6: NO | FG6: 30 | FM6: 30 | FT6: 0 | GA6: 0 | GH6: 0 | GI6: 10 | GO6: 10 | GV6: 0 | GW6: 10 | HC6: 10 | HK6: 0 | HL6: 50 | HM6: 0 | HN6: 0 | HO6: 0 | HP6: 0 | HQ6: 0 | HR6: 50 | HS6: 10 | HY6: 10 | IF6: 0 | IG6: 40 | IM6: 40 | IT6: 0 | JA6: 0 | JB6: 50 | JC6: 0 | JD6: 0 | JE6: 0 | JF6: 0 | JG6: 0 | JH6: 50 | JI6: 0 | JK6: 100 | JN6: 30 | JT6: 30 | KA6: 0 | KH6: 0 | KO6: 0 | KP6: 10 | KV6: 10 | LC6: 0 | LD6: 10 | LJ6: 10 | LR6: 0 | LS6: 50 | LT6: 0 | LU6: 0 | LV6: 0 | LW6: 0 | LX6: 0 | LY6: 50 | OK6: 0 | QW6: 0 | TI6: 0 | VU6: 0 | YG6: 0 | YH6: 1 | YI6: 1 | YJ6: 1 | YK6: Mozilla/5.0 (Windows NT 6.1; WOW64) AppleWebKit/537.36 (KHTML, like Gecko) Chrome/47.0.2526.111 Safari/537.36 | YL6: 57 | YM6: NVVJT621 | YN6: INREV | YO6: Bluehouse Capital Advisors | YP6: Victor Pisante | YQ6: vpisante@bluehousecapital.com | YS6: http://click.surveylab.co.uk/anrev-inrev-ncreif-capital-raising-2016/?survey=NVVJT621
A7: 28 | B7: NVZLN199 | C7: survey=NVZLN199 | D7: 42398.409 | E7: 42398.435 | F7: 14 | G7: 1|2|2|3|4|5|6|7|8|9|15| | I7: 212.114.207.108 | J7: INREV | K7: Joni Sekula | L7: PATRIZIA Immobilien AG | M7: =VLOOKUP(MID(O7,SEARCH("@",O7,1),LEN(O7)-SEARCH("@",O7,1)+1),[1]Sheet1!$D:$F,3,FALSE) -> M180 | N7: Manager | O7: joni.sekula@patrizia.ag | P7: +49 821 50910731 | Q7: Germany | R7: EUR | T7: 1 | W7: 604.7 | X7: 790 | Z7: 62.45 | AC7: 1457.15 | AJ7: 0 | AQ7: 0 | AX7: 0 | BE7: 0 | BL7: 0 | BM7: 604.7 | BN7: 790 | BO7: 0 | BP7: 62.45 | BQ7: 0 | BR7: 0 | BS7: 1457.15 | BT7: TRUE | BU7: FALSE | BV7: FALSE | BW7: FALSE | BX7: FALSE | BY7: FALSE | BZ7: 10 | CA7: 5 | CC7: 2 | CF7: 17 | CM7: 0 | CT7: 0 | DA7: 0 | DH7: 0 | DO7: 0 | DP7: 10 | DQ7: 5 | DR7: 0 | DS7: 2 | DT7: 0 | DU7: 0 | DV7: 17 | DW7: YES | DX7: YES | DY7: NO | DZ7: YES | EA7: NO | EB7: NO | EC7: NO | ED7: NO | EE7: NO | EF7: NO | EG7: NO | EH7: NO | EI7: NO | EJ7: NO | EK7: NO | EL7: NO | EM7: NO | EN7: NO | EO7: NO | EP7: NO | EQ7: NO | ER7: NO | ES7: NO | ET7: NO | EU7: NO | EV7: NO | EW7: NO | EX7: NO | EY7: NO | EZ7: NO | FA7: NO | FB7: NO | FC7: NO | FD7: NO | FE7: NO | FF7: NO | FG7: 132 | FH7: 174 | FJ7: 44.95 | FM7: 350.95 | FN7: 15 | FO7: 466 | FT7: 481 | GA7: 0 | GH7: 0 | GO7: 0 | GV7: 0 | HC7: 0 | HD7: Mainly Sparkassen (savings banks) | HE7: 457.7 | HF7: 150 | HH7: 17.5 | HK7: 625.2 | HL7: 604.7 | HM7: 790 | HN7: 0 | HO7: 62.45 | HP7: 0 | HQ7: 0 | HR7: 1457.15 | HS7: 604.7 | HT7: 324 | HV7: 62.45 | HY7: 991.15 | IA7: 466 | IF7: 466 | IM7: 0 | IT7: 0 | JA7: 0 | JB7: 604.7 | JC7: 790 | JD7: 0 | JE7: 62.45 | JF7: 0 | JG7: 0 | JH7: 1457.15 | JI7: 0 | JJ7: 20 | JK7: 80 | JN7: 132 | JO7: 174 | JQ7: 44.95 | JT7: 350.95 | JU7: 15 | JV7: 466 | KA7: 481 | KH7: 0 | KO7: 0 | KV7: 0 | LC7: 0 | LG7: 17.5 | LJ7: 17.5 | LK7: Mainly Sparkassen (savings banks) | LL7: 457.7 | LM7: 150 | LR7: 607.7 | LS7: 604.7 | LT7: 790 | LU7: 0 | LV7: 62.45 | LW7: 0 | LX7: 0 | LY7: 1457.15 | OK7: 0 | QW7: 0 | TI7: 0 | VU7: 0 | YG7: 0 | YH7: 1 | YI7: 3 | YJ7: 1 | YK7: Mozilla/5.0 (Windows NT 6.1; WOW64; Trident/7.0; rv:11.0) like Gecko | YL7: 273 | YM7: NVZLN199 | YN7: INREV | YO7: PATRIZIA Immobilien AG | YP7: Joni Sekula | YQ7: joni.sekula@patrizia.ag | YS7: http://click.surveylab.co.uk/anrev-inrev-ncreif-capital-raising-2016/?survey=NVZLN199
A8: 29 | B8: NVAMM517 | C8: survey=NVAMM517 | D8: 42403.611 | F8: 1 | G8: 1|2|2| | I8: 205.201.132.14 | J8: INREV | M8: =VLOOKUP(MID(O8,SEARCH("@",O8,1),LEN(O8)-SEARCH("@",O8,1)+1),[1]Sheet1!$D:$F,3,FALSE) -> #VALUE! | YL8: 230 | YM8: NVAMM517 | YN8: INREV | YO8: Mayfair Capital | YP8: Simon Martindale | YQ8: smartindale@mayfaircapital.co.uk | YS8: http://click.surveylab.co.uk/anrev-inrev-ncreif-capital-raising-2016/?survey=NVAMM517
A9: 30 | B9: NVHTC024 | C9: survey=NVHTC024 | D9: 42409.31 | E9: 42409.356 | F9: 14 | G9: 1|2|3|4|3|4|5|6|7|8|9|15| | I9: 194.136.168.146 | J9: INREV | K9: Nerijus Zebrauskas | L9: Northern Horizon Capital | M9: =VLOOKUP(MID(O9,SEARCH("@",O9,1),LEN(O9)-SEARCH("@",O9,1)+1),[1]Sheet1!$D:$F,3,FALSE) -> M174 | N9: Head of Fund Controlling | O9: Nerijus.Zebrauskas@nh-cap.com | P9: 37052047122 | Q9: Denmark | R9: EUR | T9: 1 | W9: 9.6 | X9: 60.2 | AC9: 69.8 | AJ9: 0 | AQ9: 0 | AX9: 0 | BE9: 0 | BL9: 0 | BM9: 9.6 | BN9: 60.2 | BO9: 0 | BP9: 0 | BQ9: 0 | BR9: 0 | BS9: 69.8 | BT9: TRUE | BU9: FALSE | BV9: FALSE | BW9: FALSE | BX9: FALSE | BY9: FALSE | BZ9: 2 | CA9: 2 | CF9: 4 | CM9: 0 | CT9: 0 | DA9: 0 | DH9: 0 | DO9: 0 | DP9: 2 | DQ9: 2 | DR9: 0 | DS9: 0 | DT9: 0 | DU9: 0 | DV9: 4 | DW9: YES | DX9: YES | DY9: NO | DZ9: NO | EA9: NO | EB9: NO | EC9: NO | ED9: NO | EE9: NO | EF9: NO | EG9: NO | EH9: NO | EI9: NO | EJ9: NO | EK9: NO | EL9: NO | EM9: NO | EN9: NO | EO9: NO | EP9: NO | EQ9: NO | ER9: NO | ES9: NO | ET9: NO | EU9: NO | EV9: NO | EW9: NO | EX9: NO | EY9: NO | EZ9: NO | FA9: NO | FB9: NO | FC9: NO | FD9: NO | FE9: NO | FF9: NO | FG9: 3 | FH9: 0.8 | FM9: 3.8 | FT9: 0 | GA9: 0 | GH9: 0 | GI9: 0.4 | GO9: 0.4 | GP9: 0.2 | GV9: 0.2 | GW9: 0.8 | HC9: 0.8 | HD9: Private companies / investment banks | HE9: 5.2 | HF9: 59.4 | HK9: 64.6 | HL9: 9.6 | HM9: 60.2 | HN9: 0 | HO9: 0 | HP9: 0 | HQ9: 0 | HR9: 69.8 | HS9: 9.6 | HT9: 60.2 | HY9: 69.8 | IF9: 0 | IM9: 0 | IT9: 0 | JA9: 0 | JB9: 9.6 | JC9: 60.2 | JD9: 0 | JE9: 0 | JF9: 0 | JG9: 0 | JH9: 69.8 | JK9: 100 | JN9: 3 | JO9: 0.8 | JT9: 3.8 | KA9: 0 | KH9: 0 | KO9: 0 | KP9: 0.4 | KV9: 0.4 | KW9: 0.2 | LC9: 0.2 | LD9: 0.8 | LJ9: 0.8 | LK9: Private companies, investment banks | LL9: 5.2 | LM9: 59.4 | LR9: 64.6 | LS9: 9.6 | LT9: 60.2 | LU9: 0 | LV9: 0 | LW9: 0 | LX9: 0 | LY9: 69.8 | OK9: 0 | QW9: 0 | TI9: 0 | VU9: 0 | YG9: 0 | YH9: 1 | YI9: 3 | YJ9: 1 | YK9: Mozilla/5.0 (Windows NT 6.1; WOW64; Trident/7.0; rv:11.0) like Gecko | YL9: 257 | YM9: NVHTC024 | YN9: INREV | YO9: Northern Horizon Capital | YP9: Nerijus Zebrauskas | YQ9: nerijus.zebrauskas@nh-cap.com | YS9: http://click.surveylab.co.uk/anrev-inrev-ncreif-capital-raising-2016/?survey=NVHTC024
A10: 31 | B10: NVBDJ636 | C10: survey=NVBDJ636 | D10: 42423.635 | E10: 42423.639 | F10: 14 | G10: 1|2|3|4|5|6|7|8|2|3|4|2|3|2|3|4|5|2|3|4|5|6|7|8|9|11|12|6|7|8|9|11|12|8|6|6|7|8|9|11|12|15|2|3|4|5|4|5|6|7|8|9|11|12|4|5|6|4|5|6|7|8|9|11|12|15| | I10: 108.179.24.66 | J10: INREV | K10: Amy Dulski | L10: Starwood Capital Group | M10: =VLOOKUP(MID(O10,SEARCH("@",O10,1),LEN(O10)-SEARCH("@",O10,1)+1),[1]Sheet1!$D:$F,3,FALSE) -> M05105 | N10: Investor Relations Coordinator | O10: adulski@starwood.com | P10: 2034227766 | Q10: United States | R10: USD | T10: 1 | Z10: 116.2 | AC10: 116.2 | AJ10: 0 | AN10: 240 | AQ10: 240 | AR10: 1327.7 | AX10: 1327.7 | BE10: 0 | BL10: 0 | BM10: 1327.7 | BN10: 0 | BO10: 0 | BP10: 356.2 | BQ10: 0 | BR10: 0 | BS10: 1683.9 | BT10: TRUE | BU10: FALSE | BV10: TRUE | BW10: TRUE | BX10: FALSE | BY10: FALSE | CC10: 1 | CF10: 1 | CM10: 0 | CQ10: 1 | CT10: 1 | CU10: 1 | DA10: 1 | DH10: 0 | DO10: 0 | DP10: 1 | DQ10: 0 | DR10: 0 | DS10: 2 | DT10: 0 | DU10: 0 | DV10: 3 | DW10: NO | DX10: NO | DY10: NO | DZ10: YES | EA10: NO | EB10: NO | EC10: NO | ED10: NO | EE10: NO | EF10: NO | EG10: NO | EH10: NO | EI10: NO | EJ10: NO | EK10: NO | EL10: YES | EM10: NO | EN10: NO | EO10: YES | EP10: NO | EQ10: NO | ER10: NO | ES10: NO | ET10: NO | EU10: NO | EV10: NO | EW10: NO | EX10: NO | EY10: NO | EZ10: NO | FA10: NO | FB10: NO | FC10: NO | FD10: NO | FE10: NO | FF10: NO | FG10: 390 | FJ10: 135 | FM10: 525 | FN10: 25 | FQ10: 0 | FT10: 25 | FU10: 545 | FX10: 210 | GA10: 755 | GB10: 0 | GE10: 0 | GH10: 0 | GI10: 226 | GL10: 0 | GO10: 226 | GP10: 28 | GS10: 5 | GV10: 33 | GW10: 109.74 | GZ10: 2.54 | HC10: 112.28 | HD10: General Partner | HE10: 3.955 | HH10: 3.662 | HK10: 7.62 | HL10: 1327.69 | HM10: 0 | HN10: 0 | HO10: 356.2 | HP10: 0 | HQ10: 0 | HR10: 1683.9 | HS10: 12.1 | HY10: 12.1 | HZ10: 950 | IC10: 230 | IF10: 1180 | IG10: 365.605 | IJ10: 126.2 | IM10: 491.81 | IT10: 0 | JA10: 0 | JB10: 1327.7 | JC10: 0 | JD10: 0 | JE10: 356.2 | JF10: 0 | JG10: 0 | JH10: 1683.9 | JI10: 19 | JJ10: 0 | JK10: 81 | JQ10: 35 | JT10: 35 | KA10: 0 | KE10: 80 | KH10: 80 | KO10: 0 | KV10: 0 | LC10: 0 | LJ10: 0 | LK10: General Partner | LO10: 1.16 | LR10: 1.16 | LS10: 0 | LT10: 0 | LU10: 0 | LV10: 116.16 | LW10: 0 | LX10: 0 | LY10: 116.16 | OK10: 0 | OO10: 100 | PC10: 130 | PX10: 5 | QE10: 2.5 | QI10: General Partner | QM10: 2.5 | QW10: 240 | QX10: 390 | RE10: 25 | RL10: 545 | RZ10: 226 | SG10: 28 | SN10: 109.75 | SU10: General Partner | SV10: 3.955 | TI10: 1327.7 | VU10: 0 | YG10: 0 | YH10: 2 | YI10: 3 | YJ10: 1 | YK10: Mozilla/5.0 (Windows NT 6.1; WOW64) AppleWebKit/537.36 (KHTML, like Gecko) Chrome/48.0.2564.82 Safari/537.36 | YL10: 323 | YM10: NVBDJ636 | YN10: INREV | YO10: Starwood Capital Group | YP10: Renee Crabtree | YQ10: rcrabtree@starwood.com | YS10: http://click.surveylab.co.uk/anrev-inrev-ncreif-capital-raising-2016/?survey=NVBDJ636
A11: 32 | B11: NVGTY873 | C11: survey=NVGTY873 | D11: 42422.675 | E11: 42422.702 | F11: 14 | G11: 1|2|2|2|2|3|2|3|4|5|6|7|8|15|2|3|4|5|3|4|5|6|5|5|2|3|4|5|4|5|4|5|6|4|3|4|5|6|6|7|8|6|7|8|6|7|8|9|7|7|8|6|7|8|9|6|7|8|9|3|4|5|6|7|8|9|3|4|2|2|3|4|5|6|7|8|9|2|3|3|4|5|6|7|8|6|7|8|9|3|4|5|6|7|8|9|15| | I11: 194.145.239.250 | J11: INREV | K11: Jan Kuhn | L11: TRIUVA Kapitalverwaltungsgesellschaft mbH | M11: =VLOOKUP(MID(O11,SEARCH("@",O11,1),LEN(O11)-SEARCH("@",O11,1)+1),[1]Sheet1!$D:$F,3,FALSE) -> M180 | N11: Head of Investor Relations | O11: jan.kuhn@triuva.com | P11: +49 69 643505–1291 | Q11: Germany | R11: EUR | T11: 1 | X11: 556 | AC11: 556 | AJ11: 0 | AQ11: 0 | AX11: 0 | BE11: 0 | BL11: 0 | BM11: 0 | BN11: 556 | BO11: 0 | BP11: 0 | BQ11: 0 | BR11: 0 | BS11: 556 | BT11: TRUE | BU11: FALSE | BV11: FALSE | BW11: FALSE | BX11: FALSE | BY11: FALSE | CA11: 7 | CF11: 7 | CM11: 0 | CT11: 0 | DA11: 0 | DH11: 0 | DO11: 0 | DP11: 0 | DQ11: 7 | DR11: 0 | DS11: 0 | DT11: 0 | DU11: 0 | DV11: 7 | DW11: NO | DX11: YES | DY11: NO | DZ11: NO | EA11: NO | EB11: NO | EC11: NO | ED11: NO | EE11: NO | EF11: NO | EG11: NO | EH11: NO | EI11: NO | EJ11: NO | EK11: NO | EL11: NO | EM11: NO | EN11: NO | EO11: NO | EP11: NO | EQ11: NO | ER11: NO | ES11: NO | ET11: NO | EU11: NO | EV11: NO | EW11: NO | EX11: NO | EY11: NO | EZ11: NO | FA11: NO | FB11: NO | FC11: NO | FD11: NO | FE11: NO | FF11: NO | FH11: 320 | FM11: 320 | FO11: 91 | FT11: 91 | GA11: 0 | GH11: 0 | GJ11: 145 | GO11: 145 | GV11: 0 | HC11: 0 | HK11: 0 | HL11: 0 | HM11: 556 | HN11: 0 | HO11: 0 | HP11: 0 | HQ11: 0 | HR11: 556 | HT11: 556 | HY11: 556 | IF11: 0 | IM11: 0 | IT11: 0 | JA11: 0 | JB11: 0 | JC11: 556 | JD11: 0 | JE11: 0 | JF11: 0 | JG11: 0 | JH11: 556 | JK11: 100 | JO11: 320 | JT11: 320 | JV11: 91 | KA11: 91 | KH11: 0 | KO11: 0 | KQ11: 145 | KV11: 145 | LC11: 0 | LJ11: 0 | LR11: 0 | LS11: 0 | LT11: 556 | LU11: 0 | LV11: 0 | LW11: 0 | LX11: 0 | LY11: 556 | OK11: 0 | QW11: 0 | TI11: 0 | VU11: 0 | YG11: 0 | YH11: 1 | YI11: 3 | YJ11: 1 | YK11: Mozilla/5.0 (compatible; MSIE 10.0; Windows NT 6.1; WOW64; Trident/6.0) | YL11: 344 | YM11: NVGTY873 | YN11: INREV | YO11: TRIUVA Kapitalverwaltungsgesellschaft mbH | YP11: Steffen Ricken | YQ11: Steffen.Ricken@triuva.com | YS11: http://click.surveylab.co.uk/anrev-inrev-ncreif-capital-raising-2016/?survey=NVGTY873
A12: 33 | B12: NVPMH038 | C12: survey=NVPMH038 | D12: 42401.69 | F12: 1 | G12: 1|2| | I12: 82.109.51.130 | J12: INREV | M12: =VLOOKUP(MID(O12,SEARCH("@",O12,1),LEN(O12)-SEARCH("@",O12,1)+1),[1]Sheet1!$D:$F,3,FALSE) -> #VALUE! | YK12: Mozilla/5.0 (Windows NT 6.1; WOW64; Trident/7.0; rv:11.0) like Gecko | YL12: 58 | YM12: NVPMH038 | YN12: INREV | YO12: BMO Real Estate Partners | YP12: Sue Bjorkegren | YQ12: sbjorkegren@bmorep.com | YS12: http://click.surveylab.co.uk/anrev-inrev-ncreif-capital-raising-2016/?survey=NVPMH038
A13: 34 | B13: NVRNR667 | C13: survey=NVRNR667 | D13: 42396.626 | F13: 1 | G13: 1|2| | I13: 12.20.3.180 | J13: INREV | M13: =VLOOKUP(MID(O13,SEARCH("@",O13,1),LEN(O13)-SEARCH("@",O13,1)+1),[1]Sheet1!$D:$F,3,FALSE) -> #VALUE! | YK13: Mozilla/5.0 (Windows NT 6.1; WOW64) AppleWebKit/537.36 (KHTML, like Gecko) Chrome/47.0.2526.111 Safari/537.36 | YL13: 365 | YM13: NVRNR667 | YN13: INREV | YO13: zzzAdditional Record | YS13: http://click.surveylab.co.uk/anrev-inrev-ncreif-capital-raising-2016/?survey=NVRNR667
A14: 35 | B14: NVMQE634 | C14: survey=NVMQE634 | D14: 42403.326 | E14: 42403.329 | F14: 14 | G14: 1|2|3|4|5|6|7|8|9|15| | I14: 217.110.92.40 | J14: INREV | K14: Sina Stegmann | L14: Warburg-HIH Invest Real Estate GmbH | M14: =VLOOKUP(MID(O14,SEARCH("@",O14,1),LEN(O14)-SEARCH("@",O14,1)+1),[1]Sheet1!$D:$F,3,FALSE) -> M277 | N14: Senior Marketing Manager | O14: sstegmann@warburg-hih.com | P14: +49 40 3282 3618 | Q14: Germany | R14: EUR | T14: 1 | W14: 268 | X14: 215 | AC14: 483 | AJ14: 0 | AQ14: 0 | AX14: 0 | BE14: 0 | BL14: 0 | BM14: 268 | BN14: 215 | BO14: 0 | BP14: 0 | BQ14: 0 | BR14: 0 | BS14: 483 | BT14: TRUE | BU14: FALSE | BV14: FALSE | BW14: FALSE | BX14: FALSE | BY14: FALSE | BZ14: 4 | CA14: 5 | CF14: 9 | CM14: 0 | CT14: 0 | DA14: 0 | DH14: 0 | DO14: 0 | DP14: 4 | DQ14: 5 | DR14: 0 | DS14: 0 | DT14: 0 | DU14: 0 | DV14: 9 | DW14: YES | DX14: YES | DY14: NO | DZ14: NO | EA14: NO | EB14: NO | EC14: NO | ED14: NO | EE14: NO | EF14: NO | EG14: NO | EH14: NO | EI14: NO | EJ14: NO | EK14: NO | EL14: NO | EM14: NO | EN14: NO | EO14: NO | EP14: NO | EQ14: NO | ER14: NO | ES14: NO | ET14: NO | EU14: NO | EV14: NO | EW14: NO | EX14: NO | EY14: NO | EZ14: NO | FA14: NO | FB14: NO | FC14: NO | FD14: NO | FE14: NO | FF14: NO | FG14: 140 | FH14: 208 | FM14: 348 | FN14: 5 | FO14: 7.5 | FT14: 12.5 | GA14: 0 | GH14: 0 | GI14: 21 | GO14: 21 | GV14: 0 | HC14: 0 | HD14: Financial Institutions | HE14: 101.5 | HK14: 101.5 | HL14: 267.5 | HM14: 215.5 | HN14: 0 | HO14: 0 | HP14: 0 | HQ14: 0 | HR14: 483 | HS14: 268 | HT14: 215 | HY14: 483 | IF14: 0 | IM14: 0 | IT14: 0 | JA14: 0 | JB14: 268 | JC14: 215 | JD14: 0 | JE14: 0 | JF14: 0 | JG14: 0 | JH14: 483 | JK14: 100 | JN14: 140 | JO14: 208 | JT14: 348 | JU14: 5 | JV14: 7.5 | KA14: 12.5 | KH14: 0 | KO14: 0 | KP14: 21 | KV14: 21 | LC14: 0 | LJ14: 0 | LK14: Financial Institutions | LL14: 101.5 | LR14: 101.5 | LS14: 267.5 | LT14: 215.5 | LU14: 0 | LV14: 0 | LW14: 0 | LX14: 0 | LY14: 483 | OK14: 0 | QW14: 0 | TI14: 0 | VU14: 0 | YG14: 0 | YH14: 1 | YI14: 3 | YJ14: 1 | YK14: Mozilla/5.0 (Windows NT 6.1; WOW64; Trident/7.0; rv:11.0) like Gecko | YL14: 357 | YM14: NVMQE634 | YN14: INREV | YO14: Warburg - Henderson KAG | YP14: Sina Stegmann | YQ14: sstegmann@warburg-henderson.com | YS14: http://click.surveylab.co.uk/anrev-inrev-ncreif-capital-raising-2016/?survey=NVMQE634
A15: 36 | B15: NVEQN229 | C15: survey=NVEQN229 | D15: 42417.64 | E15: 42417.647 | F15: 14 | G15: 1|2|3|4|5|6|7|8|9|9|10|15| | I15: 193.104.25.125 | J15: INREV | K15: Naomi Vlakancic | L15: Savills Investment Management | M15: =VLOOKUP(MID(O15,SEARCH("@",O15,1),LEN(O15)-SEARCH("@",O15,1)+1),[1]Sheet1!$D:$F,3,FALSE) -> M079 | N15: Head of Investor Relations | O15: naomi.vlakancic@savillsim.com | P15: 44 20 7409 5927 | Q15: United Kingdom | R15: EUR | T15: 1 | W15: 515 | X15: 1060 | AC15: 1575 | AD15: 75 | AE15: 39 | AJ15: 114 | AQ15: 0 | AX15: 0 | BE15: 0 | BL15: 0 | BM15: 590 | BN15: 1099 | BO15: 0 | BP15: 0 | BQ15: 0 | BR15: 0 | BS15: 1689 | BT15: TRUE | BU15: TRUE | BV15: FALSE | BW15: FALSE | BX15: FALSE | BY15: FALSE | BZ15: 8 | CA15: 5 | CF15: 13 | CG15: 1 | CH15: 2 | CM15: 3 | CT15: 0 | DA15: 0 | DH15: 0 | DO15: 0 | DP15: 9 | DQ15: 7 | DR15: 0 | DS15: 0 | DT15: 0 | DU15: 0 | DV15: 16 | DW15: YES | DX15: YES | DY15: NO | DZ15: NO | EA15: NO | EB15: NO | EC15: YES | ED15: YES | EE15: NO | EF15: NO | EG15: NO | EH15: NO | EI15: NO | EJ15: NO | EK15: NO | EL15: NO | EM15: NO | EN15: NO | EO15: NO | EP15: NO | EQ15: NO | ER15: NO | ES15: NO | ET15: NO | EU15: NO | EV15: NO | EW15: NO | EX15: NO | EY15: NO | EZ15: NO | FA15: NO | FB15: NO | FC15: NO | FD15: NO | FE15: NO | FF15: NO | FG15: 25 | FH15: 728 | FM15: 753 | FN15: 263 | FT15: 263 | GA15: 0 | GH15: 0 | GI15: 173 | GO15: 173 | GV15: 0 | GW15: 42 | HC15: 42 | HD15: Wealth Mgt, Bank, Private Equity, Investment company | HE15: 87 | HF15: 371 | HK15: 458 | HL15: 590 | HM15: 1099 | HN15: 0 | HO15: 0 | HP15: 0 | HQ15: 0 | HR15: 1689 | HS15: 478 | HY15: 478 | HZ15: 113 | IA15: 728 | IF15: 841 | IH15: 371 | IM15: 371 | IT15: 0 | JA15: 0 | JB15: 591 | JC15: 1099 | JD15: 0 | JE15: 0 | JF15: 0 | JG15: 0 | JH15: 1690 | JI15: 1 | JK15: 99 | JN15: 25 | JO15: 728 | JT15: 753 | JU15: 263 | KA15: 263 | KH15: 0 | KO15: 0 | KP15: 173 | KV15: 173 | LC15: 0 | LD15: 2 | LJ15: 2 | LK15: Wealth Management, Bank, Private Equity, Investment Company | LL15: 52 | LM15: 332 | LR15: 384 | LS15: 515 | LT15: 1060 | LU15: 0 | LV15: 0 | LW15: 0 | LX15: 0 | LY15: 1575 | NP15: 75 | NV15: 75 | NW15: Investment Company | NY15: 39 | OD15: 39 | OE15: 75 | OF15: 39 | OK15: 114 | QW15: 0 | TI15: 0 | VU15: 0 | YG15: 0 | YH15: 3 | YI15: 2 | YJ15: 1 | YK15: Mozilla/5.0 (Windows NT 6.1; WOW64; Trident/7.0; rv:11.0) like Gecko | YL15: 93 | YM15: NVEQN229 | YN15: INREV | YO15: Cordea Savills | YP15: Naomi Vlakancic | YQ15: naomi.vlakancic@cordeasavills.com | YS15: http://click.surveylab.co.uk/anrev-inrev-ncreif-capital-raising-2016/?survey=NVEQN229
A16: 37 | B16: NVDYF083 | C16: survey=NVDYF083 | D16: 42402.762 | E16: 42402.767 | F16: 14 | G16: 1|2|2|2|3|4|5|6|7|8|2|3|4|5|6|7|8|2|3|4|5|6|7|8|9|11|11|8|9|11|11|11|2|3|4|5|6|7|8|9|11|2|3|4|5|6|7|8|9|11|15| | I16: 209.236.106.85 | J16: INREV | K16: Adrian Fernandez | L16: Prologis | M16: =VLOOKUP(MID(O16,SEARCH("@",O16,1),LEN(O16)-SEARCH("@",O16,1)+1),[1]Sheet1!$D:$F,3,FALSE) -> M024 | N16: VP, Fund Operations | O16: acfernandez@prologis.com | P16: 415-733-9418 | Q16: United States | R16: USD | T16: 1 | W16: 356.8 | Z16: 242.8 | AC16: 599.6 | AJ16: 0 | AK16: 143 | AN16: 2400.4 | AQ16: 2543.4 | AX16: 0 | BE16: 0 | BL16: 0 | BM16: 499.8 | BN16: 0 | BO16: 0 | BP16: 2643.2 | BQ16: 0 | BR16: 0 | BS16: 3143 | BT16: TRUE | BU16: FALSE | BV16: TRUE | BW16: FALSE | BX16: FALSE | BY16: FALSE | BZ16: 1 | CC16: 1 | CF16: 2 | CM16: 0 | CN16: 1 | CQ16: 1 | CT16: 2 | DA16: 0 | DH16: 0 | DO16: 0 | DP16: 2 | DQ16: 0 | DR16: 0 | DS16: 2 | DT16: 0 | DU16: 0 | DV16: 4 | DW16: YES | DX16: NO | DY16: NO | DZ16: YES | EA16: NO | EB16: NO | EC16: NO | ED16: NO | EE16: NO | EF16: NO | EG16: NO | EH16: NO | EI16: YES | EJ16: NO | EK16: NO | EL16: YES | EM16: NO | EN16: NO | EO16: NO | EP16: NO | EQ16: NO | ER16: NO | ES16: NO | ET16: NO | EU16: NO | EV16: NO | EW16: NO | EX16: NO | EY16: NO | EZ16: NO | FA16: NO | FB16: NO | FC16: NO | FD16: NO | FE16: NO | FF16: NO | FG16: 236.8 | FM16: 236.8 | FN16: 250.8 | FT16: 250.8 | FX16: 2643.2 | GA16: 2643.2 | GH16: 0 | GO16: 0 | GV16: 0 | HC16: 0 | HD16: Trust, Registered Investment Company | HE16: 12.2 | HK16: 12.2 | HL16: 499.8 | HM16: 0 | HN16: 0 | HO16: 2643.2 | HP16: 0 | HQ16: 0 | HR16: 3143 | HS16: 356.8 | HV16: 242.8 | HY16: 599.6 | IF16: 0 | IG16: 143 | IJ16: 2400.4 | IM16: 2543.4 | IT16: 0 | JA16: 0 | JB16: 499.8 | JC16: 0 | JD16: 0 | JE16: 2643.2 | JF16: 0 | JG16: 0 | JH16: 3143 | JJ16: 1.59 | JK16: 98.41 | JN16: 158.9 | JT16: 158.9 | JU16: 195.8 | KA16: 195.8 | KE16: 242.8 | KH16: 242.8 | KO16: 0 | KV16: 0 | LC16: 0 | LJ16: 0 | LK16: Trust | LL16: 2.1 | LR16: 2.1 | LS16: 356.8 | LT16: 0 | LU16: 0 | LV16: 242.8 | LW16: 0 | LX16: 0 | LY16: 599.6 | OK16: 0 | OL16: 78 | OS16: 55 | PC16: 2400.4 | QI16: Registered Investment Company | QJ16: 10 | QW16: 2543.4 | TI16: 0 | VU16: 0 | YG16: 0 | YH16: 2 | YI16: 1 | YJ16: 1 | YK16: Mozilla/5.0 (Windows NT 6.1; Trident/7.0; rv:11.0) like Gecko | YL16: 286 | YM16: NVDYF083 | YN16: INREV | YO16: Prologis | YP16: Adrian Fernandez | YQ16: acfernandez@prologis.com | YS16: http://click.surveylab.co.uk/anrev-inrev-ncreif-capital-raising-2016/?survey=NVDYF083
A17: 38 | B17: NVDXY475 | C17: survey=NVDXY475 | D17: 42396.765 | E17: 42396.767 | F17: 14 | G17: 1|2|3|15| | I17: 213.205.84.209 | J17: INREV | K17: joao lelis | L17: sonae sierra | M17: =VLOOKUP(MID(O17,SEARCH("@",O17,1),LEN(O17)-SEARCH("@",O17,1)+1),[1]Sheet1!$D:$F,3,FALSE) -> M028 | N17: fund manager | O17: jclelis@sonaesierra.com | P17: 351220104549 | Q17: Portugal | R17: EUR | T17: 2 | U17: 6 | V17: strategy | AC17: 0 | AJ17: 0 | AQ17: 0 | AX17: 0 | BE17: 0 | BL17: 0 | BM17: 0 | BN17: 0 | BO17: 0 | BP17: 0 | BQ17: 0 | BR17: 0 | BS17: 0 | BT17: FALSE | BU17: FALSE | BV17: FALSE | BW17: FALSE | BX17: FALSE | BY17: FALSE | CF17: 0 | CM17: 0 | CT17: 0 | DA17: 0 | DH17: 0 | DO17: 0 | DP17: 0 | DQ17: 0 | DR17: 0 | DS17: 0 | DT17: 0 | DU17: 0 | DV17: 0 | DW17: NO | DX17: NO | DY17: NO | DZ17: NO | EA17: NO | EB17: NO | EC17: NO | ED17: NO | EE17: NO | EF17: NO | EG17: NO | EH17: NO | EI17: NO | EJ17: NO | EK17: NO | EL17: NO | EM17: NO | EN17: NO | EO17: NO | EP17: NO | EQ17: NO | ER17: NO | ES17: NO | ET17: NO | EU17: NO | EV17: NO | EW17: NO | EX17: NO | EY17: NO | EZ17: NO | FA17: NO | FB17: NO | FC17: NO | FD17: NO | FE17: NO | FF17: NO | FM17: 0 | FT17: 0 | GA17: 0 | GH17: 0 | GO17: 0 | GV17: 0 | HC17: 0 | HK17: 0 | HL17: 0 | HM17: 0 | HN17: 0 | HO17: 0 | HP17: 0 | HQ17: 0 | HR17: 0 | HY17: 0 | IF17: 0 | IM17: 0 | IT17: 0 | JA17: 0 | JB17: 0 | JC17: 0 | JD17: 0 | JE17: 0 | JF17: 0 | JG17: 0 | JH17: 0 | JT17: 0 | KA17: 0 | KH17: 0 | KO17: 0 | KV17: 0 | LC17: 0 | LJ17: 0 | LR17: 0 | LS17: 0 | LT17: 0 | LU17: 0 | LV17: 0 | LW17: 0 | LX17: 0 | LY17: 0 | OK17: 0 | QW17: 0 | TI17: 0 | VU17: 0 | YG17: 0 | YH17: 1 | YI17: 2 | YJ17: 1 | YK17: Mozilla/5.0 (Windows NT 6.1; WOW64; Trident/7.0; rv:11.0) like Gecko | YL17: 316 | YM17: NVDXY475 | YN17: INREV | YO17: Sonae Sierra SGPS | YP17: Joao Lelis | YQ17: jclelis@sonaesierra.com | YS17: http://click.surveylab.co.uk/anrev-inrev-ncreif-capital-raising-2016/?survey=NVDXY475
A18: 40 | B18: ANDVF042 | C18: survey=ANDVF042 | D18: 42416.33 | E18: 42416.333 | F18: 14 | G18: 1|2|3|4|5|6|7|8|6|7|8|10|15| | I18: 122.216.24.202 | J18: ANREV | K18: Johan Shah | L18: AEP Investment Management | M18: =VLOOKUP(MID(O18,SEARCH("@",O18,1),LEN(O18)-SEARCH("@",O18,1)+1),[1]Sheet1!$D:$F,3,FALSE) -> M0291 | N18: VP | O18: johan.shah@aep-im.com | P18: 82006982 | Q18: Singapore | R18: USD | T18: 1 | AC18: 0 | AD18: 150 | AJ18: 150 | AQ18: 0 | AX18: 0 | BE18: 0 | BL18: 0 | BM18: 150 | BN18: 0 | BO18: 0 | BP18: 0 | BQ18: 0 | BR18: 0 | BS18: 150 | BT18: FALSE | BU18: TRUE | BV18: FALSE | BW18: FALSE | BX18: FALSE | BY18: FALSE | CF18: 0 | CG18: 1 | CM18: 1 | CT18: 0 | DA18: 0 | DH18: 0 | DO18: 0 | DP18: 1 | DQ18: 0 | DR18: 0 | DS18: 0 | DT18: 0 | DU18: 0 | DV18: 1 | DW18: NO | DX18: NO | DY18: NO | DZ18: NO | EA18: NO | EB18: NO | EC18: YES | ED18: NO | EE18: NO | EF18: NO | EG18: NO | EH18: NO | EI18: NO | EJ18: NO | EK18: NO | EL18: NO | EM18: NO | EN18: NO | EO18: NO | EP18: NO | EQ18: NO | ER18: NO | ES18: NO | ET18: NO | EU18: NO | EV18: NO | EW18: NO | EX18: NO | EY18: NO | EZ18: NO | FA18: NO | FB18: NO | FC18: NO | FD18: NO | FE18: NO | FF18: NO | FM18: 0 | FN18: 10 | FT18: 10 | GA18: 0 | GH18: 0 | GI18: 22.5 | GO18: 22.5 | GV18: 0 | GW18: 75 | HC18: 75 | HD18: Banks/Haj Funds | HE18: 42.5 | HK18: 42.5 | HL18: 150 | HM18: 0 | HN18: 0 | HO18: 0 | HP18: 0 | HQ18: 0 | HR18: 150 | HY18: 0 | HZ18: 150 | IF18: 150 | IM18: 0 | IT18: 0 | JA18: 0 | JB18: 150 | JC18: 0 | JD18: 0 | JE18: 0 | JF18: 0 | JG18: 0 | JH18: 150 | JK18: 100 | JT18: 0 | KA18: 0 | KH18: 0 | KO18: 0 | KV18: 0 | LC18: 0 | LJ18: 0 | LR18: 0 | LS18: 0 | LT18: 0 | LU18: 0 | LV18: 0 | LW18: 0 | LX18: 0 | LY18: 0 | MG18: 10 | MM18: 10 | NB18: 22.5 | NH18: 22.5 | NP18: 75 | NV18: 75 | NW18: Banks/Haj Funds | NX18: 42.5 | OD18: 42.5 | OE18: 150 | OF18: 0 | OK18: 150 | QW18: 0 | TI18: 0 | VU18: 0 | YG18: 0 | YH18: 1 | YI18: 1 | YJ18: 1 | YK18: Mozilla/5.0 (Windows NT 6.1; WOW64) AppleWebKit/537.36 (KHTML, like Gecko) Chrome/47.0.2526.111 Safari/537.36 | YL18: 17 | YM18: ANDVF042 | YN18: ANREV | YO18: AEP Investment Management Pte Ltd | YP18: Yusof Wahid | YQ18: yusof.wahid@aep-im.com | YS18: http://click.surveylab.co.uk/anrev-inrev-ncreif-capital-raising-2016/?survey=ANDVF042
A19: 41 | B19: NVAGG295 | C19: survey=NVAGG295 | D19: 42397.497 | E19: 42397.499 | F19: 14 | G19: 1|2|3|15| | I19: 195.144.249.4 | J19: INREV | K19: Steven Wayne | L19: Jensen Group | M19: =VLOOKUP(MID(O19,SEARCH("@",O19,1),LEN(O19)-SEARCH("@",O19,1)+1),[1]Sheet1!$D:$F,3,FALSE) -> M662 | N19: CEO | O19: sww@jensen.ru | P19: 78123251306 | Q19: Russian Federation | R19: USD | T19: 2 | U19: 6 | V19: Russia unpopular | AC19: 0 | AJ19: 0 | AQ19: 0 | AX19: 0 | BE19: 0 | BL19: 0 | BM19: 0 | BN19: 0 | BO19: 0 | BP19: 0 | BQ19: 0 | BR19: 0 | BS19: 0 | BT19: FALSE | BU19: FALSE | BV19: FALSE | BW19: FALSE | BX19: FALSE | BY19: FALSE | CF19: 0 | CM19: 0 | CT19: 0 | DA19: 0 | DH19: 0 | DO19: 0 | DP19: 0 | DQ19: 0 | DR19: 0 | DS19: 0 | DT19: 0 | DU19: 0 | DV19: 0 | DW19: NO | DX19: NO | DY19: NO | DZ19: NO | EA19: NO | EB19: NO | EC19: NO | ED19: NO | EE19: NO | EF19: NO | EG19: NO | EH19: NO | EI19: NO | EJ19: NO | EK19: NO | EL19: NO | EM19: NO | EN19: NO | EO19: NO | EP19: NO | EQ19: NO | ER19: NO | ES19: NO | ET19: NO | EU19: NO | EV19: NO | EW19: NO | EX19: NO | EY19: NO | EZ19: NO | FA19: NO | FB19: NO | FC19: NO | FD19: NO | FE19: NO | FF19: NO | FM19: 0 | FT19: 0 | GA19: 0 | GH19: 0 | GO19: 0 | GV19: 0 | HC19: 0 | HK19: 0 | HL19: 0 | HM19: 0 | HN19: 0 | HO19: 0 | HP19: 0 | HQ19: 0 | HR19: 0 | HY19: 0 | IF19: 0 | IM19: 0 | IT19: 0 | JA19: 0 | JB19: 0 | JC19: 0 | JD19: 0 | JE19: 0 | JF19: 0 | JG19: 0 | JH19: 0 | JT19: 0 | KA19: 0 | KH19: 0 | KO19: 0 | KV19: 0 | LC19: 0 | LJ19: 0 | LR19: 0 | LS19: 0 | LT19: 0 | LU19: 0 | LV19: 0 | LW19: 0 | LX19: 0 | LY19: 0 | OK19: 0 | QW19: 0 | TI19: 0 | VU19: 0 | YG19: 0 | YH19: 1 | YI19: 3 | YJ19: 1 | YK19: Mozilla/5.0 (Windows NT 6.3; WOW64; Trident/7.0; Touch; MASAJS; rv:11.0) like Gecko | YL19: 196 | YM19: NVAGG295 | YN19: INREV | YO19: Jensen Group | YP19: Steven Wayne | YQ19: Steven.W.Wayne@jensen.ru | YS19: http://click.surveylab.co.uk/anrev-inrev-ncreif-capital-raising-2016/?survey=NVAGG295
A20: 42 | B20: ANFCR868 | C20: survey=ANFCR868 | D20: 42415.222 | E20: 42415.224 | F20: 14 | G20: 1|2|3|3|4|5|6|7|8|3|2|2|3|4|5|6|7|8|9|10|11|2|2|3|4|5|6|7|8|2|3|4|5|6|7|8|9|9|9|10|11|15|2|3|4|5|6|7|8|9|9|10|11|15| | I20: 58.228.125.22 | J20: ANREV | K20: Joseph Lee | L20: IGIS Asset Management | M20: =VLOOKUP(MID(O20,SEARCH("@",O20,1),LEN(O20)-SEARCH("@",O20,1)+1),[1]Sheet1!$D:$F,3,FALSE) -> M0333 | N20: Senior Managing Director | O20: joseph.lee@igisam.com | P20: 822-6959-3102 | Q20: Korea, Republic Of | R20: KRW | T20: 1 | Z20: 167050 | AA20: 76800 | AC20: 243850 | AG20: 491900 | AJ20: 491900 | AN20: 165022.18 | AO20: 56795 | AQ20: 221817.18 | AX20: 0 | BE20: 0 | BL20: 0 | BM20: 0 | BN20: 0 | BO20: 0 | BP20: 823972.18 | BQ20: 133595 | BR20: 0 | BS20: 957567.18 | BT20: TRUE | BU20: TRUE | BV20: TRUE | BW20: FALSE | BX20: FALSE | BY20: FALSE | CC20: 2 | CD20: 2 | CF20: 4 | CJ20: 9 | CM20: 9 | CQ20: 1 | CR20: 1 | CT20: 2 | DA20: 0 | DH20: 0 | DO20: 0 | DP20: 0 | DQ20: 0 | DR20: 0 | DS20: 12 | DT20: 3 | DU20: 0 | DV20: 15 | DW20: NO | DX20: NO | DY20: NO | DZ20: YES | EA20: YES | EB20: NO | EC20: NO | ED20: NO | EE20: NO | EF20: YES | EG20: NO | EH20: NO | EI20: NO | EJ20: NO | EK20: NO | EL20: YES | EM20: YES | EN20: NO | EO20: NO | EP20: NO | EQ20: NO | ER20: NO | ES20: NO | ET20: NO | EU20: NO | EV20: NO | EW20: NO | EX20: NO | EY20: NO | EZ20: NO | FA20: NO | FB20: NO | FC20: NO | FD20: NO | FE20: NO | FF20: NO | FJ20: 13300 | FK20: 122235 | FM20: 135535 | FQ20: 194118.14 | FR20: 11360 | FT20: 205478.14 | GA20: 0 | GE20: 157717.24 | GH20: 157717.24 | GL20: 4999.95 | GO20: 4999.95 | GS20: 160700 | GV20: 160700 | HC20: 0 | HD20: Banks, Securities, Corporate, Other financial institutions | HH20: 293136.85 | HK20: 293136.85 | HL20: 0 | HM20: 0 | HN20: 0 | HO20: 823972.18 | HP20: 133595 | HQ20: 0 | HR20: 957567.18 | HV20: 167050 | HW20: 76800 | HY20: 243850 | IC20: 491900 | IF20: 491900 | IJ20: 165022.18 | IK20: 56795 | IM20: 221817.18 | IT20: 0 | JA20: 0 | JB20: 0 | JC20: 0 | JD20: 0 | JE20: 823972.18 | JF20: 133595 | JG20: 0 | JH20: 957567.18 | JJ20: 100 | JQ20: 13300 | JR20: 76800 | JT20: 90100 | KA20: 0 | KH20: 0 | KL20: 99613.2 | KO20: 99613.2 | KS20: 4999.95 | KV20: 4999.95 | LC20: 0 | LJ20: 0 | LK20: Banks, Securities, Corporate, Other financial institutions | LO20: 49136.85 | LR20: 49136.85 | LS20: 0 | LT20: 0 | LU20: 0 | LV20: 167050 | LW20: 76800 | LX20: 0 | LY20: 243850 | MJ20: 87200 | NL20: 160700 | NW20: Banks, Securities, Corporate, Other financial institutions | OA20: 244000 | OK20: 491900 | OP20: 45435 | OV20: 106918.14 | OW20: 11360 | PJ20: 58104.04 | QW20: 221817.18 | TI20: 0 | VU20: 0 | YG20: 0 | YH20: 1 | YI20: 1 | YJ20: 1 | YK20: Mozilla/5.0 (iPhone; CPU iPhone OS 9_2_1 like Mac OS X) AppleWebKit/601.1.46 (KHTML, like Gecko) Version/9.0 Mobile/13D15 Safari/601.1 | YL20: 183 | YM20: ANFCR868 | YN20: ANREV | YO20: IGIS Asset Management | YP20: Joseph | YQ20: joseph.lee@igisam.com | YS20: http://click.surveylab.co.uk/anrev-inrev-ncreif-capital-raising-2016/?survey=ANFCR868
A21: 43 | B21: ANATG834 | C21: survey=ANATG834 | D21: 42404.424 | F21: 11 | G21: 1|2|3|2|3|2|2|3|4|5|6|7|8|12|2|3|4|5|6|3|4|5|6|7|8|12|12|2|3|4|5|6|7|8|12| | I21: 118.201.195.144 | J21: ANREV | K21: Chew Weiting | L21: CapitaLand Fund Management Pte. Ltd. | M21: =VLOOKUP(MID(O21,SEARCH("@",O21,1),LEN(O21)-SEARCH("@",O21,1)+1),[1]Sheet1!$D:$F,3,FALSE) -> M0091 | N21: Senior Analyst | O21: chew.weiting@capitaland.com | P21: 65 6713 3108 | Q21: Singapore | R21: USD | T21: 1 | AC21: 0 | AJ21: 0 | AQ21: 0 | AU21: 600 | AX21: 600 | BE21: 0 | BL21: 0 | BM21: 0 | BN21: 0 | BO21: 0 | BP21: 600 | BQ21: 0 | BR21: 0 | BS21: 600 | BT21: FALSE | BU21: FALSE | BV21: FALSE | BW21: TRUE | BX21: FALSE | BY21: FALSE | CF21: 0 | CM21: 0 | CT21: 0 | CX21: 1 | DA21: 1 | DH21: 0 | DO21: 0 | DP21: 0 | DQ21: 0 | DR21: 0 | DS21: 1 | DT21: 0 | DU21: 0 | DV21: 1 | DW21: NO | DX21: NO | DY21: NO | DZ21: NO | EA21: NO | EB21: NO | EC21: NO | ED21: NO | EE21: NO | EF21: NO | EG21: NO | EH21: NO | EI21: NO | EJ21: NO | EK21: NO | EL21: NO | EM21: NO | EN21: NO | EO21: NO | EP21: NO | EQ21: NO | ER21: YES | ES21: NO | ET21: NO | EU21: NO | EV21: NO | EW21: NO | EX21: NO | EY21: NO | EZ21: NO | FA21: NO | FB21: NO | FC21: NO | FD21: NO | FE21: NO | FF21: NO | FM21: 0 | FT21: 0 | FX21: 300 | GA21: 300 | GH21: 0 | GO21: 0 | GV21: 0 | HC21: 0 | HD21: Corporate | HH21: 300 | HK21: 300 | HL21: 0 | HM21: 0 | HN21: 0 | HO21: 600 | HP21: 0 | HQ21: 0 | HR21: 600 | HY21: 0 | IC21: 600 | IF21: 600 | IM21: 0 | IT21: 0 | JA21: 0 | JB21: 0 | JC21: 0 | JD21: 0 | JE21: 600 | JF21: 0 | JG21: 0 | JH21: 600 | JK21: 100 | JT21: 0 | KA21: 0 | KH21: 0 | KO21: 0 | KV21: 0 | LC21: 0 | LJ21: 0 | LR21: 0 | LS21: 0 | LT21: 0 | LU21: 0 | LV21: 0 | LW21: 0 | LX21: 0 | LY21: 0 | OK21: 0 | QW21: 0 | RO21: 300 | SU21: Corporate | SY21: 300 | TI21: 600 | YK21: Mozilla/5.0 (Windows NT 6.1; Trident/7.0; rv:11.0) like Gecko | YL21: 68 | YM21: ANATG834 | YN21: ANREV | YO21: CapitaLand | YP21: Chew Weiting | YQ21: chew.weiting@capitaland.com | YS21: http://click.surveylab.co.uk/anrev-inrev-ncreif-capital-raising-2016/?survey=ANATG834
A22: 44 | B22: NVYGZ815 | C22: survey=NVYGZ815 | D22: 42417.622 | E22: 42417.659 | F22: 14 | G22: 1|2|3|4|4|5|6|2|3|4|5|6|7|8|8|3|4|5|6|7|8|9|3|4|5|6|7|8|9|11|12|12|2|3|4|5|3|3|4|5|4|3|4|5|6|2|3|3|4|5|6|7|8|9|15| | I22: 193.138.107.81 | J22: INREV | K22: Geoff Cunningham | L22: Standard Life Investments | M22: =VLOOKUP(MID(O22,SEARCH("@",O22,1),LEN(O22)-SEARCH("@",O22,1)+1),[1]Sheet1!$D:$F,3,FALSE) -> M675 | N22: Management Information Analyst | O22: geoff_cunningham@standardlife.com | P22: +44 (0)131 245 6862 | Q22: United Kingdom | R22: GBP | T22: 1 | W22: 294.98 | Z22: 276.61 | AB22: 55 | AC22: 626.59 | AJ22: 0 | AQ22: 0 | AX22: 0 | BE22: 0 | BL22: 0 | BM22: 294.98 | BN22: 0 | BO22: 0 | BP22: 276.61 | BQ22: 0 | BR22: 55 | BS22: 626.59 | BT22: TRUE | BU22: FALSE | BV22: FALSE | BW22: FALSE | BX22: FALSE | BY22: FALSE | BZ22: 4 | CC22: 1 | CE22: 1 | CF22: 6 | CM22: 0 | CT22: 0 | DA22: 0 | DH22: 0 | DO22: 0 | DP22: 4 | DQ22: 0 | DR22: 0 | DS22: 1 | DT22: 0 | DU22: 1 | DV22: 6 | DW22: YES | DX22: NO | DY22: NO | DZ22: YES | EA22: NO | EB22: YES | EC22: NO | ED22: NO | EE22: NO | EF22: NO | EG22: NO | EH22: NO | EI22: NO | EJ22: NO | EK22: NO | EL22: NO | EM22: NO | EN22: NO | EO22: NO | EP22: NO | EQ22: NO | ER22: NO | ES22: NO | ET22: NO | EU22: NO | EV22: NO | EW22: NO | EX22: NO | EY22: NO | EZ22: NO | FA22: NO | FB22: NO | FC22: NO | FD22: NO | FE22: NO | FF22: NO | FG22: 134.47 | FJ22: 230.66 | FL22: 55 | FM22: 420.13 | FN22: 77.88 | FQ22: 21.21 | FT22: 99.09 | FU22: 82.64 | GA22: 82.64 | GH22: 0 | GL22: 24.74 | GO22: 24.74 | GV22: 0 | HC22: 0 | HK22: 0 | HL22: 294.99 | HM22: 0 | HN22: 0 | HO22: 276.61 | HP22: 0 | HQ22: 55 | HR22: 626.6 | HS22: 212.34 | HV22: 60.09 | HX22: 55 | HY22: 327.43 | HZ22: 82.64 | IC22: 17.67 | IF22: 100.31 | IJ22: 198.85 | IM22: 198.85 | IT22: 0 | JA22: 0 | JB22: 294.98 | JC22: 0 | JD22: 0 | JE22: 276.61 | JF22: 0 | JG22: 55 | JH22: 626.59 | JK22: 100 | JN22: 134.47 | JQ22: 230.66 | JS22: 55 | JT22: 420.13 | JU22: 77.88 | JX22: 21.21 | KA22: 99.09 | KB22: 82.64 | KH22: 82.64 | KO22: 0 | KS22: 24.74 | KV22: 24.74 | LC22: 0 | LJ22: 0 | LR22: 0 | LS22: 294.99 | LT22: 0 | LU22: 0 | LV22: 276.61 | LW22: 0 | LX22: 55 | LY22: 626.6 | OK22: 0 | QW22: 0 | TI22: 0 | VU22: 0 | YG22: 0 | YH22: 3 | YI22: 2 | YJ22: 2 | YK22: Mozilla/5.0 (Windows NT 6.1; WOW64; Trident/7.0; rv:11.0) like Gecko | YL22: 321 | YM22: NVYGZ815 | YN22: INREV | YO22: Standard Life Investments | YP22: Geoff Cunningham | YQ22: geoff_cunningham@standardlife.com | YS22: http://click.surveylab.co.uk/anrev-inrev-ncreif-capital-raising-2016/?survey=NVYGZ815
A23: 46 | B23: NVEBT812 | C23: survey=NVEBT812 | D23: 42401.473 | E23: 42401.495 | F23: 14 | G23: 1|2|3|3|4|5|5|4|5|6|7|8|6|7|7|7|8|9|4|5|6|7|8|9|3|4|5|6|7|8|9|2|3|4|5|6|7|8|6|6|7|8|9|4|5|6|7|8|9|15| | I23: 57.66.102.116 | J23: INREV | K23: Martin Wheeler/Cilla Yngvesson | L23: ICG-Longbow | M23: =VLOOKUP(MID(O23,SEARCH("@",O23,1),LEN(O23)-SEARCH("@",O23,1)+1),[1]Sheet1!$D:$F,3,FALSE) -> M674 | N23: Co-head/ClientRelations | O23: Cilla.Yngvesson@icgplc.com | P23: +44 (0)20 3201 7772 | Q23: United Kingdom | R23: GBP | T23: 1 | AB23: 982 | AC23: 982 | AJ23: 0 | AQ23: 0 | AX23: 0 | BE23: 0 | BL23: 0 | BM23: 0 | BN23: 0 | BO23: 0 | BP23: 0 | BQ23: 0 | BR23: 982 | BS23: 982 | BT23: TRUE | BU23: FALSE | BV23: FALSE | BW23: FALSE | BX23: FALSE | BY23: FALSE | CE23: 2 | CF23: 2 | CM23: 0 | CT23: 0 | DA23: 0 | DH23: 0 | DO23: 0 | DP23: 0 | DQ23: 0 | DR23: 0 | DS23: 0 | DT23: 0 | DU23: 2 | DV23: 2 | DW23: NO | DX23: NO | DY23: NO | DZ23: NO | EA23: NO | EB23: YES | EC23: NO | ED23: NO | EE23: NO | EF23: NO | EG23: NO | EH23: NO | EI23: NO | EJ23: NO | EK23: NO | EL23: NO | EM23: NO | EN23: NO | EO23: NO | EP23: NO | EQ23: NO | ER23: NO | ES23: NO | ET23: NO | EU23: NO | EV23: NO | EW23: NO | EX23: NO | EY23: NO | EZ23: NO | FA23: NO | FB23: NO | FC23: NO | FD23: NO | FE23: NO | FF23: NO | FL23: 681 | FM23: 681 | FS23: 156 | FT23: 156 | GA23: 0 | GH23: 0 | GO23: 0 | GU23: 90 | GV23: 90 | HC23: 0 | HD23: Endowment Plan/Industry Body | HJ23: 55 | HK23: 55 | HL23: 0 | HM23: 0 | HN23: 0 | HO23: 0 | HP23: 0 | HQ23: 982 | HR23: 982 | HX23: 872 | HY23: 872 | IE23: 110 | IF23: 110 | IM23: 0 | IT23: 0 | JA23: 0 | JB23: 0 | JC23: 0 | JD23: 0 | JE23: 0 | JF23: 0 | JG23: 982 | JH23: 982 | JK23: 100 | JS23: 681 | JT23: 681 | JZ23: 156 | KA23: 156 | KH23: 0 | KO23: 0 | KV23: 0 | LB23: 90 | LC23: 90 | LJ23: 0 | LK23: Endowment Plan/Industry Body | LQ23: 55 | LR23: 55 | LS23: 0 | LT23: 0 | LU23: 0 | LV23: 0 | LW23: 0 | LX23: 982 | LY23: 982 | OK23: 0 | QW23: 0 | TI23: 0 | VU23: 0 | YG23: 0 | YH23: 1 | YI23: 1 | YJ23: 1 | YK23: Mozilla/5.0 (compatible; MSIE 10.0; Windows NT 6.1; WOW64; Trident/6.0) | YL23: 177 | YM23: NVEBT812 | YN23: INREV | YO23: ICG-Longbow | YP23: Cilla Yngvesson | YQ23: cilla.yngvesson@icgam.com | YS23: http://click.surveylab.co.uk/anrev-inrev-ncreif-capital-raising-2016/?survey=NVEBT812
A24: 47 | B24: NVCBA144 | C24: survey=NVCBA144 | D24: 42417.457 | E24: 42417.49 | F24: 14 | G24: 1|2|2|3|4|5|6|7|8|2|2|3|2|2|3|2|3|4|4|5|6|7|8|3|2|3|4|5|6|7|8|9|9|10|11|11|10|2|3|4|5|6|7|8|6|7|8|6|7|8|9|10|11|9|10|11|7|4|3|2|3|4|5|6|7|7|8|9|10|11|2|3|4|3|4|5|6|7|3|4|5|5|3|4|5|6|7|8|9|10|11|15| | I24: 185.48.69.2 | J24: INREV | K24: Iris Gelten | L24: Bouwinvest Real Estate Investment Management (REIM) | M24: =VLOOKUP(MID(O24,SEARCH("@",O24,1),LEN(O24)-SEARCH("@",O24,1)+1),[1]Sheet1!$D:$F,3,FALSE) -> M660 | N24: Corporate Marketing & Communication Adviser | O24: i.gelten@bouwinvest.nl | P24: +31 (0)6 22227735 | Q24: Netherlands | R24: EUR | T24: 1 | W24: 291.5 | AC24: 291.5 | AD24: 46 | AJ24: 46 | AK24: 12 | AQ24: 12 | AX24: 0 | BE24: 0 | BL24: 0 | BM24: 349.5 | BN24: 0 | BO24: 0 | BP24: 0 | BQ24: 0 | BR24: 0 | BS24: 349.5 | BT24: TRUE | BU24: TRUE | BV24: TRUE | BW24: FALSE | BX24: FALSE | BY24: FALSE | BZ24: 6 | CF24: 6 | CG24: 3 | CM24: 3 | CN24: 1 | CT24: 1 | DA24: 0 | DH24: 0 | DO24: 0 | DP24: 10 | DQ24: 0 | DR24: 0 | DS24: 0 | DT24: 0 | DU24: 0 | DV24: 10 | DW24: YES | DX24: NO | DY24: NO | DZ24: NO | EA24: NO | EB24: NO | EC24: YES | ED24: NO | EE24: NO | EF24: NO | EG24: NO | EH24: NO | EI24: YES | EJ24: NO | EK24: NO | EL24: NO | EM24: NO | EN24: NO | EO24: NO | EP24: NO | EQ24: NO | ER24: NO | ES24: NO | ET24: NO | EU24: NO | EV24: NO | EW24: NO | EX24: NO | EY24: NO | EZ24: NO | FA24: NO | FB24: NO | FC24: NO | FD24: NO | FE24: NO | FF24: NO | FG24: 339.5 | FM24: 339.5 | FN24: 10 | FT24: 10 | GA24: 0 | GH24: 0 | GO24: 0 | GV24: 0 | HC24: 0 | HK24: 0 | HL24: 349.5 | HM24: 0 | HN24: 0 | HO24: 0 | HP24: 0 | HQ24: 0 | HR24: 349.5 | HS24: 349.5 | HY24: 349.5 | IF24: 0 | IM24: 0 | IT24: 0 | JA24: 0 | JB24: 349.5 | JC24: 0 | JD24: 0 | JE24: 0 | JF24: 0 | JG24: 0 | JH24: 349.5 | JI24: 29 | JK24: 71 | JN24: 281.5 | JT24: 281.5 | JU24: 10 | KA24: 10 | KH24: 0 | KO24: 0 | KV24: 0 | LC24: 0 | LJ24: 0 | LR24: 0 | LS24: 291.5 | LT24: 0 | LU24: 0 | LV24: 0 | LW24: 0 | LX24: 0 | LY24: 291.5 | LZ24: 46 | OK24: 46 | OL24: 12 | QW24: 12 | TI24: 0 | VU24: 0 | YG24: 0 | YH24: 1 | YI24: 1 | YJ24: 1 | YK24: Mozilla/5.0 (compatible; MSIE 10.0; Windows NT 6.2; WOW64; Trident/6.0) | YL24: 61 | YM24: NVCBA144 | YN24: INREV | YO24: Bouwinvest REIM B.V. | YP24: Iris Gelten | YQ24: i.gelten@bouwnvest.nl | YS24: http://click.surveylab.co.uk/anrev-inrev-ncreif-capital-raising-2016/?survey=NVCBA144
