Workbook
Name RMITeam: [1]ContactDetails!$B$9:$B$13

Sheet DataCompleted
A1: Surveycode | B1: Association_Sample | C1: Company_Sample | D1: REGION1 | E1: DateCompleted_Asia | F1: REGION2 | G1: DateCompleted_Europe | H1: REGION3 | I1: DateCompleted_NorthAmerica | J1: REGION4 | K1: DateCompleted_Global | L1: REGION5 | M1: DateCompleted_SouthAmerica | N1: REGION6 | O1: DateCompleted_Africa | P1: ShowEurope | Q1: ShowAsia | R1: ShowNA | S1: ShowGlobal | T1: ShowSA | U1: ShowAfrica | V1: RecordNo | W1: DateCompleted | X1: IPaddress | Y1: Version | Z1: qName | AA1: qCompany | AB1: mnumber | AC1: qJobtitle | AD1: qEmail | AE1: qTelephone | AF1: qCountry | AG1: qCurrency | AH1: qCurrencyOther | AI1: q1 | AJ1: q2 | AK1: q2other | AL1: q3A_TotalRealEstate | AM1: q3A_NonListedRealEstate | AN1: q3B_TotalRealEstate | AO1: q3B_NonListedRealEstate | AP1: q31_1 | AQ1: q31_2 | AR1: q31_3 | AS1: q31_4 | AT1: q31_5 | AU1: q31_6 | AV1: q3ROW1_hidden | AW1: q32_1 | AX1: q32_2 | AY1: q32_3 | AZ1: q32_4 | BA1: q32_5 | BB1: q32_6 | BC1: q3ROW2_hidden | BD1: q33_1 | BE1: q33_2 | BF1: q33_3 | BG1: q33_4 | BH1: q33_5 | BI1: q33_6 | BJ1: q3ROW3_hidden | BK1: q34_1 | BL1: q34_2 | BM1: q34_3 | BN1: q34_4 | BO1: q34_5 | BP1: q34_6 | BQ1: q3ROW4_hidden | BR1: q35_1 | BS1: q35_2 | BT1: q35_3 | BU1: q35_4 | BV1: q35_5 | BW1: q35_6 | BX1: q3ROW5_hidden | BY1: q36_1 | BZ1: q36_2 | CA1: q36_3 | CB1: q36_4 | CC1: q36_5 | CD1: q36_6 | CE1: q3ROW6_hidden | CF1: q3COL1_hidden | CG1: q3COL2_hidden | CH1: q3COL3_hidden | CI1: q3COL4_hidden | CJ1: q3COL5_hidden | CK1: q3COL6_hidden | CL1: q3GRANDTotal_hidden | CM1: q41_1 | CN1: q41_2 | CO1: q41_3 | CP1: q41_4 | CQ1: q41_5 | CR1: q41_6 | CS1: q4ROW1_hidden | CT1: q42_1 | CU1: q42_2 | CV1: q42_3 | CW1: q42_4 | CX1: q42_5 | CY1: q42_6 | CZ1: q4ROW2_hidden | DA1: q43_1 | DB1: q43_2 | DC1: q43_3 | DD1: q43_4 | DE1: q43_5 | DF1: q43_6 | DG1: q4ROW3_hidden | DH1: q44_1 | DI1: q44_2 | DJ1: q44_3 | DK1: q44_4 | DL1: q44_5 | DM1: q44_6 | DN1: q4ROW4_hidden | DO1: q45_1 | DP1: q45_2 | DQ1: q45_3 | DR1: q45_4 | DS1: q45_5 | DT1: q45_6 | DU1: q4ROW5_hidden | DV1: q46_1 | DW1: q46_2 | DX1: q46_3 | DY1: q46_4 | DZ1: q46_5 | EA1: q46_6 | EB1: q4ROW6_hidden | EC1: q4COL1_hidden | ED1: q4COL2_hidden | EE1: q4COL3_hidden | EF1: q4COL4_hidden | EG1: q4COL5_hidden | EH1: q4COL6_hidden | EI1: q4GRANDTotal_hidden | EJ1: Alert41_1 | EK1: Alert41_2 | EL1: Alert41_3 | EM1: Alert41_4 | EN1: Alert41_5 | EO1: Alert41_6 | EP1: Alert42_1 | EQ1: Alert42_2 | ER1: Alert42_3 | ES1: Alert42_4 | ET1: Alert42_5 | EU1: Alert42_6 | EV1: Alert43_1 | EW1: Alert43_2 | EX1: Alert43_3 | EY1: Alert43_4 | EZ1: Alert43_5 | FA1: Alert43_6 | FB1: Alert44_1 | FC1: Alert44_2 | FD1: Alert44_3 | FE1: Alert44_4 | FF1: Alert44_5 | FG1: Alert44_6 | FH1: Alert45_1 | FI1: Alert45_2 | FJ1: Alert45_3 | FK1: Alert45_4 | FL1: Alert45_5 | FM1: Alert45_6 | FN1: Alert46_1 | FO1: Alert46_2 | FP1: Alert46_3 | FQ1: Alert46_4 | FR1: Alert46_5 | FS1: Alert46_6 | FT1: q51_1 | FU1: q51_2 | FV1: q51_3 | FW1: q51_4 | FX1: q51_5 | FY1: q51_6 | FZ1: q5ROW1_hidden | GA1: q52_1 | GB1: q52_2 | GC1: q52_3 | GD1: q52_4 | GE1: q52_5 | GF1: q52_6 | GG1: q5ROW2_hidden | GH1: q53_1 | GI1: q53_2 | GJ1: q53_3 | GK1: q53_4 | GL1: q53_5 | GM1: q53_6 | GN1: q5ROW3_hidden | GO1: q54_1 | GP1: q54_2 | GQ1: q54_3 | GR1: q54_4 | GS1: q54_5 | GT1: q54_6 | GU1: q5ROW4_hidden | GV1: q55_1 | GW1: q55_2 | GX1: q55_3 | GY1: q55_4 | GZ1: q55_5 | HA1: q55_6 | HB1: q5ROW5_hidden | HC1: q56_1 | HD1: q56_2 | HE1: q56_3 | HF1: q56_4 | HG1: q56_5 | HH1: q56_6 | HI1: q5ROW6_hidden | HJ1: q57_1 | HK1: q57_2 | HL1: q57_3 | HM1: q57_4 | HN1: q57_5 | HO1: q57_6 | HP1: q5ROW7_hidden | HQ1: q5other | HR1: q58_1 | HS1: q58_2 | HT1: q58_3 | HU1: q58_4 | HV1: q58_5 | HW1: q58_6 | HX1: q5ROW8_hidden | HY1: q5COL1_hidden | HZ1: q5COL2_hidden | IA1: q5COL3_hidden | IB1: q5COL4_hidden | IC1: q5COL5_hidden | ID1: q5COL6_hidden | IE1: q5GRANDTotal_hidden | IF1: q61_1 | IG1: q61_2 | IH1: q61_3 | II1: q61_4 | IJ1: q61_5 | IK1: q61_6 | IL1: q6ROW1_hidden | IM1: q62_1 | IN1: q62_2 | IO1: q62_3 | IP1: q62_4 | IQ1: q62_5 | IR1: q62_6 | IS1: q6ROW2_hidden | IT1: q63_1 | IU1: q63_2 | IV1: q63_3 | IW1: q63_4 | IX1: q63_5 | IY1: q63_6 | IZ1: q6ROW3_hidden | JA1: q64_1 | JB1: q64_2 | JC1: q64_3 | JD1: q64_4 | JE1: q64_5 | JF1: q64_6 | JG1: q6ROW4_hidden | JH1: q65_1 | JI1: q65_2 | JJ1: q65_3 | JK1: q65_4 | JL1: q65_5 | JM1: q65_6 | JN1: q6ROW5_hidden | JO1: q6COL1_hidden | JP1: q6COL2_hidden | JQ1: q6COL3_hidden | JR1: q6COL4_hidden | JS1: q6COL5_hidden | JT1: q6COL6_hidden | JU1: q6GRANDTotal_hidden | JV1: q7_1 | JW1: q7_2 | JX1: q7_3 | JY1: q7other | JZ1: q7_4 | KA1: q8 | KB1: q9 | KC1: q91 | KD1: ASIAPACIFIC_apac | KE1: q101_1_apac | KF1: q101_2_apac | KG1: q101_3_apac | KH1: q101_4_apac | KI1: q101_5_apac | KJ1: q101_6_apac | KK1: q10ROW1_hidden_apac | KL1: q102_1_apac | KM1: q102_2_apac | KN1: q102_3_apac | KO1: q102_4_apac | KP1: q102_5_apac | KQ1: q102_6_apac | KR1: q10ROW2_hidden_apac | KS1: q103_1_apac | KT1: q103_2_apac | KU1: q103_3_apac | KV1: q103_4_apac | KW1: q103_5_apac | KX1: q103_6_apac | KY1: q10ROW3_hidden_apac | KZ1: q104_1_apac | LA1: q104_2_apac | LB1: q104_3_apac | LC1: q104_4_apac | LD1: q104_5_apac | LE1: q104_6_apac | LF1: q10ROW4_hidden_apac | LG1: q105_1_apac | LH1: q105_2_apac | LI1: q105_3_apac | LJ1: q105_4_apac | LK1: q105_5_apac | LL1: q105_6_apac | LM1: q10ROW5_hidden_apac | LN1: q106_1_apac | LO1: q106_2_apac | LP1: q106_3_apac | LQ1: q106_4_apac | LR1: q106_5_apac | LS1: q106_6_apac | LT1: q10ROW6_hidden_apac | LU1: q107_1_apac | LV1: q107_2_apac | LW1: q107_3_apac | LX1: q107_4_apac | LY1: q107_5_apac | LZ1: q107_6_apac | MA1: q10ROW7_hidden_apac | MB1: q10other_apac | MC1: q108_1_apac | MD1: q108_2_apac | ME1: q108_3_apac | MF1: q108_4_apac | MG1: q108_5_apac | MH1: q108_6_apac | MI1: q10ROW8_hidden_apac | MJ1: q10COL1_hidden_apac | MK1: q10COL2_hidden_apac | ML1: q10COL3_hidden_apac | MM1: q10COL4_hidden_apac | MN1: q10COL5_hidden_apac | MO1: q10COL6_hidden_apac | MP1: q10GRANDTotal_hidden_apac | MQ1: q111_1_apac | MR1: q111_2_apac | MS1: q111_3_apac | MT1: q111_4_apac | MU1: q111_5_apac | MV1: q111_6_apac | MW1: q11ROW1_hidden_apac | MX1: q112_1_apac | MY1: q112_2_apac | MZ1: q112_3_apac | NA1: q112_4_apac | NB1: q112_5_apac | NC1: q112_6_apac | ND1: q11ROW2_hidden_apac | NE1: q113_1_apac | NF1: q113_2_apac | NG1: q113_3_apac | NH1: q113_4_apac | NI1: q113_5_apac | NJ1: q113_6_apac | NK1: q11ROW3_hidden_apac | NL1: q114_1_apac | NM1: q114_2_apac | NN1: q114_3_apac | NO1: q114_4_apac | NP1: q114_5_apac | NQ1: q114_6_apac | NR1: q11ROW4_hidden_apac | NS1: q115_1_apac | NT1: q115_2_apac | NU1: q115_3_apac | NV1: q115_4_apac | NW1: q115_5_apac | NX1: q115_6_apac | NY1: q11ROW5_hidden_apac | NZ1: q11COL1_hidden_apac | OA1: q11COL2_hidden_apac | OB1: q11COL3_hidden_apac | OC1: q11COL4_hidden_apac | OD1: q11COL5_hidden_apac | OE1: q11COL6_hidden_apac | OF1: q11GRANDTotal_hidden_apac | OG1: EUROPE_europe | OH1: q101_1_europe | OI1: q101_2_europe | OJ1: q101_3_europe | OK1: q101_4_europe | OL1: q101_5_europe | OM1: q101_6_europe | ON1: q10ROW1_hidden_europe | OO1: q102_1_europe | OP1: q102_2_europe | OQ1: q102_3_europe | OR1: q102_4_europe | OS1: q102_5_europe | OT1: q102_6_europe | OU1: q10ROW2_hidden_europe | OV1: q103_1_europe | OW1: q103_2_europe | OX1: q103_3_europe | OY1: q103_4_europe | OZ1: q103_5_europe | PA1: q103_6_europe | PB1: q10ROW3_hidden_europe | PC1: q104_1_europe | PD1: q104_2_europe | PE1: q104_3_europe | PF1: q104_4_europe | PG1: q104_5_europe | PH1: q104_6_europe | PI1: q10ROW4_hidden_europe | PJ1: q105_1_europe | PK1: q105_2_europe | PL1: q105_3_europe | PM1: q105_4_europe | PN1: q105_5_europe | PO1: q105_6_europe | PP1: q10ROW5_hidden_europe | PQ1: q106_1_europe | PR1: q106_2_europe | PS1: q106_3_europe | PT1: q106_4_europe | PU1: q106_5_europe | PV1: q106_6_europe | PW1: q10ROW6_hidden_europe | PX1: q107_1_europe | PY1: q107_2_europe | PZ1: q107_3_europe | QA1: q107_4_europe | QB1: q107_5_europe | QC1: q107_6_europe | QD1: q10ROW7_hidden_europe | QE1: q10other_europe | QF1: q108_1_europe | QG1: q108_2_europe | QH1: q108_3_europe | QI1: q108_4_europe | QJ1: q108_5_europe | QK1: q108_6_europe | QL1: q10ROW8_hidden_europe | QM1: q10COL1_hidden_europe | QN1: q10COL2_hidden_europe | QO1: q10COL3_hidden_europe | QP1: q10COL4_hidden_europe | QQ1: q10COL5_hidden_europe | QR1: q10COL6_hidden_europe | QS1: q10GRANDTotal_hidden_europe | QT1: q111_1_europe | QU1: q111_2_europe | QV1: q111_3_europe | QW1: q111_4_europe | QX1: q111_5_europe | QY1: q111_6_europe | QZ1: q11ROW1_hidden_europe | RA1: q112_1_europe | RB1: q112_2_europe | RC1: q112_3_europe | RD1: q112_4_europe | RE1: q112_5_europe | RF1: q112_6_europe | RG1: q11ROW2_hidden_europe | RH1: q113_1_europe | RI1: q113_2_europe | RJ1: q113_3_europe | RK1: q113_4_europe | RL1: q113_5_europe | RM1: q113_6_europe | RN1: q11ROW3_hidden_europe | RO1: q114_1_europe | RP1: q114_2_europe | RQ1: q114_3_europe | RR1: q114_4_europe | RS1: q114_5_europe | RT1: q114_6_europe | RU1: q11ROW4_hidden_europe | RV1: q115_1_europe | RW1: q115_2_europe | RX1: q115_3_europe | RY1: q115_4_europe | RZ1: q115_5_europe | SA1: q115_6_europe | SB1: q11ROW5_hidden_europe | SC1: q11COL1_hidden_europe | SD1: q11COL2_hidden_europe | SE1: q11COL3_hidden_europe | SF1: q11COL4_hidden_europe | SG1: q11COL5_hidden_europe | SH1: q11COL6_hidden_europe | SI1: q11GRANDTotal_hidden_europe | SJ1: NORTHAMERICA_northamerica | SK1: q101_1_northamerica | SL1: q101_2_northamerica | SM1: q101_3_northamerica | SN1: q101_4_northamerica | SO1: q101_5_northamerica | SP1: q101_6_northamerica | SQ1: q10ROW1_hidden_northamerica | SR1: q102_1_northamerica | SS1: q102_2_northamerica | ST1: q102_3_northamerica | SU1: q102_4_northamerica | SV1: q102_5_northamerica | SW1: q102_6_northamerica | SX1: q10ROW2_hidden_northamerica | SY1: q103_1_northamerica | SZ1: q103_2_northamerica | TA1: q103_3_northamerica | TB1: q103_4_northamerica | TC1: q103_5_northamerica | TD1: q103_6_northamerica | TE1: q10ROW3_hidden_northamerica | TF1: q104_1_northamerica | TG1: q104_2_northamerica | TH1: q104_3_northamerica | TI1: q104_4_northamerica | TJ1: q104_5_northamerica | TK1: q104_6_northamerica | TL1: q10ROW4_hidden_northamerica | TM1: q105_1_northamerica | TN1: q105_2_northamerica | TO1: q105_3_northamerica | TP1: q105_4_northamerica | TQ1: q105_5_northamerica | TR1: q105_6_northamerica | TS1: q10ROW5_hidden_northamerica | TT1: q106_1_northamerica | TU1: q106_2_northamerica | TV1: q106_3_northamerica | TW1: q106_4_northamerica | TX1: q106_5_northamerica | TY1: q106_6_northamerica | TZ1: q10ROW6_hidden_northamerica | UA1: q107_1_northamerica | UB1: q107_2_northamerica | UC1: q107_3_northamerica | UD1: q107_4_northamerica | UE1: q107_5_northamerica | UF1: q107_6_northamerica | UG1: q10ROW7_hidden_northamerica | UH1: q10other_northamerica | UI1: q108_1_northamerica | UJ1: q108_2_northamerica | UK1: q108_3_northamerica | UL1: q108_4_northamerica | UM1: q108_5_northamerica | UN1: q108_6_northamerica | UO1: q10ROW8_hidden_northamerica | UP1: q10COL1_hidden_northamerica | UQ1: q10COL2_hidden_northamerica | UR1: q10COL3_hidden_northamerica | US1: q10COL4_hidden_northamerica | UT1: q10COL5_hidden_northamerica | UU1: q10COL6_hidden_northamerica | UV1: q10GRANDTotal_hidden_northamerica | UW1: q111_1_northamerica | UX1: q111_2_northamerica | UY1: q111_3_northamerica | UZ1: q111_4_northamerica | VA1: q111_5_northamerica | VB1: q111_6_northamerica | VC1: q11ROW1_hidden_northamerica | VD1: q112_1_northamerica | VE1: q112_2_northamerica | VF1: q112_3_northamerica | VG1: q112_4_northamerica | VH1: q112_5_northamerica | VI1: q112_6_northamerica | VJ1: q11ROW2_hidden_northamerica | VK1: q113_1_northamerica | VL1: q113_2_northamerica | VM1: q113_3_northamerica | VN1: q113_4_northamerica | VO1: q113_5_northamerica | VP1: q113_6_northamerica | VQ1: q11ROW3_hidden_northamerica | VR1: q114_1_northamerica | VS1: q114_2_northamerica | VT1: q114_3_northamerica | VU1: q114_4_northamerica | VV1: q114_5_northamerica | VW1: q114_6_northamerica | VX1: q11ROW4_hidden_northamerica | VY1: q115_1_northamerica | VZ1: q115_2_northamerica | WA1: q115_3_northamerica | WB1: q115_4_northamerica | WC1: q115_5_northamerica | WD1: q115_6_northamerica | WE1: q11ROW5_hidden_northamerica | WF1: q11COL1_hidden_northamerica | WG1: q11COL2_hidden_northamerica | WH1: q11COL3_hidden_northamerica | WI1: q11COL4_hidden_northamerica | WJ1: q11COL5_hidden_northamerica | WK1: q11COL6_hidden_northamerica | WL1: q11GRANDTotal_hidden_northamerica | WM1: Global_global | WN1: q101_1_global | WO1: q101_2_global | WP1: q101_3_global | WQ1: q101_4_global | WR1: q101_5_global | WS1: q101_6_global | WT1: q10ROW1_hidden_global | WU1: q102_1_global | WV1: q102_2_global | WW1: q102_3_global | WX1: q102_4_global | WY1: q102_5_global | WZ1: q102_6_global | XA1: q10ROW2_hidden_global | XB1: q103_1_global | XC1: q103_2_global | XD1: q103_3_global | XE1: q103_4_global | XF1: q103_5_global | XG1: q103_6_global | XH1: q10ROW3_hidden_global | XI1: q104_1_global | XJ1: q104_2_global | XK1: q104_3_global | XL1: q104_4_global | XM1: q104_5_global | XN1: q104_6_global | XO1: q10ROW4_hidden_global | XP1: q105_1_global | XQ1: q105_2_global | XR1: q105_3_global | XS1: q105_4_global | XT1: q105_5_global | XU1: q105_6_global | XV1: q10ROW5_hidden_global | XW1: q106_1_global | XX1: q106_2_global | XY1: q106_3_global | XZ1: q106_4_global | YA1: q106_5_global | YB1: q106_6_global | YC1: q10ROW6_hidden_global | YD1: q107_1_global | YE1: q107_2_global | YF1: q107_3_global | YG1: q107_4_global | YH1: q107_5_global | YI1: q107_6_global | YJ1: q10ROW7_hidden_global | YK1: q10other_global | YL1: q108_1_global | YM1: q108_2_global | YN1: q108_3_global | YO1: q108_4_global | YP1: q108_5_global | YQ1: q108_6_global | YR1: q10ROW8_hidden_global | YS1: q10COL1_hidden_global | YT1: q10COL2_hidden_global | YU1: q10COL3_hidden_global | YV1: q10COL4_hidden_global | YW1: q10COL5_hidden_global | YX1: q10COL6_hidden_global | YY1: q10GRANDTotal_hidden_global | YZ1: q111_1_global | ZA1: q111_2_global | ZB1: q111_3_global | ZC1: q111_4_global | ZD1: q111_5_global | ZE1: q111_6_global | ZF1: q11ROW1_hidden_global | ZG1: q112_1_global | ZH1: q112_2_global | ZI1: q112_3_global | ZJ1: q112_4_global | ZK1: q112_5_global | ZL1: q112_6_global | ZM1: q11ROW2_hidden_global | ZN1: q113_1_global | ZO1: q113_2_global | ZP1: q113_3_global | ZQ1: q113_4_global | ZR1: q113_5_global | ZS1: q113_6_global | ZT1: q11ROW3_hidden_global | ZU1: q114_1_global | ZV1: q114_2_global | ZW1: q114_3_global | ZX1: q114_4_global | ZY1: q114_5_global | ZZ1: q114_6_global | AAA1: q11ROW4_hidden_global | AAB1: q115_1_global | AAC1: q115_2_global | AAD1: q115_3_global | AAE1: q115_4_global | AAF1: q115_5_global | AAG1: q115_6_global | AAH1: q11ROW5_hidden_global | AAI1: q11COL1_hidden_global | AAJ1: q11COL2_hidden_global | AAK1: q11COL3_hidden_global | AAL1: q11COL4_hidden_global | AAM1: q11COL5_hidden_global | AAN1: q11COL6_hidden_global | AAO1: q11GRANDTotal_hidden_global | AAP1: SOUTHAMERICA_southamerica | AAQ1: q101_1_southamerica | AAR1: q101_2_southamerica | AAS1: q101_3_southamerica | AAT1: q101_4_southamerica | AAU1: q101_5_southamerica | AAV1: q101_6_southamerica | AAW1: q10ROW1_hidden_southamerica | AAX1: q102_1_southamerica | AAY1: q102_2_southamerica | AAZ1: q102_3_southamerica | ABA1: q102_4_southamerica | ABB1: q102_5_southamerica | ABC1: q102_6_southamerica | ABD1: q10ROW2_hidden_southamerica | ABE1: q103_1_southamerica | ABF1: q103_2_southamerica | ABG1: q103_3_southamerica | ABH1: q103_4_southamerica | ABI1: q103_5_southamerica | ABJ1: q103_6_southamerica | ABK1: q10ROW3_hidden_southamerica | ABL1: q104_1_southamerica | ABM1: q104_2_southamerica | ABN1: q104_3_southamerica | ABO1: q104_4_southamerica | ABP1: q104_5_southamerica | ABQ1: q104_6_southamerica | ABR1: q10ROW4_hidden_southamerica | ABS1: q105_1_southamerica | ABT1: q105_2_southamerica | ABU1: q105_3_southamerica | ABV1: q105_4_southamerica | ABW1: q105_5_southamerica | ABX1: q105_6_southamerica | ABY1: q10ROW5_hidden_southamerica | ABZ1: q106_1_southamerica | ACA1: q106_2_southamerica | ACB1: q106_3_southamerica | ACC1: q106_4_southamerica | ACD1: q106_5_southamerica | ACE1: q106_6_southamerica | ACF1: q10ROW6_hidden_southamerica | ACG1: q107_1_southamerica | ACH1: q107_2_southamerica | ACI1: q107_3_southamerica | ACJ1: q107_4_southamerica | ACK1: q107_5_southamerica | ACL1: q107_6_southamerica | ACM1: q10ROW7_hidden_southamerica | ACN1: q10other_southamerica | ACO1: q108_1_southamerica | ACP1: q108_2_southamerica | ACQ1: q108_3_southamerica | ACR1: q108_4_southamerica | ACS1: q108_5_southamerica | ACT1: q108_6_southamerica | ACU1: q10ROW8_hidden_southamerica | ACV1: q10COL1_hidden_southamerica | ACW1: q10COL2_hidden_southamerica | ACX1: q10COL3_hidden_southamerica | ACY1: q10COL4_hidden_southamerica | ACZ1: q10COL5_hidden_southamerica | ADA1: q10COL6_hidden_southamerica | ADB1: q10GRANDTotal_hidden_southamerica | ADC1: q111_1_southamerica | ADD1: q111_2_southamerica | ADE1: q111_3_southamerica | ADF1: q111_4_southamerica | ADG1: q111_5_southamerica | ADH1: q111_6_southamerica | ADI1: q11ROW1_hidden_southamerica | ADJ1: q112_1_southamerica | ADK1: q112_2_southamerica | ADL1: q112_3_southamerica | ADM1: q112_4_southamerica | ADN1: q112_5_southamerica | ADO1: q112_6_southamerica | ADP1: q11ROW2_hidden_southamerica | ADQ1: q113_1_southamerica | ADR1: q113_2_southamerica | ADS1: q113_3_southamerica | ADT1: q113_4_southamerica | ADU1: q113_5_southamerica | ADV1: q113_6_southamerica | ADW1: q11ROW3_hidden_southamerica | ADX1: q114_1_southamerica | ADY1: q114_2_southamerica | ADZ1: q114_3_southamerica | AEA1: q114_4_southamerica | AEB1: q114_5_southamerica | AEC1: q114_6_southamerica | AED1: q11ROW4_hidden_southamerica | AEE1: q115_1_southamerica | AEF1: q115_2_southamerica | AEG1: q115_3_southamerica | AEH1: q115_4_southamerica | AEI1: q115_5_southamerica | AEJ1: q115_6_southamerica | AEK1: q11ROW5_hidden_southamerica | AEL1: q11COL1_hidden_southamerica | AEM1: q11COL2_hidden_southamerica | AEN1: q11COL3_hidden_southamerica | AEO1: q11COL4_hidden_southamerica | AEP1: q11COL5_hidden_southamerica | AEQ1: q11COL6_hidden_southamerica | AER1: q11GRANDTotal_hidden_southamerica | AES1: AFRICA_africa | AET1: q101_1_africa | AEU1: q101_2_africa | AEV1: q101_3_africa | AEW1: q101_4_africa | AEX1: q101_5_africa | AEY1: q101_6_africa | AEZ1: q10ROW1_hidden_africa | AFA1: q102_1_africa | AFB1: q102_2_africa | AFC1: q102_3_africa | AFD1: q102_4_africa | AFE1: q102_5_africa | AFF1: q102_6_africa | AFG1: q10ROW2_hidden_africa | AFH1: q103_1_africa | AFI1: q103_2_africa | AFJ1: q103_3_africa | AFK1: q103_4_africa | AFL1: q103_5_africa | AFM1: q103_6_africa | AFN1: q10ROW3_hidden_africa | AFO1: q104_1_africa | AFP1: q104_2_africa | AFQ1: q104_3_africa | AFR1: q104_4_africa | AFS1: q104_5_africa | AFT1: q104_6_africa | AFU1: q10ROW4_hidden_africa | AFV1: q105_1_africa | AFW1: q105_2_africa | AFX1: q105_3_africa | AFY1: q105_4_africa | AFZ1: q105_5_africa | AGA1: q105_6_africa | AGB1: q10ROW5_hidden_africa | AGC1: q106_1_africa | AGD1: q106_2_africa | AGE1: q106_3_africa | AGF1: q106_4_africa | AGG1: q106_5_africa | AGH1: q106_6_africa | AGI1: q10ROW6_hidden_africa | AGJ1: q107_1_africa | AGK1: q107_2_africa | AGL1: q107_3_africa | AGM1: q107_4_africa | AGN1: q107_5_africa | AGO1: q107_6_africa | AGP1: q10ROW7_hidden_africa | AGQ1: q10other_africa | AGR1: q108_1_africa | AGS1: q108_2_africa | AGT1: q108_3_africa | AGU1: q108_4_africa | AGV1: q108_5_africa | AGW1: q108_6_africa | AGX1: q10ROW8_hidden_africa | AGY1: q10COL1_hidden_africa | AGZ1: q10COL2_hidden_africa | AHA1: q10COL3_hidden_africa | AHB1: q10COL4_hidden_africa | AHC1: q10COL5_hidden_africa | AHD1: q10COL6_hidden_africa | AHE1: q10GRANDTotal_hidden_africa | AHF1: q111_1_africa | AHG1: q111_2_africa | AHH1: q111_3_africa | AHI1: q111_4_africa | AHJ1: q111_5_africa | AHK1: q111_6_africa | AHL1: q11ROW1_hidden_africa | AHM1: q112_1_africa | AHN1: q112_2_africa | AHO1: q112_3_africa | AHP1: q112_4_africa | AHQ1: q112_5_africa | AHR1: q112_6_africa | AHS1: q11ROW2_hidden_africa | AHT1: q113_1_africa | AHU1: q113_2_africa | AHV1: q113_3_africa | AHW1: q113_4_africa | AHX1: q113_5_africa | AHY1: q113_6_africa | AHZ1: q11ROW3_hidden_africa | AIA1: q114_1_africa | AIB1: q114_2_africa | AIC1: q114_3_africa | AID1: q114_4_africa | AIE1: q114_5_africa | AIF1: q114_6_africa | AIG1: q11ROW4_hidden_africa | AIH1: q115_1_africa | AII1: q115_2_africa | AIJ1: q115_3_africa | AIK1: q115_4_africa | AIL1: q115_5_africa | AIM1: q115_6_africa | AIN1: q11ROW5_hidden_africa | AIO1: q11COL1_hidden_africa | AIP1: q11COL2_hidden_africa | AIQ1: q11COL3_hidden_africa | AIR1: q11COL4_hidden_africa | AIS1: q11COL5_hidden_africa | AIT1: q11COL6_hidden_africa | AIU1: q11GRANDTotal_hidden_africa
A2: C9AAC498C | B2: INREV | C2: Northern Horizon Capital A/S | P2: TRUE | Q2: FALSE | R2: FALSE | S2: FALSE | T2: FALSE | U2: FALSE | V2: 629 | W2: 43520.312 | X2: 46.255.210.106 | Y2: 2019 | Z2: Nerijus Zebrauskas | AA2: Northern Horizon Capital | AB2: =VLOOKUP(MID(AD2,SEARCH("@",AD2,1),LEN(AD2)-SEARCH("@",AD2,1)+1),[2]Sheet1!$D:$F,3,FALSE) -> M174 | AD2: nerijus.zebrauskas@nh-cap.com | AF2: Denmark | AG2: EUR | AI2: 1 | AL2: 73 | AM2: 71 | AN2: 2 | AO2: 0 | AV2: 0 | AW2: 71 | BC2: 71 | BJ2: 0 | BQ2: 0 | BX2: 0 | CE2: 0 | CF2: 71 | CG2: 0 | CH2: 0 | CI2: 0 | CJ2: 0 | CK2: 0 | CL2: 71 | CS2: 0 | CT2: 1 | CZ2: 1 | DG2: 0 | DN2: 0 | DU2: 0 | EB2: 0 | EC2: 1 | ED2: 0 | EE2: 0 | EF2: 0 | EG2: 0 | EH2: 0 | EI2: 1 | EJ2: NO | EK2: NO | EL2: NO | EM2: NO | EN2: NO | EO2: NO | EP2: YES | EQ2: NO | ER2: NO | ES2: NO | ET2: NO | EU2: NO | EV2: NO | EW2: NO | EX2: NO | EY2: NO | EZ2: NO | FA2: NO | FB2: NO | FC2: NO | FD2: NO | FE2: NO | FF2: NO | FG2: NO | FH2: NO | FI2: NO | FJ2: NO | FK2: NO | FL2: NO | FM2: NO | FN2: NO | FO2: NO | FP2: NO | FQ2: NO | FR2: NO | FS2: NO | FT2: 59 | FZ2: 59 | GG2: 0 | GN2: 0 | GU2: 0 | GV2: 6 | HB2: 6 | HI2: 0 | HP2: 0 | HQ2: Other financial vehicles | HR2: 6 | HX2: 6 | HY2: 71 | HZ2: 0 | IA2: 0 | IB2: 0 | IC2: 0 | ID2: 0 | IE2: 71 | IL2: 0 | IM2: 71 | IS2: 71 | IZ2: 0 | JG2: 0 | JN2: 0 | JO2: 71 | JP2: 0 | JQ2: 0 | JR2: 0 | JS2: 0 | JT2: 0 | JU2: 71 | JV2: 34 | JX2: 66 | KA2: 2 | KB2: 3 | KC2: 1 | KD2: START Asia Pacific: | OG2: START Europe: | SJ2: START North America: | WM2: START Global: | AAP2: START SOUTH America: | AES2: START Africa:
A3: C9AEF726V | B3: ANREV | C3: Logos | P3: FALSE | Q3: TRUE | R3: FALSE | S3: FALSE | T3: FALSE | U3: FALSE | V3: 708 | W3: 43510.219 | X3: 49.255.15.22 | Y3: 2019 | Z3: Paul Yeo | AA3: LOGOS | AB3: =VLOOKUP(MID(AD3,SEARCH("@",AD3,1),LEN(AD3)-SEARCH("@",AD3,1)+1),[2]Sheet1!$D:$F,3,FALSE) -> M0318 | AD3: paulyeo@logosproperty.com | AF3: Australia | AG3: AUD | AI3: 1 | AL3: 150 | AM3: 150 | AN3: 150 | AO3: 150 | AP3: 150 | AV3: 150 | BC3: 0 | BJ3: 0 | BQ3: 0 | BX3: 0 | CE3: 0 | CF3: 150 | CG3: 0 | CH3: 0 | CI3: 0 | CJ3: 0 | CK3: 0 | CL3: 150 | CM3: 2 | CS3: 2 | CZ3: 0 | DG3: 0 | DN3: 0 | DU3: 0 | EB3: 0 | EC3: 2 | ED3: 0 | EE3: 0 | EF3: 0 | EG3: 0 | EH3: 0 | EI3: 2 | EJ3: YES | EK3: NO | EL3: NO | EM3: NO | EN3: NO | EO3: NO | EP3: NO | EQ3: NO | ER3: NO | ES3: NO | ET3: NO | EU3: NO | EV3: NO | EW3: NO | EX3: NO | EY3: NO | EZ3: NO | FA3: NO | FB3: NO | FC3: NO | FD3: NO | FE3: NO | FF3: NO | FG3: NO | FH3: NO | FI3: NO | FJ3: NO | FK3: NO | FL3: NO | FM3: NO | FN3: NO | FO3: NO | FP3: NO | FQ3: NO | FR3: NO | FS3: NO | FT3: 100 | FZ3: 100 | GG3: 0 | GN3: 0 | GU3: 0 | HB3: 0 | HI3: 0 | HP3: 0 | HQ3: Financial Institution | HR3: 50 | HX3: 50 | HY3: 150 | HZ3: 0 | IA3: 0 | IB3: 0 | IC3: 0 | ID3: 0 | IE3: 150 | IF3: 150 | IL3: 150 | IS3: 0 | IZ3: 0 | JG3: 0 | JN3: 0 | JO3: 150 | JP3: 0 | JQ3: 0 | JR3: 0 | JS3: 0 | JT3: 0 | JU3: 150 | JX3: 100 | KA3: 1 | KB3: 3 | KC3: 1 | KD3: START Asia Pacific: | OG3: START Europe: | SJ3: START North America: | WM3: START Global: | AAP3: START SOUTH America: | AES3: START Africa:
A4: C9ALB751D | B4: ANREV | C4: Additional Record | P4: FALSE | Q4: TRUE | R4: FALSE | S4: FALSE | T4: FALSE | U4: FALSE | V4: 535 | W4: 43523.355 | X4: 101.78.249.218 | Y4: 2019 | Z4: Kivanch Mehmet | AA4: Charter Hall Group | AB4: =VLOOKUP(MID(AD4,SEARCH("@",AD4,1),LEN(AD4)-SEARCH("@",AD4,1)+1),[2]Sheet1!$D:$F,3,FALSE) -> M03232 | AC4: Head of Wholesale Investor Relations | AD4: Kivanch.Mehmet@charterhall.com.au | AE4: +61 429 362 079 | AF4: Australia | AG4: AUD | AI4: 1 | AL4: 1244 | AM4: 1244 | AN4: 1244 | AO4: 1244 | AP4: 1065 | AS4: 179 | AV4: 1244 | BC4: 0 | BJ4: 0 | BQ4: 0 | BX4: 0 | CE4: 0 | CF4: 1065 | CG4: 0 | CH4: 0 | CI4: 179 | CJ4: 0 | CK4: 0 | CL4: 1244 | CM4: 2 | CP4: 4 | CS4: 6 | CZ4: 0 | DG4: 0 | DN4: 0 | DU4: 0 | EB4: 0 | EC4: 2 | ED4: 0 | EE4: 0 | EF4: 4 | EG4: 0 | EH4: 0 | EI4: 6 | EJ4: YES | EK4: NO | EL4: NO | EM4: YES | EN4: NO | EO4: NO | EP4: NO | EQ4: NO | ER4: NO | ES4: NO | ET4: NO | EU4: NO | EV4: NO | EW4: NO | EX4: NO | EY4: NO | EZ4: NO | FA4: NO | FB4: NO | FC4: NO | FD4: NO | FE4: NO | FF4: NO | FG4: NO | FH4: NO | FI4: NO | FJ4: NO | FK4: NO | FL4: NO | FM4: NO | FN4: NO | FO4: NO | FP4: NO | FQ4: NO | FR4: NO | FS4: NO | FT4: 922 | FW4: 121 | FZ4: 1043 | GA4: 121 | GG4: 121 | GH4: 2 | GK4: 58 | GN4: 60 | GU4: 0 | HB4: 0 | HC4: 20 | HI4: 20 | HP4: 0 | HX4: 0 | HY4: 1065 | HZ4: 0 | IA4: 0 | IB4: 179 | IC4: 0 | ID4: 0 | IE4: 1244 | IF4: 957 | II4: 179 | IL4: 1136 | IM4: 108 | IS4: 108 | IZ4: 0 | JG4: 0 | JN4: 0 | JO4: 1065 | JP4: 0 | JQ4: 0 | JR4: 179 | JS4: 0 | JT4: 0 | JU4: 1244 | JX4: 100 | KA4: 3 | KB4: 3 | KC4: 1 | KD4: START Asia Pacific: | OG4: START Europe: | SJ4: START North America: | WM4: START Global: | AAP4: START SOUTH America: | AES4: START Africa:
A5: C9AQT300Y | B5: INREV | C5: UBS AG | P5: TRUE | Q5: TRUE | R5: TRUE | S5: TRUE | T5: TRUE | U5: FALSE | V5: 642 | W5: 43524.722 | X5: 155.145.208.132 | Y5: 2019 | Z5: Luka Lukic | AA5: UBS Asset Management | AB5: =VLOOKUP(MID(AD5,SEARCH("@",AD5,1),LEN(AD5)-SEARCH("@",AD5,1)+1),[2]Sheet1!$D:$F,3,FALSE) -> M064 | AD5: luka.lukic@ubs.com | AF5: Switzerland | AG5: EUR | AI5: 1 | AL5: 5110.4 | AM5: 5027 | AP5: 17.4 | AQ5: 3.2 | AT5: 66 | AV5: 86.6 | AW5: 363.5 | AX5: 319.4 | BB5: 15.6 | BC5: 698.5 | BD5: 1490.5 | BE5: 516.7 | BF5: 31 | BJ5: 2038.2 | BL5: 106.4 | BM5: 223.8 | BO5: 1845.3 | BQ5: 2175.5 | BW5: 28.4 | BX5: 28.4 | CE5: 0 | CF5: 1871.4 | CG5: 945.7 | CH5: 254.8 | CI5: 0 | CJ5: 1911.3 | CK5: 44 | CL5: 5027.2 | CS5: 0 | CZ5: 0 | DG5: 0 | DN5: 0 | DU5: 0 | EB5: 0 | EC5: 0 | ED5: 0 | EE5: 0 | EF5: 0 | EG5: 0 | EH5: 0 | EI5: 0 | EJ5: YES | EK5: YES | EL5: NO | EM5: NO | EN5: YES | EO5: NO | EP5: YES | EQ5: YES | ER5: NO | ES5: NO | ET5: NO | EU5: YES | EV5: YES | EW5: YES | EX5: YES | EY5: NO | EZ5: NO | FA5: NO | FB5: NO | FC5: YES | FD5: YES | FE5: NO | FF5: YES | FG5: NO | FH5: NO | FI5: NO | FJ5: NO | FK5: NO | FL5: NO | FM5: YES | FN5: NO | FO5: NO | FP5: NO | FQ5: NO | FR5: NO | FS5: NO | FZ5: 0 | GG5: 0 | GN5: 0 | GU5: 0 | HB5: 0 | HI5: 0 | HP5: 0 | HX5: 0 | HY5: 0 | HZ5: 0 | IA5: 0 | IB5: 0 | IC5: 0 | ID5: 0 | IE5: 0 | IL5: 0 | IS5: 0 | IZ5: 0 | JG5: 0 | JN5: 0 | JO5: 0 | JP5: 0 | JQ5: 0 | JR5: 0 | JS5: 0 | JT5: 0 | JU5: 0 | KA5: 1 | KB5: 3 | KC5: 1 | KD5: START Asia Pacific: | OG5: START Europe: | SJ5: START North America: | WM5: START Global: | AAP5: START SOUTH America: | AES5: START Africa:
A6: C9ARC522E | B6: INREV | C6: PlusAlpina Real Estate Advisors GmbH | P6: TRUE | Q6: FALSE | R6: FALSE | S6: FALSE | T6: FALSE | U6: FALSE | V6: 759 | W6: 43524.366 | X6: 94.79.138.90 | Y6: 2019 | Z6: Laura Meindl | AA6: CONREN Land Management GmbH | AB6: =VLOOKUP(MID(AD6,SEARCH("@",AD6,1),LEN(AD6)-SEARCH("@",AD6,1)+1),[2]Sheet1!$D:$F,3,FALSE) -> M690 | AD6: laura.meindl@conrenland.com | AF6: Germany | AG6: EUR | AI6: 1 | AL6: 65 | AM6: 65 | AN6: 16 | AO6: 16 | AV6: 0 | AW6: 65 | BC6: 65 | BJ6: 0 | BQ6: 0 | BX6: 0 | CE6: 0 | CF6: 65 | CG6: 0 | CH6: 0 | CI6: 0 | CJ6: 0 | CK6: 0 | CL6: 65 | CS6: 0 | CT6: 2 | CZ6: 2 | DG6: 0 | DN6: 0 | DU6: 0 | EB6: 0 | EC6: 2 | ED6: 0 | EE6: 0 | EF6: 0 | EG6: 0 | EH6: 0 | EI6: 2 | EJ6: NO | EK6: NO | EL6: NO | EM6: NO | EN6: NO | EO6: NO | EP6: YES | EQ6: NO | ER6: NO | ES6: NO | ET6: NO | EU6: NO | EV6: NO | EW6: NO | EX6: NO | EY6: NO | EZ6: NO | FA6: NO | FB6: NO | FC6: NO | FD6: NO | FE6: NO | FF6: NO | FG6: NO | FH6: NO | FI6: NO | FJ6: NO | FK6: NO | FL6: NO | FM6: NO | FN6: NO | FO6: NO | FP6: NO | FQ6: NO | FR6: NO | FS6: NO | FZ6: 0 | GG6: 0 | GN6: 0 | GU6: 0 | HB6: 0 | HC6: 65 | HI6: 65 | HP6: 0 | HX6: 0 | HY6: 65 | HZ6: 0 | IA6: 0 | IB6: 0 | IC6: 0 | ID6: 0 | IE6: 65 | IL6: 0 | IM6: 65 | IS6: 65 | IZ6: 0 | JG6: 0 | JN6: 0 | JO6: 65 | JP6: 0 | JQ6: 0 | JR6: 0 | JS6: 0 | JT6: 0 | JU6: 65 | JX6: 100 | KA6: 1 | KB6: 3 | KC6: 1 | KD6: START Asia Pacific: | OG6: START Europe: | SJ6: START North America: | WM6: START Global: | AAP6: START SOUTH America: | AES6: START Africa:
A7: C9AWD500U | B7: INREV | C7: Nordika | P7: TRUE | Q7: FALSE | R7: FALSE | S7: FALSE | T7: FALSE | U7: FALSE | V7: 768 | W7: 43516.551 | X7: 95.195.213.146 | Y7: 2019 | Z7: Gabriel Cronstedt | AA7: Nordika Fastigheter | AB7: =VLOOKUP(MID(AD7,SEARCH("@",AD7,1),LEN(AD7)-SEARCH("@",AD7,1)+1),[2]Sheet1!$D:$F,3,FALSE) -> M03188 | AC7: Partner | AD7: gc@nordika.se | AE7: 708870995 | AF7: Sweden | AG7: EUR | AI7: 1 | AL7: 75 | AM7: 75 | AN7: 17 | AO7: 17 | AV7: 0 | AW7: 75 | AX7: 0 | AY7: 0 | AZ7: 0 | BA7: 0 | BB7: 0 | BC7: 75 | BJ7: 0 | BQ7: 0 | BX7: 0 | CE7: 0 | CF7: 75 | CG7: 0 | CH7: 0 | CI7: 0 | CJ7: 0 | CK7: 0 | CL7: 75 | CS7: 0 | CT7: 1 | CZ7: 1 | DG7: 0 | DN7: 0 | DU7: 0 | EB7: 0 | EC7: 1 | ED7: 0 | EE7: 0 | EF7: 0 | EG7: 0 | EH7: 0 | EI7: 1 | EJ7: NO | EK7: NO | EL7: NO | EM7: NO | EN7: NO | EO7: NO | EP7: YES | EQ7: NO | ER7: NO | ES7: NO | ET7: NO | EU7: NO | EV7: NO | EW7: NO | EX7: NO | EY7: NO | EZ7: NO | FA7: NO | FB7: NO | FC7: NO | FD7: NO | FE7: NO | FF7: NO | FG7: NO | FH7: NO | FI7: NO | FJ7: NO | FK7: NO | FL7: NO | FM7: NO | FN7: NO | FO7: NO | FP7: NO | FQ7: NO | FR7: NO | FS7: NO | FT7: 75 | FZ7: 75 | GG7: 0 | GN7: 0 | GU7: 0 | HB7: 0 | HI7: 0 | HP7: 0 | HX7: 0 | HY7: 75 | HZ7: 0 | IA7: 0 | IB7: 0 | IC7: 0 | ID7: 0 | IE7: 75 | IL7: 0 | IM7: 75 | IS7: 75 | IZ7: 0 | JG7: 0 | JN7: 0 | JO7: 75 | JP7: 0 | JQ7: 0 | JR7: 0 | JS7: 0 | JT7: 0 | JU7: 75 | JV7: 0 | JW7: 0 | JX7: 100 | KA7: 1 | KB7: 3 | KC7: 1 | KD7: START Asia Pacific: | OG7: START Europe: | SJ7: START North America: | WM7: START Global: | AAP7: START SOUTH America: | AES7: START Africa:
A8: C9AWJ875T | B8: ANREV | C8: QIC | P8: FALSE | Q8: TRUE | R8: FALSE | S8: FALSE | T8: FALSE | U8: FALSE | V8: 539 | W8: 43517.973 | X8: 165.225.114.92 | Y8: 2019 | Z8: Grant Brady | AA8: QIC | AB8: =VLOOKUP(MID(AD8,SEARCH("@",AD8,1),LEN(AD8)-SEARCH("@",AD8,1)+1),[2]Sheet1!$D:$F,3,FALSE) -> M0350 | AC8: Director – Investment Specialist, Global Real Estate | AD8: g.brady@qic.com | AE8: +61 7 3020 7203 | AF8: Australia | AG8: AUD | AI8: 1 | AL8: 1000 | AM8: 1000 | AN8: 1000 | AO8: 1000 | AP8: 1000 | AV8: 1000 | BC8: 0 | BJ8: 0 | BQ8: 0 | BX8: 0 | CE8: 0 | CF8: 1000 | CG8: 0 | CH8: 0 | CI8: 0 | CJ8: 0 | CK8: 0 | CL8: 1000 | CM8: 2 | CS8: 2 | CZ8: 0 | DG8: 0 | DN8: 0 | DU8: 0 | EB8: 0 | EC8: 2 | ED8: 0 | EE8: 0 | EF8: 0 | EG8: 0 | EH8: 0 | EI8: 2 | EJ8: YES | EK8: NO | EL8: NO | EM8: NO | EN8: NO | EO8: NO | EP8: NO | EQ8: NO | ER8: NO | ES8: NO | ET8: NO | EU8: NO | EV8: NO | EW8: NO | EX8: NO | EY8: NO | EZ8: NO | FA8: NO | FB8: NO | FC8: NO | FD8: NO | FE8: NO | FF8: NO | FG8: NO | FH8: NO | FI8: NO | FJ8: NO | FK8: NO | FL8: NO | FM8: NO | FN8: NO | FO8: NO | FP8: NO | FQ8: NO | FR8: NO | FS8: NO | FT8: 477.3 | FZ8: 477.3 | GG8: 0 | GN8: 0 | GO8: 522.7 | GU8: 522.7 | HB8: 0 | HI8: 0 | HP8: 0 | HX8: 0 | HY8: 1000 | HZ8: 0 | IA8: 0 | IB8: 0 | IC8: 0 | ID8: 0 | IE8: 1000 | IF8: 1000 | IL8: 1000 | IS8: 0 | IZ8: 0 | JG8: 0 | JN8: 0 | JO8: 1000 | JP8: 0 | JQ8: 0 | JR8: 0 | JS8: 0 | JT8: 0 | JU8: 1000 | JX8: 100 | KA8: 1 | KB8: 3 | KC8: 1 | KD8: START Asia Pacific: | OG8: START Europe: | SJ8: START North America: | WM8: START Global: | AAP8: START SOUTH America: | AES8: START Africa:
A9: C9AYY554M | B9: INREV | C9: Steen & Strøm | P9: FALSE | Q9: FALSE | R9: FALSE | S9: FALSE | T9: FALSE | U9: FALSE | V9: 651 | W9: 43490.673 | X9: 213.52.102.35 | Y9: 2019 | Z9: Nils Eivind Risvand | AA9: Steen & Strøm AS | AB9: =VLOOKUP(MID(AD9,SEARCH("@",AD9,1),LEN(AD9)-SEARCH("@",AD9,1)+1),[2]Sheet1!$D:$F,3,FALSE) -> M676 | AC9: Head of Legal | AD9: nils.eivind.risvand@steenstrom.com | AE9: 4793402718 | AF9: Norway | AG9: NOK | AI9: 2 | AJ9: 6 | AK9: No need for capital | AV9: 0 | BC9: 0 | BJ9: 0 | BQ9: 0 | BX9: 0 | CE9: 0 | CF9: 0 | CG9: 0 | CH9: 0 | CI9: 0 | CJ9: 0 | CK9: 0 | CL9: 0 | CS9: 0 | CZ9: 0 | DG9: 0 | DN9: 0 | DU9: 0 | EB9: 0 | EC9: 0 | ED9: 0 | EE9: 0 | EF9: 0 | EG9: 0 | EH9: 0 | EI9: 0 | EJ9: NO | EK9: NO | EL9: NO | EM9: NO | EN9: NO | EO9: NO | EP9: NO | EQ9: NO | ER9: NO | ES9: NO | ET9: NO | EU9: NO | EV9: NO | EW9: NO | EX9: NO | EY9: NO | EZ9: NO | FA9: NO | FB9: NO | FC9: NO | FD9: NO | FE9: NO | FF9: NO | FG9: NO | FH9: NO | FI9: NO | FJ9: NO | FK9: NO | FL9: NO | FM9: NO | FN9: NO | FO9: NO | FP9: NO | FQ9: NO | FR9: NO | FS9: NO | FZ9: 0 | GG9: 0 | GN9: 0 | GU9: 0 | HB9: 0 | HI9: 0 | HP9: 0 | HX9: 0 | HY9: 0 | HZ9: 0 | IA9: 0 | IB9: 0 | IC9: 0 | ID9: 0 | IE9: 0 | IL9: 0 | IS9: 0 | IZ9: 0 | JG9: 0 | JN9: 0 | JO9: 0 | JP9: 0 | JQ9: 0 | JR9: 0 | JS9: 0 | JT9: 0 | JU9: 0 | KA9: 3 | KB9: 3 | KC9: 1 | KD9: START Asia Pacific: | OG9: START Europe: | SJ9: START North America: | WM9: START Global: | AAP9: START SOUTH America: | AES9: START Africa:
A10: C9BVL581A | B10: INREV | C10: Wealthcap Kapitalverwaltungsgesellschaft mbH | P10: TRUE | Q10: FALSE | R10: FALSE | S10: FALSE | T10: FALSE | U10: FALSE | V10: 563 | W10: 43475.475 | X10: 194.145.239.236 | Y10: 2019 | Z10: Sebastian Zehrer | AA10: Wealthcap | AB10: =VLOOKUP(MID(AD10,SEARCH("@",AD10,1),LEN(AD10)-SEARCH("@",AD10,1)+1),[2]Sheet1!$D:$F,3,FALSE) -> M700 | AD10: sebastian.zehrer@wealthcap.com | AF10: Germany | AG10: EUR | AI10: 1 | AL10: 260 | AM10: 0 | AN10: 260 | AO10: 0 | AV10: 0 | AX10: 60 | AY10: 200 | BC10: 260 | BJ10: 0 | BQ10: 0 | BX10: 0 | CE10: 0 | CF10: 0 | CG10: 60 | CH10: 200 | CI10: 0 | CJ10: 0 | CK10: 0 | CL10: 260 | CS10: 0 | CU10: 1 | CV10: 1 | CZ10: 2 | DG10: 0 | DN10: 0 | DU10: 0 | EB10: 0 | EC10: 0 | ED10: 1 | EE10: 1 | EF10: 0 | EG10: 0 | EH10: 0 | EI10: 2 | EJ10: NO | EK10: NO | EL10: NO | EM10: NO | EN10: NO | EO10: NO | EP10: NO | EQ10: YES | ER10: YES | ES10: NO | ET10: NO | EU10: NO | EV10: NO | EW10: NO | EX10: NO | EY10: NO | EZ10: NO | FA10: NO | FB10: NO | FC10: NO | FD10: NO | FE10: NO | FF10: NO | FG10: NO | FH10: NO | FI10: NO | FJ10: NO | FK10: NO | FL10: NO | FM10: NO | FN10: NO | FO10: NO | FP10: NO | FQ10: NO | FR10: NO | FS10: NO | FZ10: 0 | GG10: 0 | GN10: 0 | GU10: 0 | HB10: 0 | HI10: 0 | HP10: 0 | HX10: 0 | HY10: 0 | HZ10: 0 | IA10: 0 | IB10: 0 | IC10: 0 | ID10: 0 | IE10: 0 | IL10: 0 | IN10: 60 | IO10: 200 | IS10: 260 | IZ10: 0 | JG10: 0 | JN10: 0 | JO10: 0 | JP10: 60 | JQ10: 200 | JR10: 0 | JS10: 0 | JT10: 0 | JU10: 260 | JX10: 100 | KA10: 3 | KB10: 3 | KC10: 2 | KD10: START Asia Pacific: | OG10: START Europe: | SJ10: START North America: | WM10: START Global: | AAP10: START SOUTH America: | AES10: START Africa:
A11: C9CAQ433M | B11: INREV | C11: Helaba Invest | D11: Asia | E11: 43517.617 | F11: europe | G11: 43517.617 | P11: TRUE | Q11: TRUE | R11: FALSE | S11: FALSE | T11: FALSE | U11: FALSE | V11: 783 | W11: 43517.617 | X11: 195.191.225.4 | Y11: 2019 | Z11: Tobias Dichtl | AA11: Helaba Invest | AB11: =VLOOKUP(MID(AD11,SEARCH("@",AD11,1),LEN(AD11)-SEARCH("@",AD11,1)+1),[2]Sheet1!$D:$F,3,FALSE) -> M663 | AC11: Portfolio Analyst Research & Strategy | AD11: tobias.dichtl@helaba-invest.de | AE11: 496929970245 | AF11: Germany | AG11: EUR | AI11: 1 | AL11: 2600 | AM11: 2600 | AN11: 1800 | AO11: 1800 | AT11: 200 | AV11: 200 | BA11: 2400 | BC11: 2400 | BJ11: 0 | BQ11: 0 | BX11: 0 | CE11: 0 | CF11: 0 | CG11: 0 | CH11: 0 | CI11: 0 | CJ11: 2600 | CK11: 0 | CL11: 2600 | CQ11: 1 | CS11: 1 | CX11: 9 | CZ11: 9 | DG11: 0 | DN11: 0 | DU11: 0 | EB11: 0 | EC11: 0 | ED11: 0 | EE11: 0 | EF11: 0 | EG11: 10 | EH11: 0 | EI11: 10 | EJ11: NO | EK11: NO | EL11: NO | EM11: NO | EN11: YES | EO11: NO | EP11: NO | EQ11: NO | ER11: NO | ES11: NO | ET11: YES | EU11: NO | EV11: NO | EW11: NO | EX11: NO | EY11: NO | EZ11: NO | FA11: NO | FB11: NO | FC11: NO | FD11: NO | FE11: NO | FF11: NO | FG11: NO | FH11: NO | FI11: NO | FJ11: NO | FK11: NO | FL11: NO | FM11: NO | FN11: NO | FO11: NO | FP11: NO | FQ11: NO | FR11: NO | FS11: NO | FZ11: 0 | GG11: 0 | GN11: 0 | GU11: 0 | HB11: 0 | HI11: 0 | HP11: 0 | HX11: 0 | HY11: 0 | HZ11: 0 | IA11: 0 | IB11: 0 | IC11: 0 | ID11: 0 | IE11: 0 | IL11: 0 | IQ11: 2600 | IS11: 2600 | IZ11: 0 | JG11: 0 | JN11: 0 | JO11: 0 | JP11: 0 | JQ11: 0 | JR11: 0 | JS11: 2600 | JT11: 0 | JU11: 2600 | JV11: 0 | JX11: 100 | KA11: 3 | KB11: 2 | KC11: 1 | KD11: START Asia Pacific: | KI11: 150 | KK11: 150 | KP11: 50 | KR11: 50 | KY11: 0 | LF11: 0 | LM11: 0 | LT11: 0 | MA11: 0 | MI11: 0 | MJ11: 0 | MK11: 0 | ML11: 0 | MM11: 0 | MN11: 200 | MO11: 0 | MP11: 200 | MU11: 200 | MW11: 200 | ND11: 0 | NK11: 0 | NR11: 0 | NY11: 0 | NZ11: 0 | OA11: 0 | OB11: 0 | OC11: 0 | OD11: 200 | OE11: 0 | OF11: 200 | OG11: START Europe: | ON11: 0 | OU11: 0 | PB11: 0 | PI11: 0 | PP11: 0 | PW11: 0 | QD11: 0 | QL11: 0 | QM11: 0 | QN11: 0 | QO11: 0 | QP11: 0 | QQ11: 0 | QR11: 0 | QS11: 0 | QX11: 2400 | QZ11: 2400 | RG11: 0 | RN11: 0 | RU11: 0 | SB11: 0 | SC11: 0 | SD11: 0 | SE11: 0 | SF11: 0 | SG11: 2400 | SH11: 0 | SI11: 2400 | SJ11: START North America: | WM11: START Global: | AAP11: START SOUTH America: | AES11: START Africa:
A12: C9CBD413T | B12: INREV | C12: Frogmore Real Estate Partners Investment Managers Limited | P12: FALSE | Q12: FALSE | R12: FALSE | S12: FALSE | T12: FALSE | U12: FALSE | V12: 745 | W12: 43514.688 | X12: 154.47.76.34 | Y12: 2019 | Z12: Swati | AA12: Frogmore | AB12: =VLOOKUP(MID(AD12,SEARCH("@",AD12,1),LEN(AD12)-SEARCH("@",AD12,1)+1),[2]Sheet1!$D:$F,3,FALSE) -> M490 | AC12: Head of Investor Relations and Client Development | AD12: swatisrivastava@frogmore.co.uk | AF12: United Kingdom | AG12: GBP | AI12: 2 | AJ12: 6 | AK12: We launched our new fourth value add in 2018 | AV12: 0 | BC12: 0 | BJ12: 0 | BQ12: 0 | BX12: 0 | CE12: 0 | CF12: 0 | CG12: 0 | CH12: 0 | CI12: 0 | CJ12: 0 | CK12: 0 | CL12: 0 | CS12: 0 | CZ12: 0 | DG12: 0 | DN12: 0 | DU12: 0 | EB12: 0 | EC12: 0 | ED12: 0 | EE12: 0 | EF12: 0 | EG12: 0 | EH12: 0 | EI12: 0 | EJ12: NO | EK12: NO | EL12: NO | EM12: NO | EN12: NO | EO12: NO | EP12: NO | EQ12: NO | ER12: NO | ES12: NO | ET12: NO | EU12: NO | EV12: NO | EW12: NO | EX12: NO | EY12: NO | EZ12: NO | FA12: NO | FB12: NO | FC12: NO | FD12: NO | FE12: NO | FF12: NO | FG12: NO | FH12: NO | FI12: NO | FJ12: NO | FK12: NO | FL12: NO | FM12: NO | FN12: NO | FO12: NO | FP12: NO | FQ12: NO | FR12: NO | FS12: NO | FZ12: 0 | GG12: 0 | GN12: 0 | GU12: 0 | HB12: 0 | HI12: 0 | HP12: 0 | HX12: 0 | HY12: 0 | HZ12: 0 | IA12: 0 | IB12: 0 | IC12: 0 | ID12: 0 | IE12: 0 | IL12: 0 | IS12: 0 | IZ12: 0 | JG12: 0 | JN12: 0 | JO12: 0 | JP12: 0 | JQ12: 0 | JR12: 0 | JS12: 0 | JT12: 0 | JU12: 0 | KA12: 1 | KB12: 2 | KC12: 1 | KD12: START Asia Pacific: | OG12: START Europe: | SJ12: START North America: | WM12: START Global: | AAP12: START SOUTH America: | AES12: START Africa:
A13: C9CBM470R | B13: INREV | C13: Legal & General Investment Management | P13: TRUE | Q13: FALSE | R13: FALSE | S13: FALSE | T13: FALSE | U13: FALSE | V13: 820 | W13: 43530.766 | X13: 193.200.176.30 | Y13: 2019 | Z13: Savraj Sahota | AA13: Legal & General Investment Management | AB13: =VLOOKUP(MID(AD13,SEARCH("@",AD13,1),LEN(AD13)-SEARCH("@",AD13,1)+1),[2]Sheet1!$D:$F,3,FALSE) -> M465 | AC13: Analyst, Real Assets | AD13: savraj.sahota@lgim.com | AE13: 2031242716 | AF13: United Kingdom | AG13: GBP | AI13: 1 | AL13: 983 | AM13: 829 | AV13: 0 | AW13: 729 | AZ13: 100 | BC13: 829 | BJ13: 0 | BQ13: 0 | BX13: 0 | CE13: 0 | CF13: 729 | CG13: 0 | CH13: 0 | CI13: 100 | CJ13: 0 | CK13: 0 | CL13: 829 | CS13: 0 | CT13: 4 | CW13: 1 | CZ13: 5 | DG13: 0 | DN13: 0 | DU13: 0 | EB13: 0 | EC13: 4 | ED13: 0 | EE13: 0 | EF13: 1 | EG13: 0 | EH13: 0 | EI13: 5 | EJ13: NO | EK13: NO | EL13: NO | EM13: NO | EN13: NO | EO13: NO | EP13: YES | EQ13: NO | ER13: NO | ES13: YES | ET13: NO | EU13: NO | EV13: NO | EW13: NO | EX13: NO | EY13: NO | EZ13: NO | FA13: NO | FB13: NO | FC13: NO | FD13: NO | FE13: NO | FF13: NO | FG13: NO | FH13: NO | FI13: NO | FJ13: NO | FK13: NO | FL13: NO | FM13: NO | FN13: NO | FO13: NO | FP13: NO | FQ13: NO | FR13: NO | FS13: NO | FT13: 652 | FW13: 50 | FZ13: 702 | GD13: 50 | GG13: 50 | GN13: 0 | GU13: 0 | HB13: 0 | HC13: 77 | HI13: 77 | HP13: 0 | HX13: 0 | HY13: 729 | HZ13: 0 | IA13: 0 | IB13: 100 | IC13: 0 | ID13: 0 | IE13: 829 | IL13: 0 | IM13: 729 | IP13: 100 | IS13: 829 | IZ13: 0 | JG13: 0 | JN13: 0 | JO13: 729 | JP13: 0 | JQ13: 0 | JR13: 100 | JS13: 0 | JT13: 0 | JU13: 829 | JX13: 100 | KA13: 3 | KB13: 3 | KC13: 1 | KD13: START Asia Pacific: | OG13: START Europe: | SJ13: START North America: | WM13: START Global: | AAP13: START SOUTH America: | AES13: START Africa:
A14: C9CDF297C | B14: INREV | C14: Grosvenor Europe Limited | F14: europe | G14: 43521.723 | H14: northamerica | I14: 43521.724 | P14: TRUE | Q14: FALSE | R14: TRUE | S14: FALSE | T14: FALSE | U14: FALSE | V14: 581 | W14: 43521.722 | X14: 154.47.76.220 | Y14: 2019 | Z14: James Raynor | AA14: Grosvenor | AB14: =VLOOKUP(MID(AD14,SEARCH("@",AD14,1),LEN(AD14)-SEARCH("@",AD14,1)+1),[2]Sheet1!$D:$F,3,FALSE) -> M052 | AC14: CEO Grosvenor Europe | AD14: james.raynor@grosvenor.com | AF14: United Kingdom | AG14: GBP | AI14: 1 | AL14: 160 | AM14: 160 | AV14: 0 | AZ14: 99 | BC14: 99 | BG14: 61 | BJ14: 61 | BQ14: 0 | BX14: 0 | CE14: 0 | CF14: 0 | CG14: 0 | CH14: 0 | CI14: 160 | CJ14: 0 | CK14: 0 | CL14: 160 | CS14: 0 | CW14: 2 | CZ14: 2 | DD14: 2 | DG14: 2 | DN14: 0 | DU14: 0 | EB14: 0 | EC14: 0 | ED14: 0 | EE14: 0 | EF14: 4 | EG14: 0 | EH14: 0 | EI14: 4 | EJ14: NO | EK14: NO | EL14: NO | EM14: NO | EN14: NO | EO14: NO | EP14: NO | EQ14: NO | ER14: NO | ES14: YES | ET14: NO | EU14: NO | EV14: NO | EW14: NO | EX14: NO | EY14: YES | EZ14: NO | FA14: NO | FB14: NO | FC14: NO | FD14: NO | FE14: NO | FF14: NO | FG14: NO | FH14: NO | FI14: NO | FJ14: NO | FK14: NO | FL14: NO | FM14: NO | FN14: NO | FO14: NO | FP14: NO | FQ14: NO | FR14: NO | FS14: NO | FW14: 15 | FZ14: 15 | GG14: 0 | GN14: 0 | GU14: 0 | HB14: 0 | HI14: 0 | HM14: 145 | HP14: 145 | HX14: 0 | HY14: 0 | HZ14: 0 | IA14: 0 | IB14: 160 | IC14: 0 | ID14: 0 | IE14: 160 | II14: 14 | IL14: 14 | IP14: 85 | IS14: 85 | IW14: 61 | IZ14: 61 | JG14: 0 | JN14: 0 | JO14: 0 | JP14: 0 | JQ14: 0 | JR14: 160 | JS14: 0 | JT14: 0 | JU14: 160 | JX14: 100 | KA14: 1 | KB14: 2 | KC14: 1 | KD14: START Asia Pacific: | OG14: START Europe: | ON14: 0 | OU14: 0 | PB14: 0 | PI14: 0 | PP14: 0 | PW14: 0 | QA14: 99 | QD14: 99 | QL14: 0 | QM14: 0 | QN14: 0 | QO14: 0 | QP14: 99 | QQ14: 0 | QR14: 0 | QS14: 99 | QW14: 85 | QZ14: 85 | RD14: 14 | RG14: 14 | RN14: 0 | RU14: 0 | SB14: 0 | SC14: 0 | SD14: 0 | SE14: 0 | SF14: 99 | SG14: 0 | SH14: 0 | SI14: 99 | SJ14: START North America: | SQ14: 0 | SX14: 0 | TE14: 0 | TL14: 0 | TS14: 0 | TZ14: 0 | UD14: 61 | UG14: 61 | UO14: 0 | UP14: 0 | UQ14: 0 | UR14: 0 | US14: 61 | UT14: 0 | UU14: 0 | UV14: 61 | VC14: 0 | VJ14: 0 | VN14: 61 | VQ14: 61 | VX14: 0 | WE14: 0 | WF14: 0 | WG14: 0 | WH14: 0 | WI14: 61 | WJ14: 0 | WK14: 0 | WL14: 61 | WM14: START Global: | AAP14: START SOUTH America: | AES14: START Africa:
A15: C9CDX506B | B15: INREV | C15: OP Real Estate Asset Management Ltd | P15: TRUE | Q15: FALSE | R15: FALSE | S15: FALSE | T15: FALSE | U15: FALSE | V15: 756 | W15: 43515.469 | X15: 157.124.30.3 | Y15: 2019 | Z15: Pami Pihlström | AA15: OP Real Estate Asset Management | AB15: =VLOOKUP(MID(AD15,SEARCH("@",AD15,1),LEN(AD15)-SEARCH("@",AD15,1)+1),[2]Sheet1!$D:$F,3,FALSE) -> M122 | AC15: CIO | AD15: pami.pihlstrom@op.fi | AE15: +358 10 | AF15: Finland | AG15: EUR | AI15: 1 | AL15: 303 | AM15: 303 | AN15: 250 | AO15: 250 | AV15: 0 | AW15: 293 | BA15: 10 | BC15: 303 | BJ15: 0 | BQ15: 0 | BX15: 0 | CE15: 0 | CF15: 293 | CG15: 0 | CH15: 0 | CI15: 0 | CJ15: 10 | CK15: 0 | CL15: 303 | CS15: 0 | CT15: 5 | CX15: 1 | CZ15: 6 | DG15: 0 | DN15: 0 | DU15: 0 | EB15: 0 | EC15: 5 | ED15: 0 | EE15: 0 | EF15: 0 | EG15: 1 | EH15: 0 | EI15: 6 | EJ15: NO | EK15: NO | EL15: NO | EM15: NO | EN15: NO | EO15: NO | EP15: YES | EQ15: NO | ER15: NO | ES15: NO | ET15: YES | EU15: NO | EV15: NO | EW15: NO | EX15: NO | EY15: NO | EZ15: NO | FA15: NO | FB15: NO | FC15: NO | FD15: NO | FE15: NO | FF15: NO | FG15: NO | FH15: NO | FI15: NO | FJ15: NO | FK15: NO | FL15: NO | FM15: NO | FN15: NO | FO15: NO | FP15: NO | FQ15: NO | FR15: NO | FS15: NO | FT15: 5 | FZ15: 5 | GA15: 6 | GE15: 5 | GG15: 11 | GN15: 0 | GU15: 0 | GV15: 5 | GZ15: 5 | HB15: 10 | HI15: 0 | HJ15: 277 | HP15: 277 | HX15: 0 | HY15: 293 | HZ15: 0 | IA15: 0 | IB15: 0 | IC15: 10 | ID15: 0 | IE15: 303 | IL15: 0 | IM15: 293 | IQ15: 10 | IS15: 303 | IZ15: 0 | JG15: 0 | JN15: 0 | JO15: 293 | JP15: 0 | JQ15: 0 | JR15: 0 | JS15: 10 | JT15: 0 | JU15: 303 | JX15: 100 | KA15: 3 | KB15: 3 | KC15: 1 | KD15: START Asia Pacific: | OG15: START Europe: | SJ15: START North America: | WM15: START Global: | AAP15: START SOUTH America: | AES15: START Africa:
A16: C9CDZ380J | B16: INREV | C16: Delancey Real Estate Asset Management | P16: TRUE | Q16: FALSE | R16: FALSE | S16: FALSE | T16: FALSE | U16: FALSE | V16: 625 | W16: 43520.65 | X16: 154.47.76.16 | Y16: 2019 | Z16: Eric Lemer | AA16: Delancey Real Estate Asset Management | AB16: =VLOOKUP(MID(AD16,SEARCH("@",AD16,1),LEN(AD16)-SEARCH("@",AD16,1)+1),[2]Sheet1!$D:$F,3,FALSE) -> M2715 | AC16: Director, Business Development | AD16: eric.lemer@delancey.com | AE16: =44-797-122-6842 -> -7717 | AF16: United Kingdom | AG16: GBP | AI16: 1 | AL16: 150 | AM16: 150 | AN16: 150 | AO16: 150 | AV16: 0 | AW16: 150 | BC16: 150 | BJ16: 0 | BQ16: 0 | BX16: 0 | CE16: 0 | CF16: 150 | CG16: 0 | CH16: 0 | CI16: 0 | CJ16: 0 | CK16: 0 | CL16: 150 | CS16: 0 | CT16: 1 | CZ16: 1 | DG16: 0 | DN16: 0 | DU16: 0 | EB16: 0 | EC16: 1 | ED16: 0 | EE16: 0 | EF16: 0 | EG16: 0 | EH16: 0 | EI16: 1 | EJ16: NO | EK16: NO | EL16: NO | EM16: NO | EN16: NO | EO16: NO | EP16: YES | EQ16: NO | ER16: NO | ES16: NO | ET16: NO | EU16: NO | EV16: NO | EW16: NO | EX16: NO | EY16: NO | EZ16: NO | FA16: NO | FB16: NO | FC16: NO | FD16: NO | FE16: NO | FF16: NO | FG16: NO | FH16: NO | FI16: NO | FJ16: NO | FK16: NO | FL16: NO | FM16: NO | FN16: NO | FO16: NO | FP16: NO | FQ16: NO | FR16: NO | FS16: NO | FT16: 40 | FZ16: 40 | GG16: 0 | GN16: 0 | GU16: 0 | HB16: 0 | HC16: 80 | HI16: 80 | HJ16: 30 | HP16: 30 | HX16: 0 | HY16: 150 | HZ16: 0 | IA16: 0 | IB16: 0 | IC16: 0 | ID16: 0 | IE16: 150 | IL16: 0 | IM16: 138 | IS16: 138 | IT16: 12 | IZ16: 12 | JG16: 0 | JN16: 0 | JO16: 150 | JP16: 0 | JQ16: 0 | JR16: 0 | JS16: 0 | JT16: 0 | JU16: 150 | JX16: 100 | KA16: 1 | KB16: 2 | KC16: 2 | KD16: START Asia Pacific: | OG16: START Europe: | SJ16: START North America: | WM16: START Global: | AAP16: START SOUTH America: | AES16: START Africa:
A17: C9CFW373W | B17: INREV | C17: Cording Real Estate Group Limited | P17: TRUE | Q17: FALSE | R17: FALSE | S17: FALSE | T17: FALSE | U17: FALSE | V17: 735 | W17: 43517.352 | X17: 195.243.133.82 | Y17: 2019 | Z17: Naomi Vlakancic | AA17: Cording Real Estate Group | AB17: =VLOOKUP(MID(AD17,SEARCH("@",AD17,1),LEN(AD17)-SEARCH("@",AD17,1)+1),[2]Sheet1!$D:$F,3,FALSE) -> M506 | AC17: Head of Investor Relations | AD17: naomi.vlakancic@cordinggroup.com | AE17: +44 (0)20 3206 7911 | AF17: United Kingdom | AG17: EUR | AI17: 1 | AL17: 328 | AM17: 328 | AN17: 268 | AO17: 268 | AV17: 0 | AW17: 202 | AX17: 126 | BC17: 328 | BJ17: 0 | BQ17: 0 | BX17: 0 | CE17: 0 | CF17: 202 | CG17: 126 | CH17: 0 | CI17: 0 | CJ17: 0 | CK17: 0 | CL17: 328 | CS17: 0 | CT17: 4 | CU17: 3 | CZ17: 7 | DG17: 0 | DN17: 0 | DU17: 0 | EB17: 0 | EC17: 4 | ED17: 3 | EE17: 0 | EF17: 0 | EG17: 0 | EH17: 0 | EI17: 7 | EJ17: NO | EK17: NO | EL17: NO | EM17: NO | EN17: NO | EO17: NO | EP17: YES | EQ17: YES | ER17: NO | ES17: NO | ET17: NO | EU17: NO | EV17: NO | EW17: NO | EX17: NO | EY17: NO | EZ17: NO | FA17: NO | FB17: NO | FC17: NO | FD17: NO | FE17: NO | FF17: NO | FG17: NO | FH17: NO | FI17: NO | FJ17: NO | FK17: NO | FL17: NO | FM17: NO | FN17: NO | FO17: NO | FP17: NO | FQ17: NO | FR17: NO | FS17: NO | FT17: 54 | FU17: 36 | FZ17: 90 | GG17: 0 | GN17: 0 | GU17: 0 | HB17: 0 | HC17: 147 | HI17: 147 | HJ17: 91 | HP17: 91 | HX17: 0 | HY17: 292 | HZ17: 36 | IA17: 0 | IB17: 0 | IC17: 0 | ID17: 0 | IE17: 328 | IL17: 0 | IM17: 292 | IN17: 36 | IS17: 328 | IZ17: 0 | JG17: 0 | JN17: 0 | JO17: 292 | JP17: 36 | JQ17: 0 | JR17: 0 | JS17: 0 | JT17: 0 | JU17: 328 | JX17: 100 | KA17: 1 | KB17: 2 | KC17: 1 | KD17: START Asia Pacific: | OG17: START Europe: | SJ17: START North America: | WM17: START Global: | AAP17: START SOUTH America: | AES17: START Africa:
A18: C9CGC870P | B18: ANREV | C18: Pamfleet | P18: FALSE | Q18: TRUE | R18: FALSE | S18: FALSE | T18: FALSE | U18: FALSE | V18: 712 | W18: 43509.165 | X18: 118.200.5.237 | Y18: 2019 | Z18: YC Tang | AA18: Pamfleet | AB18: =VLOOKUP(MID(AD18,SEARCH("@",AD18,1),LEN(AD18)-SEARCH("@",AD18,1)+1),[2]Sheet1!$D:$F,3,FALSE) -> M0125 | AC18: Head of Investor Relations | AD18: yc.tang@pamfleet.com | AE18: 65 6325 0160 | AF18: Hong Kong | AG18: USD | AI18: 1 | AL18: 420 | AM18: 420 | AN18: 0 | AO18: 0 | AP18: 420 | AV18: 420 | BC18: 0 | BJ18: 0 | BQ18: 0 | BX18: 0 | CE18: 0 | CF18: 420 | CG18: 0 | CH18: 0 | CI18: 0 | CJ18: 0 | CK18: 0 | CL18: 420 | CM18: 1 | CS18: 1 | CZ18: 0 | DG18: 0 | DN18: 0 | DU18: 0 | EB18: 0 | EC18: 1 | ED18: 0 | EE18: 0 | EF18: 0 | EG18: 0 | EH18: 0 | EI18: 1 | EJ18: YES | EK18: NO | EL18: NO | EM18: NO | EN18: NO | EO18: NO | EP18: NO | EQ18: NO | ER18: NO | ES18: NO | ET18: NO | EU18: NO | EV18: NO | EW18: NO | EX18: NO | EY18: NO | EZ18: NO | FA18: NO | FB18: NO | FC18: NO | FD18: NO | FE18: NO | FF18: NO | FG18: NO | FH18: NO | FI18: NO | FJ18: NO | FK18: NO | FL18: NO | FM18: NO | FN18: NO | FO18: NO | FP18: NO | FQ18: NO | FR18: NO | FS18: NO | FT18: 150 | FZ18: 150 | GA18: 35 | GG18: 35 | GN18: 0 | GU18: 0 | GV18: 50 | HB18: 50 | HC18: 165 | HI18: 165 | HJ18: 13 | HP18: 13 | HQ18: GP coinvestment | HR18: 7 | HX18: 7 | HY18: 420 | HZ18: 0 | IA18: 0 | IB18: 0 | IC18: 0 | ID18: 0 | IE18: 420 | IF18: 107 | IL18: 107 | IM18: 178 | IS18: 178 | IT18: 135 | IZ18: 135 | JG18: 0 | JN18: 0 | JO18: 420 | JP18: 0 | JQ18: 0 | JR18: 0 | JS18: 0 | JT18: 0 | JU18: 420 | JV18: 19 | JX18: 79 | JY18: GP coinvestment | JZ18: 2 | KA18: 1 | KB18: 2 | KC18: 1 | KD18: START Asia Pacific: | OG18: START Europe: | SJ18: START North America: | WM18: START Global: | AAP18: START SOUTH America: | AES18: START Africa:
A19: C9CJR360D | B19: ANREV | C19: CITIC Capital Holdings Limited | P19: FALSE | Q19: TRUE | R19: FALSE | S19: FALSE | T19: FALSE | U19: FALSE | V19: 635 | W19: 43508.421 | X19: 61.244.118.81 | Y19: 2019 | Z19: Kash Lam | AA19: CITIC Capital | AB19: =VLOOKUP(MID(AD19,SEARCH("@",AD19,1),LEN(AD19)-SEARCH("@",AD19,1)+1),[2]Sheet1!$D:$F,3,FALSE) -> M0107 | AC19: Vice President | AD19: kashlam@citiccapital.com | AE19: 3710 6952 | AF19: Hong Kong | AG19: CNY | AI19: 1 | AL19: 420 | AM19: 420 | AN19: 340 | AO19: 340 | AP19: 420 | AV19: 420 | BC19: 0 | BJ19: 0 | BQ19: 0 | BX19: 0 | CE19: 0 | CF19: 420 | CG19: 0 | CH19: 0 | CI19: 0 | CJ19: 0 | CK19: 0 | CL19: 420 | CM19: 2 | CS19: 2 | CZ19: 0 | DG19: 0 | DN19: 0 | DU19: 0 | EB19: 0 | EC19: 2 | ED19: 0 | EE19: 0 | EF19: 0 | EG19: 0 | EH19: 0 | EI19: 2 | EJ19: YES | EK19: NO | EL19: NO | EM19: NO | EN19: NO | EO19: NO | EP19: NO | EQ19: NO | ER19: NO | ES19: NO | ET19: NO | EU19: NO | EV19: NO | EW19: NO | EX19: NO | EY19: NO | EZ19: NO | FA19: NO | FB19: NO | FC19: NO | FD19: NO | FE19: NO | FF19: NO | FG19: NO | FH19: NO | FI19: NO | FJ19: NO | FK19: NO | FL19: NO | FM19: NO | FN19: NO | FO19: NO | FP19: NO | FQ19: NO | FR19: NO | FS19: NO | FT19: 420 | FZ19: 420 | GG19: 0 | GN19: 0 | GU19: 0 | HB19: 0 | HI19: 0 | HP19: 0 | HX19: 0 | HY19: 420 | HZ19: 0 | IA19: 0 | IB19: 0 | IC19: 0 | ID19: 0 | IE19: 420 | IF19: 420 | IL19: 420 | IS19: 0 | IZ19: 0 | JG19: 0 | JN19: 0 | JO19: 420 | JP19: 0 | JQ19: 0 | JR19: 0 | JS19: 0 | JT19: 0 | JU19: 420 | JX19: 100 | KA19: 3 | KB19: 3 | KC19: 1 | KD19: START Asia Pacific: | OG19: START Europe: | SJ19: START North America: | WM19: START Global: | AAP19: START SOUTH America: | AES19: START Africa:
A20: C9CRE548M | B20: INREV | C20: Sirius Capital Partners | P20: TRUE | Q20: FALSE | R20: FALSE | S20: FALSE | T20: FALSE | U20: FALSE | V20: 592 | W20: 43508.549 | X20: 194.111.75.232 | Y20: 2019 | Z20: Nina Cainberg | AA20: Sirius Capital Partners | AB20: =VLOOKUP(MID(AD20,SEARCH("@",AD20,1),LEN(AD20)-SEARCH("@",AD20,1)+1),[2]Sheet1!$D:$F,3,FALSE) -> M757 | AD20: nina.cainberg@sirius.fi | AF20: Finland | AG20: EUR | AI20: 1 | AL20: 35 | AM20: 35 | AN20: 30 | AO20: 30 | AV20: 0 | AW20: 35 | BC20: 35 | BJ20: 0 | BQ20: 0 | BX20: 0 | CE20: 0 | CF20: 35 | CG20: 0 | CH20: 0 | CI20: 0 | CJ20: 0 | CK20: 0 | CL20: 35 | CS20: 0 | CT20: 1 | CZ20: 1 | DG20: 0 | DN20: 0 | DU20: 0 | EB20: 0 | EC20: 1 | ED20: 0 | EE20: 0 | EF20: 0 | EG20: 0 | EH20: 0 | EI20: 1 | EJ20: NO | EK20: NO | EL20: NO | EM20: NO | EN20: NO | EO20: NO | EP20: YES | EQ20: NO | ER20: NO | ES20: NO | ET20: NO | EU20: NO | EV20: NO | EW20: NO | EX20: NO | EY20: NO | EZ20: NO | FA20: NO | FB20: NO | FC20: NO | FD20: NO | FE20: NO | FF20: NO | FG20: NO | FH20: NO | FI20: NO | FJ20: NO | FK20: NO | FL20: NO | FM20: NO | FN20: NO | FO20: NO | FP20: NO | FQ20: NO | FR20: NO | FS20: NO | FT20: 25 | FZ20: 25 | GG20: 0 | GN20: 0 | GU20: 0 | HB20: 0 | HC20: 5 | HI20: 5 | HJ20: 5 | HP20: 5 | HX20: 0 | HY20: 35 | HZ20: 0 | IA20: 0 | IB20: 0 | IC20: 0 | ID20: 0 | IE20: 35 | IL20: 0 | IM20: 35 | IS20: 35 | IZ20: 0 | JG20: 0 | JN20: 0 | JO20: 35 | JP20: 0 | JQ20: 0 | JR20: 0 | JS20: 0 | JT20: 0 | JU20: 35 | JX20: 100 | KA20: 3 | KB20: 3 | KC20: 1 | KD20: START Asia Pacific: | OG20: START Europe: | SJ20: START North America: | WM20: START Global: | AAP20: START SOUTH America: | AES20: START Africa:
A21: C9CWV526T | B21: INREV | C21: PROJECT Investment AG | P21: FALSE | Q21: FALSE | R21: FALSE | S21: FALSE | T21: FALSE | U21: FALSE | V21: 741 | W21: 43515.463 | X21: 37.60.5.66 | Y21: 2019 | Z21: Uwira Jürgen | AA21: PROJECT Investment AG | AB21: =VLOOKUP(MID(AD21,SEARCH("@",AD21,1),LEN(AD21)-SEARCH("@",AD21,1)+1),[2]Sheet1!$D:$F,3,FALSE) -> M680 | AC21: Managing Director PROJECT Real Estate Trust | AD21: j.uwira@project-investment.de | AE21: 0049 89 599890861 | AF21: Germany | AG21: EUR | AI21: 2 | AJ21: 6 | AK21: Open commitments, to avoid conflicts of interest start of next AIF in 2019 | AV21: 0 | BC21: 0 | BJ21: 0 | BQ21: 0 | BX21: 0 | CE21: 0 | CF21: 0 | CG21: 0 | CH21: 0 | CI21: 0 | CJ21: 0 | CK21: 0 | CL21: 0 | CS21: 0 | CZ21: 0 | DG21: 0 | DN21: 0 | DU21: 0 | EB21: 0 | EC21: 0 | ED21: 0 | EE21: 0 | EF21: 0 | EG21: 0 | EH21: 0 | EI21: 0 | EJ21: NO | EK21: NO | EL21: NO | EM21: NO | EN21: NO | EO21: NO | EP21: NO | EQ21: NO | ER21: NO | ES21: NO | ET21: NO | EU21: NO | EV21: NO | EW21: NO | EX21: NO | EY21: NO | EZ21: NO | FA21: NO | FB21: NO | FC21: NO | FD21: NO | FE21: NO | FF21: NO | FG21: NO | FH21: NO | FI21: NO | FJ21: NO | FK21: NO | FL21: NO | FM21: NO | FN21: NO | FO21: NO | FP21: NO | FQ21: NO | FR21: NO | FS21: NO | FZ21: 0 | GG21: 0 | GN21: 0 | GU21: 0 | HB21: 0 | HI21: 0 | HP21: 0 | HX21: 0 | HY21: 0 | HZ21: 0 | IA21: 0 | IB21: 0 | IC21: 0 | ID21: 0 | IE21: 0 | IL21: 0 | IS21: 0 | IZ21: 0 | JG21: 0 | JN21: 0 | JO21: 0 | JP21: 0 | JQ21: 0 | JR21: 0 | JS21: 0 | JT21: 0 | JU21: 0 | KA21: 1 | KB21: 2 | KC21: 1 | KD21: START Asia Pacific: | OG21: START Europe: | SJ21: START North America: | WM21: START Global: | AAP21: START SOUTH America: | AES21: START Africa:
A22: C9CYV634C | B22: NCREIF | C22: Equus Capital Partners | P22: FALSE | Q22: FALSE | R22: TRUE | S22: FALSE | T22: FALSE | U22: FALSE | V22: 600 | W22: 43481.849 | X22: 204.237.132.2 | Y22: 2019 | Z22: Joseph G Nahas, Jr CRE | AA22: Equus Capital Partners, Ltd. | AB22: =VLOOKUP(MID(AD22,SEARCH("@",AD22,1),LEN(AD22)-SEARCH("@",AD22,1)+1),[2]Sheet1!$D:$F,3,FALSE) -> NC017 | AC22: Sr. Vice President | AD22: jnahas@equuspartners.com | AE22: 215-575-2363 | AF22: United States | AG22: USD | AI22: 1 | AL22: 710 | AM22: 710 | AN22: 561 | AO22: 561 | AV22: 0 | BC22: 0 | BD22: 237 | BE22: 473 | BJ22: 710 | BQ22: 0 | BX22: 0 | CE22: 0 | CF22: 237 | CG22: 473 | CH22: 0 | CI22: 0 | CJ22: 0 | CK22: 0 | CL22: 710 | CS22: 0 | CZ22: 0 | DA22: 1 | DB22: 2 | DG22: 3 | DN22: 0 | DU22: 0 | EB22: 0 | EC22: 1 | ED22: 2 | EE22: 0 | EF22: 0 | EG22: 0 | EH22: 0 | EI22: 3 | EJ22: NO | EK22: NO | EL22: NO | EM22: NO | EN22: NO | EO22: NO | EP22: NO | EQ22: NO | ER22: NO | ES22: NO | ET22: NO | EU22: NO | EV22: YES | EW22: YES | EX22: NO | EY22: NO | EZ22: NO | FA22: NO | FB22: NO | FC22: NO | FD22: NO | FE22: NO | FF22: NO | FG22: NO | FH22: NO | FI22: NO | FJ22: NO | FK22: NO | FL22: NO | FM22: NO | FN22: NO | FO22: NO | FP22: NO | FQ22: NO | FR22: NO | FS22: NO | FT22: 191 | FZ22: 191 | GG22: 0 | GN22: 0 | GU22: 0 | GV22: 26 | HB22: 26 | HD22: 473 | HI22: 473 | HJ22: 20 | HP22: 20 | HX22: 0 | HY22: 237 | HZ22: 473 | IA22: 0 | IB22: 0 | IC22: 0 | ID22: 0 | IE22: 710 | IL22: 0 | IS22: 0 | IT22: 237 | IU22: 473 | IZ22: 710 | JG22: 0 | JN22: 0 | JO22: 237 | JP22: 473 | JQ22: 0 | JR22: 0 | JS22: 0 | JT22: 0 | JU22: 710 | JV22: 0 | JX22: 100 | KA22: 2 | KB22: 3 | KC22: 2 | KD22: START Asia Pacific: | OG22: START Europe: | SJ22: START North America: | WM22: START Global: | AAP22: START SOUTH America: | AES22: START Africa:
A23: C9CZY636N | B23: NCREIF | C23: Farmland Opportunity | LLC | P23: FALSE | Q23: FALSE | R23: FALSE | S23: FALSE | T23: FALSE | U23: FALSE | V23: 609 | W23: 43482.051 | X23: 174.216.26.60 | Y23: 2019 | Z23: Jay Girotto | AA23: Farmland Opportunity, LLC | AB23: =VLOOKUP(MID(AD23,SEARCH("@",AD23,1),LEN(AD23)-SEARCH("@",AD23,1)+1),[2]Sheet1!$D:$F,3,FALSE) -> NC001 | AC23: President | AD23: jgirotto@farmopp.com | AE23: 4253010728 | AF23: United States | AG23: USD | AI23: 2 | AJ23: 6 | AK23: High net worth, single family offices only | AV23: 0 | BC23: 0 | BJ23: 0 | BQ23: 0 | BX23: 0 | CE23: 0 | CF23: 0 | CG23: 0 | CH23: 0 | CI23: 0 | CJ23: 0 | CK23: 0 | CL23: 0 | CS23: 0 | CZ23: 0 | DG23: 0 | DN23: 0 | DU23: 0 | EB23: 0 | EC23: 0 | ED23: 0 | EE23: 0 | EF23: 0 | EG23: 0 | EH23: 0 | EI23: 0 | EJ23: NO | EK23: NO | EL23: NO | EM23: NO | EN23: NO | EO23: NO | EP23: NO | EQ23: NO | ER23: NO | ES23: NO | ET23: NO | EU23: NO | EV23: NO | EW23: NO | EX23: NO | EY23: NO | EZ23: NO | FA23: NO | FB23: NO | FC23: NO | FD23: NO | FE23: NO | FF23: NO | FG23: NO | FH23: NO | FI23: NO | FJ23: NO | FK23: NO | FL23: NO | FM23: NO | FN23: NO | FO23: NO | FP23: NO | FQ23: NO | FR23: NO | FS23: NO | FZ23: 0 | GG23: 0 | GN23: 0 | GU23: 0 | HB23: 0 | HI23: 0 | HP23: 0 | HX23: 0 | HY23: 0 | HZ23: 0 | IA23: 0 | IB23: 0 | IC23: 0 | ID23: 0 | IE23: 0 | IL23: 0 | IS23: 0 | IZ23: 0 | JG23: 0 | JN23: 0 | JO23: 0 | JP23: 0 | JQ23: 0 | JR23: 0 | JS23: 0 | JT23: 0 | JU23: 0 | KA23: 1 | KB23: 3 | KC23: 1 | KD23: START Asia Pacific: | OG23: START Europe: | SJ23: START North America: | WM23: START Global: | AAP23: START SOUTH America: | AES23: START Africa:
