Workbook
Name RMITeam: [1]ContactDetails!$B$9:$B$13

Sheet DataCompleted
A1: Surveycode | B1: Association | C1: Company | D1: FullName | E1: EmailAddress | F1: SampleNote | G1: SurveyURL | H1: REGION1 | I1: DateCompleted1 | J1: REGION2 | K1: DateCompleted2 | L1: REGION3 | M1: DateCompleted3 | N1: REGION4 | O1: DateCompleted4 | P1: REGION5 | Q1: DateCompleted5 | R1: REGION6 | S1: DateCompleted6 | T1: ShowEurope | U1: ShowAsia | V1: ShowNA | W1: ShowGlobal | X1: ShowSA | Y1: ShowAfrica | Z1: RecordNo | AA1: DateCompleted | AB1: IPaddress | AC1: Version | AD1: qName | AE1: qCompany | AF1: mnumber | AG1: qJobtitle | AH1: qEmail | AI1: qTelephone | AJ1: qCountry | AK1: qCurrency | AL1: qCurrencyOther | AM1: q1 | AN1: q2 | AO1: q2other | AP1: q31_1 | AQ1: q31_2 | AR1: q31_3 | AS1: q31_4 | AT1: q31_5 | AU1: q31_6 | AV1: q3ROW1_hidden | AW1: q32_1 | AX1: q32_2 | AY1: q32_3 | AZ1: q32_4 | BA1: q32_5 | BB1: q32_6 | BC1: q3ROW2_hidden | BD1: q33_1 | BE1: q33_2 | BF1: q33_3 | BG1: q33_4 | BH1: q33_5 | BI1: q33_6 | BJ1: q3ROW3_hidden | BK1: q34_1 | BL1: q34_2 | BM1: q34_3 | BN1: q34_4 | BO1: q34_5 | BP1: q34_6 | BQ1: q3ROW4_hidden | BR1: q35_1 | BS1: q35_2 | BT1: q35_3 | BU1: q35_4 | BV1: q35_5 | BW1: q35_6 | BX1: q3ROW5_hidden | BY1: q36_1 | BZ1: q36_2 | CA1: q36_3 | CB1: q36_4 | CC1: q36_5 | CD1: q36_6 | CE1: q3ROW6_hidden | CF1: q3COL1_hidden | CG1: q3COL2_hidden | CH1: q3COL3_hidden | CI1: q3COL4_hidden | CJ1: q3COL5_hidden | CK1: q3COL6_hidden | CL1: q3GRANDTotal_hidden | CM1: q41_1 | CN1: q41_2 | CO1: q41_3 | CP1: q41_4 | CQ1: q41_5 | CR1: q41_6 | CS1: q4ROW1_hidden | CT1: q42_1 | CU1: q42_2 | CV1: q42_3 | CW1: q42_4 | CX1: q42_5 | CY1: q42_6 | CZ1: q4ROW2_hidden | DA1: q43_1 | DB1: q43_2 | DC1: q43_3 | DD1: q43_4 | DE1: q43_5 | DF1: q43_6 | DG1: q4ROW3_hidden | DH1: q44_1 | DI1: q44_2 | DJ1: q44_3 | DK1: q44_4 | DL1: q44_5 | DM1: q44_6 | DN1: q4ROW4_hidden | DO1: q45_1 | DP1: q45_2 | DQ1: q45_3 | DR1: q45_4 | DS1: q45_5 | DT1: q45_6 | DU1: q4ROW5_hidden | DV1: q46_1 | DW1: q46_2 | DX1: q46_3 | DY1: q46_4 | DZ1: q46_5 | EA1: q46_6 | EB1: q4ROW6_hidden | EC1: q4COL1_hidden | ED1: q4COL2_hidden | EE1: q4COL3_hidden | EF1: q4COL4_hidden | EG1: q4COL5_hidden | EH1: q4COL6_hidden | EI1: q4GRANDTotal_hidden | EJ1: Alert41_1 | EK1: Alert41_2 | EL1: Alert41_3 | EM1: Alert41_4 | EN1: Alert41_5 | EO1: Alert41_6 | EP1: Alert42_1 | EQ1: Alert42_2 | ER1: Alert42_3 | ES1: Alert42_4 | ET1: Alert42_5 | EU1: Alert42_6 | EV1: Alert43_1 | EW1: Alert43_2 | EX1: Alert43_3 | EY1: Alert43_4 | EZ1: Alert43_5 | FA1: Alert43_6 | FB1: Alert44_1 | FC1: Alert44_2 | FD1: Alert44_3 | FE1: Alert44_4 | FF1: Alert44_5 | FG1: Alert44_6 | FH1: Alert45_1 | FI1: Alert45_2 | FJ1: Alert45_3 | FK1: Alert45_4 | FL1: Alert45_5 | FM1: Alert45_6 | FN1: Alert46_1 | FO1: Alert46_2 | FP1: Alert46_3 | FQ1: Alert46_4 | FR1: Alert46_5 | FS1: Alert46_6 | FT1: q51_1 | FU1: q51_2 | FV1: q51_3 | FW1: q51_4 | FX1: q51_5 | FY1: q51_6 | FZ1: q5ROW1_hidden | GA1: q52_1 | GB1: q52_2 | GC1: q52_3 | GD1: q52_4 | GE1: q52_5 | GF1: q52_6 | GG1: q5ROW2_hidden | GH1: q53_1 | GI1: q53_2 | GJ1: q53_3 | GK1: q53_4 | GL1: q53_5 | GM1: q53_6 | GN1: q5ROW3_hidden | GO1: q54_1 | GP1: q54_2 | GQ1: q54_3 | GR1: q54_4 | GS1: q54_5 | GT1: q54_6 | GU1: q5ROW4_hidden | GV1: q55_1 | GW1: q55_2 | GX1: q55_3 | GY1: q55_4 | GZ1: q55_5 | HA1: q55_6 | HB1: q5ROW5_hidden | HC1: q56_1 | HD1: q56_2 | HE1: q56_3 | HF1: q56_4 | HG1: q56_5 | HH1: q56_6 | HI1: q5ROW6_hidden | HJ1: q57_1 | HK1: q57_2 | HL1: q57_3 | HM1: q57_4 | HN1: q57_5 | HO1: q57_6 | HP1: q5ROW7_hidden | HQ1: q5other | HR1: q58_1 | HS1: q58_2 | HT1: q58_3 | HU1: q58_4 | HV1: q58_5 | HW1: q58_6 | HX1: q5ROW8_hidden | HY1: q5COL1_hidden | HZ1: q5COL2_hidden | IA1: q5COL3_hidden | IB1: q5COL4_hidden | IC1: q5COL5_hidden | ID1: q5COL6_hidden | IE1: q5GRANDTotal_hidden | IF1: q61_1 | IG1: q61_2 | IH1: q61_3 | II1: q61_4 | IJ1: q61_5 | IK1: q61_6 | IL1: q6ROW1_hidden | IM1: q62_1 | IN1: q62_2 | IO1: q62_3 | IP1: q62_4 | IQ1: q62_5 | IR1: q62_6 | IS1: q6ROW2_hidden | IT1: q63_1 | IU1: q63_2 | IV1: q63_3 | IW1: q63_4 | IX1: q63_5 | IY1: q63_6 | IZ1: q6ROW3_hidden | JA1: q64_1 | JB1: q64_2 | JC1: q64_3 | JD1: q64_4 | JE1: q64_5 | JF1: q64_6 | JG1: q6ROW4_hidden | JH1: q65_1 | JI1: q65_2 | JJ1: q65_3 | JK1: q65_4 | JL1: q65_5 | JM1: q65_6 | JN1: q6ROW5_hidden | JO1: q6COL1_hidden | JP1: q6COL2_hidden | JQ1: q6COL3_hidden | JR1: q6COL4_hidden | JS1: q6COL5_hidden | JT1: q6COL6_hidden | JU1: q6GRANDTotal_hidden | JV1: q7_1 | JW1: q7_2 | JX1: q7_3 | JY1: q7other | JZ1: q7_4 | KA1: q8 | KB1: q9 | KC1: q91 | KD1: ASIA PACIFIC_apac | KE1: q101_1_apac | KF1: q101_2_apac | KG1: q101_3_apac | KH1: q101_4_apac | KI1: q101_5_apac | KJ1: q101_6_apac | KK1: q10ROW1_hidden_apac | KL1: q102_1_apac | KM1: q102_2_apac | KN1: q102_3_apac | KO1: q102_4_apac | KP1: q102_5_apac | KQ1: q102_6_apac | KR1: q10ROW2_hidden_apac | KS1: q103_1_apac | KT1: q103_2_apac | KU1: q103_3_apac | KV1: q103_4_apac | KW1: q103_5_apac | KX1: q103_6_apac | KY1: q10ROW3_hidden_apac | KZ1: q104_1_apac | LA1: q104_2_apac | LB1: q104_3_apac | LC1: q104_4_apac | LD1: q104_5_apac | LE1: q104_6_apac | LF1: q10ROW4_hidden_apac | LG1: q105_1_apac | LH1: q105_2_apac | LI1: q105_3_apac | LJ1: q105_4_apac | LK1: q105_5_apac | LL1: q105_6_apac | LM1: q10ROW5_hidden_apac | LN1: q106_1_apac | LO1: q106_2_apac | LP1: q106_3_apac | LQ1: q106_4_apac | LR1: q106_5_apac | LS1: q106_6_apac | LT1: q10ROW6_hidden_apac | LU1: q107_1_apac | LV1: q107_2_apac | LW1: q107_3_apac | LX1: q107_4_apac | LY1: q107_5_apac | LZ1: q107_6_apac | MA1: q10ROW7_hidden_apac | MB1: q10other_apac | MC1: q108_1_apac | MD1: q108_2_apac | ME1: q108_3_apac | MF1: q108_4_apac | MG1: q108_5_apac | MH1: q108_6_apac | MI1: q10ROW8_hidden_apac | MJ1: q10COL1_hidden_apac | MK1: q10COL2_hidden_apac | ML1: q10COL3_hidden_apac | MM1: q10COL4_hidden_apac | MN1: q10COL5_hidden_apac | MO1: q10COL6_hidden_apac | MP1: q10GRANDTotal_hidden_apac | MQ1: q111_1_apac | MR1: q111_2_apac | MS1: q111_3_apac | MT1: q111_4_apac | MU1: q111_5_apac | MV1: q111_6_apac | MW1: q11ROW1_hidden_apac | MX1: q112_1_apac | MY1: q112_2_apac | MZ1: q112_3_apac | NA1: q112_4_apac | NB1: q112_5_apac | NC1: q112_6_apac | ND1: q11ROW2_hidden_apac | NE1: q113_1_apac | NF1: q113_2_apac | NG1: q113_3_apac | NH1: q113_4_apac | NI1: q113_5_apac | NJ1: q113_6_apac | NK1: q11ROW3_hidden_apac | NL1: q114_1_apac | NM1: q114_2_apac | NN1: q114_3_apac | NO1: q114_4_apac | NP1: q114_5_apac | NQ1: q114_6_apac | NR1: q11ROW4_hidden_apac | NS1: q115_1_apac | NT1: q115_2_apac | NU1: q115_3_apac | NV1: q115_4_apac | NW1: q115_5_apac | NX1: q115_6_apac | NY1: q11ROW5_hidden_apac | NZ1: q11COL1_hidden_apac | OA1: q11COL2_hidden_apac | OB1: q11COL3_hidden_apac | OC1: q11COL4_hidden_apac | OD1: q11COL5_hidden_apac | OE1: q11COL6_hidden_apac | OF1: q11GRANDTotal_hidden_apac | OG1: EUROPE_europe | OH1: q101_1_europe | OI1: q101_2_europe | OJ1: q101_3_europe | OK1: q101_4_europe | OL1: q101_5_europe | OM1: q101_6_europe | ON1: q10ROW1_hidden_europe | OO1: q102_1_europe | OP1: q102_2_europe | OQ1: q102_3_europe | OR1: q102_4_europe | OS1: q102_5_europe | OT1: q102_6_europe | OU1: q10ROW2_hidden_europe | OV1: q103_1_europe | OW1: q103_2_europe | OX1: q103_3_europe | OY1: q103_4_europe | OZ1: q103_5_europe | PA1: q103_6_europe | PB1: q10ROW3_hidden_europe | PC1: q104_1_europe | PD1: q104_2_europe | PE1: q104_3_europe | PF1: q104_4_europe | PG1: q104_5_europe | PH1: q104_6_europe | PI1: q10ROW4_hidden_europe | PJ1: q105_1_europe | PK1: q105_2_europe | PL1: q105_3_europe | PM1: q105_4_europe | PN1: q105_5_europe | PO1: q105_6_europe | PP1: q10ROW5_hidden_europe | PQ1: q106_1_europe | PR1: q106_2_europe | PS1: q106_3_europe | PT1: q106_4_europe | PU1: q106_5_europe | PV1: q106_6_europe | PW1: q10ROW6_hidden_europe | PX1: q107_1_europe | PY1: q107_2_europe | PZ1: q107_3_europe | QA1: q107_4_europe | QB1: q107_5_europe | QC1: q107_6_europe | QD1: q10ROW7_hidden_europe | QE1: q10other_europe | QF1: q108_1_europe | QG1: q108_2_europe | QH1: q108_3_europe | QI1: q108_4_europe | QJ1: q108_5_europe | QK1: q108_6_europe | QL1: q10ROW8_hidden_europe | QM1: q10COL1_hidden_europe | QN1: q10COL2_hidden_europe | QO1: q10COL3_hidden_europe | QP1: q10COL4_hidden_europe | QQ1: q10COL5_hidden_europe | QR1: q10COL6_hidden_europe | QS1: q10GRANDTotal_hidden_europe | QT1: q111_1_europe | QU1: q111_2_europe | QV1: q111_3_europe | QW1: q111_4_europe | QX1: q111_5_europe | QY1: q111_6_europe | QZ1: q11ROW1_hidden_europe | RA1: q112_1_europe | RB1: q112_2_europe | RC1: q112_3_europe | RD1: q112_4_europe | RE1: q112_5_europe | RF1: q112_6_europe | RG1: q11ROW2_hidden_europe | RH1: q113_1_europe | RI1: q113_2_europe | RJ1: q113_3_europe | RK1: q113_4_europe | RL1: q113_5_europe | RM1: q113_6_europe | RN1: q11ROW3_hidden_europe | RO1: q114_1_europe | RP1: q114_2_europe | RQ1: q114_3_europe | RR1: q114_4_europe | RS1: q114_5_europe | RT1: q114_6_europe | RU1: q11ROW4_hidden_europe | RV1: q115_1_europe | RW1: q115_2_europe | RX1: q115_3_europe | RY1: q115_4_europe | RZ1: q115_5_europe | SA1: q115_6_europe | SB1: q11ROW5_hidden_europe | SC1: q11COL1_hidden_europe | SD1: q11COL2_hidden_europe | SE1: q11COL3_hidden_europe | SF1: q11COL4_hidden_europe | SG1: q11COL5_hidden_europe | SH1: q11COL6_hidden_europe | SI1: q11GRANDTotal_hidden_europe | SJ1: NORTH AMERICA_northamerica | SK1: q101_1_northamerica | SL1: q101_2_northamerica | SM1: q101_3_northamerica | SN1: q101_4_northamerica | SO1: q101_5_northamerica | SP1: q101_6_northamerica | SQ1: q10ROW1_hidden_northamerica | SR1: q102_1_northamerica | SS1: q102_2_northamerica | ST1: q102_3_northamerica | SU1: q102_4_northamerica | SV1: q102_5_northamerica | SW1: q102_6_northamerica | SX1: q10ROW2_hidden_northamerica | SY1: q103_1_northamerica | SZ1: q103_2_northamerica | TA1: q103_3_northamerica | TB1: q103_4_northamerica | TC1: q103_5_northamerica | TD1: q103_6_northamerica | TE1: q10ROW3_hidden_northamerica | TF1: q104_1_northamerica | TG1: q104_2_northamerica | TH1: q104_3_northamerica | TI1: q104_4_northamerica | TJ1: q104_5_northamerica | TK1: q104_6_northamerica | TL1: q10ROW4_hidden_northamerica | TM1: q105_1_northamerica | TN1: q105_2_northamerica | TO1: q105_3_northamerica | TP1: q105_4_northamerica | TQ1: q105_5_northamerica | TR1: q105_6_northamerica | TS1: q10ROW5_hidden_northamerica | TT1: q106_1_northamerica | TU1: q106_2_northamerica | TV1: q106_3_northamerica | TW1: q106_4_northamerica | TX1: q106_5_northamerica | TY1: q106_6_northamerica | TZ1: q10ROW6_hidden_northamerica | UA1: q107_1_northamerica | UB1: q107_2_northamerica | UC1: q107_3_northamerica | UD1: q107_4_northamerica | UE1: q107_5_northamerica | UF1: q107_6_northamerica | UG1: q10ROW7_hidden_northamerica | UH1: q10other_northamerica | UI1: q108_1_northamerica | UJ1: q108_2_northamerica | UK1: q108_3_northamerica | UL1: q108_4_northamerica | UM1: q108_5_northamerica | UN1: q108_6_northamerica | UO1: q10ROW8_hidden_northamerica | UP1: q10COL1_hidden_northamerica | UQ1: q10COL2_hidden_northamerica | UR1: q10COL3_hidden_northamerica | US1: q10COL4_hidden_northamerica | UT1: q10COL5_hidden_northamerica | UU1: q10COL6_hidden_northamerica | UV1: q10GRANDTotal_hidden_northamerica | UW1: q111_1_northamerica | UX1: q111_2_northamerica | UY1: q111_3_northamerica | UZ1: q111_4_northamerica | VA1: q111_5_northamerica | VB1: q111_6_northamerica | VC1: q11ROW1_hidden_northamerica | VD1: q112_1_northamerica | VE1: q112_2_northamerica | VF1: q112_3_northamerica | VG1: q112_4_northamerica | VH1: q112_5_northamerica | VI1: q112_6_northamerica | VJ1: q11ROW2_hidden_northamerica | VK1: q113_1_northamerica | VL1: q113_2_northamerica | VM1: q113_3_northamerica | VN1: q113_4_northamerica | VO1: q113_5_northamerica | VP1: q113_6_northamerica | VQ1: q11ROW3_hidden_northamerica | VR1: q114_1_northamerica | VS1: q114_2_northamerica | VT1: q114_3_northamerica | VU1: q114_4_northamerica | VV1: q114_5_northamerica | VW1: q114_6_northamerica | VX1: q11ROW4_hidden_northamerica | VY1: q115_1_northamerica | VZ1: q115_2_northamerica | WA1: q115_3_northamerica | WB1: q115_4_northamerica | WC1: q115_5_northamerica | WD1: q115_6_northamerica | WE1: q11ROW5_hidden_northamerica | WF1: q11COL1_hidden_northamerica | WG1: q11COL2_hidden_northamerica | WH1: q11COL3_hidden_northamerica | WI1: q11COL4_hidden_northamerica | WJ1: q11COL5_hidden_northamerica | WK1: q11COL6_hidden_northamerica | WL1: q11GRANDTotal_hidden_northamerica | WM1: Global_global | WN1: q101_1_global | WO1: q101_2_global | WP1: q101_3_global | WQ1: q101_4_global | WR1: q101_5_global | WS1: q101_6_global | WT1: q10ROW1_hidden_global | WU1: q102_1_global | WV1: q102_2_global | WW1: q102_3_global | WX1: q102_4_global | WY1: q102_5_global | WZ1: q102_6_global | XA1: q10ROW2_hidden_global | XB1: q103_1_global | XC1: q103_2_global | XD1: q103_3_global | XE1: q103_4_global | XF1: q103_5_global | XG1: q103_6_global | XH1: q10ROW3_hidden_global | XI1: q104_1_global | XJ1: q104_2_global | XK1: q104_3_global | XL1: q104_4_global | XM1: q104_5_global | XN1: q104_6_global | XO1: q10ROW4_hidden_global | XP1: q105_1_global | XQ1: q105_2_global | XR1: q105_3_global | XS1: q105_4_global | XT1: q105_5_global | XU1: q105_6_global | XV1: q10ROW5_hidden_global | XW1: q106_1_global | XX1: q106_2_global | XY1: q106_3_global | XZ1: q106_4_global | YA1: q106_5_global | YB1: q106_6_global | YC1: q10ROW6_hidden_global | YD1: q107_1_global | YE1: q107_2_global | YF1: q107_3_global | YG1: q107_4_global | YH1: q107_5_global | YI1: q107_6_global | YJ1: q10ROW7_hidden_global | YK1: q10other_global | YL1: q108_1_global | YM1: q108_2_global | YN1: q108_3_global | YO1: q108_4_global | YP1: q108_5_global | YQ1: q108_6_global | YR1: q10ROW8_hidden_global | YS1: q10COL1_hidden_global | YT1: q10COL2_hidden_global | YU1: q10COL3_hidden_global | YV1: q10COL4_hidden_global | YW1: q10COL5_hidden_global | YX1: q10COL6_hidden_global | YY1: q10GRANDTotal_hidden_global | YZ1: q111_1_global | ZA1: q111_2_global | ZB1: q111_3_global | ZC1: q111_4_global | ZD1: q111_5_global | ZE1: q111_6_global | ZF1: q11ROW1_hidden_global | ZG1: q112_1_global | ZH1: q112_2_global | ZI1: q112_3_global | ZJ1: q112_4_global | ZK1: q112_5_global | ZL1: q112_6_global | ZM1: q11ROW2_hidden_global | ZN1: q113_1_global | ZO1: q113_2_global | ZP1: q113_3_global | ZQ1: q113_4_global | ZR1: q113_5_global | ZS1: q113_6_global | ZT1: q11ROW3_hidden_global | ZU1: q114_1_global | ZV1: q114_2_global | ZW1: q114_3_global | ZX1: q114_4_global | ZY1: q114_5_global | ZZ1: q114_6_global | AAA1: q11ROW4_hidden_global | AAB1: q115_1_global | AAC1: q115_2_global | AAD1: q115_3_global | AAE1: q115_4_global | AAF1: q115_5_global | AAG1: q115_6_global | AAH1: q11ROW5_hidden_global | AAI1: q11COL1_hidden_global | AAJ1: q11COL2_hidden_global | AAK1: q11COL3_hidden_global | AAL1: q11COL4_hidden_global | AAM1: q11COL5_hidden_global | AAN1: q11COL6_hidden_global | AAO1: q11GRANDTotal_hidden_global | AAP1: SOUTH AMERICA_southamerica | AAQ1: q101_1_southamerica | AAR1: q101_2_southamerica | AAS1: q101_3_southamerica | AAT1: q101_4_southamerica | AAU1: q101_5_southamerica | AAV1: q101_6_southamerica | AAW1: q10ROW1_hidden_southamerica | AAX1: q102_1_southamerica | AAY1: q102_2_southamerica | AAZ1: q102_3_southamerica | ABA1: q102_4_southamerica | ABB1: q102_5_southamerica | ABC1: q102_6_southamerica | ABD1: q10ROW2_hidden_southamerica | ABE1: q103_1_southamerica | ABF1: q103_2_southamerica | ABG1: q103_3_southamerica | ABH1: q103_4_southamerica | ABI1: q103_5_southamerica | ABJ1: q103_6_southamerica | ABK1: q10ROW3_hidden_southamerica | ABL1: q104_1_southamerica | ABM1: q104_2_southamerica | ABN1: q104_3_southamerica | ABO1: q104_4_southamerica | ABP1: q104_5_southamerica | ABQ1: q104_6_southamerica | ABR1: q10ROW4_hidden_southamerica | ABS1: q105_1_southamerica | ABT1: q105_2_southamerica | ABU1: q105_3_southamerica | ABV1: q105_4_southamerica | ABW1: q105_5_southamerica | ABX1: q105_6_southamerica | ABY1: q10ROW5_hidden_southamerica | ABZ1: q106_1_southamerica | ACA1: q106_2_southamerica | ACB1: q106_3_southamerica | ACC1: q106_4_southamerica | ACD1: q106_5_southamerica | ACE1: q106_6_southamerica | ACF1: q10ROW6_hidden_southamerica | ACG1: q107_1_southamerica | ACH1: q107_2_southamerica | ACI1: q107_3_southamerica | ACJ1: q107_4_southamerica | ACK1: q107_5_southamerica | ACL1: q107_6_southamerica | ACM1: q10ROW7_hidden_southamerica | ACN1: q10other_southamerica | ACO1: q108_1_southamerica | ACP1: q108_2_southamerica | ACQ1: q108_3_southamerica | ACR1: q108_4_southamerica | ACS1: q108_5_southamerica | ACT1: q108_6_southamerica | ACU1: q10ROW8_hidden_southamerica | ACV1: q10COL1_hidden_southamerica | ACW1: q10COL2_hidden_southamerica | ACX1: q10COL3_hidden_southamerica | ACY1: q10COL4_hidden_southamerica | ACZ1: q10COL5_hidden_southamerica | ADA1: q10COL6_hidden_southamerica | ADB1: q10GRANDTotal_hidden_southamerica | ADC1: q111_1_southamerica | ADD1: q111_2_southamerica | ADE1: q111_3_southamerica | ADF1: q111_4_southamerica | ADG1: q111_5_southamerica | ADH1: q111_6_southamerica | ADI1: q11ROW1_hidden_southamerica | ADJ1: q112_1_southamerica | ADK1: q112_2_southamerica | ADL1: q112_3_southamerica | ADM1: q112_4_southamerica | ADN1: q112_5_southamerica | ADO1: q112_6_southamerica | ADP1: q11ROW2_hidden_southamerica | ADQ1: q113_1_southamerica | ADR1: q113_2_southamerica | ADS1: q113_3_southamerica | ADT1: q113_4_southamerica | ADU1: q113_5_southamerica | ADV1: q113_6_southamerica | ADW1: q11ROW3_hidden_southamerica | ADX1: q114_1_southamerica | ADY1: q114_2_southamerica | ADZ1: q114_3_southamerica | AEA1: q114_4_southamerica | AEB1: q114_5_southamerica | AEC1: q114_6_southamerica | AED1: q11ROW4_hidden_southamerica | AEE1: q115_1_southamerica | AEF1: q115_2_southamerica | AEG1: q115_3_southamerica | AEH1: q115_4_southamerica | AEI1: q115_5_southamerica | AEJ1: q115_6_southamerica | AEK1: q11ROW5_hidden_southamerica | AEL1: q11COL1_hidden_southamerica | AEM1: q11COL2_hidden_southamerica | AEN1: q11COL3_hidden_southamerica | AEO1: q11COL4_hidden_southamerica | AEP1: q11COL5_hidden_southamerica | AEQ1: q11COL6_hidden_southamerica | AER1: q11GRANDTotal_hidden_southamerica | AES1: AFRICA_africa | AET1: q101_1_africa | AEU1: q101_2_africa | AEV1: q101_3_africa | AEW1: q101_4_africa | AEX1: q101_5_africa | AEY1: q101_6_africa | AEZ1: q10ROW1_hidden_africa | AFA1: q102_1_africa | AFB1: q102_2_africa | AFC1: q102_3_africa | AFD1: q102_4_africa | AFE1: q102_5_africa | AFF1: q102_6_africa | AFG1: q10ROW2_hidden_africa | AFH1: q103_1_africa | AFI1: q103_2_africa | AFJ1: q103_3_africa | AFK1: q103_4_africa | AFL1: q103_5_africa | AFM1: q103_6_africa | AFN1: q10ROW3_hidden_africa | AFO1: q104_1_africa | AFP1: q104_2_africa | AFQ1: q104_3_africa | AFR1: q104_4_africa | AFS1: q104_5_africa | AFT1: q104_6_africa | AFU1: q10ROW4_hidden_africa | AFV1: q105_1_africa | AFW1: q105_2_africa | AFX1: q105_3_africa | AFY1: q105_4_africa | AFZ1: q105_5_africa | AGA1: q105_6_africa | AGB1: q10ROW5_hidden_africa | AGC1: q106_1_africa | AGD1: q106_2_africa | AGE1: q106_3_africa | AGF1: q106_4_africa | AGG1: q106_5_africa | AGH1: q106_6_africa | AGI1: q10ROW6_hidden_africa | AGJ1: q107_1_africa | AGK1: q107_2_africa | AGL1: q107_3_africa | AGM1: q107_4_africa | AGN1: q107_5_africa | AGO1: q107_6_africa | AGP1: q10ROW7_hidden_africa | AGQ1: q10other_africa | AGR1: q108_1_africa | AGS1: q108_2_africa | AGT1: q108_3_africa | AGU1: q108_4_africa | AGV1: q108_5_africa | AGW1: q108_6_africa | AGX1: q10ROW8_hidden_africa | AGY1: q10COL1_hidden_africa | AGZ1: q10COL2_hidden_africa | AHA1: q10COL3_hidden_africa | AHB1: q10COL4_hidden_africa | AHC1: q10COL5_hidden_africa | AHD1: q10COL6_hidden_africa | AHE1: q10GRANDTotal_hidden_africa | AHF1: q111_1_africa | AHG1: q111_2_africa | AHH1: q111_3_africa | AHI1: q111_4_africa | AHJ1: q111_5_africa | AHK1: q111_6_africa | AHL1: q11ROW1_hidden_africa | AHM1: q112_1_africa | AHN1: q112_2_africa | AHO1: q112_3_africa | AHP1: q112_4_africa | AHQ1: q112_5_africa | AHR1: q112_6_africa | AHS1: q11ROW2_hidden_africa | AHT1: q113_1_africa | AHU1: q113_2_africa | AHV1: q113_3_africa | AHW1: q113_4_africa | AHX1: q113_5_africa | AHY1: q113_6_africa | AHZ1: q11ROW3_hidden_africa | AIA1: q114_1_africa | AIB1: q114_2_africa | AIC1: q114_3_africa | AID1: q114_4_africa | AIE1: q114_5_africa | AIF1: q114_6_africa | AIG1: q11ROW4_hidden_africa | AIH1: q115_1_africa | AII1: q115_2_africa | AIJ1: q115_3_africa | AIK1: q115_4_africa | AIL1: q115_5_africa | AIM1: q115_6_africa | AIN1: q11ROW5_hidden_africa | AIO1: q11COL1_hidden_africa | AIP1: q11COL2_hidden_africa | AIQ1: q11COL3_hidden_africa | AIR1: q11COL4_hidden_africa | AIS1: q11COL5_hidden_africa | AIT1: q11COL6_hidden_africa | AIU1: q11GRANDTotal_hidden_africa | AIV1: Domain
A2: A0BHE1R | B2: ANREV | C2: Proprium Capital Partners, L.P. | E2: rajul.patel@proprium.com | G2: https://secure.surveylab.co.uk/anrev-inrev-ncreif-capital-raising-2018/default.asp?survey=A0BHE1R | T2: FALSE | U2: FALSE | V2: FALSE | W2: FALSE | X2: FALSE | Y2: FALSE | Z2: 447 | AA2: 43153.792 | AB2: 38.88.11.74 | AC2: 2018 | AD2: Rajul Patel | AE2: Proprium Capital Partners, L.P. | AF2: =VLOOKUP(MID(E2,SEARCH("@",E2,1),LEN(E2)-SEARCH("@",E2,1)+1),[2]Sheet1!$D:$F,3,FALSE) -> M0201 | AG2: Principal | AH2: rajul.patel@proprium.com | AI2: 404-334-3312 | AJ2: United States | AK2: USD | AM2: 2 | AN2: 6 | AO2: Started Marketing Process during the year | AV2: 0 | BC2: 0 | BJ2: 0 | BQ2: 0 | BX2: 0 | CE2: 0 | CF2: 0 | CG2: 0 | CH2: 0 | CI2: 0 | CJ2: 0 | CK2: 0 | CL2: 0 | CS2: 0 | CZ2: 0 | DG2: 0 | DN2: 0 | DU2: 0 | EB2: 0 | EC2: 0 | ED2: 0 | EE2: 0 | EF2: 0 | EG2: 0 | EH2: 0 | EI2: 0 | EJ2: NO | EK2: NO | EL2: NO | EM2: NO | EN2: NO | EO2: NO | EP2: NO | EQ2: NO | ER2: NO | ES2: NO | ET2: NO | EU2: NO | EV2: NO | EW2: NO | EX2: NO | EY2: NO | EZ2: NO | FA2: NO | FB2: NO | FC2: NO | FD2: NO | FE2: NO | FF2: NO | FG2: NO | FH2: NO | FI2: NO | FJ2: NO | FK2: NO | FL2: NO | FM2: NO | FN2: NO | FO2: NO | FP2: NO | FQ2: NO | FR2: NO | FS2: NO | FZ2: 0 | GG2: 0 | GN2: 0 | GU2: 0 | HB2: 0 | HI2: 0 | HP2: 0 | HX2: 0 | HY2: 0 | HZ2: 0 | IA2: 0 | IB2: 0 | IC2: 0 | ID2: 0 | IE2: 0 | IL2: 0 | IS2: 0 | IZ2: 0 | JG2: 0 | JN2: 0 | JO2: 0 | JP2: 0 | JQ2: 0 | JR2: 0 | JS2: 0 | JT2: 0 | JU2: 0 | KA2: 1 | KB2: 3 | KC2: 1 | KD2: START Asia Pacific: | OG2: START Europe: | SJ2: START North America: | WM2: START Global: | AAP2: START SOUTH America: | AES2: START Africa: | AIV2: =IFERROR(RIGHT(AH2,LEN(AH2)-SEARCH("@",AH2,1)),"") -> proprium.com
A3: A0JVE5M | B3: ANREV | C3: Tokyu Land Capital Management | E3: Yumiko_Nakamoto@tokyu-tlcm.co.jp | G3: https://secure.surveylab.co.uk/anrev-inrev-ncreif-capital-raising-2018/default.asp?survey=A0JVE5M | T3: FALSE | U3: TRUE | V3: FALSE | W3: FALSE | X3: FALSE | Y3: FALSE | Z3: 472 | AA3: 43165.403 | AB3: 118.103.94.201 | AC3: 2018 | AD3: Yumiko Nakamoto | AE3: Tokyu Land Capital Management Inc. | AF3: =VLOOKUP(MID(E3,SEARCH("@",E3,1),LEN(E3)-SEARCH("@",E3,1)+1),[2]Sheet1!$D:$F,3,FALSE) -> M0298 | AG3: Manager | AH3: Yumiko_Nakamoto@tokyu-tlcm.co.jp | AI3: -16835 | AJ3: Japan | AK3: JPY | AM3: 1 | AR3: 127.1 | AV3: 127.1 | BC3: 0 | BJ3: 0 | BQ3: 0 | BX3: 0 | CE3: 0 | CF3: 0 | CG3: 0 | CH3: 127.1 | CI3: 0 | CJ3: 0 | CK3: 0 | CL3: 127.1 | CO3: 7 | CS3: 7 | CZ3: 0 | DG3: 0 | DN3: 0 | DU3: 0 | EB3: 0 | EC3: 0 | ED3: 0 | EE3: 7 | EF3: 0 | EG3: 0 | EH3: 0 | EI3: 7 | EJ3: NO | EK3: NO | EL3: YES | EM3: NO | EN3: NO | EO3: NO | EP3: NO | EQ3: NO | ER3: NO | ES3: NO | ET3: NO | EU3: NO | EV3: NO | EW3: NO | EX3: NO | EY3: NO | EZ3: NO | FA3: NO | FB3: NO | FC3: NO | FD3: NO | FE3: NO | FF3: NO | FG3: NO | FH3: NO | FI3: NO | FJ3: NO | FK3: NO | FL3: NO | FM3: NO | FN3: NO | FO3: NO | FP3: NO | FQ3: NO | FR3: NO | FS3: NO | FZ3: 0 | GG3: 0 | GN3: 0 | GU3: 0 | HB3: 0 | HI3: 0 | HP3: 0 | HT3: 127.1 | HX3: 127.1 | HY3: 0 | HZ3: 0 | IA3: 127.1 | IB3: 0 | IC3: 0 | ID3: 0 | IE3: 127.1 | IH3: 127.1 | IL3: 127.1 | IS3: 0 | IZ3: 0 | JG3: 0 | JN3: 0 | JO3: 0 | JP3: 0 | JQ3: 127.1 | JR3: 0 | JS3: 0 | JT3: 0 | JU3: 127.1 | JX3: 100 | KA3: 3 | KB3: 3 | KC3: 1 | KD3: START Asia Pacific: | OG3: START Europe: | SJ3: START North America: | WM3: START Global: | AAP3: START SOUTH America: | AES3: START Africa: | AIV3: =IFERROR(RIGHT(AH3,LEN(AH3)-SEARCH("@",AH3,1)),"") -> tokyu-tlcm.co.jp
A4: A0QKG9H | B4: ANREV | C4: KaiLong Investments | E4: don.tan@kailongrei.com | G4: https://secure.surveylab.co.uk/anrev-inrev-ncreif-capital-raising-2018/default.asp?survey=A0QKG9H | H4: asia | I4: 43138.342 | T4: FALSE | U4: TRUE | V4: FALSE | W4: FALSE | X4: FALSE | Y4: FALSE | Z4: 417 | AA4: 43138.34 | AB4: 180.87.13.170 | AC4: 2018 | AD4: Don Tan | AE4: KaiLong Investments | AF4: =VLOOKUP(MID(E4,SEARCH("@",E4,1),LEN(E4)-SEARCH("@",E4,1)+1),[2]Sheet1!$D:$F,3,FALSE) -> M0226 | AG4: SVP, Fund Management | AH4: don.tan@kailongrei.com | AI4: 85237982627 | AJ4: China | AK4: USD | AM4: 1 | AQ4: 176 | AV4: 176 | BC4: 0 | BJ4: 0 | BQ4: 0 | BX4: 0 | CE4: 0 | CF4: 0 | CG4: 176 | CH4: 0 | CI4: 0 | CJ4: 0 | CK4: 0 | CL4: 176 | CN4: 2 | CS4: 2 | CZ4: 0 | DG4: 0 | DN4: 0 | DU4: 0 | EB4: 0 | EC4: 0 | ED4: 2 | EE4: 0 | EF4: 0 | EG4: 0 | EH4: 0 | EI4: 2 | EJ4: NO | EK4: YES | EL4: NO | EM4: NO | EN4: NO | EO4: NO | EP4: NO | EQ4: NO | ER4: NO | ES4: NO | ET4: NO | EU4: NO | EV4: NO | EW4: NO | EX4: NO | EY4: NO | EZ4: NO | FA4: NO | FB4: NO | FC4: NO | FD4: NO | FE4: NO | FF4: NO | FG4: NO | FH4: NO | FI4: NO | FJ4: NO | FK4: NO | FL4: NO | FM4: NO | FN4: NO | FO4: NO | FP4: NO | FQ4: NO | FR4: NO | FS4: NO | FZ4: 0 | GG4: 0 | GN4: 0 | GP4: 5 | GU4: 5 | HB4: 0 | HI4: 0 | HK4: 132 | HP4: 132 | HQ4: Banks | HS4: 39 | HX4: 39 | HY4: 0 | HZ4: 176 | IA4: 0 | IB4: 0 | IC4: 0 | ID4: 0 | IE4: 176 | IG4: 156 | IL4: 156 | IN4: 20 | IS4: 20 | IZ4: 0 | JG4: 0 | JN4: 0 | JO4: 0 | JP4: 176 | JQ4: 0 | JR4: 0 | JS4: 0 | JT4: 0 | JU4: 176 | JX4: 100 | KA4: 1 | KB4: 1 | KC4: 1 | KD4: START Asia Pacific: | KK4: 0 | KR4: 0 | KY4: 0 | LA4: 20 | LF4: 20 | LM4: 0 | LT4: 0 | LV4: 116 | MA4: 116 | MB4: Banks | MD4: 40 | MI4: 40 | MJ4: 0 | MK4: 176 | ML4: 0 | MM4: 0 | MN4: 0 | MO4: 0 | MP4: 176 | MR4: 20 | MW4: 20 | MY4: 156 | ND4: 156 | NK4: 0 | NR4: 0 | NY4: 0 | NZ4: 0 | OA4: 176 | OB4: 0 | OC4: 0 | OD4: 0 | OE4: 0 | OF4: 176 | OG4: START Europe: | SJ4: START North America: | WM4: START Global: | AAP4: START SOUTH America: | AES4: START Africa: | AIV4: =IFERROR(RIGHT(AH4,LEN(AH4)-SEARCH("@",AH4,1)),"") -> kailongrei.com
A5: A0QVB6X | B5: ANREV | C5: EG Fund Management | E5: rparker@eg.com.au | G5: https://secure.surveylab.co.uk/anrev-inrev-ncreif-capital-raising-2018/default.asp?survey=A0QVB6X | H5: asia | I5: 43123.292 | T5: FALSE | U5: TRUE | V5: FALSE | W5: FALSE | X5: FALSE | Y5: FALSE | Z5: 369 | AA5: 43123.29 | AB5: 59.100.170.162 | AC5: 2018 | AD5: Linh Pham | AE5: EG Funds Management | AF5: =VLOOKUP(MID(E5,SEARCH("@",E5,1),LEN(E5)-SEARCH("@",E5,1)+1),[2]Sheet1!$D:$F,3,FALSE) -> M0249 | AG5: Analyst | AH5: lpham@eg.com.au | AJ5: Australia | AK5: AUD | AM5: 1 | AP5: 67.5 | AV5: 67.5 | BC5: 0 | BJ5: 0 | BQ5: 0 | BX5: 0 | CE5: 0 | CF5: 67.5 | CG5: 0 | CH5: 0 | CI5: 0 | CJ5: 0 | CK5: 0 | CL5: 67.5 | CM5: 2 | CS5: 2 | CZ5: 0 | DG5: 0 | DN5: 0 | DU5: 0 | EB5: 0 | EC5: 2 | ED5: 0 | EE5: 0 | EF5: 0 | EG5: 0 | EH5: 0 | EI5: 2 | EJ5: YES | EK5: NO | EL5: NO | EM5: NO | EN5: NO | EO5: NO | EP5: NO | EQ5: NO | ER5: NO | ES5: NO | ET5: NO | EU5: NO | EV5: NO | EW5: NO | EX5: NO | EY5: NO | EZ5: NO | FA5: NO | FB5: NO | FC5: NO | FD5: NO | FE5: NO | FF5: NO | FG5: NO | FH5: NO | FI5: NO | FJ5: NO | FK5: NO | FL5: NO | FM5: NO | FN5: NO | FO5: NO | FP5: NO | FQ5: NO | FR5: NO | FS5: NO | FT5: 60 | FZ5: 60 | GG5: 0 | GN5: 0 | GU5: 0 | HB5: 0 | HI5: 0 | HP5: 0 | HQ5: Endowment Fund | HR5: 7.5 | HX5: 7.5 | HY5: 67.5 | HZ5: 0 | IA5: 0 | IB5: 0 | IC5: 0 | ID5: 0 | IE5: 67.5 | IF5: 67.5 | IL5: 67.5 | IS5: 0 | IZ5: 0 | JG5: 0 | JN5: 0 | JO5: 67.5 | JP5: 0 | JQ5: 0 | JR5: 0 | JS5: 0 | JT5: 0 | JU5: 67.5 | JX5: 100 | KA5: 1 | KB5: 2 | KC5: 1 | KD5: START Asia Pacific: | KE5: 67.5 | KK5: 67.5 | KR5: 0 | KY5: 0 | LF5: 0 | LM5: 0 | LT5: 0 | MA5: 0 | MI5: 0 | MJ5: 67.5 | MK5: 0 | ML5: 0 | MM5: 0 | MN5: 0 | MO5: 0 | MP5: 67.5 | MW5: 0 | MX5: 67.5 | ND5: 67.5 | NK5: 0 | NR5: 0 | NY5: 0 | NZ5: 67.5 | OA5: 0 | OB5: 0 | OC5: 0 | OD5: 0 | OE5: 0 | OF5: 67.5 | OG5: START Europe: | SJ5: START North America: | WM5: START Global: | AAP5: START SOUTH America: | AES5: START Africa: | AIV5: =IFERROR(RIGHT(AH5,LEN(AH5)-SEARCH("@",AH5,1)),"") -> eg.com.au
A6: A0WWG6Z | B6: ANREV | C6: Mitsubishi UFJ Trust and Banking Corporation | E6: soichiro_tabu@tr.mufg.jp | G6: https://secure.surveylab.co.uk/anrev-inrev-ncreif-capital-raising-2018/default.asp?survey=A0WWG6Z | H6: asia | I6: 43138.039 | T6: FALSE | U6: TRUE | V6: FALSE | W6: FALSE | X6: FALSE | Y6: FALSE | Z6: 412 | AA6: 43138.038 | AB6: 103.9.97.232 | AC6: 2018 | AD6: Soichiro Tabu | AE6: Mitsubishi UFJ Trust and Banking Corporation | AF6: =VLOOKUP(MID(E6,SEARCH("@",E6,1),LEN(E6)-SEARCH("@",E6,1)+1),[2]Sheet1!$D:$F,3,FALSE) -> M0232 | AG6: Senior Manager | AH6: soichiro.tabu@tr.mufg.jp | AI6: 8162146580 | AJ6: Japan | AK6: JPY | AM6: 1 | AQ6: 1000 | AV6: 1000 | BC6: 0 | BJ6: 0 | BQ6: 0 | BX6: 0 | CE6: 0 | CF6: 0 | CG6: 1000 | CH6: 0 | CI6: 0 | CJ6: 0 | CK6: 0 | CL6: 1000 | CN6: 1 | CS6: 1 | CZ6: 0 | DG6: 0 | DN6: 0 | DU6: 0 | EB6: 0 | EC6: 0 | ED6: 1 | EE6: 0 | EF6: 0 | EG6: 0 | EH6: 0 | EI6: 1 | EJ6: NO | EK6: YES | EL6: NO | EM6: NO | EN6: NO | EO6: NO | EP6: NO | EQ6: NO | ER6: NO | ES6: NO | ET6: NO | EU6: NO | EV6: NO | EW6: NO | EX6: NO | EY6: NO | EZ6: NO | FA6: NO | FB6: NO | FC6: NO | FD6: NO | FE6: NO | FF6: NO | FG6: NO | FH6: NO | FI6: NO | FJ6: NO | FK6: NO | FL6: NO | FM6: NO | FN6: NO | FO6: NO | FP6: NO | FQ6: NO | FR6: NO | FS6: NO | FZ6: 0 | GG6: 0 | GN6: 0 | GU6: 0 | HB6: 0 | HD6: 1000 | HI6: 1000 | HP6: 0 | HX6: 0 | HY6: 0 | HZ6: 1000 | IA6: 0 | IB6: 0 | IC6: 0 | ID6: 0 | IE6: 1000 | IG6: 1000 | IL6: 1000 | IS6: 0 | IZ6: 0 | JG6: 0 | JN6: 0 | JO6: 0 | JP6: 1000 | JQ6: 0 | JR6: 0 | JS6: 0 | JT6: 0 | JU6: 1000 | JX6: 100 | KA6: 1 | KB6: 1 | KC6: 1 | KD6: START Asia Pacific: | KK6: 0 | KR6: 0 | KY6: 0 | LF6: 0 | LM6: 0 | LO6: 1000 | LT6: 1000 | MA6: 0 | MI6: 0 | MJ6: 0 | MK6: 1000 | ML6: 0 | MM6: 0 | MN6: 0 | MO6: 0 | MP6: 1000 | MW6: 0 | MY6: 1000 | ND6: 1000 | NK6: 0 | NR6: 0 | NY6: 0 | NZ6: 0 | OA6: 1000 | OB6: 0 | OC6: 0 | OD6: 0 | OE6: 0 | OF6: 1000 | OG6: START Europe: | SJ6: START North America: | WM6: START Global: | AAP6: START SOUTH America: | AES6: START Africa: | AIV6: =IFERROR(RIGHT(AH6,LEN(AH6)-SEARCH("@",AH6,1)),"") -> tr.mufg.jp
A7: A1EZQ9H | B7: ANREV | C7: Creditease | E7: pengzhang@creditease.hk | G7: https://secure.surveylab.co.uk/anrev-inrev-ncreif-capital-raising-2018/default.asp?survey=A1EZQ9H | T7: FALSE | U7: FALSE | V7: FALSE | W7: FALSE | X7: FALSE | Y7: FALSE | Z7: 409 | AA7: 43136.38 | AB7: 42.61.55.10 | AC7: 2018 | AD7: Evangeline Ho | AE7: CreditEase Asset Management (Singapore) Pte Ltd | AF7: =VLOOKUP(MID(E7,SEARCH("@",E7,1),LEN(E7)-SEARCH("@",E7,1)+1),[2]Sheet1!$D:$F,3,FALSE) -> N0278 | AH7: evangeline.ho@creditease.com.sg | AJ7: China | AK7: USD | AM7: 2 | AN7: 6 | AO7: Focus is on HNWI | AV7: 0 | BC7: 0 | BJ7: 0 | BQ7: 0 | BX7: 0 | CE7: 0 | CF7: 0 | CG7: 0 | CH7: 0 | CI7: 0 | CJ7: 0 | CK7: 0 | CL7: 0 | CS7: 0 | CZ7: 0 | DG7: 0 | DN7: 0 | DU7: 0 | EB7: 0 | EC7: 0 | ED7: 0 | EE7: 0 | EF7: 0 | EG7: 0 | EH7: 0 | EI7: 0 | EJ7: NO | EK7: NO | EL7: NO | EM7: NO | EN7: NO | EO7: NO | EP7: NO | EQ7: NO | ER7: NO | ES7: NO | ET7: NO | EU7: NO | EV7: NO | EW7: NO | EX7: NO | EY7: NO | EZ7: NO | FA7: NO | FB7: NO | FC7: NO | FD7: NO | FE7: NO | FF7: NO | FG7: NO | FH7: NO | FI7: NO | FJ7: NO | FK7: NO | FL7: NO | FM7: NO | FN7: NO | FO7: NO | FP7: NO | FQ7: NO | FR7: NO | FS7: NO | FZ7: 0 | GG7: 0 | GN7: 0 | GU7: 0 | HB7: 0 | HI7: 0 | HP7: 0 | HX7: 0 | HY7: 0 | HZ7: 0 | IA7: 0 | IB7: 0 | IC7: 0 | ID7: 0 | IE7: 0 | IL7: 0 | IS7: 0 | IZ7: 0 | JG7: 0 | JN7: 0 | JO7: 0 | JP7: 0 | JQ7: 0 | JR7: 0 | JS7: 0 | JT7: 0 | JU7: 0 | KA7: 2 | KB7: 2 | KC7: 2 | KD7: START Asia Pacific: | OG7: START Europe: | SJ7: START North America: | WM7: START Global: | AAP7: START SOUTH America: | AES7: START Africa: | AIV7: =IFERROR(RIGHT(AH7,LEN(AH7)-SEARCH("@",AH7,1)),"") -> creditease.com.sg
A8: A1MCM9B | B8: ANREV | C8: Kenedix, Inc. | E8: masahiko_tajima@kenedix.com | G8: https://secure.surveylab.co.uk/anrev-inrev-ncreif-capital-raising-2018/default.asp?survey=A1MCM9B | T8: FALSE | U8: FALSE | V8: FALSE | W8: FALSE | X8: FALSE | Y8: FALSE | Z8: 384 | AA8: 43146.075 | AB8: 119.245.128.17 | AC8: 2018 | AD8: Motohiro Horiuchi | AE8: Kenedix, Inc. | AF8: =VLOOKUP(MID(E8,SEARCH("@",E8,1),LEN(E8)-SEARCH("@",E8,1)+1),[2]Sheet1!$D:$F,3,FALSE) -> M0230 | AH8: motohiro_horiuchi@kenedix.com | AJ8: Japan | AK8: JPY | AM8: 1 | AV8: 0 | BC8: 0 | BJ8: 0 | BQ8: 0 | BX8: 0 | CE8: 0 | CF8: 0 | CG8: 0 | CH8: 0 | CI8: 0 | CJ8: 0 | CK8: 0 | CL8: 0 | CS8: 0 | CZ8: 0 | DG8: 0 | DN8: 0 | DU8: 0 | EB8: 0 | EC8: 0 | ED8: 0 | EE8: 0 | EF8: 0 | EG8: 0 | EH8: 0 | EI8: 0 | EJ8: NO | EK8: NO | EL8: NO | EM8: NO | EN8: NO | EO8: NO | EP8: NO | EQ8: NO | ER8: NO | ES8: NO | ET8: NO | EU8: NO | EV8: NO | EW8: NO | EX8: NO | EY8: NO | EZ8: NO | FA8: NO | FB8: NO | FC8: NO | FD8: NO | FE8: NO | FF8: NO | FG8: NO | FH8: NO | FI8: NO | FJ8: NO | FK8: NO | FL8: NO | FM8: NO | FN8: NO | FO8: NO | FP8: NO | FQ8: NO | FR8: NO | FS8: NO | FZ8: 0 | GG8: 0 | GN8: 0 | GU8: 0 | HB8: 0 | HI8: 0 | HP8: 0 | HX8: 0 | HY8: 0 | HZ8: 0 | IA8: 0 | IB8: 0 | IC8: 0 | ID8: 0 | IE8: 0 | IL8: 0 | IS8: 0 | IZ8: 0 | JG8: 0 | JN8: 0 | JO8: 0 | JP8: 0 | JQ8: 0 | JR8: 0 | JS8: 0 | JT8: 0 | JU8: 0 | KA8: 1 | KB8: 3 | KC8: 2 | KD8: START Asia Pacific: | OG8: START Europe: | SJ8: START North America: | WM8: START Global: | AAP8: START SOUTH America: | AES8: START Africa: | AIV8: =IFERROR(RIGHT(AH8,LEN(AH8)-SEARCH("@",AH8,1)),"") -> kenedix.com
A9: A1NJV4Y | B9: ANREV | C9: Pamfleet | E9: singuz.lo@pamfleet.com | G9: https://secure.surveylab.co.uk/anrev-inrev-ncreif-capital-raising-2018/default.asp?survey=A1NJV4Y | T9: FALSE | U9: FALSE | V9: FALSE | W9: FALSE | X9: FALSE | Y9: FALSE | Z9: 483 | AA9: 43160.272 | AB9: 118.200.5.237 | AC9: 2018 | AD9: YC TANG | AE9: PAMFLEET | AF9: =VLOOKUP(MID(E9,SEARCH("@",E9,1),LEN(E9)-SEARCH("@",E9,1)+1),[2]Sheet1!$D:$F,3,FALSE) -> M0125 | AG9: Director | AH9: yc.tang@pamfleet.com | AI9: +65 6325 0160 | AJ9: Hong Kong | AK9: USD | AM9: 2 | AN9: 6 | AO9: no product | AV9: 0 | BC9: 0 | BJ9: 0 | BQ9: 0 | BX9: 0 | CE9: 0 | CF9: 0 | CG9: 0 | CH9: 0 | CI9: 0 | CJ9: 0 | CK9: 0 | CL9: 0 | CS9: 0 | CZ9: 0 | DG9: 0 | DN9: 0 | DU9: 0 | EB9: 0 | EC9: 0 | ED9: 0 | EE9: 0 | EF9: 0 | EG9: 0 | EH9: 0 | EI9: 0 | EJ9: NO | EK9: NO | EL9: NO | EM9: NO | EN9: NO | EO9: NO | EP9: NO | EQ9: NO | ER9: NO | ES9: NO | ET9: NO | EU9: NO | EV9: NO | EW9: NO | EX9: NO | EY9: NO | EZ9: NO | FA9: NO | FB9: NO | FC9: NO | FD9: NO | FE9: NO | FF9: NO | FG9: NO | FH9: NO | FI9: NO | FJ9: NO | FK9: NO | FL9: NO | FM9: NO | FN9: NO | FO9: NO | FP9: NO | FQ9: NO | FR9: NO | FS9: NO | FZ9: 0 | GG9: 0 | GN9: 0 | GU9: 0 | HB9: 0 | HI9: 0 | HP9: 0 | HX9: 0 | HY9: 0 | HZ9: 0 | IA9: 0 | IB9: 0 | IC9: 0 | ID9: 0 | IE9: 0 | IL9: 0 | IS9: 0 | IZ9: 0 | JG9: 0 | JN9: 0 | JO9: 0 | JP9: 0 | JQ9: 0 | JR9: 0 | JS9: 0 | JT9: 0 | JU9: 0 | KA9: 1 | KB9: 2 | KC9: 1 | KD9: START Asia Pacific: | OG9: START Europe: | SJ9: START North America: | WM9: START Global: | AAP9: START SOUTH America: | AES9: START Africa: | AIV9: =IFERROR(RIGHT(AH9,LEN(AH9)-SEARCH("@",AH9,1)),"") -> pamfleet.com
A10: A1PBK7A | B10: ANREV | C10: Additional Record | E10: Arvydas.Jadevicius@inrev.org | G10: https://secure.surveylab.co.uk/anrev-inrev-ncreif-capital-raising-2018/default.asp?survey=A1PBK7A | H10: asia | I10: 43161.158 | L10: northamerica | M10: 43161.159 | N10: global | O10: 43161.16 | T10: FALSE | U10: TRUE | V10: TRUE | W10: TRUE | X10: FALSE | Y10: FALSE | Z10: 366 | AA10: 43161.157 | AB10: 101.78.165.56 | AC10: 2018 | AD10: Paul Keogh | AE10: Morgan Stanley Real Estate Investing | AF10: =VLOOKUP(MID(E10,SEARCH("@",E10,1),LEN(E10)-SEARCH("@",E10,1)+1),[2]Sheet1!$D:$F,3,FALSE) -> M636 | AG10: Managing Director | AH10: paul.keogh@morganstanley.com | AI10: +65 6834-8388 | AJ10: United States | AK10: USD | AM10: 1 | AP10: 471 | AV10: 471 | BC10: 0 | BD10: 1960.78 | BJ10: 1960.78 | BK10: 2577.36 | BQ10: 2577.36 | BX10: 0 | CE10: 0 | CF10: 5009.14 | CG10: 0 | CH10: 0 | CI10: 0 | CJ10: 0 | CK10: 0 | CL10: 5009.14 | CM10: 1 | CS10: 1 | CZ10: 0 | DA10: 1 | DG10: 1 | DH10: 1 | DN10: 1 | DU10: 0 | EB10: 0 | EC10: 3 | ED10: 0 | EE10: 0 | EF10: 0 | EG10: 0 | EH10: 0 | EI10: 3 | EJ10: YES | EK10: NO | EL10: NO | EM10: NO | EN10: NO | EO10: NO | EP10: NO | EQ10: NO | ER10: NO | ES10: NO | ET10: NO | EU10: NO | EV10: YES | EW10: NO | EX10: NO | EY10: NO | EZ10: NO | FA10: NO | FB10: YES | FC10: NO | FD10: NO | FE10: NO | FF10: NO | FG10: NO | FH10: NO | FI10: NO | FJ10: NO | FK10: NO | FL10: NO | FM10: NO | FN10: NO | FO10: NO | FP10: NO | FQ10: NO | FR10: NO | FS10: NO | FT10: 2108.55 | FZ10: 2108.55 | GA10: 466 | GG10: 466 | GH10: 825 | GN10: 825 | GO10: 519 | GU10: 519 | GV10: 214.11 | HB10: 214.11 | HC10: 522.67 | HI10: 522.67 | HJ10: 88.2 | HP10: 88.2 | HQ10: Corporations, Unions, Taft-Hartley, Trusts | HR10: 265.62 | HX10: 265.62 | HY10: 5009.15 | HZ10: 0 | IA10: 0 | IB10: 0 | IC10: 0 | ID10: 0 | IE10: 5009.15 | IF10: 1251.57 | IL10: 1251.57 | IM10: 2076.8 | IS10: 2076.8 | IT10: 1680.77 | IZ10: 1680.77 | JG10: 0 | JN10: 0 | JO10: 5009.14 | JP10: 0 | JQ10: 0 | JR10: 0 | JS10: 0 | JT10: 0 | JU10: 5009.14 | JX10: 100 | KA10: 3 | KB10: 3 | KC10: 1 | KD10: START Asia Pacific: | KE10: 205.83 | KK10: 205.83 | KL10: 25 | KR10: 25 | KY10: 0 | LF10: 0 | LM10: 0 | LN10: 230.17 | LT10: 230.17 | MA10: 0 | MC10: 10 | MI10: 10 | MJ10: 471 | MK10: 0 | ML10: 0 | MM10: 0 | MN10: 0 | MO10: 0 | MP10: 471 | MQ10: 461 | MW10: 461 | MX10: 10 | ND10: 10 | NK10: 0 | NR10: 0 | NY10: 0 | NZ10: 471 | OA10: 0 | OB10: 0 | OC10: 0 | OD10: 0 | OE10: 0 | OF10: 471 | OG10: START Europe: | SJ10: START North America: | SK10: 1264.41 | SQ10: 1264.41 | SR10: 44 | SX10: 44 | TE10: 0 | TF10: 119 | TL10: 119 | TM10: 214.11 | TS10: 214.11 | TT10: 232.5 | TZ10: 232.5 | UA10: 7.2 | UG10: 7.2 | UI10: 79.56 | UO10: 79.56 | UP10: 1960.78 | UQ10: 0 | UR10: 0 | US10: 0 | UT10: 0 | UU10: 0 | UV10: 1960.78 | UW10: 220 | VC10: 220 | VD10: 256.32 | VJ10: 256.32 | VK10: 1484.46 | VQ10: 1484.46 | VX10: 0 | WE10: 0 | WF10: 1960.78 | WG10: 0 | WH10: 0 | WI10: 0 | WJ10: 0 | WK10: 0 | WL10: 1960.78 | WM10: START Global: | WN10: 638.3 | WT10: 638.3 | WU10: 397 | XA10: 397 | XB10: 825 | XH10: 825 | XI10: 400 | XO10: 400 | XV10: 0 | XW10: 60 | YC10: 60 | YD10: 81 | YJ10: 81 | YL10: 176.06 | YR10: 176.06 | YS10: 2577.36 | YT10: 0 | YU10: 0 | YV10: 0 | YW10: 0 | YX10: 0 | YY10: 2577.36 | YZ10: 1395.8 | ZF10: 1395.8 | ZG10: 985.25 | ZM10: 985.25 | ZN10: 196.31 | ZT10: 196.31 | AAA10: 0 | AAH10: 0 | AAI10: 2577.36 | AAJ10: 0 | AAK10: 0 | AAL10: 0 | AAM10: 0 | AAN10: 0 | AAO10: 2577.36 | AAP10: START SOUTH America: | AES10: START Africa: | AIV10: =IFERROR(RIGHT(AH10,LEN(AH10)-SEARCH("@",AH10,1)),"") -> morganstanley.com
A11: A1PXF1R | B11: ANREV | C11: Chelsfield | E11: wlo@chelsfield.com | G11: https://secure.surveylab.co.uk/anrev-inrev-ncreif-capital-raising-2018/default.asp?survey=A1PXF1R | T11: FALSE | U11: FALSE | V11: FALSE | W11: FALSE | X11: FALSE | Y11: FALSE | Z11: 456 | AA11: 43171.522 | AB11: 218.255.227.142 | AC11: 2018 | AD11: William Lo | AE11: Chelsfield Asia (Hong Kong) Limited | AF11: =VLOOKUP(MID(E11,SEARCH("@",E11,1),LEN(E11)-SEARCH("@",E11,1)+1),[2]Sheet1!$D:$F,3,FALSE) -> M03089 | AG11: Chief Operating Officer | AH11: wlo@chelsfield.com | AI11: +852 3589 5562 | AJ11: United Kingdom | AK11: USD | AM11: 1 | AV11: 0 | BC11: 0 | BJ11: 0 | BQ11: 0 | BX11: 0 | CE11: 0 | CF11: 0 | CG11: 0 | CH11: 0 | CI11: 0 | CJ11: 0 | CK11: 0 | CL11: 0 | CS11: 0 | CZ11: 0 | DG11: 0 | DN11: 0 | DU11: 0 | EB11: 0 | EC11: 0 | ED11: 0 | EE11: 0 | EF11: 0 | EG11: 0 | EH11: 0 | EI11: 0 | EJ11: NO | EK11: NO | EL11: NO | EM11: NO | EN11: NO | EO11: NO | EP11: NO | EQ11: NO | ER11: NO | ES11: NO | ET11: NO | EU11: NO | EV11: NO | EW11: NO | EX11: NO | EY11: NO | EZ11: NO | FA11: NO | FB11: NO | FC11: NO | FD11: NO | FE11: NO | FF11: NO | FG11: NO | FH11: NO | FI11: NO | FJ11: NO | FK11: NO | FL11: NO | FM11: NO | FN11: NO | FO11: NO | FP11: NO | FQ11: NO | FR11: NO | FS11: NO | FZ11: 0 | GG11: 0 | GN11: 0 | GU11: 0 | HB11: 0 | HI11: 0 | HP11: 0 | HX11: 0 | HY11: 0 | HZ11: 0 | IA11: 0 | IB11: 0 | IC11: 0 | ID11: 0 | IE11: 0 | IL11: 0 | IS11: 0 | IZ11: 0 | JG11: 0 | JN11: 0 | JO11: 0 | JP11: 0 | JQ11: 0 | JR11: 0 | JS11: 0 | JT11: 0 | JU11: 0 | KC11: 1 | KD11: START Asia Pacific: | OG11: START Europe: | SJ11: START North America: | WM11: START Global: | AAP11: START SOUTH America: | AES11: START Africa: | AIV11: =IFERROR(RIGHT(AH11,LEN(AH11)-SEARCH("@",AH11,1)),"") -> chelsfield.com
A12: A1QPU4E | B12: ANREV | C12: Mitsui Fudosan Investment Advisors, Inc. | E12: k-hiratani@mfia.co.jp | G12: https://secure.surveylab.co.uk/anrev-inrev-ncreif-capital-raising-2018/default.asp?survey=A1QPU4E | H12: asia | I12: 43152.285 | T12: FALSE | U12: TRUE | V12: FALSE | W12: FALSE | X12: FALSE | Y12: FALSE | Z12: 346 | AA12: 43152.283 | AB12: 101.78.165.56 | AC12: 2018 | AD12: NAKAO IIJIMA | AE12: Mitsui Fudosan Investment Advisors, Inc. | AF12: =VLOOKUP(MID(E12,SEARCH("@",E12,1),LEN(E12)-SEARCH("@",E12,1)+1),[2]Sheet1!$D:$F,3,FALSE) -> M0177 | AG12: General Manager, Research Department | AH12: n-iijima@mfia.co.jp | AI12: 81-3-3246-3332 | AJ12: Japan | AK12: JPY | AM12: 1 | AP12: 2930 | AQ12: 3182 | AR12: 0 | AS12: 0 | AT12: 0 | AU12: 0 | AV12: 6112 | AW12: 0 | AX12: 0 | AY12: 0 | AZ12: 0 | BA12: 0 | BB12: 0 | BC12: 0 | BD12: 0 | BE12: 0 | BF12: 0 | BG12: 0 | BH12: 0 | BI12: 0 | BJ12: 0 | BK12: 0 | BL12: 0 | BM12: 0 | BN12: 0 | BO12: 0 | BP12: 0 | BQ12: 0 | BR12: 0 | BS12: 0 | BT12: 0 | BU12: 0 | BV12: 0 | BW12: 0 | BX12: 0 | BY12: 0 | BZ12: 0 | CA12: 0 | CB12: 0 | CC12: 0 | CD12: 0 | CE12: 0 | CF12: 2930 | CG12: 3182 | CH12: 0 | CI12: 0 | CJ12: 0 | CK12: 0 | CL12: 6112 | CM12: 1 | CN12: 1 | CS12: 2 | CZ12: 0 | DG12: 0 | DN12: 0 | DU12: 0 | EB12: 0 | EC12: 1 | ED12: 1 | EE12: 0 | EF12: 0 | EG12: 0 | EH12: 0 | EI12: 2 | EJ12: YES | EK12: YES | EL12: NO | EM12: NO | EN12: NO | EO12: NO | EP12: NO | EQ12: NO | ER12: NO | ES12: NO | ET12: NO | EU12: NO | EV12: NO | EW12: NO | EX12: NO | EY12: NO | EZ12: NO | FA12: NO | FB12: NO | FC12: NO | FD12: NO | FE12: NO | FF12: NO | FG12: NO | FH12: NO | FI12: NO | FJ12: NO | FK12: NO | FL12: NO | FM12: NO | FN12: NO | FO12: NO | FP12: NO | FQ12: NO | FR12: NO | FS12: NO | FT12: 2930 | FZ12: 2930 | GG12: 0 | GN12: 0 | GU12: 0 | HB12: 0 | HI12: 0 | HP12: 0 | HQ12: Parent company | HS12: 3182 | HX12: 3182 | HY12: 2930 | HZ12: 3182 | IA12: 0 | IB12: 0 | IC12: 0 | ID12: 0 | IE12: 6112 | IF12: 2930 | IG12: 3182 | IL12: 6112 | IS12: 0 | IZ12: 0 | JG12: 0 | JN12: 0 | JO12: 2930 | JP12: 3182 | JQ12: 0 | JR12: 0 | JS12: 0 | JT12: 0 | JU12: 6112 | JX12: 100 | KA12: 1 | KB12: 2 | KC12: 1 | KD12: START Asia Pacific: | KE12: 2930 | KK12: 2930 | KR12: 0 | KY12: 0 | LF12: 0 | LM12: 0 | LT12: 0 | MA12: 0 | MB12: Parent company | MD12: 3182 | MI12: 3182 | MJ12: 2930 | MK12: 3182 | ML12: 0 | MM12: 0 | MN12: 0 | MO12: 0 | MP12: 6112 | MW12: 0 | MX12: 2930 | MY12: 3182 | ND12: 6112 | NK12: 0 | NR12: 0 | NY12: 0 | NZ12: 2930 | OA12: 3182 | OB12: 0 | OC12: 0 | OD12: 0 | OE12: 0 | OF12: 6112 | OG12: START Europe: | SJ12: START North America: | WM12: START Global: | AAP12: START SOUTH America: | AES12: START Africa: | AIV12: =IFERROR(RIGHT(AH12,LEN(AH12)-SEARCH("@",AH12,1)),"") -> mfia.co.jp
A13: A1ZJM9T | B13: ANREV | C13: Aventus | E13: lawrence@aventusproperty.com.au | G13: https://secure.surveylab.co.uk/anrev-inrev-ncreif-capital-raising-2018/default.asp?survey=A1ZJM9T | T13: FALSE | U13: FALSE | V13: FALSE | W13: FALSE | X13: FALSE | Y13: FALSE | Z13: 453 | AA13: 43151.921 | AB13: 61.68.16.22 | AC13: 2018 | AD13: Lawrence Wong | AE13: Aventus | AF13: =VLOOKUP(MID(E13,SEARCH("@",E13,1),LEN(E13)-SEARCH("@",E13,1)+1),[2]Sheet1!$D:$F,3,FALSE) -> N0302 | AG13: CFO | AH13: lawrence@aventusproperty.com.au | AI13: 02 9285 6703 | AJ13: Australia | AK13: AUD | AM13: 2 | AN13: 5 | AV13: 0 | BC13: 0 | BJ13: 0 | BQ13: 0 | BX13: 0 | CE13: 0 | CF13: 0 | CG13: 0 | CH13: 0 | CI13: 0 | CJ13: 0 | CK13: 0 | CL13: 0 | CS13: 0 | CZ13: 0 | DG13: 0 | DN13: 0 | DU13: 0 | EB13: 0 | EC13: 0 | ED13: 0 | EE13: 0 | EF13: 0 | EG13: 0 | EH13: 0 | EI13: 0 | EJ13: NO | EK13: NO | EL13: NO | EM13: NO | EN13: NO | EO13: NO | EP13: NO | EQ13: NO | ER13: NO | ES13: NO | ET13: NO | EU13: NO | EV13: NO | EW13: NO | EX13: NO | EY13: NO | EZ13: NO | FA13: NO | FB13: NO | FC13: NO | FD13: NO | FE13: NO | FF13: NO | FG13: NO | FH13: NO | FI13: NO | FJ13: NO | FK13: NO | FL13: NO | FM13: NO | FN13: NO | FO13: NO | FP13: NO | FQ13: NO | FR13: NO | FS13: NO | FZ13: 0 | GG13: 0 | GN13: 0 | GU13: 0 | HB13: 0 | HI13: 0 | HP13: 0 | HX13: 0 | HY13: 0 | HZ13: 0 | IA13: 0 | IB13: 0 | IC13: 0 | ID13: 0 | IE13: 0 | IL13: 0 | IS13: 0 | IZ13: 0 | JG13: 0 | JN13: 0 | JO13: 0 | JP13: 0 | JQ13: 0 | JR13: 0 | JS13: 0 | JT13: 0 | JU13: 0 | KA13: 2 | KB13: 3 | KC13: 1 | KD13: START Asia Pacific: | OG13: START Europe: | SJ13: START North America: | WM13: START Global: | AAP13: START SOUTH America: | AES13: START Africa: | AIV13: =IFERROR(RIGHT(AH13,LEN(AH13)-SEARCH("@",AH13,1)),"") -> aventusproperty.com.au
A14: A2FUA9N | B14: ANREV | C14: AEP Investment Management | E14: yusof.wahid@aep-im.com | G14: https://secure.surveylab.co.uk/anrev-inrev-ncreif-capital-raising-2018/default.asp?survey=A2FUA9N | H14: asia | I14: 43137.627 | T14: FALSE | U14: TRUE | V14: FALSE | W14: FALSE | X14: FALSE | Y14: FALSE | Z14: 413 | AA14: 43137.361 | AB14: 122.11.137.216 | AC14: 2018 | AD14: Roland Kyle | AE14: AEP Investment Management | AF14: =VLOOKUP(MID(E14,SEARCH("@",E14,1),LEN(E14)-SEARCH("@",E14,1)+1),[2]Sheet1!$D:$F,3,FALSE) -> M0291 | AG14: Senior Principal | AH14: roland.kyle@aep-im.com | AI14: 62260212 | AJ14: Singapore | AK14: USD | AM14: 1 | AP14: 50 | AV14: 50 | BC14: 0 | BJ14: 0 | BQ14: 0 | BX14: 0 | CE14: 0 | CF14: 50 | CG14: 0 | CH14: 0 | CI14: 0 | CJ14: 0 | CK14: 0 | CL14: 50 | CM14: 1 | CS14: 1 | CZ14: 0 | DG14: 0 | DN14: 0 | DU14: 0 | EB14: 0 | EC14: 1 | ED14: 0 | EE14: 0 | EF14: 0 | EG14: 0 | EH14: 0 | EI14: 1 | EJ14: YES | EK14: NO | EL14: NO | EM14: NO | EN14: NO | EO14: NO | EP14: NO | EQ14: NO | ER14: NO | ES14: NO | ET14: NO | EU14: NO | EV14: NO | EW14: NO | EX14: NO | EY14: NO | EZ14: NO | FA14: NO | FB14: NO | FC14: NO | FD14: NO | FE14: NO | FF14: NO | FG14: NO | FH14: NO | FI14: NO | FJ14: NO | FK14: NO | FL14: NO | FM14: NO | FN14: NO | FO14: NO | FP14: NO | FQ14: NO | FR14: NO | FS14: NO | FZ14: 0 | GG14: 0 | GH14: 25 | GN14: 25 | GU14: 0 | HB14: 0 | HI14: 0 | HJ14: 25 | HP14: 25 | HX14: 0 | HY14: 50 | HZ14: 0 | IA14: 0 | IB14: 0 | IC14: 0 | ID14: 0 | IE14: 50 | IF14: 50 | IL14: 50 | IS14: 0 | IZ14: 0 | JG14: 0 | JN14: 0 | JO14: 50 | JP14: 0 | JQ14: 0 | JR14: 0 | JS14: 0 | JT14: 0 | JU14: 50 | JX14: 100 | KA14: 1 | KB14: 3 | KC14: 1 | KD14: START Asia Pacific: | KK14: 0 | KR14: 0 | KS14: 25 | KY14: 25 | LF14: 0 | LM14: 0 | LT14: 0 | LU14: 25 | MA14: 25 | MI14: 0 | MJ14: 50 | MK14: 0 | ML14: 0 | MM14: 0 | MN14: 0 | MO14: 0 | MP14: 50 | MW14: 0 | MX14: 50 | ND14: 50 | NK14: 0 | NR14: 0 | NY14: 0 | NZ14: 50 | OA14: 0 | OB14: 0 | OC14: 0 | OD14: 0 | OE14: 0 | OF14: 50 | OG14: START Europe: | SJ14: START North America: | WM14: START Global: | AAP14: START SOUTH America: | AES14: START Africa: | AIV14: =IFERROR(RIGHT(AH14,LEN(AH14)-SEARCH("@",AH14,1)),"") -> aep-im.com
A15: A2WHW5Y | B15: ANREV | C15: Baring Private Equity Asia Pte Ltd | E15: karenko@bpeasia.com | G15: https://secure.surveylab.co.uk/anrev-inrev-ncreif-capital-raising-2018/default.asp?survey=A2WHW5Y | H15: asia | I15: 43151.354 | T15: FALSE | U15: TRUE | V15: FALSE | W15: FALSE | X15: FALSE | Y15: FALSE | Z15: 411 | AA15: 43151.353 | AB15: 101.78.178.130 | AC15: 2018 | AD15: Tiffany Wang | AE15: Baring Private Equity Asia | AF15: =VLOOKUP(MID(E15,SEARCH("@",E15,1),LEN(E15)-SEARCH("@",E15,1)+1),[2]Sheet1!$D:$F,3,FALSE) -> M0149 | AG15: Corporate Communication Officer | AH15: TiffanyWang@bpeasia.com | AI15: +852 2843 9362 | AJ15: Hong Kong | AK15: USD | AM15: 1 | AP15: 488 | AV15: 488 | BC15: 0 | BJ15: 0 | BQ15: 0 | BX15: 0 | CE15: 0 | CF15: 488 | CG15: 0 | CH15: 0 | CI15: 0 | CJ15: 0 | CK15: 0 | CL15: 488 | CM15: 1 | CS15: 1 | CZ15: 0 | DG15: 0 | DN15: 0 | DU15: 0 | EB15: 0 | EC15: 1 | ED15: 0 | EE15: 0 | EF15: 0 | EG15: 0 | EH15: 0 | EI15: 1 | EJ15: YES | EK15: NO | EL15: NO | EM15: NO | EN15: NO | EO15: NO | EP15: NO | EQ15: NO | ER15: NO | ES15: NO | ET15: NO | EU15: NO | EV15: NO | EW15: NO | EX15: NO | EY15: NO | EZ15: NO | FA15: NO | FB15: NO | FC15: NO | FD15: NO | FE15: NO | FF15: NO | FG15: NO | FH15: NO | FI15: NO | FJ15: NO | FK15: NO | FL15: NO | FM15: NO | FN15: NO | FO15: NO | FP15: NO | FQ15: NO | FR15: NO | FS15: NO | FZ15: 0 | GG15: 0 | GN15: 0 | GU15: 0 | HB15: 0 | HI15: 0 | HP15: 0 | HX15: 0 | HY15: 0 | HZ15: 0 | IA15: 0 | IB15: 0 | IC15: 0 | ID15: 0 | IE15: 0 | IL15: 0 | IS15: 0 | IZ15: 0 | JG15: 0 | JN15: 0 | JO15: 0 | JP15: 0 | JQ15: 0 | JR15: 0 | JS15: 0 | JT15: 0 | JU15: 0 | KA15: 3 | KB15: 3 | KC15: 2 | KD15: START Asia Pacific: | KK15: 0 | KR15: 0 | KY15: 0 | LF15: 0 | LM15: 0 | LT15: 0 | MA15: 0 | MI15: 0 | MJ15: 0 | MK15: 0 | ML15: 0 | MM15: 0 | MN15: 0 | MO15: 0 | MP15: 0 | MW15: 0 | ND15: 0 | NK15: 0 | NR15: 0 | NY15: 0 | NZ15: 0 | OA15: 0 | OB15: 0 | OC15: 0 | OD15: 0 | OE15: 0 | OF15: 0 | OG15: START Europe: | SJ15: START North America: | WM15: START Global: | AAP15: START SOUTH America: | AES15: START Africa: | AIV15: =IFERROR(RIGHT(AH15,LEN(AH15)-SEARCH("@",AH15,1)),"") -> bpeasia.com
A16: A3AAT7R | B16: ANREV | C16: BlackRock | E16: nicholas.dempsey@blackrock.com | G16: https://secure.surveylab.co.uk/anrev-inrev-ncreif-capital-raising-2018/default.asp?survey=A3AAT7R | H16: asia | I16: 43153.722 | J16: europe | K16: 43153.722 | L16: northamerica | M16: 43153.722 | T16: TRUE | U16: TRUE | V16: TRUE | W16: FALSE | X16: FALSE | Y16: FALSE | Z16: 328 | AA16: 43153.722 | AB16: 69.52.69.38 | AC16: 2018 | AD16: Lauren Anderson | AE16: BlackRock | AF16: =VLOOKUP(MID(E16,SEARCH("@",E16,1),LEN(E16)-SEARCH("@",E16,1)+1),[2]Sheet1!$D:$F,3,FALSE) -> M181 | AG16: Analyst | AH16: lauren.anderson@blackrock.com | AI16: 2077431621 | AJ16: United States | AK16: USD | AM16: 1 | AP16: 251 | AQ16: 62 | AV16: 313 | AW16: 954 | BB16: 100 | BC16: 1054 | BD16: 224 | BE16: 650 | BI16: 753 | BJ16: 1627 | BQ16: 0 | BX16: 0 | CE16: 0 | CF16: 1429 | CG16: 712 | CH16: 0 | CI16: 0 | CJ16: 0 | CK16: 853 | CL16: 2994 | CM16: 1 | CN16: 1 | CS16: 2 | CT16: 2 | CY16: 1 | CZ16: 3 | DA16: 1 | DB16: 7 | DF16: 2 | DG16: 10 | DN16: 0 | DU16: 0 | EB16: 0 | EC16: 4 | ED16: 8 | EE16: 0 | EF16: 0 | EG16: 0 | EH16: 3 | EI16: 15 | EJ16: YES | EK16: YES | EL16: NO | EM16: NO | EN16: NO | EO16: NO | EP16: YES | EQ16: NO | ER16: NO | ES16: NO | ET16: NO | EU16: YES | EV16: YES | EW16: YES | EX16: NO | EY16: NO | EZ16: NO | FA16: YES | FB16: NO | FC16: NO | FD16: NO | FE16: NO | FF16: NO | FG16: NO | FH16: NO | FI16: NO | FJ16: NO | FK16: NO | FL16: NO | FM16: NO | FN16: NO | FO16: NO | FP16: NO | FQ16: NO | FR16: NO | FS16: NO | FT16: 629 | FU16: 712 | FY16: 391 | FZ16: 1732 | GA16: 180 | GF16: 104 | GG16: 284 | GH16: 114 | GM16: 200 | GN16: 314 | GU16: 0 | HA16: 1 | HB16: 1 | HC16: 4 | HI16: 4 | HJ16: 63 | HO16: 57 | HP16: 120 | HQ16: Institutional | HR16: 439 | HW16: 100 | HX16: 539 | HY16: 1429 | HZ16: 712 | IA16: 0 | IB16: 0 | IC16: 0 | ID16: 853 | IE16: 2994 | IF16: 206 | IG16: 62 | IK16: 375 | IL16: 643 | IM16: 876 | IR16: 160 | IS16: 1036 | IT16: 347 | IU16: 650 | IY16: 318 | IZ16: 1315 | JG16: 0 | JN16: 0 | JO16: 1429 | JP16: 712 | JQ16: 0 | JR16: 0 | JS16: 0 | JT16: 853 | JU16: 2994 | JX16: 100 | KA16: 1 | KB16: 3 | KC16: 1 | KD16: START Asia Pacific: | KE16: 83 | KF16: 62 | KK16: 145 | KL16: 159 | KR16: 159 | KY16: 0 | LF16: 0 | LM16: 0 | LT16: 0 | MA16: 0 | MB16: Institutional | MC16: 9 | MI16: 9 | MJ16: 251 | MK16: 62 | ML16: 0 | MM16: 0 | MN16: 0 | MO16: 0 | MP16: 313 | MQ16: 120 | MR16: 62 | MW16: 182 | MX16: 69 | ND16: 69 | NE16: 62 | NK16: 62 | NR16: 0 | NY16: 0 | NZ16: 251 | OA16: 62 | OB16: 0 | OC16: 0 | OD16: 0 | OE16: 0 | OF16: 313 | OG16: START Europe: | OH16: 529 | ON16: 529 | OO16: 21 | OU16: 21 | OV16: 114 | PB16: 114 | PI16: 0 | PP16: 0 | PW16: 0 | PX16: 60 | QD16: 60 | QE16: Institutional | QF16: 230 | QK16: 100 | QL16: 330 | QM16: 954 | QN16: 0 | QO16: 0 | QP16: 0 | QQ16: 0 | QR16: 100 | QS16: 1054 | QT16: 756 | QY16: 100 | QZ16: 856 | RA16: 137 | RG16: 137 | RH16: 61 | RN16: 61 | RU16: 0 | SB16: 0 | SC16: 954 | SD16: 0 | SE16: 0 | SF16: 0 | SG16: 0 | SH16: 100 | SI16: 1054 | SJ16: START North America: | SK16: 17 | SL16: 650 | SP16: 391 | SQ16: 1058 | SW16: 104 | SX16: 104 | TD16: 200 | TE16: 200 | TL16: 0 | TR16: 1 | TS16: 1 | TT16: 4 | TZ16: 4 | UA16: 3 | UF16: 57 | UG16: 60 | UH16: Institutional | UI16: 200 | UO16: 200 | UP16: 224 | UQ16: 650 | UR16: 0 | US16: 0 | UT16: 0 | UU16: 753 | UV16: 1627 | VB16: 60 | VC16: 60 | VI16: 375 | VJ16: 375 | VK16: 224 | VL16: 650 | VP16: 318 | VQ16: 1192 | VX16: 0 | WE16: 0 | WF16: 224 | WG16: 650 | WH16: 0 | WI16: 0 | WJ16: 0 | WK16: 753 | WL16: 1627 | WM16: START Global: | AAP16: START SOUTH America: | AES16: START Africa: | AIV16: =IFERROR(RIGHT(AH16,LEN(AH16)-SEARCH("@",AH16,1)),"") -> blackrock.com
A17: A3DNZ5Q | B17: ANREV | C17: ESR Singapore Pte. Ltd. | E17: wlim@sg.esr.com | G17: https://secure.surveylab.co.uk/anrev-inrev-ncreif-capital-raising-2018/default.asp?survey=A3DNZ5Q | H17: asia | I17: 43136.33 | T17: FALSE | U17: TRUE | V17: FALSE | W17: FALSE | X17: FALSE | Y17: FALSE | Z17: 388 | AA17: 43136.329 | AB17: 58.185.53.226 | AC17: 2018 | AD17: LIM WEI HUANG | AE17: ESR Singapore Pte Ltd | AF17: =VLOOKUP(MID(E17,SEARCH("@",E17,1),LEN(E17)-SEARCH("@",E17,1)+1),[2]Sheet1!$D:$F,3,FALSE) -> M0231 | AG17: Senior Corporate Controller | AH17: wlim@sg.esr.com | AI17: 65-6850 0449 | AJ17: Singapore | AK17: USD | AM17: 1 | AP17: 110 | AV17: 110 | BC17: 0 | BJ17: 0 | BQ17: 0 | BX17: 0 | CE17: 0 | CF17: 110 | CG17: 0 | CH17: 0 | CI17: 0 | CJ17: 0 | CK17: 0 | CL17: 110 | CM17: 1 | CS17: 1 | CZ17: 0 | DG17: 0 | DN17: 0 | DU17: 0 | EB17: 0 | EC17: 1 | ED17: 0 | EE17: 0 | EF17: 0 | EG17: 0 | EH17: 0 | EI17: 1 | EJ17: YES | EK17: NO | EL17: NO | EM17: NO | EN17: NO | EO17: NO | EP17: NO | EQ17: NO | ER17: NO | ES17: NO | ET17: NO | EU17: NO | EV17: NO | EW17: NO | EX17: NO | EY17: NO | EZ17: NO | FA17: NO | FB17: NO | FC17: NO | FD17: NO | FE17: NO | FF17: NO | FG17: NO | FH17: NO | FI17: NO | FJ17: NO | FK17: NO | FL17: NO | FM17: NO | FN17: NO | FO17: NO | FP17: NO | FQ17: NO | FR17: NO | FS17: NO | FZ17: 0 | GG17: 0 | GN17: 0 | GU17: 0 | HB17: 0 | HC17: 110 | HI17: 110 | HP17: 0 | HX17: 0 | HY17: 110 | HZ17: 0 | IA17: 0 | IB17: 0 | IC17: 0 | ID17: 0 | IE17: 110 | IL17: 0 | IM17: 100 | IS17: 100 | IT17: 10 | IZ17: 10 | JG17: 0 | JN17: 0 | JO17: 110 | JP17: 0 | JQ17: 0 | JR17: 0 | JS17: 0 | JT17: 0 | JU17: 110 | JX17: 100 | KA17: 1 | KB17: 3 | KC17: 2 | KD17: START Asia Pacific: | KK17: 0 | KR17: 0 | KY17: 0 | LF17: 0 | LM17: 0 | LN17: 110 | LT17: 110 | MA17: 0 | MI17: 0 | MJ17: 110 | MK17: 0 | ML17: 0 | MM17: 0 | MN17: 0 | MO17: 0 | MP17: 110 | MQ17: 100 | MW17: 100 | ND17: 0 | NE17: 10 | NK17: 10 | NR17: 0 | NY17: 0 | NZ17: 110 | OA17: 0 | OB17: 0 | OC17: 0 | OD17: 0 | OE17: 0 | OF17: 110 | OG17: START Europe: | SJ17: START North America: | WM17: START Global: | AAP17: START SOUTH America: | AES17: START Africa: | AIV17: =IFERROR(RIGHT(AH17,LEN(AH17)-SEARCH("@",AH17,1)),"") -> sg.esr.com
A18: A3WFZ9X | B18: ANREV | C18: The Blackstone Group L.P. | E18: Jenner.Currier@blackstone.com | G18: https://secure.surveylab.co.uk/anrev-inrev-ncreif-capital-raising-2018/default.asp?survey=A3WFZ9X | T18: TRUE | U18: TRUE | V18: TRUE | W18: TRUE | X18: FALSE | Y18: FALSE | Z18: 308 | AA18: 43166.363 | AB18: 67.202.213.1 | AC18: 2018 | AD18: Jenner Currier | AE18: The Blackstone Group L.P. | AF18: =VLOOKUP(MID(E18,SEARCH("@",E18,1),LEN(E18)-SEARCH("@",E18,1)+1),[2]Sheet1!$D:$F,3,FALSE) -> M178 | AG18: Analyst | AH18: jenner.currier@blackstone.com | AI18: +1 (212) 390-2691 | AJ18: United States | AK18: USD | AM18: 1 | AP18: 5873 | AQ18: 0 | AR18: 0 | AS18: 0 | AT18: 0 | AU18: 0 | AV18: 5873 | AW18: 2293 | AX18: 5961 | AY18: 0 | AZ18: 0 | BA18: 0 | BB18: 0 | BC18: 8254 | BD18: 3409 | BE18: 51 | BF18: 0 | BG18: 0 | BH18: 0 | BI18: 0 | BJ18: 3460 | BK18: 197 | BL18: 559 | BM18: 0 | BN18: 0 | BO18: 0 | BP18: 1929 | BQ18: 2685 | BX18: 0 | CE18: 0 | CF18: 11772 | CG18: 6571 | CH18: 0 | CI18: 0 | CJ18: 0 | CK18: 1929 | CL18: 20272 | CM18: 1 | CS18: 1 | CT18: 2 | CU18: 1 | CZ18: 3 | DA18: 2 | DB18: 1 | DG18: 3 | DH18: 1 | DI18: 2 | DM18: 9 | DN18: 12 | DU18: 0 | EB18: 0 | EC18: 6 | ED18: 4 | EE18: 0 | EF18: 0 | EG18: 0 | EH18: 9 | EI18: 19 | EJ18: YES | EK18: NO | EL18: NO | EM18: NO | EN18: NO | EO18: NO | EP18: YES | EQ18: YES | ER18: NO | ES18: NO | ET18: NO | EU18: NO | EV18: YES | EW18: YES | EX18: NO | EY18: NO | EZ18: NO | FA18: NO | FB18: YES | FC18: YES | FD18: NO | FE18: NO | FF18: NO | FG18: YES | FH18: NO | FI18: NO | FJ18: NO | FK18: NO | FL18: NO | FM18: NO | FN18: NO | FO18: NO | FP18: NO | FQ18: NO | FR18: NO | FS18: NO | FZ18: 0 | GG18: 0 | GN18: 0 | GU18: 0 | HB18: 0 | HI18: 0 | HP18: 0 | HX18: 0 | HY18: 0 | HZ18: 0 | IA18: 0 | IB18: 0 | IC18: 0 | ID18: 0 | IE18: 0 | IL18: 0 | IS18: 0 | IZ18: 0 | JG18: 0 | JN18: 0 | JO18: 0 | JP18: 0 | JQ18: 0 | JR18: 0 | JS18: 0 | JT18: 0 | JU18: 0 | KC18: 1 | KD18: START Asia Pacific: | OG18: START Europe: | SJ18: START North America: | WM18: START Global: | AAP18: START SOUTH America: | AES18: START Africa: | AIV18: =IFERROR(RIGHT(AH18,LEN(AH18)-SEARCH("@",AH18,1)),"") -> blackstone.com
